Workbook

Sheet Checklist madiba
B3: CHECKLIST PREPARATION PRODUCTION MADIBA | G3: Date:
C4: WTP | D4: Water Treatment Plant | G4: Heure début:
E6: FAIT? | G6: Heure fin :
B7: N° | C7: DESCRIPTION DES TACHES | D7: Durée | E7: OUI | F7: NON | G7: REMARQUES
B8: 1 | C8: Vérifier le taux du Mn à UFout et dans le Permeate tank
B9: =+B8+1 -> 2 | C9: Vérifier le fonctionnement de la pompe NaOH et Purger le circuit
B10: =B9+1 -> 3 | C10: Vérifier l'arriver du CO2 et purger le circuit
B11: =B10+1 -> 4 | C11: Vérifier le fonctionnement de la pompe lime water et purger le circuit
B12: =B11+1 -> 5 | C12: Nettoyer la lamper UV
B13: =B12+1 -> 6 | C13: Contrôler la les paramètres du lime water dans le tank
B14: =B13+1 -> 7 | C14: Vérifier le stock et l'état des réactifs pour contrôles physicochimiques
B15: =B14+1 -> 8 | C15: Purger la ligne de transfert d'eau madiba
B16: =B15+1 -> 9 | C16: Etalonner les pH-mètres ( EUWA et Labo) avec les mêmes solutions tampons
B17: =B16+1 -> 10 | C17: Vérifier les ecarts entre les 03 pH-mètres
B18: =B17+1 -> 11 | C18: Consigner la valeur du pH à considèrer en ligne
B19: =B18+1 -> 12 | C19: Vérifier le taux du ClO2 avant et après UV
B20: =B19+1 -> 13 | C20: Contrôler le taux de O3 dans l'eau
B21: =B20+1 -> 14 | C21: Vérifier le débit de transfert
... B26: =B25+1 -> 19 | C26: Deposer un échantillon au labo et communiquer l'heure du dépôt dans le forum Whatsapp
B27: =B26+1 -> 20
B28: Commentaire | D28: Nom et Visa Intervenants | G28: Nom et Visa Responsables

Sheet Checklist prise de Service
B3: Checklist prise de Service
C4: Date: | D4: Water Treatment Plant | G4: 06h-14h | H4: 14h-22h | L4: 22h-06
E6: FAIT? | G6: Heure fin : | I6: FAIT? | K6: Heure fin : | M6: FAIT? | O6: Heure fin :
B7: N° | C7: DESCRIPTION DES TACHES | D7: Durée | E7: OUI | F7: NON | G7: REMARQUES | H7: Durée | I7: OUI | J7: NON | K7: REMARQUES | L7: Durée | M7: OUI | N7: NON | O7: REMARQUES
B8: 1 | C8: Vérifier la mise en service de UF
B9: =+B8+1 -> 2 | C9: Vérifier la mise en service de RO
B10: =B9+1 -> 3 | C10: Vérifier la mise en service d'ELIWA
B11: =B10+1 -> 4 | C11: Vérifier les paramètres de remplissage des tanks (Serv, Permeate, Lime water, Rocleaning, Lime milk)
B12: =B11+1 -> 5 | C12: Vérifier les niveaux des tanks ( KMnO4,Epi Guard, H2SO4, HCl, NaOH, NaOCl, ClO2)
B13: =B12+1 -> 6 | C13: Vérifier la disponibilité des Matières Premières ( Ca(OH)2, Acide citrique, KMnO4)
B14: =B13+1 -> 7 | C14: Vérifier le fonctionnement des pompes doseuses
B15: =B14+1 -> 8 | C15: Vérifier la disponibilité des fiches de suivis productions WTP
B16: =B15+1 -> 9 | C16: Vérifier la disponibilité des réactifs et kits pour contrôles physicochimiques
B17: =B16+1 -> 10 | C17: Effectuer la lectures des rapports précedents
B18: =B17+1 -> 11 | C18: Vérifier le remplissage des fiches de suivis production du quart précedent
B19: =B18+1 -> 12 | C19: Vérifier l'envoi éffective des rapport via mail
B20: =B19+1 -> 13 | C20: Vérifier la mise à jour du tableau 5S
B21: =B20+1 -> 14 | C21: Vérifier l'état des forages ( cages de protection, proprété, accès...)
B22: Commentaire | D22: Nom et Visa Intervenants | G22: Nom et Visa Responsables | H22: Nom et Visa Intervenants | K22: Nom et Visa Responsables | L22: Nom et Visa Intervenants | O22: Nom et Visa Responsables

Sheet Checklist CIP UF
B3: CHECKLIST RECIRCULATION COMPLETE UF | G3: Date:
C4: WTP | D4: Water Treatment Plant | G4: Heure début:
E6: FAIT? | G6: Heure fin :
B7: N° | C7: DESCRIPTION DES TACHES | D7: Durée | E7: OUI | F7: NON | G7: REMARQUES
B8: 1 | C8: Arrêter l'unité UF et RO (MODE OFF°)
B9: 2 | C9: Lancer le CC auto à la Soude (10min x 02)
B10: 3 | C10: Mettre le RO_Cleaning Tank à niveau (70 à 85%) et Lancer l'agitateur
B11: 4 | C11: Ouvrir la vanne manuelle de purge UF
B12: 5 | C12: Préparer une solution d'acide (25Kg d'acide citrique + 50 L de H2SO4)
B13: 6 | C13: Fermer toutes les vannes manuelles avant et après les boosters pumps
B14: 7 | C14: Mettre les vannes pneumatiques UF et RO en mode Manuel
B15: 8 | C15: Ouvrir les les vannes pneumatiques RO01Y05 et HE01Y03
B16: 9 | C16: Ouvrir la vanne manuelle de recirculation UF ( au dessus de RO) et fermer la vanne manuelle ROint
B17: 10 | C17: Fermer la vanne de purge UF01H01
B18: 11 | C18: Vérifier le pH de la solution acide [1,0-1,5]
B19: 12 | C19: Ouvrir la vanne pneumatique UF01Y01 et la vanne manuelle basse pour recirculation UF
... B34: 27 | C34: Remettre toutes les vannes en postion de filtration normale, prendre l'index du compteur UF int revenir au mode automatiques à UF et RO et lancer la filtration
B35: Commentaire | D35: Nom et Visa Intervenants | G35: Nom et Visa Responsables

Sheet UF_HEB
B3: CHECKLIST MECANIQUE | G3: Date:
C4: ULTRA FILTRATION | D4: Water Treatment Plant | G4: =+'Line & frequency'!C2 -> HEBDOMADAIRE
E6: FAIT?
B7: N° | C7: DESCRIPTION DES TACHES | D7: Durée | E7: OUI | F7: NON | G7: REMARQUES (MATERIEL + PIECES)
B8: 1 | C8: Vérifier la vanne d'aération d'air
B9: 2 | C9: Contrôler les fuites sur les flexibles d'air
B10: 3 | C10: Nettoyager chimique par recircultion
B11: 4
B12: 5
B13: 6
B14: Commentaire | D14: Nom et Visa Intervenants | G14: Nom et Visa Responsables

Sheet RO_HEB
B3: CHECKLIST MECANIQUE | G3: Date:
C4: OSMOSE INVERSE | D4: Water Treatment Plant | G4: =+'Line & frequency'!C2 -> HEBDOMADAIRE
E6: FAIT?
B7: N° | C7: DESCRIPTION DES TACHES | D7: Durée | E7: OUI | F7: NON | G7: REMARQUES (MATERIEL + PIECES)
B8: 1 | C8: Vérifier la vanne d'aération d'air
B9: =+B8+1 -> 2 | C9: Vérifier le fonctionnement de l'agitateur du ROcleaning tank
B10: =+B9+1 -> 3 | C10: Inspecter les bruits anormales
B11: =B10+1 -> 4 | C11: Vérifier les éventuelles bruits
B12: =B11+1 -> 5 | C12: Nettoyager chimique
B13: =B12+1 -> 6 | C13: Contrôler des fuites sur les flexibles d'air
B14: =B13+1 -> 7
B15: =B14+1 -> 8
B16: =B15+1 -> 9
B17: =B16+1 -> 10
B18: Commentaire | D18: Nom et Visa Intervenants | G18: Nom et Visa Responsables

Sheet Eliwa_HEB
B3: CHECKLIST MECANIQUE | G3: Date:
C4: ELIWA | D4: Water Treatment Plant | G4: =+'Line & frequency'!C2 -> HEBDOMADAIRE
E6: FAIT?
B7: N° | C7: DESCRIPTION DES TACHES | D7: Durée | E7: OUI | F7: NON | G7: REMARQUES (MATERIEL + PIECES)
B8: 1 | C8: Contrôler les fuites sur les flexibles d'air
B9: =B8+1 -> 2 | C9: Vérifier le fonctionnement des pompes
B10: =+B9+1 -> 3 | C10: Nettoyer et étalonner l'ectrode de pH
B11: =+B10+1 -> 4 | C11: Vérifier le fonctionnement de l'agitateur du Lime milk tank
B12: =+B11+1 -> 5
B13: =+B12+1 -> 6
B14: =+B13+1 -> 7
B15: Commentaire | D15: Nom et Visa Intervenants | G15: Nom et Visa Responsables

Sheet WTP_HEB
B3: CHECKLIST MECANIQUE | G3: Date:
C4: WTP | D4: Water Treatment Plant | G4: =+'Line & frequency'!C2 -> HEBDOMADAIRE
E6: FAIT?
B7: N° | C7: DESCRIPTION DES TACHES | D7: Durée | E7: OUI | F7: NON | G7: REMARQUES (MATERIEL + PIECES)
B8: 1 | C8: Nettoyer et étalonner les électrodes de pH et ClO2
B9: 2 | C9: Nettoyages des armoires de protection pompes doseuses
B10: 3 | C10: Contrôle du fonctionnement des pompes doseuses
B11: 4 | C11: vérification des fuites sur les flexibles des produits chimiques
B12: 5 | C12: Vérification des fuites sur les flexibles d'air
B13: 6 | C13: Vérification des débimètres (salle de transfert)
B14: 7 | C14: Vérification du fonctionnement des pompes (salle de transfert)
B15: 8 | C15: Vérification du fonctionnement des Unité d'UV
B16: =B15+1 -> 9
B17: =B16+1 -> 10
B18: =B17+1 -> 11
B19: =B18+1 -> 12
B20: Commentaire | D20: Nom et Visa Intervenants | G20: Nom et Visa Responsables

Sheet UF_MENS
B3: CHECKLIST MECANIQUE | G3: Date:
C4: ULTRA FILTRATION | D4: Water Treatment Plant | G4: MENSUELLE
E5: FAIT?
B6: N° | C6: DESCRIPTION DES TACHES | D6: Durée | E6: OUI | F6: NON | G6: REMARQUES (MATERIEL + PIECES)
B7: 1 | C7: Vérifier les vannes manuelles
B8: =B7+1 -> 2 | C8: Vérifier les vannes pneumatiques
B9: =+B8+1 -> 3 | C9: Serrer les couvercles des modules de membranes
B10: =B9+1 -> 4 | C10: Vérifier le bon fonctionnement des transmetteurs de pression
B11: =+B10+1 -> 5 | C11: Contrôler les raccords d'injection des produits
B12: =B11+1 -> 6 | C12: Contrôler les distributeurs d'airs
B13: Commentaire | D13: Nom et Visa Intervenants | G13: Nom et Visa Responsables

Sheet RO_MENS
B3: CHECKLIST MECANIQUE | G3: Date:
C4: OSMOSE INVERSE | D4: Water Treatment Plant | G4: MENSUELLE
E6: FAIT?
B7: N° | C7: DESCRIPTION DES TACHES | D7: Durée | E7: OUI | F7: NON | G7: REMARQUES (MATERIEL + PIECES)
B8: 1 | C8: Vérifier les vannes pneumatiques
B9: =B8+1 -> 2 | C9: Vérifier les vannes manuelles
B10: =+B9+1 -> 3 | C10: Vérifier les vannes de régulations
B11: =+B10+1 -> 4 | C11: Serrer les couvercles des modules à membranes
B12: =+B11+1 -> 5 | C12: Contrôler le fonctionnement des manomètres
B13: =+B12+1 -> 6 | C13: Vérifier le fonctionnement des transmetteurs de pression
B14: =+B13+1 -> 7 | C14: Contrôler les distributeurs d'air
B15: Commentaire | D15: Nom et Visa Intervenants | G15: Nom et Visa Responsables

Sheet ELIWA_MENS
B3: CHECKLIST MECANIQUE | G3: Date:
C4: ELIWA | D4: Water Treatment Plant | G4: MENSUELLE
E6: FAIT?
B7: N° | C7: DESCRIPTION DES TACHES | D7: Durée | E7: OUI | F7: NON | G7: REMARQUES (MATERIEL + PIECES)
B8: 1 | C8: Contrôler les distributeurs d'air
B9: 2 | C9: contrôler les vannes pneumatiques
B10: 3 | C10: Contrôler les vannes manuelles
B11: 4 | C11: vérifier les transmetteurs de pression
B12: 5 | C12: Vérifier le fonctionnement de la vanne de régulation d'eau
B13: 6 | C13: Vérifier et nettoyer le transmetteur de niveau lime milk tank
B14: 7 | C14: nettoyer le lime milk tank
B15: Commentaire | D15: Nom et Visa Intervenants | G15: Nom et Visa Responsables

Sheet WP_MENS
B3: CHECKLIST MECANIQUE | G3: Date:
C4: WTP | D4: Water Treatment Plant | G4: MENSUELLE
E6: FAIT?
B7: N° | C7: DESCRIPTION DES TACHES | D7: Durée | E7: OUI | F7: NON | G7: REMARQUES (MATERIEL + PIECES)
B8: 1 | C8: Vérifier le fonctionnement des vannes pneumatiques (BackWash)
B9: =+B8+1 -> 2 | C9: Vérifier les raccords d'injections (BackWash)
B10: =B9+1 -> 3 | C10: Vérifier les clapet-antiretour (BackWash)
B11: =+B10+1 -> 4 | C11: Contrôler le fonctionnement de l'élecltrovanne (BackWash)
B12: =B11+1 -> 5 | C12: Vérifier le fonctionnement des vannes manuelles (BackWash)
B13: =+B12+1 -> 6 | C13: Contrôler les manomètre (salle transfert)
B14: =B13+1 -> 7 | C14: contrôler le fonctionnement des pompes (Salles transfert)
B15: 8 | C15: Graisser les pompes
B16: =+B15+1 -> 9 | C16: Contrôler les transmetteurs de pression (salle de transfert)
B17: 10 | C17: Contrôler les vannes vannes manuelles(salle de transfert)
B18: =+B17+1 -> 11 | C18: Contrôler les vannes pneumatiques (salle de transfert)
B19: =B18+1 -> 12 | C19: Vérifier les vannes de régulation CO2
B20: 13 | C20: Contrôler les distributeurs d'air (salle de transfert)
B21: 14 | C21: Vérifier le fonctionnement de l'ozoneur
B22: 15 | C22: Etalonner des électrode de mesures d'ozone
B23: 16 | C23: vérifier le fonctionnement du générateur du ClO2
B24: 17 | C24: Vérifier le fonctionnement des commutateurs de niveau
B25: =+B24+1 -> 18 | C25: Vérifier le fonctionnement du HMI
B26: 19 | C26: Inspecter les fuites d'eau dans l'usine
B27: Commentaire | D27: Nom et Visa Intervenants | G27: Nom et Visa Responsables

Sheet UF_TRIM
B3: CHECKLIST MECANIQUE | G3: Date:
C4: ULTRA FILTRATION | D4: Water Treatment Plant | G4: TRIMESTRIELLE
E6: FAIT?
B7: N° | C7: DESCRIPTION DES TACHES | D7: Durée | E7: OUI | F7: NON | G7: REMARQUES (MATERIEL + PIECES)
B8: 1 | C8: Nettoyer et calibrer l'électrode de turbidité
B9: =B8+1 -> 2 | C9: Nettoyer le fine filter
B10: =+B9+1 -> 3 | C10: Nettoyer le melangeur statique
B11: =B10+1 -> 4 | C11: Vérifier le fonctionnement du débimètre
B12: Commentaire | D12: Nom et Visa Intervenants | G12: Nom et Visa Responsables

Sheet RO_TRIM
B3: CHECKLIST MECANIQUE | G3: Date:
C4: OSMOSE INVERSE | D4: Water Treatment Plant | G4: TRIMESTRIELLE
E6: FAIT?
B7: N° | C7: DESCRIPTION DES TACHES | D7: Durée | E7: OUI | F7: NON | G7: REMARQUES (MATERIEL + PIECES)
B8: 1 | C8: Nettoyer et calibrer les électrodes de conductivité
B9: 2 | C9: Nettoyer le melengeur statique
B10: 3 | C10: Vérifier le fonctionnement des débimètres
B11: Commentaire | D11: Nom et Visa Intervenants | G11: Nom et Visa Responsables

Sheet ELIWA_TRIM
B3: CHECKLIST MECANIQUE/ ELECTRIQUE | G3: Date:
C4: ELIWA | D4: Water Treatment Plant | G4: TRIMESTRIELLE
E5: FAIT?
B6: N° | C6: DESCRIPTION DES TACHES | D6: Durée | E6: OUI | F6: NON | G6: REMARQUES (MATERIEL + PIECES)
B7: 1 | C7: Vérifier le fonctionnement des débimètres
B8: =B7+1 -> 2 | C8: Nettoyer et étalonner l'électrode de conductivité
B9: =+B8+1 -> 3 | C9: Nettoyer et calibrer l'élelctrode de turbidité
B10: Commentaire | D10: Nom et Visa Intervenants | G10: Nom et Visa Responsables

Sheet WP_TRIM
B3: CHECKLIST MECANIQUE / ELECTRIQUE | G3: Date:
C4: WTP | D4: Water Treatment Plant | G4: TRIMESTRIELLE
E5: FAIT?
B6: N° | C6: DESCRIPTION DES TACHES | D6: Durée | E6: OUI | F6: NON | G6: REMARQUES (MATERIEL + PIECES)
B7: 1 | C7: Vérifier le fonctionnement du débimètre (Back Wash)
B8: =B7+1 -> 2 | C8: Nettoyer et calibrer les éléctrodes de conductivité BW et DW
B9: =+B8+1 -> 3 | C9: Vérifier leses transmetteurs de niveau des tanks de conservation
B10: 4 | C10: Nettoyer les melengeurs statiques
B11: 5 | C11: vérifier les clapets anti-retour(salle de transfert)
B12: 6 | C12: Nettoyer le filtre Raw water
B13: 7 | C13: Inspecter et nettoyer le buffert tank
B14: 8 | C14: tester les convertiseurs de fréquences
B15: 9 | C15: Contrôler les débimètres mécaniques
B16: 10 | C16: Inspecter les pièces critiques
B17: =B16+1 -> 11 | C17: Vérifier le fonctionnement du générateur d'OZONE
B18: Commentaire | D18: Nom et Visa Intervenants | G18: Nom et Visa Responsables

Sheet UF_AN
B3: CHECKLIST MECANIQUE | G3: Date:
C4: ULTRA FILTRATION | D4: Water Treatment Plant | G4: ANNUELLE
E5: FAIT?
B6: N° | C6: DESCRIPTION DES TACHES | D6: Durée | E6: OUI | F6: NON | G6: REMARQUES (MATERIEL + PIECES)
B7: 1 | C7: Test d'intégrité des membranes
B8: 2
B9: Commentaire | D9: Nom et Visa Intervenants | G9: Nom et Visa Responsables

Sheet Cvyr Btles
B3: CHECKLIST MECANIQUE | G3: Date
C4: PALETTISEUR | D4: =+'Line & frequency'!C1 -> CHAINE 4 | G4: =+'Line & frequency'!C2 -> HEBDOMADAIRE
E6: FAIT?
B7: N° | C7: DESCRIPTION DES TACHES | D7: Durée | E7: OUI | F7: NON | G7: REMARQUES (MATERIEL + PIECES)
B8: 1
B9: =B8+1 -> 2
B10: =+B9+1 -> 3
B11: =B10+1 -> 4
B12: =+B11+1 -> 5
B13: =B12+1 -> 6
B14: =+B13+1 -> 7
B15: =B14+1 -> 8
B16: =+B15+1 -> 9
B17: =B16+1 -> 10
B18: =+B17+1 -> 11
B19: =B18+1 -> 12
B20: =+B19+1 -> 13
B21: =B20+1 -> 14
B22: =+B21+1 -> 15
B23: =B22+1 -> 16
B24: =+B23+1 -> 17
B25: =B24+1 -> 18
B26: =+B25+1 -> 19
B27: =B26+1 -> 20
B28: =+B27+1 -> 21
B29: =B28+1 -> 22
B30: =+B29+1 -> 23
B31: =B30+1 -> 24
B32: =+B31+1 -> 25
B33: =B32+1 -> 26
B34: =+B33+1 -> 27
B35: =B34+1 -> 28
B36: =+B35+1 -> 29
B37: =B36+1 -> 30
B38: =+B37+1 -> 31
B39: =B38+1 -> 32
B40: =+B39+1 -> 33
B41: =B40+1 -> 34
B42: =+B41+1 -> 35
B43: =B42+1 -> 36
...

Sheet CC C1
B3: CHECKLIST MECANIQUE | G3: Date
C4: CONVOYEURS CASIERS C1 | D4: =+'Line & frequency'!C1 -> CHAINE 4 | G4: =+'Line & frequency'!C2 -> HEBDOMADAIRE
E6: FAIT?
B7: N° | C7: DESCRIPTION DES TACHES | D7: Durée | E7: OUI | F7: NON | G7: REMARQUES (MATERIEL + PIECES)
B8: 1 | C8: controler l'arret d'huile et le remplacé au besoin. Aucune fuite d'huile n'est acceptable. | D8: 10
B9: =B8+1 -> 2 | C9: controler la fixation du réducteur sur le convoyeur et corriger si necessaire. | D9: 30
B10: =+B9+1 -> 3 | C10: controler l'usure du pignon et le remplacé au besoin. Aucun glissement n'est acceptable. | D10: 30
B11: =B10+1 -> 4 | C11: controler l'alignement et la fixation du pignon de l'axe moteur et remedier au besoin. | D11: 30
B12: =+B11+1 -> 5 | C12: controler l'usure de la roue libre et la remplacée au besoin. Aucun glissement n'est acceptable. | D12: 30
B13: =B12+1 -> 6 | C13: controler l'alignement et la fixation de la roue libre et remedier au problème. | D13: 30
B14: =+B13+1 -> 7 | C14: controler l'usure de la clavette et la rainure et reparer au besoin | D14: 30
B15: =B14+1 -> 8 | C15: controler l'état des glissières et remplacer les au besoin | D15: 25
B16: =+B15+1 -> 9 | C16: controler l'arret d'huile et le remplacé au besoin. Aucune fuite d'huile n'est acceptable. | D16: 10
B17: =B16+1 -> 10 | C17: controler l'usure des roulements et paliers de l'axe moteur et remplacer si necessaire. | D17: 30
B18: =+B17+1 -> 11 | C18: controler l'usure du pignon et le remplacé au besoin. Aucun glissement n'est acceptable. | D18: 30
B19: =B18+1 -> 12 | C19: controler l'alignement et la fixation du pignon de l'axe moteur et remedier au besoin. | D19: 30
B20: =+B19+1 -> 13 | C20: controler l'usure de la clavette et la rainure et reparer au besoin | D20: 30
B21: =B20+1 -> 14 | C21: controler l'usure des roulements et paliers de l'axe moteur et remplacer si necessaire. | D21: 30
B22: =+B21+1 -> 15 | C22: controler l'usure de la roue libre et la remplacée au besoin. Aucun glissement n'est acceptable. | D22: 30
B23: =B22+1 -> 16 | C23: controler l'alignement et la fixation de la roue libre et remedier au problème. | D23: 30
B24: =+B23+1 -> 17 | C24: controler l'usure de la clavette et la rainure et reparer au besoin | D24: 30
B25: =B24+1 -> 18 | C25: controler l'arret d'huile et le remplacé au besoin. Aucune fuite d'huile n'est acceptable. | D25: 10
B26: =+B25+1 -> 19 | C26: controler la fixation du réducteur sur le convoyeur et corriger si necessaire. | D26: 30
B27: =B26+1 -> 20 | C27: controler l'usure des roulements et paliers de l'axe moteur et remplacer si necessaire. | D27: 30
B28: =+B27+1 -> 21 | C28: controler l'usure du pignon et le remplacé au besoin. Aucun glissement n'est acceptable. | D28: 30
B29: =B28+1 -> 22 | C29: controler l'alignement et la fixation du pignon de l'axe moteur et remedier au besoin. | D29: 30
B30: =+B29+1 -> 23 | C30: controler l'usure de la clavette et la rainure et reparer au besoin | D30: 30
B31: =B30+1 -> 24 | C31: controler l'usure des roulements et paliers de l'axe moteur et remplacer si necessaire. | D31: 30
B32: =+B31+1 -> 25 | C32: controler l'usure de la clavette et la rainure et reparer au besoin | D32: 30
B33: =B32+1 -> 26 | C33: controler l'état des glissières et remplacer les au besoin | D33: 25
B34: =+B33+1 -> 27 | C34: controler l'arret d'huile et le remplacé au besoin. Aucune fuite d'huile n'est acceptable. | D34: 10
B35: =B34+1 -> 28 | C35: controler la fixation du réducteur sur le convoyeur et corriger si necessaire. | D35: 30
B36: =+B35+1 -> 29 | C36: controler l'usure des roulements et paliers de l'axe moteur et remplacer si necessaire. | D36: 30
B37: =B36+1 -> 30 | C37: controler l'usure des pignons et les remplacés au besoin. Aucun glissement n'est acceptable. | D37: 30
B38: =+B37+1 -> 31 | C38: controler l'alignement et la fixation du pignon de l'axe moteur et remedier au besoin. | D38: 30
B39: =B38+1 -> 32 | C39: controler l'usure de la clavette et la rainure et reparer au besoin | D39: 30
B40: =+B39+1 -> 33 | C40: controler l'état des glissières et remplacer les au besoin | D40: 25
B41: =B40+1 -> 34 | C41: controler l'usure du tapis et remplacer les portions usées ou maillons cassés | D41: 120
B42: =+B41+1 -> 35 | C42: controler la tenson des tapis et ajuster au besoin | D42: 60
B43: =B42+1 -> 36 | C43: controler l'arret d'huile et le remplacé au besoin. Aucune fuite d'huile n'est acceptable. | D43: 10
...

Sheet CC C2
B3: CHECKLIST MECANIQUE | G3: Date
C4: CONVOYEURS CASIERS C2 | D4: =+'Line & frequency'!C1 -> CHAINE 4 | G4: =+'Line & frequency'!C2 -> HEBDOMADAIRE
E6: FAIT?
B7: N° | C7: DESCRIPTION DES TACHES | D7: Durée | E7: OUI | F7: NON | G7: REMARQUES (MATERIEL + PIECES)
B8: 1 | C8: controler l'arret d'huile et le remplacé au besoin. Aucune fuite d'huile n'est acceptable. | D8: 10
B9: =B8+1 -> 2 | C9: controler la fixation du réducteur sur le convoyeur et corriger si necessaire. | D9: 30
B10: =+B9+1 -> 3 | C10: controler l'usure du pignon et le remplacé au besoin. Aucun glissement n'est acceptable. | D10: 30
B11: =B10+1 -> 4 | C11: controler l'alignement et la fixation du pignon de l'axe moteur et remedier au besoin. | D11: 30
B12: =+B11+1 -> 5 | C12: controler l'usure de la roue libre et la remplacée au besoin. Aucun glissement n'est acceptable. | D12: 30
B13: =B12+1 -> 6 | C13: controler l'alignement et la fixation de la roue libre et remedier au problème. | D13: 30
B14: =+B13+1 -> 7 | C14: controler l'usure de la clavette et la rainure et reparer au besoin | D14: 30
B15: =B14+1 -> 8 | C15: controler l'état des glissières et remplacer les au besoin | D15: 25
B16: =+B15+1 -> 9 | C16: controler l'arret d'huile et le remplacé au besoin. Aucune fuite d'huile n'est acceptable. | D16: 10
B17: =B16+1 -> 10 | C17: controler l'usure des roulements et paliers de l'axe moteur et remplacer si necessaire. | D17: 30
B18: =+B17+1 -> 11 | C18: controler l'usure du pignon et le remplacé au besoin. Aucun glissement n'est acceptable. | D18: 30
B19: =B18+1 -> 12 | C19: controler l'alignement et la fixation du pignon de l'axe moteur et remedier au besoin. | D19: 30
B20: =+B19+1 -> 13 | C20: controler l'usure de la clavette et la rainure et reparer au besoin | D20: 30
B21: =B20+1 -> 14 | C21: controler l'usure des roulements et paliers de l'axe moteur et remplacer si necessaire. | D21: 30
B22: =+B21+1 -> 15 | C22: controler l'usure de la roue libre et la remplacée au besoin. Aucun glissement n'est acceptable. | D22: 30
B23: =B22+1 -> 16 | C23: controler l'alignement et la fixation de la roue libre et remedier au problème. | D23: 30
B24: =+B23+1 -> 17 | C24: controler l'usure de la clavette et la rainure et reparer au besoin | D24: 30
B25: =B24+1 -> 18 | C25: controler l'arret d'huile et le remplacé au besoin. Aucune fuite d'huile n'est acceptable. | D25: 10
B26: =+B25+1 -> 19 | C26: controler la fixation du réducteur sur le convoyeur et corriger si necessaire. | D26: 30
B27: =B26+1 -> 20 | C27: controler l'usure des roulements et paliers de l'axe moteur et remplacer si necessaire. | D27: 30
B28: =+B27+1 -> 21 | C28: controler l'usure des pignons et les remplacés au besoin. Aucun glissement n'est acceptable. | D28: 30
B29: =B28+1 -> 22 | C29: controler l'alignement et la fixation du pignon de l'axe moteur et remedier au besoin. | D29: 30
B30: =+B29+1 -> 23 | C30: controler l'usure de la clavette et la rainure et reparer au besoin | D30: 30
B31: =B30+1 -> 24 | C31: controler l'état des glissières et remplacer les au besoin | D31: 25
B32: =+B31+1 -> 25 | C32: controler l'usure du tapis et remplacer les portions usées ou maillons cassés | D32: 120
B33: =B32+1 -> 26 | C33: controler la tenson des tapis et ajuster au besoin | D33: 60
B34: =+B33+1 -> 27
B35: =B34+1 -> 28
B36: =+B35+1 -> 29
B37: =B36+1 -> 30
B38: =+B37+1 -> 31
B39: =B38+1 -> 32
B40: =+B39+1 -> 33
B41: =B40+1 -> 34
B42: =+B41+1 -> 35
B43: =B42+1 -> 36
...

Sheet CC C3
B3: CHECKLIST MECANIQUE | G3: Date
C4: CONVOYEURS CASIERS C3 | D4: =+'Line & frequency'!C1 -> CHAINE 4 | G4: =+'Line & frequency'!C2 -> HEBDOMADAIRE
E6: FAIT?
B7: N° | C7: DESCRIPTION DES TACHES | D7: Durée | E7: OUI | F7: NON | G7: REMARQUES (MATERIEL + PIECES)
B8: 1 | C8: controler l'arret d'huile et le remplacé au besoin. Aucune fuite d'huile n'est acceptable. | D8: 10
B9: =B8+1 -> 2 | C9: controler la fixation du réducteur sur le convoyeur et corriger si necessaire. | D9: 30
B10: =+B9+1 -> 3 | C10: controler l'usure du pignon et le remplacé au besoin. Aucun glissement n'est acceptable. | D10: 30
B11: =B10+1 -> 4 | C11: controler l'alignement et la fixation du pignon de l'axe moteur et remedier au besoin. | D11: 30
B12: =+B11+1 -> 5 | C12: controler l'usure de la roue libre et la remplacée au besoin. Aucun glissement n'est acceptable. | D12: 30
B13: =B12+1 -> 6 | C13: controler l'alignement et la fixation de la roue libre et remedier au problème. | D13: 30
B14: =+B13+1 -> 7 | C14: controler l'usure de la clavette et la rainure et reparer au besoin | D14: 30
B15: =B14+1 -> 8 | C15: controler l'état des glissières et remplacer les au besoin | D15: 25
B16: =+B15+1 -> 9 | C16: controler l'arret d'huile et le remplacé au besoin. Aucune fuite d'huile n'est acceptable. | D16: 10
B17: =B16+1 -> 10 | C17: controler l'usure des roulements et paliers de l'axe moteur et remplacer si necessaire. | D17: 30
B18: =+B17+1 -> 11 | C18: controler l'usure du pignon et le remplacé au besoin. Aucun glissement n'est acceptable. | D18: 30
B19: =B18+1 -> 12 | C19: controler l'alignement et la fixation du pignon de l'axe moteur et remedier au besoin. | D19: 30
B20: =+B19+1 -> 13 | C20: controler l'usure de la clavette et la rainure et reparer au besoin | D20: 30
B21: =B20+1 -> 14 | C21: controler l'usure des roulements et paliers de l'axe moteur et remplacer si necessaire. | D21: 30
B22: =+B21+1 -> 15 | C22: controler l'usure de la roue libre et la remplacée au besoin. Aucun glissement n'est acceptable. | D22: 30
B23: =B22+1 -> 16 | C23: controler l'alignement et la fixation de la roue libre et remedier au problème. | D23: 30
B24: =+B23+1 -> 17 | C24: controler l'usure de la clavette et la rainure et reparer au besoin | D24: 30
B25: =B24+1 -> 18
B26: =+B25+1 -> 19
B27: =B26+1 -> 20
B28: =+B27+1 -> 21
B29: =B28+1 -> 22
B30: =+B29+1 -> 23
B31: =B30+1 -> 24
B32: =+B31+1 -> 25
B33: Commentaire | D33: Nom et Visa Intervenants | G33: Nom et Visa Responsables

Sheet CC C4
B3: CHECKLIST MECANIQUE | G3: Date
C4: CONVOYEURS CASIERS C4 | D4: =+'Line & frequency'!C1 -> CHAINE 4 | G4: =+'Line & frequency'!C2 -> HEBDOMADAIRE
E6: FAIT?
B7: N° | C7: DESCRIPTION DES TACHES | D7: Durée | E7: OUI | F7: NON | G7: REMARQUES (MATERIEL + PIECES)
B8: 1 | C8: controler l'arret d'huile et le remplacé au besoin. Aucune fuite d'huile n'est acceptable. | D8: 10
B9: =B8+1 -> 2 | C9: controler la fixation du réducteur sur le convoyeur et corriger si necessaire. | D9: 30
B10: =+B9+1 -> 3 | C10: controler l'usure du pignon et le remplacé au besoin. Aucun glissement n'est acceptable. | D10: 30
B11: =B10+1 -> 4 | C11: controler l'alignement et la fixation du pignon de l'axe moteur et remedier au besoin. | D11: 30
B12: =+B11+1 -> 5 | C12: controler l'usure de la roue libre et la remplacée au besoin. Aucun glissement n'est acceptable. | D12: 30
B13: =B12+1 -> 6 | C13: controler l'alignement et la fixation de la roue libre et remedier au problème. | D13: 30
B14: =+B13+1 -> 7 | C14: controler l'usure de la clavette et la rainure et reparer au besoin | D14: 30
B15: =B14+1 -> 8 | C15: controler l'état des glissières et remplacer les au besoin | D15: 25
B16: =+B15+1 -> 9 | C16: controler l'arret d'huile et le remplacé au besoin. Aucune fuite d'huile n'est acceptable. | D16: 10
B17: =B16+1 -> 10 | C17: controler l'usure des roulements et paliers de l'axe moteur et remplacer si necessaire. | D17: 30
B18: =+B17+1 -> 11 | C18: controler l'usure du pignon et le remplacé au besoin. Aucun glissement n'est acceptable. | D18: 30
B19: =B18+1 -> 12 | C19: controler l'alignement et la fixation du pignon de l'axe moteur et remedier au besoin. | D19: 30
B20: =+B19+1 -> 13 | C20: controler l'usure de la clavette et la rainure et reparer au besoin | D20: 30
B21: =B20+1 -> 14 | C21: controler l'usure des roulements et paliers de l'axe moteur et remplacer si necessaire. | D21: 30
B22: =+B21+1 -> 15 | C22: controler l'usure de la roue libre et la remplacée au besoin. Aucun glissement n'est acceptable. | D22: 30
B23: =B22+1 -> 16 | C23: controler l'alignement et la fixation de la roue libre et remedier au problème. | D23: 30
B24: =+B23+1 -> 17 | C24: controler l'usure de la clavette et la rainure et reparer au besoin | D24: 30
B25: =B24+1 -> 18 | C25: controler l'arret d'huile et le remplacé au besoin. Aucune fuite d'huile n'est acceptable. | D25: 10
B26: =B25+1 -> 19 | C26: controler la fixation du réducteur sur le convoyeur et corriger si necessaire. | D26: 30
B27: =+B26+1 -> 20 | C27: controler l'usure des roulements et paliers de l'axe moteur et remplacer si necessaire. | D27: 30
B28: =B27+1 -> 21 | C28: controler l'usure du pignon et le remplacé au besoin. Aucun glissement n'est acceptable. | D28: 30
B29: =B28+1 -> 22 | C29: controler l'alignement et la fixation du pignon de l'axe moteur et remedier au besoin. | D29: 30
B30: =+B29+1 -> 23 | C30: controler l'usure de la clavette et la rainure et reparer au besoin | D30: 30
B31: =B30+1 -> 24 | C31: controler l'usure des roulements et paliers de l'axe moteur et remplacer si necessaire. | D31: 30
B32: =B31+1 -> 25 | C32: controler l'usure de la clavette et la rainure et reparer au besoin | D32: 30
B33: =+B32+1 -> 26 | C33: controler l'état des glissières et remplacer les au besoin | D33: 25
B34: =B33+1 -> 27
B35: =B34+1 -> 28
B36: =+B35+1 -> 29
B37: =B36+1 -> 30
B38: Commentaire | D38: Nom et Visa Intervenants | G38: Nom et Visa Responsables

Sheet CC C5
B3: CHECKLIST MECANIQUE | G3: Date
C4: CONVOYEURS CASIERS C5 | D4: =+'Line & frequency'!C1 -> CHAINE 4 | G4: =+'Line & frequency'!C2 -> HEBDOMADAIRE
E6: FAIT?
B7: N° | C7: DESCRIPTION DES TACHES | D7: Durée | E7: OUI | F7: NON | G7: REMARQUES (MATERIEL + PIECES)
B8: 1 | C8: controler l'arret d'huile et le remplacé au besoin. Aucune fuite d'huile n'est acceptable. | D8: 10
B9: =B8+1 -> 2 | C9: controler la fixation du réducteur sur le convoyeur et corriger si necessaire. | D9: 30
B10: =+B9+1 -> 3 | C10: controler l'usure du pignon et le remplacé au besoin. Aucun glissement n'est acceptable. | D10: 30
B11: =B10+1 -> 4 | C11: controler l'alignement et la fixation du pignon de l'axe moteur et remedier au besoin. | D11: 30
B12: =+B11+1 -> 5 | C12: controler l'usure de la roue libre et la remplacée au besoin. Aucun glissement n'est acceptable. | D12: 30
B13: =B12+1 -> 6 | C13: controler l'alignement et la fixation de la roue libre et remedier au problème. | D13: 30
B14: =+B13+1 -> 7 | C14: controler l'usure de la clavette et la rainure et reparer au besoin | D14: 30
B15: =B14+1 -> 8 | C15: controler l'état des glissières et remplacer les au besoin | D15: 25
B16: =+B15+1 -> 9 | C16: controler l'arret d'huile et le remplacé au besoin. Aucune fuite d'huile n'est acceptable. | D16: 10
B17: =B16+1 -> 10 | C17: controler l'usure des roulements et paliers de l'axe moteur et remplacer si necessaire. | D17: 30
B18: =+B17+1 -> 11 | C18: controler l'usure du pignon et le remplacé au besoin. Aucun glissement n'est acceptable. | D18: 30
B19: =B18+1 -> 12 | C19: controler l'alignement et la fixation du pignon de l'axe moteur et remedier au besoin. | D19: 30
B20: =+B19+1 -> 13 | C20: controler l'usure de la clavette et la rainure et reparer au besoin | D20: 30
B21: =B20+1 -> 14 | C21: controler l'usure des roulements et paliers de l'axe moteur et remplacer si necessaire. | D21: 30
B22: =+B21+1 -> 15 | C22: controler l'usure de la roue libre et la remplacée au besoin. Aucun glissement n'est acceptable. | D22: 30
B23: =B22+1 -> 16 | C23: controler l'alignement et la fixation de la roue libre et remedier au problème. | D23: 30
B24: =+B23+1 -> 17 | C24: controler l'usure de la clavette et la rainure et reparer au besoin | D24: 30
B25: =B24+1 -> 18
B26: =B25+1 -> 19
B27: =+B26+1 -> 20
B28: =B27+1 -> 21
B29: =B28+1 -> 22
B30: =+B29+1 -> 23
B31: =B30+1 -> 24
B32: =B31+1 -> 25
B33: =+B32+1 -> 26
B34: =B33+1 -> 27
B35: =B34+1 -> 28
B36: =+B35+1 -> 29
B37: =B36+1 -> 30
B38: Commentaire | D38: Nom et Visa Intervenants | G38: Nom et Visa Responsables

Sheet CC C6
B3: CHECKLIST MECANIQUE | G3: Date
C4: CONVOYEURS CASIERS C6 | D4: =+'Line & frequency'!C1 -> CHAINE 4 | G4: =+'Line & frequency'!C2 -> HEBDOMADAIRE
E6: FAIT?
B7: N° | C7: DESCRIPTION DES TACHES | D7: Durée | E7: OUI | F7: NON | G7: REMARQUES (MATERIEL + PIECES)
B8: 1 | C8: controler l'arret d'huile et le remplacé au besoin. Aucune fuite d'huile n'est acceptable. | D8: 10
B9: =B8+1 -> 2 | C9: controler la fixation du réducteur sur le convoyeur et corriger si necessaire. | D9: 30
B10: =+B9+1 -> 3 | C10: controler l'usure du pignon et le remplacé au besoin. Aucun glissement n'est acceptable. | D10: 30
B11: =B10+1 -> 4 | C11: controler l'alignement et la fixation du pignon de l'axe moteur et remedier au besoin. | D11: 30
B12: =+B11+1 -> 5 | C12: controler l'usure de la roue libre et la remplacée au besoin. Aucun glissement n'est acceptable. | D12: 30
B13: =B12+1 -> 6 | C13: controler l'alignement et la fixation de la roue libre et remedier au problème. | D13: 30
B14: =+B13+1 -> 7 | C14: controler l'usure de la clavette et la rainure et reparer au besoin | D14: 30
B15: =B14+1 -> 8 | C15: controler l'état des glissières et remplacer les au besoin | D15: 25
B16: =+B15+1 -> 9 | C16: controler l'arret d'huile et le remplacé au besoin. Aucune fuite d'huile n'est acceptable. | D16: 10
B17: =B16+1 -> 10 | C17: controler l'usure des roulements et paliers de l'axe moteur et remplacer si necessaire. | D17: 30
B18: =+B17+1 -> 11 | C18: controler l'usure du pignon et le remplacé au besoin. Aucun glissement n'est acceptable. | D18: 30
B19: =B18+1 -> 12 | C19: controler l'alignement et la fixation du pignon de l'axe moteur et remedier au besoin. | D19: 30
B20: =+B19+1 -> 13 | C20: controler l'usure de la clavette et la rainure et reparer au besoin | D20: 30
B21: =B20+1 -> 14 | C21: controler l'usure des roulements et paliers de l'axe moteur et remplacer si necessaire. | D21: 30
B22: =+B21+1 -> 15 | C22: controler l'usure de la roue libre et la remplacée au besoin. Aucun glissement n'est acceptable. | D22: 30
B23: =B22+1 -> 16 | C23: controler l'alignement et la fixation de la roue libre et remedier au problème. | D23: 30
B24: =+B23+1 -> 17 | C24: controler l'usure de la clavette et la rainure et reparer au besoin | D24: 30
B25: =B24+1 -> 18 | C25: controler l'arret d'huile et le remplacé au besoin. Aucune fuite d'huile n'est acceptable. | D25: 10
B26: =B25+1 -> 19 | C26: controler la fixation du réducteur sur le convoyeur et corriger si necessaire. | D26: 30
B27: =+B26+1 -> 20 | C27: controler l'usure des roulements et paliers de l'axe moteur et remplacer si necessaire. | D27: 30
B28: =B27+1 -> 21 | C28: controler l'usure des pignons et les remplacés au besoin. Aucun glissement n'est acceptable. | D28: 30
B29: =B28+1 -> 22 | C29: controler l'alignement et la fixation du pignon de l'axe moteur et remedier au besoin. | D29: 30
B30: =+B29+1 -> 23 | C30: controler l'usure de la clavette et la rainure et reparer au besoin | D30: 30
B31: =B30+1 -> 24 | C31: controler l'état des glissières et remplacer les au besoin | D31: 25
B32: =B31+1 -> 25 | C32: controler l'usure du tapis et remplacer les portions usées ou maillons cassés | D32: 120
B33: =+B32+1 -> 26 | C33: controler la tenson des tapis et ajuster au besoin | D33: 60
B34: =B33+1 -> 27
B35: =B34+1 -> 28
B36: =+B35+1 -> 29
B37: =B36+1 -> 30
B38: Commentaire | D38: Nom et Visa Intervenants | G38: Nom et Visa Responsables

Sheet CC C7
B3: CHECKLIST MECANIQUE | G3: Date
C4: CONVOYEURS CASIERS C7 | D4: =+'Line & frequency'!C1 -> CHAINE 4 | G4: =+'Line & frequency'!C2 -> HEBDOMADAIRE
E6: FAIT?
B7: N° | C7: DESCRIPTION DES TACHES | D7: Durée | E7: OUI | F7: NON | G7: REMARQUES (MATERIEL + PIECES)
B8: 1 | C8: controler l'arret d'huile et le remplacé au besoin. Aucune fuite d'huile n'est acceptable. | D8: 10
B9: =B8+1 -> 2 | C9: controler la fixation du réducteur sur le convoyeur et corriger si necessaire. | D9: 30
B10: =+B9+1 -> 3 | C10: controler l'usure du pignon et le remplacé au besoin. Aucun glissement n'est acceptable. | D10: 30
B11: =B10+1 -> 4 | C11: controler l'alignement et la fixation du pignon de l'axe moteur et remedier au besoin. | D11: 30
B12: =+B11+1 -> 5 | C12: controler l'usure de la roue libre et la remplacée au besoin. Aucun glissement n'est acceptable. | D12: 30
B13: =B12+1 -> 6 | C13: controler l'alignement et la fixation de la roue libre et remedier au problème. | D13: 30
B14: =+B13+1 -> 7 | C14: controler l'usure de la clavette et la rainure et reparer au besoin | D14: 30
B15: =B14+1 -> 8 | C15: controler l'état des glissières et remplacer les au besoin | D15: 25
B16: =+B15+1 -> 9 | C16: controler l'arret d'huile et le remplacé au besoin. Aucune fuite d'huile n'est acceptable. | D16: 10
B17: =B16+1 -> 10 | C17: controler l'usure des roulements et paliers de l'axe moteur et remplacer si necessaire. | D17: 30
B18: =+B17+1 -> 11 | C18: controler l'usure du pignon et le remplacé au besoin. Aucun glissement n'est acceptable. | D18: 30
B19: =B18+1 -> 12 | C19: controler l'alignement et la fixation du pignon de l'axe moteur et remedier au besoin. | D19: 30
B20: =+B19+1 -> 13 | C20: controler l'usure de la clavette et la rainure et reparer au besoin | D20: 30
B21: =B20+1 -> 14 | C21: controler l'usure des roulements et paliers de l'axe moteur et remplacer si necessaire. | D21: 30
B22: =+B21+1 -> 15 | C22: controler l'usure de la roue libre et la remplacée au besoin. Aucun glissement n'est acceptable. | D22: 30
B23: =B22+1 -> 16 | C23: controler l'alignement et la fixation de la roue libre et remedier au problème. | D23: 30
B24: =+B23+1 -> 17 | C24: controler l'usure de la clavette et la rainure et reparer au besoin | D24: 30
B25: =B24+1 -> 18 | C25: controler l'arret d'huile et le remplacé au besoin. Aucune fuite d'huile n'est acceptable. | D25: 10
B26: =B25+1 -> 19 | C26: controler la fixation du réducteur sur le convoyeur et corriger si necessaire. | D26: 30
B27: =+B26+1 -> 20 | C27: controler l'usure des roulements et paliers de l'axe moteur et remplacer si necessaire. | D27: 30
B28: =B27+1 -> 21 | C28: controler l'usure des pignons et les remplacés au besoin. Aucun glissement n'est acceptable. | D28: 30
B29: =B28+1 -> 22 | C29: controler l'alignement et la fixation du pignon de l'axe moteur et remedier au besoin. | D29: 30
B30: =+B29+1 -> 23 | C30: controler l'usure de la clavette et la rainure et reparer au besoin | D30: 30
B31: =B30+1 -> 24 | C31: controler l'état des glissières et remplacer les au besoin | D31: 25
B32: =B31+1 -> 25 | C32: controler l'usure du tapis et remplacer les portions usées ou maillons cassés | D32: 120
B33: =+B32+1 -> 26 | C33: controler la tenson des tapis et ajuster au besoin | D33: 60
B34: =B33+1 -> 27
B35: =B34+1 -> 28
B36: =+B35+1 -> 29
B37: =B36+1 -> 30
B38: Commentaire | D38: Nom et Visa Intervenants | G38: Nom et Visa Responsables

Sheet CC C8
B3: CHECKLIST MECANIQUE | G3: Date
C4: CONVOYEURS CASIERS C8 | D4: =+'Line & frequency'!C1 -> CHAINE 4 | G4: =+'Line & frequency'!C2 -> HEBDOMADAIRE
E6: FAIT?
B7: N° | C7: DESCRIPTION DES TACHES | D7: Durée | E7: OUI | F7: NON | G7: REMARQUES (MATERIEL + PIECES)
B8: 1 | C8: controler l'arret d'huile et le remplacé au besoin. Aucune fuite d'huile n'est acceptable. | D8: 10
B9: =B8+1 -> 2 | C9: controler la fixation du réducteur sur le convoyeur et corriger si necessaire. | D9: 30
B10: =+B9+1 -> 3 | C10: controler l'usure du pignon et le remplacé au besoin. Aucun glissement n'est acceptable. | D10: 30
B11: =B10+1 -> 4 | C11: controler l'alignement et la fixation du pignon de l'axe moteur et remedier au besoin. | D11: 30
B12: =+B11+1 -> 5 | C12: controler l'usure de la roue libre et la remplacée au besoin. Aucun glissement n'est acceptable. | D12: 30
B13: =B12+1 -> 6 | C13: controler l'alignement et la fixation de la roue libre et remedier au problème. | D13: 30
B14: =+B13+1 -> 7 | C14: controler l'usure de la clavette et la rainure et reparer au besoin | D14: 30
B15: =B14+1 -> 8 | C15: controler l'état des glissières et remplacer les au besoin | D15: 25
B16: =+B15+1 -> 9 | C16: controler l'arret d'huile et le remplacé au besoin. Aucune fuite d'huile n'est acceptable. | D16: 10
B17: =B16+1 -> 10 | C17: controler la fixation du réducteur sur le convoyeur et corriger si necessaire. | D17: 30
B18: =+B17+1 -> 11 | C18: controler l'usure des roulements et paliers de l'axe moteur et remplacer si necessaire. | D18: 30
B19: =B18+1 -> 12 | C19: controler l'usure des pignons et les remplacés au besoin. Aucun glissement n'est acceptable. | D19: 30
B20: =+B19+1 -> 13 | C20: controler l'alignement et la fixation du pignon de l'axe moteur et remedier au besoin. | D20: 30
B21: =B20+1 -> 14 | C21: controler l'usure de la clavette et la rainure et reparer au besoin | D21: 30
B22: =+B21+1 -> 15 | C22: controler l'état des glissières et remplacer les au besoin | D22: 25
B23: =B22+1 -> 16 | C23: controler l'usure du tapis et remplacer les portions usées ou maillons cassés | D23: 120
B24: =+B23+1 -> 17 | C24: controler la tenson des tapis et ajuster au besoin | D24: 60
B25: =B24+1 -> 18
B26: =B25+1 -> 19
B27: =+B26+1 -> 20
B28: =B27+1 -> 21
B29: =B28+1 -> 22
B30: =+B29+1 -> 23
B31: =B30+1 -> 24
B32: =B31+1 -> 25
B33: =+B32+1 -> 26
B34: =B33+1 -> 27
B35: =B34+1 -> 28
B36: =+B35+1 -> 29
B37: =B36+1 -> 30
B38: Commentaire | D38: Nom et Visa Intervenants | G38: Nom et Visa Responsables

Sheet Line & frequency
B1: Line | C1: CHAINE 4
B2: Frequency | C2: HEBDOMADAIRE
B3: Date | C3: 44273 | G3: =+'Line & frequency'!C3 -> 44273

Sheet RO_AN
B3: CHECKLIST MECANIQUE | G3: Date:
C4: OSMOSE INVERSE | D4: Water Treatment Plant | G4: ANNUELLE
E5: FAIT?
B6: N° | C6: DESCRIPTION DES TACHES | D6: Durée | E6: OUI | F6: NON | G6: REMARQUES (MATERIEL + PIECES)
B7: 1 | C7: Vérifier le fonctionnement du thermomètre
B8: =B7+1 -> 2 | C8: Vérifier le fonctionnement de l'echangeur thermique
B9: =B8+1 -> 3
B10: Commentaire | D10: Nom et Visa Intervenants | G10: Nom et Visa Responsables

Sheet ELIWA_AN
B3: CHECKLIST MECANIQUE | G3: Date:
C4: ELIWA | D4: Water Treatment Plant | G4: ANNUELLE
E5: FAIT?
B6: N° | C6: DESCRIPTION DES TACHES | D6: Durée | E6: OUI | F6: NON | G6: REMARQUES (MATERIEL + PIECES)
B7: 1 | C7: Test d'intégrité des membranes
B8: 2
B9: Commentaire | D9: Nom et Visa Intervenants | G9: Nom et Visa Responsables

Sheet WP_AN
B3: CHECKLIST MECANIQUE | G3: Date:
C4: WTP | D4: Water Treatment Plant | G4: ANNUELLE
E5: FAIT?
B6: N° | C6: DESCRIPTION DES TACHES | D6: Durée | E6: OUI | F6: NON | G6: REMARQUES (MATERIEL + PIECES)
B7: 1 | C7: Inspecter et nettoyer du lime tank
B8: =B7+1 -> 2 | C8: Inspecter et nettoyer du Service tank
B9: =+B8+1 -> 3 | C9: Inspecter et nettoyer du permeat tank
B10: 4 | C10: inspecter le tank d'ozone
B11: 5 | C11: Etalonner les débimètres Mag
B12: =+B11+1 -> 6 | C12: Vidager et remplacer l'huile des pompes doseuses
B13: =B12+1 -> 7
B14: Commentaire | D14: Nom et Visa Intervenants | G14: Nom et Visa Responsables

Sheet FORAGES
B3: CHECKLIST MECANIQUE | G3: Date:
C4: FORAGES | D4: Water Treatment Plant | G4: ANNUELLE
E5: FAIT?
B6: N° | C6: DESCRIPTION DES TACHES | D6: Durée | E6: OUI | F6: NON | G6: REMARQUES (MATERIEL + PIECES)
B7: 1 | C7: soufler le forage DSD
B8: =B7+1 -> 2 | C8: soufler le forage SIDEL
B9: =+B8+1 -> 3 | C9: soufler le forage INF
B10: 4 | C10: soufler le forage PARKING
B11: 5
B12: =+B11+1 -> 6
B13: =B12+1 -> 7
B14: Commentaire | D14: Nom et Visa Intervenants | G14: Nom et Visa Responsables

Sheet RESERVOIR INCENDIE
B3: CHECKLIST MECANIQUE | G3: Date:
C4: RESERVOIR INCENDIE | D4: Water Treatment Plant | G4: ANNUELLE
E5: FAIT?
B6: N° | C6: DESCRIPTION DES TACHES | D6: Durée | E6: OUI | F6: NON | G6: REMARQUES (MATERIEL + PIECES)
B7: 1 | C7: Insepcter et nettoyer le reservoir d'eau sous sol RIA
B8: =B7+1 -> 2
B9: Commentaire | D9: Nom et Visa Intervenants | G9: Nom et Visa Responsables
