Workbook
Name _PG1: #REF!
Name _PG2: #REF!
Name _PG3: #REF!
Name _PG4: #REF!
Name _PG5: #REF!
Name _PG6: #REF!
Name _PG7: #REF!
Name _PG8: #REF!
Name ACCOUNT: [1]SAP!$C$5:$C$977
Name act2nd: #REF!
Name act2ndrands: #REF!
Name actual1st: #REF!
Name actual1strands: #REF!
Name actualacccc: #REF!
Name actuals: #REF!
Name budgetacccc: #REF!
Name CCACCOUNT: [1]SAP!$Q$5:$Q$977
Name CCMM: [1]SAP!$H$5:$H$977
Name CCMMBRAND: [1]SAP!$M$5:$M$977
Name DATA1: #REF!
Name DATA10: #REF!
Name DATA11: #REF!
Name DATA2: #REF!
Name DATA3: #REF!
Name DATA4: #REF!
Name DATA5: #REF!
Name DATA6: #REF!
Name DATA7: #REF!
Name DATA8: #REF!
Name DATA9: #REF!
Name desc: [2]Sheet1!$H$35:$I$240
Name desc: [3]Sheet1!$H$35:$I$240
Name NORTH: #REF!
Name OPPASUMM: #REF!
Name RAND: [1]SAP!$G$5:$G$977
Name rands: #REF!
Name randsact: #REF!
Name randsbud: #REF!
Name SOUTH: #REF!
Name TEST0: #REF!
Name TESTHKEY: #REF!
Name TESTKEYS: #REF!
Name TESTVKEY: #REF!
Name wksorder: #REF!
Name wksorderrands: #REF!

Sheet Date
B2: Week ... 2025

Sheet Apolloss graissage + Lub
B3: CHECKLIST LUBRIFICATION ET GRAISSAGE | G3: =Date!B2 -> Week ... 2025
C4: Apollos | D4: =+'Line & frequency'!C1 -> CHAINE 5 | G4: =+'Line & frequency'!C2 -> HEBDOMADAIRE
B5: INTERVENANT | D5: JOYCE
C6: Heure début:……………………………………………… Heure fin : ……………………………………… | E6: FAIT?
B7: N° | C7: DESCRIPTION DES TACHES | D7: Durée | E7: OUI | F7: NON | G7: REMARQUES (MATERIEL + PIECES)
B8: 1 | C8: Controler le niveau de l'huile à l'intérieur des reducteurs de convoyeur Apollo 1
B9: =B8+1 -> 2 | C9: Controler le niveau de l'huile à l'intérieur des reducteurs de convoyeur Apollo 2
B10: =+B9+1 -> 3 | C10: Controler le niveau de l'huile à l'intérieur des reducteurs de convoyeur Apollo 3
B11: =B10+1 -> 4 | C11: Controler le niveau de l'huile à l'intérieur des reducteurs de convoyeur Apollo 4
B12: =+B11+1 -> 5 | C12: Graisser les roulements de paliers du convoyeur Apollo 1
B13: =B12+1 -> 6 | C13: Graisser les roulements de paliers du convoyeur Apollo 2
B14: =+B13+1 -> 7 | C14: Graisser les roulements de paliers du convoyeur Apollo 3
B15: =B14+1 -> 8 | C15: Graisser les roulements de paliers du convoyeur Apollo 4
B16: =+B15+1 -> 9 | C16: Lubrifier la chaine motrice du convoyeur Apollo 1
B17: =B16+1 -> 10 | C17: Lubrifier la chaine motrice du convoyeur Apollo 2
B18: =+B17+1 -> 11 | C18: Lubrifier la chaine motrice du convoyeur Apollo 3
B19: =B18+1 -> 12 | C19: Lubrifier la chaine motrice du convoyeur Apollo 4
B20: =+B19+1 -> 13
B21: =B20+1 -> 14
B22: Commentaire | D22: Nom et Visa Intervenants | G22: Nom et Visa Responsables

Sheet Decaisseuse Graissage + Lub
D3: CHECKLIST GRAISSAGE + LUBRIFICATION | I3: CODE:
I4: =Date!B2 -> Week ... 2025
I5: Semaine:
B6: MACHINE | D6: DECAISSEUSE
B7: INTERVENANT
G10: FAIT?
B11: N° | C11: DESCRIPTION DES TACHES | F11: Durée | G11: OUI | H11: NON | I11: REMARQUES (MATERIEL + PIECES)
B12: 1 | C12: Graisser les rails du chariot de levage
B13: =B12+1 -> 2 | C13: Graisser les roulements de paliers du convoyeur interne
B14: =B13+1 -> 3 | C14: Graisser les roulements des paliers sur l'axe des motoreducteurs du chariot de levage
B15: =B14+1 -> 4 | C15: Graisser les roulements des paliers du motoreducteurs de la traverse
B16: =B15+1 -> 5 | C16: Graisser les roulements des paliers de la table
B17: =B16+1 -> 6 | C17: Graisser les roulements des paliers du convoyeur à la sortie
B18: =B17+1 -> 7 | C18: Graisser les roulements de paliers du guide frame
B19: =B18+1 -> 8 | C19: Graisser les roulements linéaires du guide frame
B20: =B19+1 -> 9 | C20: Faire appoint huile reducteur du guide frame
B21: =B20+1 -> 10 | C21: Faire appoint huile reducteur du convoyeur interne
B22: =B21+1 -> 11 | C22: Faire appoint huile reducteurs principaux de levage
B23: =B22+1 -> 12 | C23: Faire appoint huile reducteur de la traverse
B24: =B23+1 -> 13 | C24: Faire appoint huile reducteurs du convoyeur casier à l'entrée et à la sortie
B25: =B24+1 -> 14 | C25: Faire appoint huile reducteur de la table
B26: =B25+1 -> 15
B27: =B26+1 -> 16
B28: =B27+1 -> 17
B29: =B28+1 -> 18
B30: =B29+1 -> 19
B31: =B30+1 -> 20
B32: =B31+1 -> 21
B33: =B32+1 -> 22
B34: Nom et Visa Intervenants | E34: Commentaire Général | I34: Nom et Visa Responsables

Sheet Encaisseuse Graissage + Lub
D3: CHECKLIST GRAISSAGE + LUBRIFICATION | I3: CODE:
I4: =Date!B2 -> Week ... 2025
I5: Semaine:
B6: MACHINE | D6: ENCAISSEUSE
B7: INTERVENANT
G10: FAIT?
B11: N° | C11: DESCRIPTION DES TACHES | F11: Durée | G11: OUI | H11: NON | I11: REMARQUES (MATERIEL + PIECES)
B12: 1 | C12: Graisser les rails du chariot de levage
B13: =B12+1 -> 2 | C13: Graisser les roulements de paliers du convoyeur interne
B14: =B13+1 -> 3 | C14: Graisser les roulements des paliers sur l'axe des motoreducteurs du chariot de levage
B15: =B14+1 -> 4 | C15: Graisser les roulements des paliers du motoreducteurs de la traverse
B16: =B15+1 -> 5 | C16: Graisser les roulements des paliers de la table
B17: =B16+1 -> 6 | C17: Graisser les roulements des paliers du convoyeur à la sortie
B18: =B17+1 -> 7 | C18: Graisser les roulements de paliers du guide frame
B19: =B18+1 -> 8 | C19: Graisser les roulements de paliers du moto reducteur des branleurs
B20: =B19+1 -> 9 | C20: Graisser les roulements linéaires du guide frame
B21: =B20+1 -> 10 | C21: Faire appoint huile reducteur du guide frame
B22: =B21+1 -> 11 | C22: Faire appoint huile reducteur du convoyeur interne
B23: =B22+1 -> 12 | C23: Faire appoint huile reducteurs principaux de levage
B24: =B23+1 -> 13 | C24: Faire appoint huile reducteur de la traverse
... B28: =B27+1 -> 17 | C28: Inspecter la rampe de lubrification de la table; Déboucher les buses et remonter toute anomalie
B29: =B28+1 -> 18
B30: =B29+1 -> 19
B31: =B30+1 -> 20
B32: =B31+1 -> 21
B33: =B32+1 -> 22
B34: Nom et Visa Intervenants | E34: Commentaire Général | I34: Nom et Visa Responsables

Sheet Depal Graissage + Lub
D3: CHECKLIST GRAISSAGE + LUBRIFICATION | I3: CODE:
I4: =Date!B2 -> Week ... 2025
I5: Semaine:
B6: MACHINE | D6: DEPALETTISEUR
B7: INTERVENANT | D7: TANKWA
G10: FAIT?
B11: N° | C11: DESCRIPTION DES TACHES | F11: Durée | G11: OUI | H11: NON | I11: REMARQUES (MATERIEL + PIECES)
B12: 1 | C12: Graisser les roulements de paliers de la première table
B13: =B12+1 -> 2 | C13: Graisser les roulements de paliers de la deuxième table
B14: =B13+1 -> 3 | C14: Graisser les roulements des paliers des deux convoyeurs convoyeurs de sortie
B15: =B14+1 -> 4 | C15: Graisser les rails du chariot de levage
B16: =B15+1 -> 5 | C16: Graisser les chaines 10b1 des convoyeurs à palettes à l'entrée et la sortie de la machine
B17: =B16+1 -> 6 | C17: Graisser les roulements des paliers sur l'axe des motoreducteurs du chariot de levage
B18: =B17+1 -> 7 | C18: Graisser les roulements des paliers du motoreducteurs de la traverse
B19: =B18+1 -> 8 | C19: Graisser les roulements de paliers du motoreducteur des slides
B20: =B19+1 -> 9 | C20: Faire appoint huile reducteur première table
B21: =B20+1 -> 10 | C21: Faire appoint huile reducteur deuxième table
B22: =B21+1 -> 11 | C22: Faire appoint huile dans les reducteurs des slides 1 et 2
B23: =B22+1 -> 12 | C23: Faire appoint huile dans les motoreducteurs des convoyeurs à palettes à l'entrée
B24: =B23+1 -> 13 | C24: Faire appoint huile dans les motoreducteurs des convoyeurs à palettes du magasin à palettes
... B28: =B27+1 -> 17 | C28: Graisser retourneur de palettes à la sortie du depaletiseur ( 4 points de graissage situés en dessous du convoyeur à palettes )
B29: =B28+1 -> 18
B30: =B29+1 -> 19
B31: =B30+1 -> 20
B32: =B31+1 -> 21
B33: =B32+1 -> 22
B34: Nom et Visa Intervenants | E34: Commentaire Général | I34: Nom et Visa Responsables

Sheet PAL Graisage + Lub
D3: CHECKLIST GRAISSAGE + LUBRIFICATION | I3: CODE:
I4: =Date!B2 -> Week ... 2025
I5: Semaine:
B6: MACHINE | D6: PALETTISEUR
B7: INTERVENANT | D7: TANKWA
G10: FAIT?
B11: N° | C11: DESCRIPTION DES TACHES | F11: Durée | G11: OUI | H11: NON | I11: REMARQUES (MATERIEL + PIECES)
B12: 1 | C12: Graisser les rails du chariot de levage
B13: =B12+1 -> 2 | C13: Graisser les chaines 10b1 des convoyeurs à palettes à l'entrée et la sortie de la machine
B14: =B13+1 -> 3 | C14: Graisser les roulements des paliers sur l'axe des motoreducteurs du chariot de levage
B15: =B14+1 -> 4 | C15: Graisser les roulements des paliers du motoreducteurs de la traverse
B16: =B15+1 -> 5 | C16: Graisser les roulements des paliers du grand tapis
B17: =B16+1 -> 6 | C17: Graisser les roulements des paliers du poussoir
B18: =B17+1 -> 7 | C18: Graisser les roulements de paliers du distributeur de casiers
B19: =B18+1 -> 8 | C19: Faire appoint huile Reducteurs principaux de levage du chariot
B20: =B19+1 -> 9 | C20: Faire appoint huile reducteur de la traverse
B21: =B20+1 -> 10 | C21: Faire appoint huile reducteurs du poussoir
B22: =B21+1 -> 11 | C22: Faire appoint huile reducteur du grand tapis
B23: =B22+1 -> 12 | C23: Faire appoint huile dans les recuteurs des convoyeurs à palettes à l'entrée et à la sortie
B24: =B23+1 -> 13 | C24: Faire appoint huile reducteur du distributeur à casiers
... B26: =B25+1 -> 15 | C26: Graisser retourneur de palettes à l'entrée du paletiseur ( 4 points de graissage situés en dessous du convoyeur à palettes )
B27: =B26+1 -> 16
B28: =B27+1 -> 17
B29: =B28+1 -> 18
B30: =B29+1 -> 19
B31: =B30+1 -> 20
B32: =B31+1 -> 21
B33: =B32+1 -> 22
B34: Nom et Visa Intervenants | E34: Commentaire Général | I34: Nom et Visa Responsables

Sheet EBI Hebdo Méca
D3: CHECKLIST HEBDOMADAIRE ELECTRIQUE | I3: CODE:
I4: =+[4]Date!B2 -> Week 30 2025
I5: Semaine:
B6: MACHINE | D6: EBI Chaine 5
B7: INTERVENANT | D7: SIMO
G10: FAIT?
B11: N° | C11: DESCRIPTION DES TACHES | F11: Durée | G11: OUI | H11: NON | I11: REMARQUES (MATERIEL + PIECES)
B12: 1 | C12: Vérifier, graisser, et retendre la chaîne de transmission pour le réglage en hauteur du caisson caméra
B13: =B12+1 -> 2 | C13: Effectuer le graissage centralisé des paliers
B14: =B13+1 -> 3 | C14: Vérifier guides bouteilles et les ajuster en fonction des repères standardisés
B15: =B14+1 -> 4
B16: =B15+1 -> 5
B17: =B16+1 -> 6
B18: =B17+1 -> 7
B19: =B18+1 -> 8
B20: =B19+1 -> 9
B21: =B20+1 -> 10
B22: =B21+1 -> 11
B23: =B22+1 -> 12
B24: Nom et Visa Intervenants | E24: Commentaire Général | I24: Nom et Visa Responsables

Sheet Etiqueteuse Graissage + Lub rev
D3: CHECKLIST GRAISSAGE + LUBRIFICATION | I3: CODE:
I4: =Date!B2 -> Week ... 2025
I5: Semaine:
B6: MACHINE | D6: Etiqueteuse
B7: INTERVENANT | D7: ITEMBE
G10: FAIT?
B11: N° | C11: DESCRIPTION DES TACHES | F11: Frequence | G11: OUI | H11: NON | I11: REMARQUES (MATERIEL + PIECES)
B12: 1 | C12: Graisser la came des supports tete de pression | F12: H
B13: =B12+1 -> 2 | C13: Controler le niveau d'huile de lubrification des selettes et faire appoint si necessaire | F13: M
B14: =B13+1 -> 3 | C14: Faire appoint graisse pour lubrification de la came de la station de staniolage | F14: 3M
B15: =B14+1 -> 4 | C15: Vidanger huile de l'aggregat station 1 ( utiliser huile 220 ) | F15: 6M
B16: =B15+1 -> 5 | C16: Nettoyer vielle graisse sur les ressorts des tetes de pression et mettre nouvelle graisse | F16: A
B17: =B16+1 -> 6 | C17: Graisser les cylindres de transfert stanioles et etiquettes ( lubrifier les galets des deux cylindres ) | F17: D
B18: =B17+1 -> 7 | C18: Mettre une petite quantité de graisse sur l'arbre des racleurs à colle | F18: H
B19: =B18+1 -> 8 | C19: Controler niveau huile à l'interieur des aggregats et faire appoint si necessaire | F19: M
B20: =B19+1 -> 9
B21: =B20+1 -> 10
B22: =B21+1 -> 11
B23: =B22+1 -> 12
B24: =B23+1 -> 13
B25: =B24+1 -> 14
B26: =B25+1 -> 15
B27: =B26+1 -> 16
B28: =B27+1 -> 17
B29: =B28+1 -> 18
B30: =B29+1 -> 19
B31: =B30+1 -> 20
... B33: =B32+1 -> 22
B34: Nom et Visa Intervenants | E34: Commentaire Général | I34: Nom et Visa Responsables

Sheet Etiqueteuse Graissage + Lub  M
D3: CHECKLIST GRAISSAGE + LUBRIFICATION | I3: CODE:
I4: =Date!B2 -> Week ... 2025
I5: Semaine:
B6: MACHINE | D6: Etiqueteuse
B7: INTERVENANT
G10: FAIT?
B11: N° | C11: DESCRIPTION DES TACHES | F11: Durée | G11: OUI | H11: NON | I11: REMARQUES (MATERIEL + PIECES)
B12: 1 | C12: Graisser le cylindre à étiquettes
B13: =B12+1 -> 2 | C13: Graisser le cylindre à stanioles
B14: =B13+1 -> 3 | C14: Graisser les roulements de paliers du convoyeur à l'entrée
B15: =B14+1 -> 4 | C15: Graisser les roulements de paliers du convoyeur à la sortie
B16: =B15+1 -> 5 | C16: Controler le fonctionnement du graissage automatique de la butée du carrousel
B17: =B16+1 -> 6 | C17: Faire appoint huile reducteur convoyeur à l'entrée
B18: =B17+1 -> 7 | C18: Faire appoint huile reducteur convoyeur à la sortie
B19: =B18+1 -> 8 | C19: Faire appoint huile reducteur entrainant le carrousel
B20: =B19+1 -> 9 | C20: Faire appoint huile reducteur entrainant les etoiles entrée et sortie
B21: =B20+1 -> 10 | C21: Faire appoint huile reducteur entrainant le carrousel
B22: =B21+1 -> 11 | C22: Faire appoint huile reducteur entrainant la station 1
B23: =B22+1 -> 12 | C23: Faire appoint huile reducteur entrainant la station 2
B24: =B23+1 -> 13 | C24: Faire appoint huile reducteur reglage en hauteur station de staniolage
B25: =B24+1 -> 14 | C25: Faire appoint huile reducteur reglage en hauteur du carrousel
B26: =B25+1 -> 15
B27: =B26+1 -> 16
B28: =B27+1 -> 17
B29: =B28+1 -> 18
B30: =B29+1 -> 19
B31: =B30+1 -> 20
B32: =B31+1 -> 21
B33: =B32+1 -> 22
B34: Nom et Visa Intervenants | E34: Commentaire Général | I34: Nom et Visa Responsables

Sheet Laveuse Graissage
D3: CHECKLIST GRAISSAGE | I3: CODE:
I4: =Date!B2 -> Week ... 2025
I5: Semaine:
B6: MACHINE | D6: Laveuse de bouteillles L5
B7: INTERVENANT
G10: FAIT?
B11: N° | C11: DESCRIPTION DES TACHES | F11: Durée | G11: OUI | H11: NON | I11: REMARQUES (MATERIEL + PIECES)
B12: 1 | C12: Graisser les roulements de paliers principaux du corps de la machine
B13: =B12+1 -> 2 | C13: Graisser les pompes basse pression
B14: =B13+1 -> 3 | C14: Graisser les roulements de paliers de l'infeed
B15: =B14+1 -> 4 | C15: Graisser les roulements de paliers de la table d'entrée
B16: =B15+1 -> 5 | C16: Graisser le système de transmission à l'entrée
B17: =B16+1 -> 6 | C17: Graisser le système de transmission à la sortie
B18: =B17+1 -> 7 | C18: Graisser les roulements de paliers à la sortie
B19: =B18+1 -> 8 | C19: Graisser les roulements de paliers du bloc d'extraction des etiquettes
B20: =B19+1 -> 9 | C20: Controler qualité huile, Vidanger si necessaire, Faire appoint huile dans reducteurs des extracteurs bain 1 à 5
B21: =B20+1 -> 10 | C21: Controler qualité huile, Vidanger si necessaire, Faire appoint huile dans reducteurs des tambours bain 1 à 5
B22: =B21+1 -> 11 | C22: Controler qualité huile, Vidanger si necessaire, Faire appoint huile dans reducteurs d'entrainement de l'infeed
B23: =B22+1 -> 12 | C23: Controler qualité huile, Vidanger si necessaire, Faire appoint huile dans reducteur d'entrainement de la sortie
B24: =B23+1 -> 13 | C24: Controler qualité huile, Vidanger si necessaire, Faire appoint huile dans reducteur d'entrainement des branleurs
... B27: =B26+1 -> 16 | C27: Controler qualité huile, Vidanger si necessaire, Faire appoint huile dans reducteur grand tapis extraction
B28: =B27+1 -> 17
B29: =B28+1 -> 18
B30: =B29+1 -> 19
B31: =B30+1 -> 20
B32: =B31+1 -> 21
B33: =B32+1 -> 22
B34: Nom et Visa Intervenants | E34: Commentaire Général | I34: Nom et Visa Responsables

Sheet Laveuse Graissage 2W
D3: CHECKLIST GRAISSAGE | I3: CODE:
I4: =Date!B2 -> Week ... 2025
I5: Semaine:
B6: MACHINE | D6: Laveuse de bouteillles
B7: INTERVENANT
G10: FAIT?
B11: N° | C11: DESCRIPTION DES TACHES | F11: Durée | G11: OUI | H11: NON | I11: REMARQUES (MATERIEL + PIECES)
B12: 1 | C12: Graisser les roulements de paliers de l'infeed
B13: =B12+1 -> 2 | C13: Graisser les roulements de paliers de la table d'entrée
B14: =B13+1 -> 3 | C14: Graisser le système de transmission à l'entrée
B15: =B14+1 -> 4 | C15: Graisser le système de transmission à la sortie
B16: =B15+1 -> 5 | C16: Graisser les roulements de paliers à la sortie
B17: =B16+1 -> 6 | C17: Graisser les roulements de paliers du bloc d'extraction des etiquettes
B18: =B17+1 -> 7 | C18: Graisser les roulements de paliers principaux du corps de la machine
B19: =B18+1 -> 8 | C19: Graisser les pompes basses pressions
B20: =B19+1 -> 9
B21: =B20+1 -> 10
B22: =B21+1 -> 11
B23: =B22+1 -> 12
B24: =B23+1 -> 13
B25: =B24+1 -> 14
B26: =B25+1 -> 15
B27: =B26+1 -> 16
B28: =B27+1 -> 17
B29: =B28+1 -> 18
B30: =B29+1 -> 19
B31: =B30+1 -> 20
... B33: =B32+1 -> 22
B34: Nom et Visa Intervenants | E34: Commentaire Général | I34: Nom et Visa Responsables

Sheet Lave caisses Graissage + Lub 
D3: CHECKLIST GRAISSAGE + LUBRIFICATION | I3: CODE:
I4: Week 38 2025
B6: MACHINE | D6: Lave caisses
B7: INTERVENANT | D7: CHOUAGOUE
G10: FAIT?
B11: N° | C11: DESCRIPTION DES TACHES | F11: Durée | G11: OUI | H11: NON | I11: REMARQUES (MATERIEL + PIECES)
B12: 1 | C12: Graisser les roulements de paliers du convoyeur interne de la lave caisse
B13: =B12+1 -> 2 | C13: Graisser les roulements de paliers du tapis extracteur N°1
B14: =B13+1 -> 3 | C14: Graisser les roulements de paliers du tapis extracteur N°2
B15: =B14+1 -> 4 | C15: Faire appoint d'huile à l'interieur du reducteur du convoyeur interne
B16: =B15+1 -> 5 | C16: Faire appoint huile dans les reducteurs des tapis extracteurs
B17: =B16+1 -> 6
B18: =B17+1 -> 7
B19: =B18+1 -> 8
B20: =B19+1 -> 9
B21: =B20+1 -> 10
B22: =B21+1 -> 11
B23: =B22+1 -> 12
B24: =B23+1 -> 13
B25: =B24+1 -> 14
B26: =B25+1 -> 15
B27: =B26+1 -> 16
B28: =B27+1 -> 17
... B33: =B32+1 -> 22
B34: Nom et Visa Intervenants | E34: Commentaire Général | I34: Nom et Visa Responsables

Sheet Pasteurisateur Graissage
D3: CHECKLIST GRAISSAGE | I3: CODE:
I4: =Date!B2 -> Week ... 2025
I5: Semaine:
B6: MACHINE | D6: Pasteurisateur L5
B7: INTERVENANT
G10: FAIT?
B11: N° | C11: DESCRIPTION DES TACHES | F11: Durée | G11: OUI | H11: NON | I11: REMARQUES (MATERIEL + PIECES)
B12: 1 | C12: Graisser les roulements de paliers du convoyeur entrée haut
B13: =B12+1 -> 2 | C13: Graisser les roulements de paliers du convoyeur entrée bas
B14: =B13+1 -> 3 | C14: Graisser les roulements de paliers du convoyeur sortie haut
B15: =B14+1 -> 4 | C15: Graisser les roulements de paliers du convoyeur sortie bas
B16: =B15+1 -> 5 | C16: Graisser les roulements de paliers du tapis haut
B17: =B16+1 -> 6 | C17: Graisser les roulements de paliers du tapis bas
B18: =B17+1 -> 7 | C18: Graisser les roulements de paliers du convoyeurs extracteur de casses
B19: =B18+1 -> 8 | C19: Controler qualité huile, Vidanger si necessaire, Faire appoint huile dans les reducteurs principaux tapis haut
B20: =B19+1 -> 9 | C20: Controler qualité huile, Vidanger si necessaire, Faire appoint huile dans les reducteurs principaux tapis bas
B21: =B20+1 -> 10 | C21: Controler qualité huile, Vidanger si necessaire, Faire appoint huile dans les reducteurs Convoyeur entrée haut et bas
B22: =B21+1 -> 11 | C22: Controler qualité huile, Vidanger si necessaire, Faire appoint huile dans les reducteurs Convoyeur sortie bas et haut
B23: =B22+1 -> 12
B24: =B23+1 -> 13
B25: =B24+1 -> 14
B26: =B25+1 -> 15
B27: =B26+1 -> 16
B28: =B27+1 -> 17
B29: =B28+1 -> 18
B30: =B29+1 -> 19
B31: =B30+1 -> 20
B32: =B31+1 -> 21
B33: =B32+1 -> 22
B34: Nom et Visa Intervenants | E34: Commentaire Général | I34: Nom et Visa Responsables

Sheet Soutireuse Graissage hebdo
D3: CHECKLIST GRAISSAGE HEBDOMADAIRE | J3: Semaine:
J4: week 39 2025
J5: Date:
B6: MACHINE | D6: Soutireuse L5
B7: INTERVENANT | D7: CHOUAGOUE
H10: FAIT?
B11: N° | C11: COMPOSANT/ZONE A GRAISSER | F11: Type de graisse / huile | G11: Durée | H11: OUI | I11: NON | J11: REMARQUES (MATERIEL + PIECES)
C12: Effectuer le graissage manuel exclusif
B13: =B12+1 -> 1 | C13: Roulement de la vis de selection (Axe de commande) | F13: Multi complex EP 2
B14: =B13+1 -> 2 | C14: Roulement de renvoi d'angle de la vis de selection | F14: Multi complex EP 2
B15: =B14+1 -> 3 | C15: Roulement de réglage de hauteur | F15: Multi complex EP 2
C16: Faire le graissage manuel des points automatiques
B17: =B16+1 -> 1 | C17: 3 Piliers des etoiles d'entrée et sortie de la boucheuse | F17: Multi complex EP 2
B18: =B17+1 -> 2 | C18: Butée de la boucheuse | F18: Multi complex EP 2
C20: Contrôler si la lubrification automatique est effective sur tous les points ci-dessous; Déconnecter les flexibles - Mettre la pompe en manuel - verifier si la graisse s'echappe des flexibles
B21: 1 | C21: 3 Piliers des etoiles d'entrée et sortie de la boucheuse | F21: Multi complex EP 2
B22: 2 | C22: Butée de la boucheuse | F22: Multi complex EP 2
B23: 3 | C23: Roulement de la grande courone (4 points de graissage) | F23: Multi complex EP 2
B24: 4 | C24: Pignon d'attaque de la grande courone | F24: Multi complex EP 2
B25: 5 | C25: Roulement principal de la boucheuse (32040) | F25: Multi complex EP 2
B28: Nom et Visa Intervenants | E28: Commentaire Général | J28: Nom et Visa Responsables

Sheet Soutireuse Graissage 2-weekly
D3: CHECKLIST GRAISSAGE BIMENSUEL | J3: Semaine:
J4: =Date!B2 -> Week ... 2025
J5: Date:
B6: MACHINE | D6: Soutireuse L5
B7: INTERVENANT | D7: CHOUAGOUE
H10: FAIT?
B11: N° | C11: COMPOSANT/ZONE A GRAISSER | F11: Type de graisse / huile | G11: Durée | H11: OUI | I11: NON | J11: REMARQUES (MATERIEL + PIECES)
B12: 1 | C12: Effectuer le Graissage manuel exclusif
B13: =B12+1 -> 2 | C13: Roulement de la colonne centrale | F13: Mobilgrease FM 222
B14: =B13+1 -> 3
B15: =B14+1 -> 4
B16: =B15+1 -> 5
B17: =B16+1 -> 6
B18: =B17+1 -> 7
B19: =B18+1 -> 8
B20: =B19+1 -> 9
B21: =B20+1 -> 10
B22: =B21+1 -> 11
B23: =B22+1 -> 12
B33: =B23+1 -> 13
B34: Nom et Visa Intervenants | E34: Commentaire Général | J34: Nom et Visa Responsables

Sheet Soutireuse Graissage mensuel
D3: CHECKLIST GRAISSAGE MENSUELLE | J3: Semaine:
J4: =Date!B2 -> Week ... 2025
J5: Date:
B6: MACHINE | D6: Soutireuse L5
B7: INTERVENANT | D7: CHOUAGOUE
H10: FAIT?
B11: N° | C11: COMPOSANT/ZONE A GRAISSER | F11: Type de graisse / huile | G11: Durée | H11: OUI | I11: NON | J11: REMARQUES (MATERIEL + PIECES)
B12: 1 | C12: Effectuer le graissage des points manuels exclusif
B13: =B12+1 -> 2 | C13: Roulements des piliers de reglage en hauteur du carrousel (6 points de graissage) | F13: Multi complex EP 2
B14: =B13+1 -> 3 | C14: 6 paliers de la tremie à capsusles | F14: Multi complex EP 2
B15: =B14+1 -> 4
C16: Faire le graissage manuel des points automatiques
B17: =B16+1 -> 1 | C17: Roulement de la grande courone (4 points de graissage) | F17: Multi complex EP 2
B18: =B17+1 -> 2 | C18: Pignon d'attaque de la grande courone | F18: Multi complex EP 2
B19: =B18+1 -> 3 | C19: Roulement principal de la boucheuse (32040) | F19: Multi complex EP 2
C20: Contrôler qualité & niveau huile, vidanger si necessaire, faire appoint d'huile
B21: 1 | C21: Reducteur principal soutireuse | F21: Total carter Xep 220
B22: 2 | C22: Reducteur principal boucheuse | F22: Total carter Xep 220
B23: 3 | C23: Reducteur reglage en hauteur boucheuse | F23: Total carter Xep 220
B24: 4 | C24: Reducteur reglage en hauteur soutireuse | F24: Total carter Xep 220
B25: 5 | C25: Reducteurs convoyeurs entrée et sortie | F25: Total carter Xep 220
B26: 6 | C26: Reducteur levage capsules | F26: Total carter Xep 220
B27: 7 | C27: Reducteur tambour capsules | F27: Total carter Xep 220
B28: 8 | C28: Reducteur levage came soutireuse | F28: Total carter Xep 220
B29: 9
B30: Nom et Visa Intervenants | E30: Commentaire Général | J30: Nom et Visa Responsables

Sheet Soutireuse Lub Quad
D3: CHECKLIST Lubrification Quadrimestre | I3: CODE:
I4: =Date!B2 -> Week ... 2025
I5: Semaine:
B6: MACHINE | D6: Soutireuse
B7: INTERVENANT | D7: FONDJA
G10: FAIT?
B11: N° | C11: DESCRIPTION DES TACHES | F11: Durée | G11: OUI | H11: NON | I11: REMARQUES (MATERIEL + PIECES)
B12: 1 | C12: Contrôler niveau d'huile des moto-réducteurs de la machine (boucheuse, carrousel, levage boucheuse, moteur pompe à vide, levage cuve et came)
B13: =B12+1 -> 2
B14: =B13+1 -> 3
B15: Nom et Visa Intervenants | E15: Commentaire Général | I15: Nom et Visa Responsables

Sheet A1
B3: CHECKLIST MECANIQUE | G3: =Date!B2 -> Week ... 2025
C4: Apollo 1 | D4: =+'Line & frequency'!C1 -> CHAINE 5 | G4: =+'Line & frequency'!C2 -> HEBDOMADAIRE
B5: INTERVENANT | D5: KWEHATCHOU
C6: Heure début:……………………………………………… Heure fin : ……………………………………… | E6: FAIT?
B7: N° | C7: DESCRIPTION DES TACHES | D7: Durée | E7: OUI | F7: NON | G7: REMARQUES (MATERIEL + PIECES)
B8: 1 | C8: controler l'arret d'huile et le remplacé au besoin. Aucune fuite d'huile n'est acceptable.
B9: =B8+1 -> 2 | C9: controler l'usure des roulements et paliers de l'axe moteur et remplacer si necessaire.
B10: =+B9+1 -> 3 | C10: controler l'usure des dents du pignon sur l'axe moteur et le remplacé au besoin. Aucun glissement n'est acceptable.
B11: =B10+1 -> 4 | C11: controler l'alignement et la fixation du pignon de l'axe moteur et remedier au besoin. Insister sur le serrage des vis de fixation des pignons
B12: =B11+1 -> 5 | C12: Controler la fixation des paliers des roulements de l'axe des moteurs principaux. Insister sur le serrage des vis de fixation des ces paliers
B13: =B12+1 -> 6 | C13: controler l'usure du pignon de la roue de renvoie en dessous de la colonne et le remplacé au besoin. Aucun glissement n'est acceptable.
B14: =B13+1 -> 7 | C14: controler le jeu des roulements de la roue de renvoie en dessous de la colonne et remedier au besoin.
B15: =B14+1 -> 8 | C15: controler l'usure du pignon de la roue libre à l'entrée ou à la sortie et remplacé au besoin. Aucun glissement n'est acceptable.
B16: =B15+1 -> 9 | C16: controler l'alignement et la fixation de la roue libre et remedier au besoin.
B17: =B16+1 -> 10 | C17: controler l'état des courroies et remplacer au besoin.
B18: =B17+1 -> 11 | C18: controler les fuites sur le vérin, sa fixation remedier aux problèmes rencontrés.
B19: =B18+1 -> 12 | C19: controler les fuites sur les raccords les remediées au besoin. Aucune fuite sur ces raccords n'est permise.
B20: =B19+1 -> 13 | C20: controler l'usure des maillons de chaine et remplacer la chaine complète au besoin.
B21: =B20+1 -> 14 | C21: controler la presence des palettes sur tout le long du convoyeur et remplacer les palettes manquantes
B22: =B21+1 -> 15 | C22: controler la hauteur des rouleaux et ajuster les au besoin. Utiliser le niveau d'eau et se rassurer l'horizontalité entre les palettes d'apollo et les convoyeurs adjacents
... B26: =B25+1 -> 19 | C26: Controler la longueur de la chaine d'apollo en se rassurant qu'a vide la distance entre le capteur de surcharge et la barre oscillante est de 45mm.
B27: Commentaire | D27: Nom et Visa Intervenants | G27: Nom et Visa Responsables

Sheet A1 MENSUELLE 
B3: CHECKLIST MECANIQUE | G3: =Date!B2 -> Week ... 2025
C4: Apollo 1 | D4: =+'Line & frequency'!C1 -> CHAINE 5 | G4: MENSUELLE
B5: INTERVENANT | D5: TCHAMO +JOYCE
C6: Heure début:……………………………………………… Heure fin : ……………………………………… | E6: FAIT?
B7: N° | C7: DESCRIPTION DES TACHES | D7: Durée | E7: OUI | F7: NON | G7: REMARQUES (MATERIEL + PIECES)
B8: 1 | C8: controler l'usure des roulements et paliers de l'axe en dessous de la colonne et remplacer si necessaire.
B9: =B8+1 -> 2 | C9: controler l'usure des roues renvoie et remplacer au besoin
B10: =+B9+1 -> 3 | C10: controler la tension de la chaine et reduire les maillons si possible.
B11: =B10+1 -> 4 | C11: controler l'etat des roulements et élément se situant entre les roulements et remplacer les au besoin. Vérifier leur fixation sur la chaine et bien fixer au besoin.
B12: =+B11+1 -> 5 | C12: verifier que tous les rouleaux entrés et sorties tournent normamelent et remplacer les si les roulements sont absents.
B13: =B12+1 -> 6
B14: =+B13+1 -> 7
B15: =B14+1 -> 8
B16: =+B15+1 -> 9
B17: =B16+1 -> 10
B18: =+B17+1 -> 11
B19: =B18+1 -> 12
B20: =+B19+1 -> 13
B21: =B20+1 -> 14
B22: =+B21+1 -> 15
B23: =B22+1 -> 16
B24: =+B23+1 -> 17
B25: =B24+1 -> 18
B26: Commentaire | D26: Nom et Visa Intervenants | G26: Nom et Visa Responsables

Sheet A2
B3: CHECKLIST MECANIQUE | G3: =Date!B2 -> Week ... 2025
C4: Apollo 2 | D4: =+'Line & frequency'!C1 -> CHAINE 5 | G4: =+'Line & frequency'!C2 -> HEBDOMADAIRE
B5: INTERVENANT
C6: Heure début:……………………………………………… Heure fin : ……………………………………… | E6: FAIT?
B7: N° | C7: DESCRIPTION DES TACHES | D7: Durée | E7: OUI | F7: NON | G7: REMARQUES (MATERIEL + PIECES)
B8: 1 | C8: controler l'arret d'huile et le remplacé au besoin. Aucune fuite d'huile n'est acceptable.
B9: =B8+1 -> 2 | C9: controler l'usure des roulements et paliers de l'axe moteur et remplacer si necessaire.
B10: =+B9+1 -> 3 | C10: controler l'usure des dents du pignon sur l'axe moteur et le remplacé au besoin. Aucun glissement n'est acceptable.
B11: =B10+1 -> 4 | C11: controler l'alignement et la fixation du pignon de l'axe moteur et remedier au besoin. Insister sur le serrage des vis de fixation des pignons
B12: =B11+1 -> 5 | C12: Controler la fixation des paliers des roulements de l'axe des moteurs principaux. Insister sur le serrage des vis de fixation des ces paliers
B13: =B12+1 -> 6 | C13: controler l'usure du pignon de la roue de renvoie en dessous de la colonne et le remplacé au besoin. Aucun glissement n'est acceptable.
B14: =B13+1 -> 7 | C14: controler le jeu des roulements de la roue de renvoie en dessous de la colonne et remedier au besoin.
B15: =B14+1 -> 8 | C15: controler l'usure du pignon de la roue libre à l'entrée ou à la sortie et remplacé au besoin. Aucun glissement n'est acceptable.
B16: =B15+1 -> 9 | C16: controler l'alignement et la fixation de la roue libre et remedier au besoin.
B17: =B16+1 -> 10 | C17: controler l'état des courroies et remplacer au besoin.
B18: =B17+1 -> 11 | C18: controler les fuites sur le vérin, sa fixation remedier aux problèmes rencontrés.
B19: =B18+1 -> 12 | C19: controler les fuites sur les raccords les remediées au besoin. Aucune fuite sur ces raccords n'est permise.
B20: =B19+1 -> 13 | C20: controler l'usure des maillons de chaine et remplacer la chaine complète au besoin.
B21: =B20+1 -> 14 | C21: controler la presence des palettes sur tout le long du convoyeur et remplacer les palettes manquantes
B22: =B21+1 -> 15 | C22: controler la hauteur des rouleaux et ajuster les au besoin. Utiliser le niveau d'eau et se rassurer l'horizontalité entre les palettes d'apollo et les convoyeurs adjacents
... B26: =B25+1 -> 19 | C26: Controler la longueur de la chaine d'apollo en se rassurant qu'a vide la distance entre le capteur de surcharge et la barre oscillante est de 45mm.
B27: Commentaire | D27: Nom et Visa Intervenants | G27: Nom et Visa Responsables

Sheet A2 MENSUELLE
B3: CHECKLIST MECANIQUE | G3: =Date!B2 -> Week ... 2025
C4: Apollo 2 | D4: =+'Line & frequency'!C1 -> CHAINE 5 | G4: MENSUELLE
B5: INTERVENANT
C6: Heure début:……………………………………………… Heure fin : ……………………………………… | E6: FAIT?
B7: N° | C7: DESCRIPTION DES TACHES | D7: Durée | E7: OUI | F7: NON | G7: REMARQUES (MATERIEL + PIECES)
B8: 1 | C8: controler l'usure des roulements et paliers de l'axe en dessous de la colonne et remplacer si necessaire.
B9: =B8+1 -> 2 | C9: controler l'usure des roues renvoie et remplacer au besoin
B10: =+B9+1 -> 3 | C10: controler la tension de la chaine et reduire les maillons si possible.
B11: =B10+1 -> 4 | C11: controler l'etat des roulements et élément se situant entre les roulements et remplacer les au besoin. Vérifier leur fixation sur la chaine et bien fixer au besoin.
B12: =+B11+1 -> 5 | C12: verifier que tous les rouleaux entrés et sorties tournent normamelent et remplacer les si les roulements sont absents.
B13: =B12+1 -> 6 | C13: Reduire un maillon de chaine sur ce convoyeur
B14: =+B13+1 -> 7
B15: =B14+1 -> 8
B16: =+B15+1 -> 9
B17: =B16+1 -> 10
B18: =+B17+1 -> 11
B19: =B18+1 -> 12
B20: =+B19+1 -> 13
B21: =B20+1 -> 14
B22: =+B21+1 -> 15
B23: =B22+1 -> 16
B24: =+B23+1 -> 17
B25: =B24+1 -> 18
B26: Commentaire | D26: Nom et Visa Intervenants | G26: Nom et Visa Responsables

Sheet A3
B3: CHECKLIST MECANIQUE | G3: =Date!B2 -> Week ... 2025
C4: Apollo 3 | D4: =+'Line & frequency'!C1 -> CHAINE 5 | G4: =+'Line & frequency'!C2 -> HEBDOMADAIRE
B5: INTERVENANT
C6: Heure début:……………………………………………… Heure fin : ……………………………………… | E6: FAIT?
B7: N° | C7: DESCRIPTION DES TACHES | D7: Durée | E7: OUI | F7: NON | G7: REMARQUES (MATERIEL + PIECES)
B8: 1 | C8: controler l'arret d'huile et le remplacé au besoin. Aucune fuite d'huile n'est acceptable.
B9: =B8+1 -> 2 | C9: controler l'usure des roulements et paliers de l'axe moteur et remplacer si necessaire.
B10: =+B9+1 -> 3 | C10: controler l'usure des dents du pignon sur l'axe moteur et le remplacé au besoin. Aucun glissement n'est acceptable.
B11: =B10+1 -> 4 | C11: controler l'alignement et la fixation du pignon de l'axe moteur et remedier au besoin. Insister sur le serrage des vis de fixation des pignons
B12: =B11+1 -> 5 | C12: Controler la fixation des paliers des roulements de l'axe des moteurs principaux. Insister sur le serrage des vis de fixation des ces paliers
B13: =B12+1 -> 6 | C13: controler l'usure du pignon de la roue de renvoie en dessous de la colonne et le remplacé au besoin. Aucun glissement n'est acceptable.
B14: =B13+1 -> 7 | C14: controler le jeu des roulements de la roue de renvoie en dessous de la colonne et remedier au besoin.
B15: =B14+1 -> 8 | C15: controler l'usure du pignon de la roue libre à l'entrée ou à la sortie et remplacé au besoin. Aucun glissement n'est acceptable.
B16: =B15+1 -> 9 | C16: controler l'alignement et la fixation de la roue libre et remedier au besoin.
B17: =B16+1 -> 10 | C17: controler l'état des courroies et remplacer au besoin.
B18: =B17+1 -> 11 | C18: controler les fuites sur le vérin, sa fixation remedier aux problèmes rencontrés.
B19: =B18+1 -> 12 | C19: controler les fuites sur les raccords les remediées au besoin. Aucune fuite sur ces raccords n'est permise.
B20: =B19+1 -> 13 | C20: controler l'usure des maillons de chaine et remplacer la chaine complète au besoin.
B21: =B20+1 -> 14 | C21: controler la presence des palettes sur tout le long du convoyeur et remplacer les palettes manquantes
B22: =B21+1 -> 15 | C22: controler la hauteur des rouleaux et ajuster les au besoin. Utiliser le niveau d'eau et se rassurer l'horizontalité entre les palettes d'apollo et les convoyeurs adjacents
... B28: =B27+1 -> 21 | C28: Inspecter maillons cassés sur la chaine principale Apollo 3 et remplacer
B29: Commentaire | D29: Nom et Visa Intervenants | G29: Nom et Visa Responsables

Sheet A3 MENSUELLE
B3: CHECKLIST MECANIQUE | G3: =Date!B2 -> Week ... 2025
C4: Apollo 3 | D4: =+'Line & frequency'!C1 -> CHAINE 5 | G4: MENSUELLE
B5: INTERVENANT
C6: Heure début:……………………………………………… Heure fin : ……………………………………… | E6: FAIT?
B7: N° | C7: DESCRIPTION DES TACHES | D7: Durée | E7: OUI | F7: NON | G7: REMARQUES (MATERIEL + PIECES)
B8: 1 | C8: controler l'usure des roulements et paliers de l'axe en dessous de la colonne et remplacer si necessaire.
B9: =B8+1 -> 2 | C9: controler l'usure des roues renvoie et remplacer au besoin
B10: =+B9+1 -> 3 | C10: controler la tension de la chaine et reduire les maillons si possible.
B11: =B10+1 -> 4 | C11: controler l'etat des roulements et élément se situant entre les roulements et remplacer les au besoin. Vérifier leur fixation sur la chaine et bien fixer au besoin.
B12: =+B11+1 -> 5 | C12: verifier que tous les rouleaux entrés et sorties tournent normamelent et remplacer les si les roulements sont absents.
B13: =B12+1 -> 6 | C13: Reduire un maillon de chaine sur ce convoyeur
B14: =+B13+1 -> 7
B15: =B14+1 -> 8
B16: =+B15+1 -> 9
B17: =B16+1 -> 10
B18: =+B17+1 -> 11
B19: =B18+1 -> 12
B20: =+B19+1 -> 13
B21: =B20+1 -> 14
B22: =+B21+1 -> 15
B23: =B22+1 -> 16
B24: =+B23+1 -> 17
B25: =B24+1 -> 18
B26: Commentaire | D26: Nom et Visa Intervenants | G26: Nom et Visa Responsables

Sheet A4
B3: CHECKLIST MECANIQUE | G3: =Date!B2 -> Week ... 2025
C4: Apollo 4 | D4: =+'Line & frequency'!C1 -> CHAINE 5 | G4: =+'Line & frequency'!C2 -> HEBDOMADAIRE
B5: INTERVENANT
C6: Heure début:……………………………………………… Heure fin : ……………………………………… | E6: FAIT?
B7: N° | C7: DESCRIPTION DES TACHES | D7: Durée | E7: OUI | F7: NON | G7: REMARQUES (MATERIEL + PIECES)
B8: 1 | C8: controler l'arret d'huile et le remplacé au besoin. Aucune fuite d'huile n'est acceptable.
B9: =B8+1 -> 2 | C9: controler l'usure des roulements et paliers de l'axe moteur et remplacer si necessaire.
B10: =+B9+1 -> 3 | C10: controler l'usure des dents du pignon sur l'axe moteur et le remplacé au besoin. Aucun glissement n'est acceptable.
B11: =B10+1 -> 4 | C11: controler l'alignement et la fixation du pignon de l'axe moteur et remedier au besoin. Insister sur le serrage des vis de fixation des pignons
B12: =+B11+1 -> 5 | C12: controler l'usure du pignon de la roue de renvoie en dessous de la colonne et le remplacé au besoin. Aucun glissement n'est acceptable.
B13: =+B12+1 -> 6 | C13: Controler la fixation des paliers des roulements de l'axe des moteurs principaux. Insister sur le serrage des vis de fixation des ces paliers
B14: =+B13+1 -> 7 | C14: controler le jeu des roulements de la roue de renvoie en dessous de la colonne et remedier au besoin.
B15: =+B14+1 -> 8 | C15: controler l'usure du pignon de la roue libre à l'entrée ou à la sortie et remplacé au besoin. Aucun glissement n'est acceptable.
B16: =+B15+1 -> 9 | C16: controler l'alignement et la fixation de la roue libre et remedier au besoin.
B17: =+B16+1 -> 10 | C17: controler l'état des courroies et remplacer au besoin.
B18: =+B17+1 -> 11 | C18: controler les fuites sur le vérin, sa fixation remedier aux problèmes rencontrés.
B19: =+B18+1 -> 12 | C19: controler les fuites sur les raccords les remediées au besoin. Aucune fuite sur ces raccords n'est permise.
B20: =+B19+1 -> 13 | C20: controler l'usure des maillons de chaine et remplacer la chaine complète au besoin.
B21: =+B20+1 -> 14 | C21: controler la presence des palettes sur tout le long du convoyeur et remplacer les palettes manquantes
B22: =+B21+1 -> 15 | C22: controler la hauteur des rouleaux et ajuster les au besoin. Utiliser le niveau d'eau et se rassurer l'horizontalité entre les palettes d'apollo et les convoyeurs adjacents
B23: =+B22+1 -> 16 | C23: controler la presence des embouts en debut et fin de glissières et remplacer si elles sont absentes.
... B26: =+B25+1 -> 19 | C26: Controler la longueur de la chaine d'apollo en se rassurant qu'a vide la distance entre le capteur de surcharge et la barre oscillante est de 45mm.
B27: =+B26+1 -> 20
B28: =+B27+1 -> 21
B29: Commentaire | D29: Nom et Visa Intervenants | G29: Nom et Visa Responsables

Sheet A4 MENSUELLE
B3: CHECKLIST MECANIQUE | G3: =Date!B2 -> Week ... 2025
C4: Apollo 4 | D4: =+'Line & frequency'!C1 -> CHAINE 5 | G4: MENSUELLE
B5: INTERVENANT | D5: CHIMI+KWEHATCHOU
C6: Heure début:……………………………………………… Heure fin : ……………………………………… | E6: FAIT?
B7: N° | C7: DESCRIPTION DES TACHES | D7: Durée | E7: OUI | F7: NON | G7: REMARQUES (MATERIEL + PIECES)
B8: 1 | C8: controler l'usure des roulements et paliers de l'axe en dessous de la colonne et remplacer si necessaire.
B9: =B8+1 -> 2 | C9: controler l'usure des roues renvoie et remplacer au besoin
B10: =+B9+1 -> 3 | C10: controler la tension de la chaine et reduire les maillons si possible.
B11: =B10+1 -> 4 | C11: controler l'etat des roulements et élément se situant entre les roulements et remplacer les au besoin. Vérifier leur fixation sur la chaine et bien fixer au besoin.
B12: =+B11+1 -> 5 | C12: verifier que tous les rouleaux entrés et sorties tournent normamelent et remplacer les si les roulements sont absents.
B13: =B12+1 -> 6 | C13: Reduire un maillon de chaine sur ce convoyeur
B14: =+B13+1 -> 7
B15: =B14+1 -> 8
B16: =+B15+1 -> 9
B17: =B16+1 -> 10
B18: =+B17+1 -> 11
B19: =B18+1 -> 12
B20: =+B19+1 -> 13
B21: =B20+1 -> 14
B22: =+B21+1 -> 15
B23: =B22+1 -> 16
B24: =+B23+1 -> 17
B25: =B24+1 -> 18
B26: Commentaire | D26: Nom et Visa Intervenants | G26: Nom et Visa Responsables

Sheet BLOWER Hebdo
B3: CHECKLIST MECANIQUE | G3: =Date!B2 -> Week ... 2025
C4: Souffleur | D4: =+'Line & frequency'!C1 -> CHAINE 5 | G4: Hebdomadaire
B5: INTERVENANT
C6: Heure début:……………………………………………… Heure fin : ……………………………………… | E6: FAIT?
B7: N° | C7: DESCRIPTION DES TACHES | D7: Durée | E7: OUI | F7: NON | G7: REMARQUES (MATERIEL + PIECES)
B8: 1 | C8: Controler le guidage des bouteilles à l'interieur et ajuster si necessaire
B9: =B8+1 -> 2 | C9: Controler la position des buses sur les bouteilles et ajuster si necessaire
B10: =+B9+1 -> 3 | C10: Controler la fixation des supports des buses et serrer si necessaire
B11: =B10+1 -> 4 | C11: Controler le fonctionnement des 4 souffleurs et remedier si necessaire
B12: =+B11+1 -> 5 | C12: Deboucher toutes les buses bouchées
B13: =B12+1 -> 6 | C13: Nettoyer les filtres sur les conduites d'aspiration des 4 souffleurs
B14: =+B13+1 -> 7
B15: =B14+1 -> 8
B16: Commentaire | D16: Nom et Visa Intervenants | G16: Nom et Visa Responsables

Sheet Décaisseuse
B3: CHECKLIST MECANIQUE | G3: =Date!B2 -> Week ... 2025
C4: DECAISSEUSE | D4: =+'Line & frequency'!C1 -> CHAINE 5 | G4: =+'Line & frequency'!C2 -> HEBDOMADAIRE
B5: INTERVENANT | D5: KUETE
C6: Heure début:……………………………………………… Heure fin : ……………………………………… | E6: FAIT?
B7: N° | C7: DESCRIPTION DES TACHES | D7: Durée | E7: OUI | F7: NON | G7: REMARQUES (MATERIEL + PIECES)
B8: 1 | C8: controler l'arret d'huile du reducteur principal et le remplacé au besoin. Aucune fuite d'huile n'est acceptable.
B9: =B8+1 -> 2 | C9: controler l'arret d'huile du reducteur numéro 2 et le remplacé au besoin. Aucune fuite d'huile n'est acceptable.
B10: =+B9+1 -> 3 | C10: controler les brides de serrage sur l'arbre des reducteurs principaux et remplacer au besoin
B11: =B10+1 -> 4 | C11: controler la fixation des tiges portant les freins de sécurité (haut et bas) et bien serrer au besoin.
B12: =+B11+1 -> 5 | C12: controler l'état des roulements de paliers du chariot de levage et les remplacés au besoin
B13: =B12+1 -> 6 | C13: controler la fixation des courroies sur le chariot de levage et ameliorer sa fixation si necessaire.
B14: =+B13+1 -> 7 | C14: controler les fuites sur les élements pneumatiques de la trasverse
B15: =B14+1 -> 8 | C15: controler l'état des rouleaux de guidage, leurs roulements et circlips de la traverse et remedier au besoin
B16: =+B15+1 -> 9 | C16: controler l'état des roulements et paliers de la traverse et remedier au besoin
B17: =B16+1 -> 10 | C17: controler l'arret d'huile du reducteur d'entrainement de la traverse et le remplacé au besoin. Aucune fuite d'huile n'est acceptable.
B18: =+B17+1 -> 11 | C18: Controler la fixation et la tension des courroies de la traverse et remedier si necessaire
B19: =B18+1 -> 12 | C19: Controler l'etat des roues libres et pignons de la traverse, leurs manchons de serrage et remedier aux problèmes rencontrés
B20: =+B19+1 -> 13 | C20: contrôler l'état des roulements des rouleaux du support des grappins et remplacer au besoin. Aucun déséquilibre du chariot n'est autorisé.
B21: =B20+1 -> 14 | C21: contrôler les circlips des rouleaux du support des grappins et remplacer au besoin. Aucun déséquilibre du chariot n'est autorisé.
B22: =+B21+1 -> 15 | C22: controler les fuites au niveau du vérin et raccords et remedier au problème rencontrés
B23: =B22+1 -> 16 | C23: controler la prise et la pose des bouteilles sur la table. Utiliser la commande manuelle à l'HMI.
B24: =+B23+1 -> 17 | C24: controler l'état du silencieux sur l'electrovanne d'arrivée d'air sur les grappins et remplacer au besoin.
B25: =B24+1 -> 18 | C25: controler les fuites sur les raccords de l'electrovanne d'alimentation du distributeur d'air des grappins et les remediées au besoin. Aucune fuite sur ces raccords n'est permise.
B26: =+B25+1 -> 19 | C26: controler les fuites sur les raccords du distributeur d'air sur les grappins et les remediées au besoin. Aucune fuite sur ces raccords n'est permise.
B27: =B26+1 -> 20 | C27: demonter et nettoyer la goutière en dessous de la table puis remonter.
B28: =+B27+1 -> 21 | C28: controler l'usure de la tole de transfert après la table et la remplacée au besoin.
B29: =B28+1 -> 22 | C29: controler l'arret d'huile du reducteur d'entrainment de la table et le remplacé au besoin. Aucune fuite d'huile n'est acceptable.
B30: =+B29+1 -> 23 | C30: controler le reglage des guides bouteilles sur le convoyeur juste avant la table et ajuster au besoin.
B31: =+B30+1 -> 24 | C31: demonter et nettoyer la goutière en dessous du convoyeur interne puis remonter.
B32: =B31+1 -> 25 | C32: controler l'arret d'huile du reducteur d'entrainement du convoyeur interne et le remplacé au besoin. Aucune fuite d'huile n'est acceptable.
B33: =+B32+1 -> 26 | C33: Controler le fonctionnement du vérin de blocage du vérin de blocage du convoyeur interne et remedier au problèmes rencontrés
B34: =B33+1 -> 27 | C34: controler le reglage des guides casiers à l'entrée et ajuster au besoin.
B35: =+B34+1 -> 28 | C35: Controler le fonctionnement du vérin de blocage à l'entrée et remedier aux problèmes rencontrés
B36: =B35+1 -> 29 | C36: controler l'état des silencieux du cadre des grappins, les nettoyés ou les remplacés au besoin. Aucun bruit anormal n'est autorisé.
B37: =+B36+1 -> 30 | C37: controler l'état des couirroies du guide frame et lesremplacés au besoin. Aucune fissure n'est acceptable sur ces courroies. Se rassurer que les cadres de protection des courroies sont bien montés.
B38: =B37+1 -> 31 | C38: controler l'arret d'huile du reducteur d'entrainement du guide frame et le remplacé au besoin. Aucune fuite d'huile n'est acceptable.
B39: =+B38+1 -> 32 | C39: controler l'ouverture et la fermeture de la vanne manuelle du bloc d'arrivée d'air de la machine et remplacer la au besoin.
B40: =B39+1 -> 33 | C40: demonter le filtre à l'interieur du silencieux et le nettoyer si nécessaire
B41: =+B40+1 -> 34 | C41: controler les fuites au niveau des raccords d'air du bloc d'arrivée d'air et les remplacés au besoin
B42: =B41+1 -> 35 | C42: Tester la machine
...

Sheet Décaisseuse Quatherly
B3: CHECKLIST MECANIQUE | G3: =Date!B2 -> Week ... 2025
C4: DECAISSEUSE | D4: =+'Line & frequency'!C1 -> CHAINE 5 | G4: Trimestriel
B5: INTERVENANT | D5: KUETE
C6: Heure début:……………………………………………… Heure fin : ……………………………………… | E6: FAIT?
B7: N° | C7: DESCRIPTION DES TACHES | D7: Durée | E7: OUI | F7: NON | G7: REMARQUES (MATERIEL + PIECES)
B8: 1 | C8: controler l'état des engrenages à l'interieur du reducteur N°1 du chariot de levage et remplacer le réducteur complet au besoin
B9: =B8+1 -> 2 | C9: controler les roulements à l'interieur du reducteur N°1 du chariot de levage et les remplacés au besoin. Aucun jeu à l'inteurieur du réducteur n'est acceptable
B10: =+B9+1 -> 3 | C10: controler l'état des engrenages à l'interieur du reducteur N°2 du chariot de levageet remplacer le réducteur complet au besoin
B11: =B10+1 -> 4 | C11: controler les roulements à l'interieur du reducteur N°2 du chariot de levage et les remplacés au besoin. Aucun jeu à l'inteurieur du réducteur n'est acceptable
B12: =+B11+1 -> 5 | C12: controler l'état des engrenages du reducteur de la traverse et remplacer le réducteur complet au besoin
B13: =B12+1 -> 6 | C13: controler les roulements du réducteur de la traverse et les remplacés au besoin. Aucun jeu à l'inteurieur du réducteur n'est acceptable
B14: =+B13+1 -> 7 | C14: ouvrir, faire nettoyer et inspecter chaines à palettes, glissières, rails, pignons, arbre et roues libres de la table et remedier aux problèmes rencontrés.
B15: =B14+1 -> 8
B16: Commentaire | D16: Nom et Visa Intervenants | G16: Nom et Visa Responsables

Sheet Encaisseuse
B3: CHECKLIST MECANIQUE | G3: =Date!B2 -> Week ... 2025
C4: ENCAISSEUSE | D4: =+'Line & frequency'!C1 -> CHAINE 5 | G4: =+'Line & frequency'!C2 -> HEBDOMADAIRE
B5: INTERVENANT | D5: KUETE
C6: Heure début:……………………………………………… Heure fin : ……………………………………… | E6: FAIT?
B7: N° | C7: DESCRIPTION DES TACHES | D7: Durée | E7: OUI | F7: NON | G7: REMARQUES (MATERIEL + PIECES)
B8: 1 | C8: controler l'arret d'huile du reducteur principal et le remplacé au besoin. Aucune fuite d'huile n'est acceptable.
B9: =B8+1 -> 2 | C9: controler l'arret d'huile du reducteur numéro 2 et le remplacé au besoin. Aucune fuite d'huile n'est acceptable.
B10: =+B9+1 -> 3 | C10: controler les brides de serrage sur l'arbre des reducteurs principaux et remplacer au besoin
B11: =B10+1 -> 4 | C11: controler la fixation des tiges portant les freins de sécurité (haut et bas) et bien serrer au besoin.
B12: 5 | C12: controler les fuites sur les élements pneumatiques ( flexible, raccord , vérins…) de la trasverse
B13: =B12+1 -> 6 | C13: controler l'état des rouleaux de guidage, leurs roulements et circlips de la traverse et remedier au besoin
B14: =+B13+1 -> 7 | C14: controler l'état des roulements et paliers de la traverse et remedier au besoin
B15: =B14+1 -> 8 | C15: controler l'arret d'huile du reducteur d'entrainement de la traverse et le remplacé au besoin. Aucune fuite d'huile n'est acceptable.
B16: =+B15+1 -> 9 | C16: Controler la fixation et la tension des courroies de la traverse et remedier si necessaire
B17: =B16+1 -> 10 | C17: Controler l'etat des roues libres et pignons de la traverse, leurs manchons de serrage et remedier aux problèmes rencontrés
B18: =+B17+1 -> 11 | C18: contrôler l'état des roulements des rouleaux du support des grappins et remplacer au besoin. Aucun déséquilibre du chariot n'est autorisé.
B19: =B18+1 -> 12 | C19: contrôler les circlips des rouleaux du support des grappins et remplacer au besoin. Aucun déséquilibre du chariot n'est autorisé.
B20: =+B19+1 -> 13 | C20: controler les fuites au niveau du vérin et raccords et remedier au problème rencontrés
B21: =B20+1 -> 14 | C21: controler la prise et la pose des bouteilles sur la table. Utiliser la commande manuelle à l'HMI.
B22: =+B21+1 -> 15 | C22: controler l'état du silencieux sur l'electrovanne d'arrivée d'air sur les grappins et remplacer au besoin.
B23: =B22+1 -> 16 | C23: controler les fuites sur les raccords de l'electrovanne d'alimentation du distributeur d'air des grappins et les remediées au besoin. Aucune fuite sur ces raccords n'est permise.
B24: =+B23+1 -> 17 | C24: controler les fuites sur les raccords du distributeur d'air sur les grappins et les remediées au besoin. Aucune fuite sur ces raccords n'est permise.
B25: =B24+1 -> 18 | C25: demonter et nettoyer la goutière en dessous de la table puis remonter.
B26: =+B25+1 -> 19 | C26: controler l'usure de la tole de transfert avant la table et la remplacée au besoin.
B27: =B26+1 -> 20 | C27: controler l'arret d'huile du reducteur d'entrainment de la table et le remplacé au besoin. Aucune fuite d'huile n'est acceptable.
B28: =+B27+1 -> 21 | C28: controler le guidage des bouteilles sur la table et reparer au besoin
B29: =B28+1 -> 22 | C29: controler la fixation et le reglage des bouteilles dans les couloirs sur la table
B30: =+B29+1 -> 23 | C30: Controler le fonctionnement des deux vérins de blocage sur la table et remedier au problèmes rencontrés
B31: =B30+1 -> 24 | C31: controler le reglage des guides bouteilles sur le convoyeur juste avant la table et ajuster au besoin.
B32: =+B31+1 -> 25 | C32: demonter et nettoyer la goutière en dessous du convoyeur interne puis remonter.
B33: =B32+1 -> 26 | C33: controler l'arret d'huile du reducteur d'entrainement du convoyeur interne et le remplacé au besoin. Aucune fuite d'huile n'est acceptable.
B34: =+B33+1 -> 27 | C34: Controler le fonctionnement du vérin de blocage du vérin de blocage du convoyeur interne et remedier au problèmes rencontrés
B35: =B34+1 -> 28 | C35: controler le reglage des guides casiers à l'entrée et ajuster au besoin.
B36: =+B35+1 -> 29 | C36: Controler le fonctionnement du vérin de blocage à l'entrée et remedier aux problèmes rencontrés
B37: =B36+1 -> 30 | C37: controler l'état des silencieux du cadre des grappins, les nettoyés ou les remplacés au besoin. Aucun bruit anormal n'est autorisé.
B38: =+B37+1 -> 31 | C38: controler l'état des couirroies du guide frame et lesremplacés au besoin. Aucune fissure n'est acceptable sur ces courroies. Se rassurer que les cadres de protection des courroies sont bien montés.
B39: =B38+1 -> 32 | C39: controler l'arret d'huile du reducteur d'entrainement du guide frame et le remplacé au besoin. Aucune fuite d'huile n'est acceptable.
B40: =+B39+1 -> 33 | C40: controler l'ouverture et la fermeture de la vanne manuelle du bloc d'arrivée d'air de la machine et remplacer la au besoin.
B41: =B40+1 -> 34 | C41: demonter le filtre à l'interieur du silencieux et le nettoyer si nécessaire
B42: =+B41+1 -> 35 | C42: controler les fuites au niveau des raccords d'air du bloc d'arrivée d'air et les remplacés au besoin
...

Sheet Encaisseuse Tri
B3: CHECKLIST MECANIQUE | G3: =Date!B2 -> Week ... 2025
C4: ENCAISSEUSE | D4: =+'Line & frequency'!C1 -> CHAINE 5 | G4: Trimestriel
B5: INTERVENANT | D5: KUETE
C6: Heure début:……………………………………………… Heure fin : ……………………………………… | E6: FAIT?
B7: N° | C7: DESCRIPTION DES TACHES | D7: Durée | E7: OUI | F7: NON | G7: REMARQUES (MATERIEL + PIECES)
B8: 1 | C8: controler l'état des roulements de paliers du chariot de levage et les remplacés au besoin
B9: =B8+1 -> 2 | C9: controler la fixation de la courroie sur le chariot et ameliorer sa fixation si necessaire.
B10: 3 | C10: controler l'état des roulements et paliers de la traverse et remedier au besoin
B11: 4 | C11: Controler la fixation et la tension des courroies de la traverse et remedier si necessaire
B12: =B11+1 -> 5 | C12: controler l'usure des courroies du chariot et remplacer les en cas de fissure. Aucune fissure n'est permise
B13: 6 | C13: controler l'usure des courroies de la traverse et remplacer les en cas de fissure. Aucune fissure n'est permise
B14: 7 | C14: controler le fonctionnement des vérins au dessus du chariot utilisés pour le changement de format
B15: =B14+1 -> 8 | C15: controler l'usure des chaines, pignons, roues libres, glissières, rails, roulements de paliers et pieds de convoyeurs de la 1ere table de chargement et les remplacées si necessaire
B16: 9 | C16: controler l'usure des chaines, pignons, roues libres, glissières, rails, roulements de paliers et pieds de convoyeurs du convoyeur interne et les remplacées si necessaire
B17: =B16+1 -> 10 | C17: controler les fuites sur le vérin de blocage de casiers à l'interieur du convoyeur interne
B18: 11 | C18: Nettoyer les pignons d'entrainement des courroies du guide frame
B19: =B18+1 -> 12 | C19: remplacer les courroies du guide frame et bien fixer les cadres de protection. Aucune casse de bouteille ne doit y parvenir.
B20: 13 | C20: controler l'état des roulements et paliers de l'arbre du moteur entrainant le guide frame et les remplacé si necessaire
B21: 14
B22: Commentaire | D22: Nom et Visa Intervenants | G22: Nom et Visa Responsables

Sheet Encaisseuse Semestriel
B3: CHECKLIST MECANIQUE | G3: =Date!B2 -> Week ... 2025
C4: ENCAISSEUSE | D4: =+'Line & frequency'!C1 -> CHAINE 5 | G4: Semestriel
B5: INTERVENANT | D5: JIOFACK
C6: Heure début:……………………………………………… Heure fin : ……………………………………… | E6: FAIT?
B7: N° | C7: DESCRIPTION DES TACHES | D7: Durée | E7: OUI | F7: NON | G7: REMARQUES (MATERIEL + PIECES)
B8: 1 | C8: controler l'usure des roues dentées du chariot et remplacées au besoin. Aucun glissement n'est acceptable.
B9: =B8+1 -> 2 | C9: controler l'usure des roues dentées de la traverse et remplacées au besoin. Aucun glissement n'est acceptable.
B10: =+B9+1 -> 3 | C10: controler l'usure sur la portée des roulements des demi arbres du chariot de levage et remplacer au besoin.
B11: =B10+1 -> 4 | C11: controler l'usure et la tension des courroies de la traverse et du chariot et remplacées si necessaire.
B12: =+B11+1 -> 5 | C12: controler l'usure des coulisseaux et des rails du guide frame et remplacer au besoin
B13: =B12+1 -> 6 | C13: controler l'usure des coulisseaux et des rails du didpositif de reglage à l'entrée et remplacer au besoin
B14: =+B13+1 -> 7 | C14: controler les roulements des roues dentées du dessus.
B15: =B14+1 -> 8 | C15: controler le débit d'envoie de la pompe de graisse et remedier au problème au besoin.
B16: =+B15+1 -> 9 | C16: controler la sortie de la graisse sur toutes les voies de sortie du distributeur et deboucher au besoin.
B17: =B16+1 -> 10
B18: =+B17+1 -> 11
B19: Commentaire | D19: Nom et Visa Intervenants | G19: Nom et Visa Responsables

Sheet Dépalettiseur
B3: CHECKLIST MECANIQUE | G3: =Date!B2 -> Week ... 2025
C4: DEPALETTISEUR | D4: =+'Line & frequency'!C1 -> CHAINE 5 | G4: =+'Line & frequency'!C2 -> HEBDOMADAIRE
B5: INTERVENANT | D5: TANKWA
C6: Heure début:……………………………………………… Heure fin : ……………………………………… | E6: FAIT?
B7: N° | C7: DESCRIPTION DES TACHES | D7: Durée | E7: OUI | F7: NON | G7: REMARQUES (MATERIEL + PIECES)
B8: 1 | C8: controler les brides de serrage sur l'arbre des reducteurs principaux et remplacer au besoin
B9: =B8+1 -> 2 | C9: controler la fixation des tiges portant les freins de sécurité (haut et bas) et bien serrer au besoin.
B10: 3 | C10: controler l'état des roulements de paliers du chariot de levage et les remplacés au besoin
B11: =B10+1 -> 4 | C11: controler la fixation des courroies sur le chariot de levage et ameliorer sa fixation si necessaire.
B12: 5 | C12: controler les fuites sur les élements pneumatiques de la trasverse etremedier au besoin
B13: 6 | C13: controler l'état des rouleaux de guidage, leurs roulements et circlips de la traverse et remedier au besoin
B14: 7 | C14: controler l'état des roulements et paliers de la traverse et remedier au besoin
B15: 8 | C15: Controler la fixation et la tension des courroies de la traverse et remedier si necessaire
B16: 9 | C16: Controler l'etat des roues libres et pignons de la traverse, leurs manchons de serrage et remedier aux problèmes rencontrés
B17: 10 | C17: controler le fonctionnement de la barre de stabilisation des casiers et reparer le clamp element au besoin
B18: 11 | C18: verifier l'alignement et le serrage des doigts par rapport aux casiers et les regler si necessaire
B19: 12 | C19: vérifier la présence du teflon en bout des doigts et faire fabriquer au besoin
B20: 13 | C20: Controler la fixation des slides 1 et 2 et remedier aux problèmes rencontrés
B21: 14 | C21: controler le guidage en translation ( galets de guidage, leurs roulements et circlip ) des slides 1 et 2 et remedier au beoin.
B22: 15 | C22: Controler l'usure des courroies des slides 1 et 2 et remplacer au besoin
B23: 16 | C23: controler le fonctionnement du vérin de blocage des caisers entre les tables et remplacer au besoin. Inspecter raccords du vérin et distributeur et remplacer si necessaire
... B48: 41 | C48: Controler les éléments du remplacement de format et rassurer que tous les éléments sont presents
B49: Commentaire | D49: Nom et Visa Intervenants | G49: Nom et Visa Responsables

Sheet Dépalettiseur Mensuel
B3: CHECKLIST MECANIQUE | G3: =Date!B2 -> Week ... 2025
C4: DEPALETTISEUR | D4: =+'Line & frequency'!C1 -> CHAINE 5 | G4: Mensuel
B5: INTERVENANT
C6: Heure début:……………………………………………… Heure fin : ……………………………………… | E6: FAIT?
B7: N° | C7: DESCRIPTION DES TACHES | D7: Durée | E7: OUI | F7: NON | G7: REMARQUES (MATERIEL + PIECES)
B8: 1 | C8: controler l'état des roulements / drive unit support carriage / transverse conveyor
B9: =B8+1 -> 2 | C9: controler l'usure des chaines de la 1ere table de chargement et les remplacées si necessaire / élements d'entrainement table 1 / table 1
B10: =+B9+1 -> 3 | C10: controler l'état des pignons et les remplacées si necessaire / élements d'entrainement table 1 / table 1
B11: =B10+1 -> 4 | C11: controler l'état des roues libres et les remplacées si necessaire / élements d'entrainement table 1 / table 1
B12: =+B11+1 -> 5 | C12: controler l'état des roulements et paliers des tapis et les remplacé si necessaire / élements d'entrainement table 1 / table 1
B13: =B12+1 -> 6 | C13: controler la tension des chaines et refaire les tendeurs au besoin. / élements d'entrainement table 1 / table 1
