Workbook

Sheet Convoyeur casiers
B3: CHECKLIST PROCESS TECHNICIAN | G3: Date:
C4: CONVOYEUR CASIERS | D4: =+'Line & frequency'!C1 -> CHAINE….. | G4: Journalière
C5: A
C6: ZONE: | E6: FAIT?
B7: N° | C7: DESCRIPTION DES TACHES | D7: Durée | E7: OUI | F7: NON | G7: REMARQUES (MATERIEL + PIECES)
B8: 1 | C8: Vérifier l'état des paliers et roulements | D8: 60
B9: 2 | C9: Vérifier l'état des chaines et leurs longueurs | D9: 20
B10: 3 | C10: Vérifier les rouleaux tendeurs guide chaine | D10: 30
B11: 4 | C11: Vérifier l'etat des guides casiers en teflon noir | D11: 25
B12: 5 | C12: Vérifier l'etat des supports de guide casiers dessere ou tordu | D12: 30
B13: 6 | C13: Vérifier l'état des pieds des convoyeurs | D13: 20
B14: 7 | C14: Contrôler l'état des TAPIS de la zone
B15: 8 | C15: Nettoyer le corps de la machine | D15: 30
B16: Commentaire | D16: Nom et Visa Intervenants | G16: Nom et Visa Responsables
C26: .
A34: =+B12+1 -> 6

Sheet Décaisseuse 
B3: CHECKLIST PROCESS TECHNICIAN
C4: DECAISSEUSE | D4: =+'Line & frequency'!C1 -> CHAINE….. | G4: Journalière
C6: Heure début:……………………………………………… Heure fin : ……………………………………… | E6: FAIT?
B7: N° | C7: DESCRIPTION DES TACHES | D7: Durée | E7: OUI | F7: NON | G7: REMARQUES (MATERIEL + PIECES)
B8: 1 | C8: controler l'arret d'huile et le remplacé au besoin. Aucune fuite d'huile n'est acceptable. | D8: 10
B9: 2 | C9: controler la pression d'air sur le chariot N,B: Elle doit etre au max de 2,5 bar | D9: 10
B10: 3 | C10: controler les fuites au niveau des vérins de guidage des grappins A et remedier au problèmes rencontrés. | D10: 10
B11: 4 | C11: controler les fuites au niveau des raccords M4 filetée à 1/4 et flexibles et remedier aux problèmes rencontrés. | D11: 30
B12: 5 | C12: controler les fuites au niveau des flexibles et remplacer ceux qui sont percés. | D12: 10
B13: 6 | C13: controler les fuites au niveau des flexibles et remplacer ceux qui sont percés. | D13: 10
B14: 7 | C14: ajuster les guides casiers et se rassurer du passage des casiers à l'interieur du convoyeur interne. | D14: 10
B15: 8 | C15: controler le fonctionnement du guide bouteilles à l'intérieur des casiers, leur fixation et surtout remedier aux problèmes de fissures rencontrés | D15: 10
B16: 9 | C16: vérifier la présence des guides bouteilles au dessus du guide frame et remplacer ceux qui sont absents. Tous ces guides doivent etre présents. | D16: 10
B17: 10 | C17: Contrôle l'etat des chaines,glissieres, pigons et lubrification du convoyeur interne
B18: 11 | C18: Controler les fuites au niveau des membranes
B19: 12 | C19: Après avoir fait une inspection générale des fuites d'air et eliminer les fuites éventuelles
B20: Commentaire | D20: Nom et Visa Intervenants | G20: Nom et Visa Responsables
C30: .

Sheet Encaisseuse
B3: CHECKLIST PROCESS TECHNICIAN | G3: Date:
C4: ENCAISSEUSE | D4: =+'Line & frequency'!C1 -> CHAINE….. | G4: Journalière
C6: Heure début:……………………………………………… Heure fin : ……………………………………… | E6: FAIT?
B7: N° | C7: DESCRIPTION DES TACHES | D7: Durée | E7: OUI | F7: NON | G7: REMARQUES (MATERIEL + PIECES)
B8: 1 | C8: Contrôler l'arret d'huile et le remplacer au besoin. Aucune fuite d'huile n'est acceptable. | D8: 10
B9: 2 | C9: Contrôler la pression d'air sur le chariot | D9: 10
B10: 3 | C10: Contrôler le niveau de graisse à la station de graissage | D10: 10
B11: 4 | C11: Contrôler les fuites au niveau des raccords M6 filetée à 1/4 et flexibles et remedier aux problèmes rencontrés. | D11: 30
B12: 5 | C12: Contrôler les fuites au niveau des membranes | D12: 10
B13: 6 | C13: Contrôler les fuites au niveau des flexibles et remplacer ceux qui sont percés. | D13: 10
B14: 7 | C14: Contrôler les fuites sur le vérin e blocage et ses raccords puis remedier aux problèmes. | D14: 15
B15: 8 | C15: Ajuster les guides casiers et se rassurer du passage des casiers à l'interieur du convoyeur interne. | D15: 10
B16: 9 | C16: Vérifier la présence des guides bouteilles au dessus du guide frame et remplacer ceux qui sont absents. Tous ces guides doivent etre présents. | D16: 10
B17: 10 | C17: Contrôler le passage des bouteilles dans les couloirs bouteilles et ajuster au besoin. Aucun blocage n'est admissible. | D17: 15
B18: 11 | C18: Contrôler le fonctionnement des branleurs et se rassurer qu'ils guident les bouteilles à l'interieur des couloir. | D18: 10
B19: 12 | C19: Inspecter les glissières et retourneurs de chaine convoyeur interne | D19: 10
... B21: 14 | C21: Après avoir fait une inspection généale des fuites d'air et éliminer les fuites éventuelles | D21: 5
B22: Commentaire | D22: Nom et Visa Intervenants | G22: Nom et Visa Responsables
C28: .

Sheet Soutireuse
B3: CHECKLIST PROCESS TECHNICIAN | G3: Date:
C4: SOUTIREUSE | D4: =+'Line & frequency'!C1 -> CHAINE….. | G4: Journalière
C6: Heure début:……………………………………………… Heure fin : ……………………………………… | E6: FAIT?
B7: N° | C7: DESCRIPTION DES TACHES | D7: Durée | E7: OUI | F7: NON | G7: REMARQUES (MATERIEL + PIECES)
B8: 1 | C8: Vérifier que les joints de tulipes sont encore en bon état | D8: 10
B9: =B8+1 -> 2 | C9: Contrôler que les porte-joints de tulipes sont encore intacts
B10: =+B9+1 -> 3 | C10: Vérifier que les petites bagues de guidage des axes sont en place | D10: 15
B11: 4 | C11: Vérifier que les axes de guidage des robinets sont droits
B12: 5 | C12: Contrôler fuite, fixation et usure des cames d'ouverture V005 et VS26 | D12: 18
B13: 6 | C13: Vérifier si tous les boutons de sniftage jouent librement | D13: 15
B14: 7 | C14: Vérifier si tous les boutons de soupape de sécurité jouent librement | D14: 10
B15: 8 | C15: Commander manuellement le vérin de l'étoile de blocage des bouteilles et vérifier si le blocage et le relâchement sont effectifs | D15: 5
B16: 9 | C16: Contrôler l'usure des encoches de l'étoile de blocage et voir si elle est encore acceptable (blocage ferme) | D16: 5
B17: 10 | C17: Contrôler l'usure des guides et glissières de guides droits et circulaire de la vis de sélection à la sortie boucheuse | D17: 8
B18: 11 | C18: S'assurer que la pression d'alimentation des pistons est normale | D18: 2
B19: 12 | C19: Contrôler que les buses de nettoyage des casses d'explosion fonctionnent bien et qu'elles sont actives | D19: 6
B20: 13 | C20: S'assurer que toutes les plaques de séparation des robinets de remplissage sont en place | D20: 5
B21: 14 | C21: S'assurer que le souffleur de capsules fonctionne bien et automatiquement | D21: 5
B22: 15 | C22: Contrôler le module de vibration du retourneur de capsules / Simuler distributeur module | D22: 5
B23: 16 | C23: Contrôler vannes - CV01 et PV01 prioritaires - raccords, détendeur et manomètres sur la conduite de bière et éliminer toutes les fuites | D23: 15
... B26: 19 | C26: Contrôler toutes les vis de serrage des têtes de bouchages | D26: 10
B27: 20 | C27: Contrôler toutes les vis de serrage du guide goulot sortie boucheuse
B28: 21 | C28: Controler l'allongement de la courroie de la vis de sélection | D28: 10
B29: 22 | C29: Tester les éléments de remplissage (Cames ouverture/Mise à vide/Fermeture/Décompression, etc.) | D29: 15
B30: Relevez le compteur fin de quart de la machine | D30: ….........................
B31: Commentaire | D31: Nom et Visa Intervenants | G31: Nom et Visa Responsables

Sheet Lave-caisses Ancien
B3: CHECKLIST PROCESS TECHNICIAN | G3: Date:
C4: LAVE-CAISSES | D4: =+'Line & frequency'!C1 -> CHAINE….. | G4: Journalière
C6: NB: Renseigner la checklist du convoyeur casier au verso
C7: Heure début:……………………………………………… Heure fin : ……………………………………… | E7: FAIT?
B8: N° | C8: DESCRIPTION DES TACHES | D8: Durée | E8: OUI | F8: NON | G8: REMARQUES (MATERIEL + PIECES)
B9: 1 | C9: Contrôler la fermeture des couvercles et ajuster au besoin. Aucune fuite n'est permise | D9: 10
B10: =B9+1 -> 2 | C10: Contrôler la présence des regards des bains, vérifier qu'ils sont bien fixés et remedier aux problèmes. | D10: 20
B11: 3 | C11: Contrôler les renvoies chaines et remplacer ceux qui sont endommagés. | D11: 15
B12: 4 | C12: Déboucher la tuyauterie en dessous de la machine | D12: 30
B13: 5 | C13: Contrôler le support du moto-réducteur et s'assurer qu'il n'est pas fissuré | D13: 5
B14: 6 | C14: Contrôler la fixation du réducteur du convoyeur interne sur son support
B15: 7 | C15: Contrôler le retourneurs de casier à l'entrée et à la sortie
B16: Commentaire | D16: Nom et Visa Intervenants | G16: Nom et Visa Responsables
C29: .

Sheet Laveuse - EBI
B3: CHECKLIST PROCESS TECHNICIAN | G3: Date:
C4: CONVOYEUR BOUTEILLES | D4: =+'Line & frequency'!C1 -> CHAINE….. | G4: Journalière
C5: Laveuse - EBI
C6: NB: Lorsques vous faites une remarque, précisez exactement la zone du convoyeur correspondante
C7: Heure début:……………………………………………… Heure fin : ……………………………………… | E7: FAIT?
B8: N° | C8: DESCRIPTION DES TACHES | D8: Durée | E8: OUI | F8: NON | G8: REMARQUES (MATERIEL + PIECES)
B9: 1 | C9: Vérifier l'état des paliers et roulements | D9: 60
B10: 2 | C10: Vérifier l'état des chaines et leurs longueurs | D10: 20
B11: 3 | C11: Vérifier les rouleaux tendeurs guide chaine | D11: 30
B12: 4 | C12: Vérifier l'etat des guides bouteilles | D12: 25
B13: 5 | C13: Vérifier l'etat des supports de guide bouteilles déssere ou terdu | D13: 30
B14: 6 | C14: Vérifier l'état des gouttieres | D14: 15
B15: 7 | C15: Vérifier le fonctionnement des buses de lubrification | D15: 30
B16: 8 | C16: Vérifier l'état des pieds des convoyeurs | D16: 20
B17: 9
B18: Commentaire | D18: Nom et Visa Intervenants | G18: Nom et Visa Responsables
C27: .
A36: =+B13+1 -> 6

Sheet Convoyeur bouteilles
B3: CHECKLIST PROCESS TECHNICIAN | G3: Date:
C4: CONVOYEUR BOUTEILLES | D4: =+'Line & frequency'!C1 -> CHAINE….. | G4: Journalière
C5: LABELLER - PACKER
C6: NB: Lorsques vous faites une remarque, précisez exactement la zone du convoyeur correspondante
C8: Heure début:……………………………………………… Heure fin : ……………………………………… | E8: FAIT?
B9: N° | C9: DESCRIPTION DES TACHES | D9: Durée | E9: OUI | F9: NON | G9: REMARQUES (MATERIEL + PIECES)
B10: 1 | C10: Vérifier l'état des paliers et roulements | D10: 60
B11: 2 | C11: Vérifier l'état des chaines et leurs longueurs | D11: 20
B12: 3 | C12: Vérifier les rouleaux tendeurs guide chaine | D12: 30
B13: 4 | C13: Vérifier l'etat des guides bouteilles | D13: 25
B14: 5 | C14: Vérifier l'etat des supports de guide bouteilles déssere ou terdu | D14: 30
B15: 6 | C15: Vérifier l'état des gouttieres | D15: 15
B16: 7 | C16: Vérifier le fonctionnement des buses de lubrification | D16: 30
B17: 8 | C17: Vérifier l'état des pieds des convoyeurs | D17: 20
B18: 9
B19: Commentaire | D19: Nom et Visa Intervenants | G19: Nom et Visa Responsables
C28: .
A37: =+B14+1 -> 6

Sheet Pasteurisateur
B3: CHECKLIST MECANIQUE
C4: PASTEURISATEUR | D4: =+'Line & frequency'!C1 -> CHAINE….. | G4: Journalière
C6: Heure début:……………………………………………… Heure fin : ……………………………………… | E6: FAIT?
B7: N° | C7: DESCRIPTION DES TACHES | D7: Durée | E7: OUI | F7: NON | G7: REMARQUES (MATERIEL + PIECES)
B8: 1 | C8: Vérifier le fonctionnement des 10 pompes d'injection | D8: 10
B9: 2 | C9: Faire une inpection d'étanchéité de la pompe d'eau chaude | D9: 5
B10: 3 | C10: Faire une inpection d'étanchéité de la pompe d'eau froide | D10: 5
B11: 4 | C11: Faire une inspection générale des manomètres de la machine/Vérifier présence huile cadrant | D11: 15
B12: 5 | C12: S'assurer que la vanne à volant d'arrivée vapeur DN100 s'ouvre et se ferme normalement | D12: 10
B13: 6 | C13: Faire une inspection générale du circuit vapeur et éliminer les fuites éventuelles / Contrôler aussi purgeurs | D13: 30
B14: 7
B15: 8
B16: 11
B17: Commentaire | D17: Nom et Visa Intervenants | G17: Nom et Visa Responsables
C28: .

Sheet Crater - Apollo 3
B3: CHECKLIST PROCESS TECHNICIAN | G3: Date:
C4: CONVOYEUR CASIERS | D4: =+'Line & frequency'!C1 -> CHAINE….. | G4: Journalière
C5: Crater - Apollo 3
C6: NB: Lorsques vous faites une remarque, précisez exactement la zone du convoyeur correspondante
E7: FAIT?
B8: N° | C8: DESCRIPTION DES TACHES | D8: Durée | E8: OUI | F8: NON | G8: REMARQUES (MATERIEL + PIECES)
B9: 1 | C9: Vérifier l'état des paliers et roulements | D9: 60
B10: 2 | C10: Vérifier l'état des chaines et leurs longueurs | D10: 20
B11: 3 | C11: Vérifier les rouleaux tendeurs guide chaine | D11: 30
B12: 4 | C12: Vérifier l'etat des guides casiers en teflon noir | D12: 25
B13: 5 | C13: Vérifier l'etat des supports de guide casiers dessere ou tordu | D13: 30
B14: 6 | C14: Vérifier l'état des pieds des convoyeurs | D14: 20
B15: 7 | C15: Contrôler l'état des TAPIS de la zone
B16: 8 | C16: Nettoyer le corps de la machine | D16: 30
B17: Commentaire | D17: Nom et Visa Intervenants | G17: Nom et Visa Responsables
C27: .
A35: =+B13+1 -> 6

Sheet Apollo 4 - Palletizer
B3: CHECKLIST PROCESS TECHNICIAN | G3: Date:
C4: CONVOYEUR CASIERS | D4: =+'Line & frequency'!C1 -> CHAINE….. | G4: Journalière
C5: Apollo 4 - Palletizer
C6: NB: Lorsques vous faites une remarque, précisez exactement la zone du convoyeur correspondante
E7: FAIT?
B8: N° | C8: DESCRIPTION DES TACHES | D8: Durée | E8: OUI | F8: NON | G8: REMARQUES (MATERIEL + PIECES)
B9: 1 | C9: Vérifier l'état des paliers et roulements | D9: 60
B10: 2 | C10: Vérifier l'état des chaines et leurs longueurs | D10: 20
B11: 3 | C11: Vérifier les rouleaux tendeurs guide chaine | D11: 30
B12: 4 | C12: Vérifier l'etat des guides casiers en teflon noir | D12: 25
B13: 5 | C13: Vérifier l'etat des supports de guide casiers dessere ou tordu | D13: 30
B14: 6 | C14: Vérifier l'état des pieds des convoyeurs | D14: 20
B15: 7 | C15: Contrôler l'état des TAPIS de la zone
B16: 8 | C16: Nettoyer le corps de la machine | D16: 30
B17: Commentaire | D17: Nom et Visa Intervenants | G17: Nom et Visa Responsables
C27: .
A35: =+B13+1 -> 6

Sheet Etiqueteuse
B3: CHECKLIST PROCESS TECHNICIAN | G3: Date:
C4: ETIQUETEUSE | D4: =+'Line & frequency'!C1 -> CHAINE….. | G4: Journalière
C6: Heure début:……………………………………………… Heure fin : ……………………………………… | E6: FAIT?
B7: N° | C7: DESCRIPTION DES TACHES | D7: Durée | E7: OUI | F7: NON | G7: REMARQUES (MATERIEL + PIECES)
B8: 1 | C8: Contrôler usure des sellettes et les remplacer au besoin | D8: 15
B9: 2 | C9: Contrôler les colliers à ergot de fixation des têtes de pression | D9: 10
B10: 3 | C10: S'assurer de la présence des embouts de protection au bout des têtes de pression | D10: 10
B11: 4 | C11: Contrôler usure vis de sélection et la remplacer si usée | D11: 5
B12: 5 | C12: S'assurer que l'injection d'eau d'arrosage est fonctionnelle sur les brosses de lissage | D12: 5
B13: 6 | C13: Contrôler état et ajuster position glissières guides à l'entrée de la machine | D13: 5
B14: 7 | C14: Contrôler état et ajuster position glissières guides à la sortie de la machine | D14: 5
B15: 8 | C15: Contrôler les ressorts du cylindre à étiquette | D15: 15
B16: 9 | C16: Contrôler les galets sur tambour stagnoles/collerettes et les remplacer si usés | D16: 30
B17: 10 | C17: Contrôler les ressorts du cylindre à stagnole | D17: 15
B18: 11 | C18: S'assurer que l'injection d'eau d'arrosage est fonctionnelle sur la brosse des éponges du cylindre de transfert sur les tambours de la station 1 | D18: 5
B19: 12 | C19: Contrôler les ressorts de rappel dispositif de pose si stagnole et remplacer si nécessaire sur les tambours de la station 1 | D19: 30
... B26: 19 | C26: Après avoir fait une inspection générale des fuites d'air et eliminer les fuites éventuelles | D26: 30
B27: 20
B28: Commentaire | D28: Nom et Visa Intervenants | G28: Nom et Visa Responsables

Sheet Palettiseur
B3: CHECKLIST PROCESS TECHNICIAN | G3: Date:
C4: PALETTISEUR | D4: =+'Line & frequency'!C1 -> CHAINE….. | G4: Journalier
C6: Heure début:……………………………………………… Heure fin : ……………………………………… | E6: FAIT?
B7: N° | C7: DESCRIPTION DES TACHES | D7: Durée | E7: OUI | F7: NON | G7: REMARQUES (MATERIEL + PIECES)
B8: 1 | C8: Controler les brides de serrage et remplacer au besoin | D8: 15
B9: 2 | C9: Controler la fixation de la tige (haut et bas) et bien serrer au besoin. | D9: 5
B10: 3 | C10: Controler la fixation de la courroie sur le chariot et ameliorer sa fixation si necessaire. | D10: 30
B11: 4 | C11: Controler l'etanchéité du disributeur et le remplacer au besoin. Aucune fuite n'est acceptable | D11: 15
B12: 5 | C12: Controler la pression d'air sur le pressostat du bloc regualteur | D12: 5
B13: 6 | C13: Controler l'état du raccord à la sortie | D13: 5
B14: 7 | C14: Controler l'usure de la courroie | D14: 15
B15: 8 | C15: Controler la fixation de la courroie | D15: 15
B16: 9 | C16: Controler la tension de la courroie | D16: 15
B17: 10 | C17: Controler les fuites sur les élements pneumatiques de la trasverse | D17: 15
B18: 11 | C18: Controler l'état des rouleaux de guidage de la traverse | D18: 10
B19: 12 | C19: Controler l'état des roulements et paliers | D19: 30
... B45: 38 | C45: Controler les fuites au niveau des raccords d'air et les remplacés au besoin | D45: 10
B46: Commentaire | D46: Nom et Visa Intervenants | G46: Nom et Visa Responsables

Sheet Dépalettiseur
B3: CHECKLIST PROCESS TECHNICIAN | G3: Date:
C4: DEPALETTISEUR | D4: =+'Line & frequency'!C1 -> CHAINE….. | G4: Journalière
C6: Heure début:……………………………………………… Heure fin : ……………………………………… | E6: FAIT?
B7: N° | C7: DESCRIPTION DES TACHES | D7: Durée | E7: OUI | F7: NON | G7: REMARQUES (MATERIEL + PIECES)
B8: 1 | C8: Controler les éléments (Régulateur, silencieux, raccords ) sur le bloc regulateur d'air | D8: 30
B9: 2 | C9: Controler les éléments de guidage en translation verticale et horizontale de la traverse et remedier si necessaire. | D9: 15
B10: 3 | C10: Verifer le petit rouleau d'entrainement de la courroire lissie 50F2-0,9-M du frame S030 et remplacer le au besoin | D10: 30
B11: 4 | C11: Controler le guidage en translation du poussoir et remedier au beoin. | D11: 30
B12: 5 | C12: Controler le fonctionnement de la barre de stabilisation des casiers et reparer le clamp element au besoin | D12: 30
B13: 6 | C13: Verifier l'usure, l'alignement et le serrage des doigts du frame S030 par rapport aux casiers et les regler si necessaire | D13: 30
B14: 7 | C14: Controler le guidage en translation du bloqueur de casiers et remedier au besoin. | D14: 30
B15: 8 | C15: Controler le fonctionnement du vérin du bloqueur de casiers et remplacer au besoin. | D15: 20
B16: 9 | C16: Controler l'ajustement des palettes sur le convoyeur à palettes et regler les guides au besoin | D16: 20
B17: 10 | C17: Controler les vérins de cintrage ( caoutchouch, torsion de la tige…) et remedier aux problèmes rencontrés. | D17: 30
B18: 11 | C18: Controler les fuites sur les éléments pneumatiques du grappin, silencieux du système de cintrage et les remediés au besoin. Aucune fuite sur le grappin n'est permise. | D18: 30
B19: 12 | C19: Controler la lubrification effective de la chaine de transmission et lubrifier au besoin | D19: 10
... B22: 15 | C22: Controler les fuites sur les raccords les remediées au besoin | D22: 10
B23: 16
B24: 17
B25: 18
B26: 19
B27: Commentaire | D27: Nom et Visa Intervenants | G27: Nom et Visa Responsables

Sheet Apollo1 - Apollo2
B3: CHECKLIST PROCESS TECHNICIAN | G3: Date:
C4: CONVOYEUR CASIERS | D4: =+'Line & frequency'!C1 -> CHAINE….. | G4: Journalière
C5: Apollo 1 - Apollo 2
C6: NB: Lorsques vous faites une remarque, précisez exactement la zone du convoyeur correspondante
E7: FAIT?
B8: N° | C8: DESCRIPTION DES TACHES | D8: Durée | E8: OUI | F8: NON | G8: REMARQUES (MATERIEL + PIECES)
B9: 1 | C9: Vérifier l'état des paliers et roulements | D9: 60
B10: 2 | C10: Vérifier l'état des chaines et leurs longueurs | D10: 20
B11: 3 | C11: Vérifier les rouleaux tendeurs guide chaine | D11: 30
B12: 4 | C12: Vérifier l'etat des guides casiers en teflon noir | D12: 25
B13: 5 | C13: Vérifier l'etat des supports de guide casiers dessere ou tordu | D13: 30
B14: 6 | C14: Vérifier l'état des pieds des convoyeurs | D14: 20
B15: 7 | C15: Contrôler l'état des TAPIS de la zone
B16: 8 | C16: Nettoyer le corps de la machine | D16: 30
B17: Commentaire | D17: Nom et Visa Intervenants | G17: Nom et Visa Responsables
C27: .
A35: =+B13+1 -> 6

Sheet Apollo2 - Decaisseuse
B3: CHECKLIST PROCESS TECHNICIAN | G3: Date:
C4: CONVOYEUR CASIERS | D4: =+'Line & frequency'!C1 -> CHAINE….. | G4: Journalière
C5: Apollo 2 - Decaisseuse
C6: NB: Lorsques vous faites une remarque, précisez exactement la zone du convoyeur correspondante
E7: FAIT?
B8: N° | C8: DESCRIPTION DES TACHES | D8: Durée | E8: OUI | F8: NON | G8: REMARQUES (MATERIEL + PIECES)
B9: 1 | C9: Vérifier l'état des paliers et roulements | D9: 60
B10: 2 | C10: Vérifier l'état des chaines et leurs longueurs | D10: 20
B11: 3 | C11: Vérifier les rouleaux tendeurs guide chaine | D11: 30
B12: 4 | C12: Vérifier l'etat des guides casiers en teflon noir | D12: 25
B13: 5 | C13: Vérifier l'etat des supports de guide casiers dessere ou tordu | D13: 30
B14: 6 | C14: Vérifier l'état des pieds des convoyeurs | D14: 20
B15: 7 | C15: Contrôler l'état des TAPIS de la zone
B16: 8 | C16: Nettoyer le corps de la machine | D16: 30
B17: Commentaire | D17: Nom et Visa Intervenants | G17: Nom et Visa Responsables
C27: .
A35: =+B13+1 -> 6

Sheet Depal - Apollo 1
B3: CHECKLIST PROCESS TECHNICIAN | G3: Date:
C4: CONVOYEUR CASIERS | D4: =+'Line & frequency'!C1 -> CHAINE….. | G4: Journalière
C5: Depal - Apollo 1
C6: NB: Lorsques vous faites une remarque, précisez exactement la zone du convoyeur correspondante
E7: FAIT?
B8: N° | C8: DESCRIPTION DES TACHES | D8: Durée | E8: OUI | F8: NON | G8: REMARQUES (MATERIEL + PIECES)
B9: 1 | C9: Vérifier l'état des paliers et roulements | D9: 60
B10: 2 | C10: Vérifier l'état des chaines et leurs longueurs | D10: 20
B11: 3 | C11: Vérifier les rouleaux tendeurs guide chaine | D11: 30
B12: 4 | C12: Vérifier l'etat des guides casiers en teflon noir | D12: 25
B13: 5 | C13: Vérifier l'etat des supports de guide casiers dessere ou tordu | D13: 30
B14: 6 | C14: Vérifier l'état des pieds des convoyeurs | D14: 20
B15: 7 | C15: Contrôler l'état des TAPIS de la zone
B16: 8 | C16: Nettoyer le corps de la machine | D16: 30
B17: Commentaire | D17: Nom et Visa Intervenants | G17: Nom et Visa Responsables
C27: .
A35: =+B13+1 -> 6

Sheet  Laveuse L4
B3: CHECKLIST PROCESS TECHNICIAN | G3: Date:
C4: LAVEUSE BOUTEILLES | D4: ='Line & frequency'!D1 -> CHAINE 4 | G4: Journalière
C6: Heure début:……………………………………………… Heure fin : ……………………………………… | E6: FAIT?
B7: N° | C7: DESCRIPTION DES TACHES | D7: Durée | E7: OUI | F7: NON | G7: REMARQUES (MATERIEL + PIECES)
B8: 1 | C8: Inspecter toutes les glaces de la laveuse et s'assurer qu'elles sont en bon état et bien ajuster | D8: 5
B9: 2 | C9: Contrôler les tubes de niveau de soude des bains et les réparés | D9: 10
B10: 3 | C10: Contrôler axes branleurs table d'accumulation Infeed et vérifier qu'ils sont bien soudés | D10: 15
B11: 4 | C11: Contrôler ressorts Infeed et vérifier serrage supports | D11: 10
B12: 5 | C12: Contrôler ressorts Décharge et vérifier serrage supports | D12: 10
B13: 6 | C13: Contrôler les 2 courroies de l'Infeed et vérifier serrage accouplement / Contrôler aussi serrage bielle | D13: 20
B14: 7 | C14: S'assurer que les bains de soude ne sont pas chauffés à plus de 80°C (risque d'endommagement des joints) | D14: 5
B15: 8 | C15: Vérifier systématiquement les roulements de la décharge | D15: 15
B16: 9 | C16: Tester l'introduction des bouteilles à l'infeed et leur dépôt à la décharge | D16: 30
B17: 10 | C17: Verifier tous les roulements de l'infeed | D17: 10
B18: 11 | C18: Inspecter la languette de sécurité de l'Infeed et remplacer si fissures observables et/ou affaiblissement | D18: 5
B19: 12 | C19: Contrôler la valeur des couples dans les différents bains | D19: 5
... B24: 17 | C24: Faire une inspection générale des fuites d'air et eliminer les fuites éventuelles | D24: 30
B25: Commentaire | D25: Nom et Visa Intervenants | G25: Nom et Visa Responsables

Sheet Laveuse L5
B3: CHECKLIST MECANIQUE | G3: =+'Line & frequency'!C3 -> 44985
C4: LAVEUSE BOUTEILLES | D4: =+'Line & frequency'!C1 -> CHAINE….. | G4: =+'Line & frequency'!C2 -> JOURNALIERE
C6: Heure début:……………………………………………… Heure fin : ……………………………………… | E6: FAIT?
B7: N° | C7: DESCRIPTION DES TACHES | D7: Durée | E7: OUI | F7: NON | G7: REMARQUES (MATERIEL + PIECES)
B8: 1 | C8: Vérifier la pression d'eau des injecteurs des différents bains (1 bar mini) | D8: 5
B9: =B8+1 -> 2 | C9: Contrôler la pression d'air du vérin de sécurité de l'infeed et de la décharge (Pmax 1,5 bar pour l'infeed et 2 bar pour la décharge) | D9: 5
B10: =+B9+1 -> 3 | C10: Contrôler le serrage du système de securité de l'infeed (fixation du vérin) | D10: 10
B11: =B10+1 -> 4 | C11: Contrôler le serrage du système de securité de la décharge (fixation du vérin) | D11: 10
B12: =+B11+1 -> 5 | C12: Vérifier la température des bains(T < 80°C) | D12: 5
B13: =B12+1 -> 6 | C13: Vérifier les différents taux de concentration de soude dans les bains | D13: 5
B14: =+B13+1 -> 7 | C14: Contrôler et nettoyer les filtres de prétrempage et de soude | D14: 15
B15: =B14+1 -> 8 | C15: Inspecters les extracteurs | D15: 10
B16: =+B15+1 -> 9 | C16: Verifier visuellement tous les injecteurs de la laveuse | D16: 10
B17: =B16+1 -> 10 | C17: Contrôler la présence des galets sur les étoiles des injecteurs | D17: 10
B18: =+B17+1 -> 11 | C18: Contrôler l'état des roulements et paliers sur la machine | D18: 10
B19: =B18+1 -> 12 | C19: Contrôler les fuites d'huile sur les moto-réducteurs | D19: 10
B20: =+B19+1 -> 13 | C20: Contrôler le niveau d'eau dans les bains de soude(petit tube de niveau) | D20: 10
B21: =B20+1 -> 14 | C21: Contrôler et nettoyer tous les filtres présents aux bains de rincage | D21: 15
B22: =+B21+1 -> 15 | C22: Maintenir l'etat de propreté sur la machine(enlever tous les objets trainants) | D22: 15
B23: =B22+1 -> 16 | C23: Controler l'etat des doigts de chargements et de dechargements | D23: 10
B24: =+B23+1 -> 17 | C24: Vérifier la valeur des couples moteur de traction: couple <80% | D24: 5
B25: =B24+1 -> 18 | C25: Faire une inspection générale des fuites d'air et eliminer les fuites éventuelles | D25: 30
B26: =+B25+1 -> 19
B27: =B26+1 -> 20
B28: =+B27+1 -> 21
B29: =B28+1 -> 22
B30: =+B29+1 -> 23
B31: =B30+1 -> 24
B32: =+B31+1 -> 25
B33: =B32+1 -> 26
B34: Commentaire | D34: Nom et Visa Intervenants | G34: Nom et Visa Responsables

Sheet Apollos
B3: CHECKLIST PROCESS TECHNICIAN | G3: Date:
C4: APOLLO | D4: ='Line & frequency'!C1 -> CHAINE….. | H4: JOUNALIERE
D5: Inspection 1 | H5: Inspection 2 | L5: Inspection 3
E6: FAIT? | I6: FAIT? | M6: FAIT?
B7: N° | C7: DESCRIPTION DES TACHES | D7: Durée | E7: OUI | F7: NON | G7: REMARQUES (MATERIEL + PIECES) | H7: Durée | I7: OUI | J7: NON | K7: REMARQUES (MATERIEL + PIECES) | L7: Durée | M7: OUI | N7: NON | O7: REMARQUES (MATERIEL + PIECES)
B8: 1 | C8: Controler l'état des courroies et remplacer au besoin. | D8: 2 | H8: 2 | L8: 2
B9: =B8+1 -> 2 | C9: Controler les fuites sur le vérin, sa fixation remedier aux problèmes rencontrés. | D9: 2 | H9: 2 | L9: 2
B10: =+B9+1 -> 3 | C10: Controler fuites sur raccords y remédier au besoin
B11: 4 | C11: Controler présence palettes sur tout le long du convoyeur et remplacer les palettes manquantes | D11: 10 | H11: 10 | L11: 10
B12: 5 | C12: Controler la hauteur des rouleaux et ajuster les au besoin. | D12: 5 | H12: 5 | L12: 5
B13: 6 | C13: Vérifier le bon état des capteurs et controler le serrage des leurs supports de fixation | D13: 2 | H13: 2 | L13: 2
B14: 7 | C14: Nettoyer les motoréducteurs et sectionneurs Et observer s'il y a présence de bruit anormal sur le moteur | D14: 2 | H14: 2 | L14: 2
B15: 8 | C15: Contrôler la presence des objets (fonds de casiers, bouteilles…) et enlever s'il ya presence | D15: 2 | H15: 2 | L15: 2
B16: 9 | C16: Cotrôler l'élongation de la chaine et observer le mouvement du tendeur et puis ajuster et corriger si mauvais fonctionnement | D16: 5 | H16: 5 | L16: 5
B17: 10 | C17: Rapporter toutes les anomalies sur la zone de commentaire et se rassurer que les convoyeurs tournent avec une bonne fluidité | D17: 2 | H17: 2 | L17: 2
B18: Commentaire | D18: Nom et Visa Intervenants | G18: Nom et Visa Responsables | H18: Nom et Visa Intervenants | K18: Nom et Visa Responsables | L18: Nom et Visa Intervenants | O18: Nom et Visa Responsables
C27: .

Sheet Cvyr Btles
B3: CHECKLIST MECANIQUE | G3: Date
C4: PALETTISEUR | D4: =+'Line & frequency'!C1 -> CHAINE….. | G4: =+'Line & frequency'!C2 -> JOURNALIERE
E6: FAIT?
B7: N° | C7: DESCRIPTION DES TACHES | D7: Durée | E7: OUI | F7: NON | G7: REMARQUES (MATERIEL + PIECES)
B8: 1
B9: =B8+1 -> 2
B10: =+B9+1 -> 3
B11: =B10+1 -> 4
B12: =+B11+1 -> 5
B13: =B12+1 -> 6
B14: =+B13+1 -> 7
B15: =B14+1 -> 8
B16: =+B15+1 -> 9
B17: =B16+1 -> 10
B18: =+B17+1 -> 11
B19: =B18+1 -> 12
B20: =+B19+1 -> 13
B21: =B20+1 -> 14
B22: =+B21+1 -> 15
B23: =B22+1 -> 16
B24: =+B23+1 -> 17
B25: =B24+1 -> 18
B26: =+B25+1 -> 19
B27: =B26+1 -> 20
B28: =+B27+1 -> 21
B29: =B28+1 -> 22
B30: =+B29+1 -> 23
B31: =B30+1 -> 24
B32: =+B31+1 -> 25
B33: =B32+1 -> 26
B34: =+B33+1 -> 27
B35: =B34+1 -> 28
B36: =+B35+1 -> 29
B37: =B36+1 -> 30
B38: =+B37+1 -> 31
B39: =B38+1 -> 32
B40: =+B39+1 -> 33
B41: =B40+1 -> 34
B42: =+B41+1 -> 35
B43: =B42+1 -> 36
...

Sheet CC C1
B3: CHECKLIST MECANIQUE | G3: Date
C4: CONVOYEURS CASIERS C1 | D4: =+'Line & frequency'!C1 -> CHAINE….. | G4: =+'Line & frequency'!C2 -> JOURNALIERE
E6: FAIT?
B7: N° | C7: DESCRIPTION DES TACHES | D7: Durée | E7: OUI | F7: NON | G7: REMARQUES (MATERIEL + PIECES)
B8: 1 | C8: controler l'arret d'huile et le remplacé au besoin. Aucune fuite d'huile n'est acceptable. | D8: 10
B9: =B8+1 -> 2 | C9: controler la fixation du réducteur sur le convoyeur et corriger si necessaire. | D9: 30
B10: =+B9+1 -> 3 | C10: controler l'usure du pignon et le remplacé au besoin. Aucun glissement n'est acceptable. | D10: 30
B11: =B10+1 -> 4 | C11: controler l'alignement et la fixation du pignon de l'axe moteur et remedier au besoin. | D11: 30
B12: =+B11+1 -> 5 | C12: controler l'usure de la roue libre et la remplacée au besoin. Aucun glissement n'est acceptable. | D12: 30
B13: =B12+1 -> 6 | C13: controler l'alignement et la fixation de la roue libre et remedier au problème. | D13: 30
B14: =+B13+1 -> 7 | C14: controler l'usure de la clavette et la rainure et reparer au besoin | D14: 30
B15: =B14+1 -> 8 | C15: controler l'état des glissières et remplacer les au besoin | D15: 25
B16: =+B15+1 -> 9 | C16: controler l'arret d'huile et le remplacé au besoin. Aucune fuite d'huile n'est acceptable. | D16: 10
B17: =B16+1 -> 10 | C17: controler l'usure des roulements et paliers de l'axe moteur et remplacer si necessaire. | D17: 30
B18: =+B17+1 -> 11 | C18: controler l'usure du pignon et le remplacé au besoin. Aucun glissement n'est acceptable. | D18: 30
B19: =B18+1 -> 12 | C19: controler l'alignement et la fixation du pignon de l'axe moteur et remedier au besoin. | D19: 30
B20: =+B19+1 -> 13 | C20: controler l'usure de la clavette et la rainure et reparer au besoin | D20: 30
B21: =B20+1 -> 14 | C21: controler l'usure des roulements et paliers de l'axe moteur et remplacer si necessaire. | D21: 30
B22: =+B21+1 -> 15 | C22: controler l'usure de la roue libre et la remplacée au besoin. Aucun glissement n'est acceptable. | D22: 30
B23: =B22+1 -> 16 | C23: controler l'alignement et la fixation de la roue libre et remedier au problème. | D23: 30
B24: =+B23+1 -> 17 | C24: controler l'usure de la clavette et la rainure et reparer au besoin | D24: 30
B25: =B24+1 -> 18 | C25: controler l'arret d'huile et le remplacé au besoin. Aucune fuite d'huile n'est acceptable. | D25: 10
B26: =+B25+1 -> 19 | C26: controler la fixation du réducteur sur le convoyeur et corriger si necessaire. | D26: 30
B27: =B26+1 -> 20 | C27: controler l'usure des roulements et paliers de l'axe moteur et remplacer si necessaire. | D27: 30
B28: =+B27+1 -> 21 | C28: controler l'usure du pignon et le remplacé au besoin. Aucun glissement n'est acceptable. | D28: 30
B29: =B28+1 -> 22 | C29: controler l'alignement et la fixation du pignon de l'axe moteur et remedier au besoin. | D29: 30
B30: =+B29+1 -> 23 | C30: controler l'usure de la clavette et la rainure et reparer au besoin | D30: 30
B31: =B30+1 -> 24 | C31: controler l'usure des roulements et paliers de l'axe moteur et remplacer si necessaire. | D31: 30
B32: =+B31+1 -> 25 | C32: controler l'usure de la clavette et la rainure et reparer au besoin | D32: 30
B33: =B32+1 -> 26 | C33: controler l'état des glissières et remplacer les au besoin | D33: 25
B34: =+B33+1 -> 27 | C34: controler l'arret d'huile et le remplacé au besoin. Aucune fuite d'huile n'est acceptable. | D34: 10
B35: =B34+1 -> 28 | C35: controler la fixation du réducteur sur le convoyeur et corriger si necessaire. | D35: 30
B36: =+B35+1 -> 29 | C36: controler l'usure des roulements et paliers de l'axe moteur et remplacer si necessaire. | D36: 30
B37: =B36+1 -> 30 | C37: controler l'usure des pignons et les remplacés au besoin. Aucun glissement n'est acceptable. | D37: 30
B38: =+B37+1 -> 31 | C38: controler l'alignement et la fixation du pignon de l'axe moteur et remedier au besoin. | D38: 30
B39: =B38+1 -> 32 | C39: controler l'usure de la clavette et la rainure et reparer au besoin | D39: 30
B40: =+B39+1 -> 33 | C40: controler l'état des glissières et remplacer les au besoin | D40: 25
B41: =B40+1 -> 34 | C41: controler l'usure du tapis et remplacer les portions usées ou maillons cassés | D41: 120
B42: =+B41+1 -> 35 | C42: controler la tenson des tapis et ajuster au besoin | D42: 60
B43: =B42+1 -> 36 | C43: controler l'arret d'huile et le remplacé au besoin. Aucune fuite d'huile n'est acceptable. | D43: 10
...

Sheet CC C2
B3: CHECKLIST MECANIQUE | G3: Date
C4: CONVOYEURS CASIERS C2 | D4: =+'Line & frequency'!C1 -> CHAINE….. | G4: =+'Line & frequency'!C2 -> JOURNALIERE
E6: FAIT?
B7: N° | C7: DESCRIPTION DES TACHES | D7: Durée | E7: OUI | F7: NON | G7: REMARQUES (MATERIEL + PIECES)
B8: 1 | C8: controler l'arret d'huile et le remplacé au besoin. Aucune fuite d'huile n'est acceptable. | D8: 10
B9: =B8+1 -> 2 | C9: controler la fixation du réducteur sur le convoyeur et corriger si necessaire. | D9: 30
B10: =+B9+1 -> 3 | C10: controler l'usure du pignon et le remplacé au besoin. Aucun glissement n'est acceptable. | D10: 30
B11: =B10+1 -> 4 | C11: controler l'alignement et la fixation du pignon de l'axe moteur et remedier au besoin. | D11: 30
B12: =+B11+1 -> 5 | C12: controler l'usure de la roue libre et la remplacée au besoin. Aucun glissement n'est acceptable. | D12: 30
B13: =B12+1 -> 6 | C13: controler l'alignement et la fixation de la roue libre et remedier au problème. | D13: 30
B14: =+B13+1 -> 7 | C14: controler l'usure de la clavette et la rainure et reparer au besoin | D14: 30
B15: =B14+1 -> 8 | C15: controler l'état des glissières et remplacer les au besoin | D15: 25
B16: =+B15+1 -> 9 | C16: controler l'arret d'huile et le remplacé au besoin. Aucune fuite d'huile n'est acceptable. | D16: 10
B17: =B16+1 -> 10 | C17: controler l'usure des roulements et paliers de l'axe moteur et remplacer si necessaire. | D17: 30
B18: =+B17+1 -> 11 | C18: controler l'usure du pignon et le remplacé au besoin. Aucun glissement n'est acceptable. | D18: 30
B19: =B18+1 -> 12 | C19: controler l'alignement et la fixation du pignon de l'axe moteur et remedier au besoin. | D19: 30
B20: =+B19+1 -> 13 | C20: controler l'usure de la clavette et la rainure et reparer au besoin | D20: 30
B21: =B20+1 -> 14 | C21: controler l'usure des roulements et paliers de l'axe moteur et remplacer si necessaire. | D21: 30
B22: =+B21+1 -> 15 | C22: controler l'usure de la roue libre et la remplacée au besoin. Aucun glissement n'est acceptable. | D22: 30
B23: =B22+1 -> 16 | C23: controler l'alignement et la fixation de la roue libre et remedier au problème. | D23: 30
B24: =+B23+1 -> 17 | C24: controler l'usure de la clavette et la rainure et reparer au besoin | D24: 30
B25: =B24+1 -> 18 | C25: controler l'arret d'huile et le remplacé au besoin. Aucune fuite d'huile n'est acceptable. | D25: 10
B26: =+B25+1 -> 19 | C26: controler la fixation du réducteur sur le convoyeur et corriger si necessaire. | D26: 30
B27: =B26+1 -> 20 | C27: controler l'usure des roulements et paliers de l'axe moteur et remplacer si necessaire. | D27: 30
B28: =+B27+1 -> 21 | C28: controler l'usure des pignons et les remplacés au besoin. Aucun glissement n'est acceptable. | D28: 30
B29: =B28+1 -> 22 | C29: controler l'alignement et la fixation du pignon de l'axe moteur et remedier au besoin. | D29: 30
B30: =+B29+1 -> 23 | C30: controler l'usure de la clavette et la rainure et reparer au besoin | D30: 30
B31: =B30+1 -> 24 | C31: controler l'état des glissières et remplacer les au besoin | D31: 25
B32: =+B31+1 -> 25 | C32: controler l'usure du tapis et remplacer les portions usées ou maillons cassés | D32: 120
B33: =B32+1 -> 26 | C33: controler la tenson des tapis et ajuster au besoin | D33: 60
B34: =+B33+1 -> 27
B35: =B34+1 -> 28
B36: =+B35+1 -> 29
B37: =B36+1 -> 30
B38: =+B37+1 -> 31
B39: =B38+1 -> 32
B40: =+B39+1 -> 33
B41: =B40+1 -> 34
B42: =+B41+1 -> 35
B43: =B42+1 -> 36
...

Sheet CC C3
B3: CHECKLIST MECANIQUE | G3: Date
C4: CONVOYEURS CASIERS C3 | D4: =+'Line & frequency'!C1 -> CHAINE….. | G4: =+'Line & frequency'!C2 -> JOURNALIERE
E6: FAIT?
B7: N° | C7: DESCRIPTION DES TACHES | D7: Durée | E7: OUI | F7: NON | G7: REMARQUES (MATERIEL + PIECES)
B8: 1 | C8: controler l'arret d'huile et le remplacé au besoin. Aucune fuite d'huile n'est acceptable. | D8: 10
B9: =B8+1 -> 2 | C9: controler la fixation du réducteur sur le convoyeur et corriger si necessaire. | D9: 30
B10: =+B9+1 -> 3 | C10: controler l'usure du pignon et le remplacé au besoin. Aucun glissement n'est acceptable. | D10: 30
B11: =B10+1 -> 4 | C11: controler l'alignement et la fixation du pignon de l'axe moteur et remedier au besoin. | D11: 30
B12: =+B11+1 -> 5 | C12: controler l'usure de la roue libre et la remplacée au besoin. Aucun glissement n'est acceptable. | D12: 30
B13: =B12+1 -> 6 | C13: controler l'alignement et la fixation de la roue libre et remedier au problème. | D13: 30
B14: =+B13+1 -> 7 | C14: controler l'usure de la clavette et la rainure et reparer au besoin | D14: 30
B15: =B14+1 -> 8 | C15: controler l'état des glissières et remplacer les au besoin | D15: 25
B16: =+B15+1 -> 9 | C16: controler l'arret d'huile et le remplacé au besoin. Aucune fuite d'huile n'est acceptable. | D16: 10
B17: =B16+1 -> 10 | C17: controler l'usure des roulements et paliers de l'axe moteur et remplacer si necessaire. | D17: 30
B18: =+B17+1 -> 11 | C18: controler l'usure du pignon et le remplacé au besoin. Aucun glissement n'est acceptable. | D18: 30
B19: =B18+1 -> 12 | C19: controler l'alignement et la fixation du pignon de l'axe moteur et remedier au besoin. | D19: 30
B20: =+B19+1 -> 13 | C20: controler l'usure de la clavette et la rainure et reparer au besoin | D20: 30
B21: =B20+1 -> 14 | C21: controler l'usure des roulements et paliers de l'axe moteur et remplacer si necessaire. | D21: 30
B22: =+B21+1 -> 15 | C22: controler l'usure de la roue libre et la remplacée au besoin. Aucun glissement n'est acceptable. | D22: 30
B23: =B22+1 -> 16 | C23: controler l'alignement et la fixation de la roue libre et remedier au problème. | D23: 30
B24: =+B23+1 -> 17 | C24: controler l'usure de la clavette et la rainure et reparer au besoin | D24: 30
B25: =B24+1 -> 18
B26: =+B25+1 -> 19
B27: =B26+1 -> 20
B28: =+B27+1 -> 21
B29: =B28+1 -> 22
B30: =+B29+1 -> 23
B31: =B30+1 -> 24
B32: =+B31+1 -> 25
B33: Commentaire | D33: Nom et Visa Intervenants | G33: Nom et Visa Responsables

Sheet CC C4
B3: CHECKLIST MECANIQUE | G3: Date
C4: CONVOYEURS CASIERS C4 | D4: =+'Line & frequency'!C1 -> CHAINE….. | G4: =+'Line & frequency'!C2 -> JOURNALIERE
E6: FAIT?
B7: N° | C7: DESCRIPTION DES TACHES | D7: Durée | E7: OUI | F7: NON | G7: REMARQUES (MATERIEL + PIECES)
B8: 1 | C8: controler l'arret d'huile et le remplacé au besoin. Aucune fuite d'huile n'est acceptable. | D8: 10
B9: =B8+1 -> 2 | C9: controler la fixation du réducteur sur le convoyeur et corriger si necessaire. | D9: 30
B10: =+B9+1 -> 3 | C10: controler l'usure du pignon et le remplacé au besoin. Aucun glissement n'est acceptable. | D10: 30
B11: =B10+1 -> 4 | C11: controler l'alignement et la fixation du pignon de l'axe moteur et remedier au besoin. | D11: 30
B12: =+B11+1 -> 5 | C12: controler l'usure de la roue libre et la remplacée au besoin. Aucun glissement n'est acceptable. | D12: 30
B13: =B12+1 -> 6 | C13: controler l'alignement et la fixation de la roue libre et remedier au problème. | D13: 30
B14: =+B13+1 -> 7 | C14: controler l'usure de la clavette et la rainure et reparer au besoin | D14: 30
B15: =B14+1 -> 8 | C15: controler l'état des glissières et remplacer les au besoin | D15: 25
B16: =+B15+1 -> 9 | C16: controler l'arret d'huile et le remplacé au besoin. Aucune fuite d'huile n'est acceptable. | D16: 10
B17: =B16+1 -> 10 | C17: controler l'usure des roulements et paliers de l'axe moteur et remplacer si necessaire. | D17: 30
B18: =+B17+1 -> 11 | C18: controler l'usure du pignon et le remplacé au besoin. Aucun glissement n'est acceptable. | D18: 30
B19: =B18+1 -> 12 | C19: controler l'alignement et la fixation du pignon de l'axe moteur et remedier au besoin. | D19: 30
B20: =+B19+1 -> 13 | C20: controler l'usure de la clavette et la rainure et reparer au besoin | D20: 30
B21: =B20+1 -> 14 | C21: controler l'usure des roulements et paliers de l'axe moteur et remplacer si necessaire. | D21: 30
B22: =+B21+1 -> 15 | C22: controler l'usure de la roue libre et la remplacée au besoin. Aucun glissement n'est acceptable. | D22: 30
B23: =B22+1 -> 16 | C23: controler l'alignement et la fixation de la roue libre et remedier au problème. | D23: 30
B24: =+B23+1 -> 17 | C24: controler l'usure de la clavette et la rainure et reparer au besoin | D24: 30
B25: =B24+1 -> 18 | C25: controler l'arret d'huile et le remplacé au besoin. Aucune fuite d'huile n'est acceptable. | D25: 10
B26: =B25+1 -> 19 | C26: controler la fixation du réducteur sur le convoyeur et corriger si necessaire. | D26: 30
B27: =+B26+1 -> 20 | C27: controler l'usure des roulements et paliers de l'axe moteur et remplacer si necessaire. | D27: 30
B28: =B27+1 -> 21 | C28: controler l'usure du pignon et le remplacé au besoin. Aucun glissement n'est acceptable. | D28: 30
B29: =B28+1 -> 22 | C29: controler l'alignement et la fixation du pignon de l'axe moteur et remedier au besoin. | D29: 30
B30: =+B29+1 -> 23 | C30: controler l'usure de la clavette et la rainure et reparer au besoin | D30: 30
B31: =B30+1 -> 24 | C31: controler l'usure des roulements et paliers de l'axe moteur et remplacer si necessaire. | D31: 30
B32: =B31+1 -> 25 | C32: controler l'usure de la clavette et la rainure et reparer au besoin | D32: 30
B33: =+B32+1 -> 26 | C33: controler l'état des glissières et remplacer les au besoin | D33: 25
B34: =B33+1 -> 27
B35: =B34+1 -> 28
B36: =+B35+1 -> 29
B37: =B36+1 -> 30
B38: Commentaire | D38: Nom et Visa Intervenants | G38: Nom et Visa Responsables

Sheet CC C5
B3: CHECKLIST MECANIQUE | G3: Date
C4: CONVOYEURS CASIERS C5 | D4: =+'Line & frequency'!C1 -> CHAINE….. | G4: =+'Line & frequency'!C2 -> JOURNALIERE
E6: FAIT?
B7: N° | C7: DESCRIPTION DES TACHES | D7: Durée | E7: OUI | F7: NON | G7: REMARQUES (MATERIEL + PIECES)
B8: 1 | C8: controler l'arret d'huile et le remplacé au besoin. Aucune fuite d'huile n'est acceptable. | D8: 10
B9: =B8+1 -> 2 | C9: controler la fixation du réducteur sur le convoyeur et corriger si necessaire. | D9: 30
B10: =+B9+1 -> 3 | C10: controler l'usure du pignon et le remplacé au besoin. Aucun glissement n'est acceptable. | D10: 30
B11: =B10+1 -> 4 | C11: controler l'alignement et la fixation du pignon de l'axe moteur et remedier au besoin. | D11: 30
B12: =+B11+1 -> 5 | C12: controler l'usure de la roue libre et la remplacée au besoin. Aucun glissement n'est acceptable. | D12: 30
B13: =B12+1 -> 6 | C13: controler l'alignement et la fixation de la roue libre et remedier au problème. | D13: 30
B14: =+B13+1 -> 7 | C14: controler l'usure de la clavette et la rainure et reparer au besoin | D14: 30
B15: =B14+1 -> 8 | C15: controler l'état des glissières et remplacer les au besoin | D15: 25
B16: =+B15+1 -> 9 | C16: controler l'arret d'huile et le remplacé au besoin. Aucune fuite d'huile n'est acceptable. | D16: 10
B17: =B16+1 -> 10 | C17: controler l'usure des roulements et paliers de l'axe moteur et remplacer si necessaire. | D17: 30
B18: =+B17+1 -> 11 | C18: controler l'usure du pignon et le remplacé au besoin. Aucun glissement n'est acceptable. | D18: 30
B19: =B18+1 -> 12 | C19: controler l'alignement et la fixation du pignon de l'axe moteur et remedier au besoin. | D19: 30
B20: =+B19+1 -> 13 | C20: controler l'usure de la clavette et la rainure et reparer au besoin | D20: 30
B21: =B20+1 -> 14 | C21: controler l'usure des roulements et paliers de l'axe moteur et remplacer si necessaire. | D21: 30
B22: =+B21+1 -> 15 | C22: controler l'usure de la roue libre et la remplacée au besoin. Aucun glissement n'est acceptable. | D22: 30
B23: =B22+1 -> 16 | C23: controler l'alignement et la fixation de la roue libre et remedier au problème. | D23: 30
B24: =+B23+1 -> 17 | C24: controler l'usure de la clavette et la rainure et reparer au besoin | D24: 30
B25: =B24+1 -> 18
B26: =B25+1 -> 19
B27: =+B26+1 -> 20
B28: =B27+1 -> 21
B29: =B28+1 -> 22
B30: =+B29+1 -> 23
B31: =B30+1 -> 24
B32: =B31+1 -> 25
B33: =+B32+1 -> 26
B34: =B33+1 -> 27
B35: =B34+1 -> 28
B36: =+B35+1 -> 29
B37: =B36+1 -> 30
B38: Commentaire | D38: Nom et Visa Intervenants | G38: Nom et Visa Responsables

Sheet CC C6
B3: CHECKLIST MECANIQUE | G3: Date
C4: CONVOYEURS CASIERS C6 | D4: =+'Line & frequency'!C1 -> CHAINE….. | G4: =+'Line & frequency'!C2 -> JOURNALIERE
E6: FAIT?
B7: N° | C7: DESCRIPTION DES TACHES | D7: Durée | E7: OUI | F7: NON | G7: REMARQUES (MATERIEL + PIECES)
B8: 1 | C8: controler l'arret d'huile et le remplacé au besoin. Aucune fuite d'huile n'est acceptable. | D8: 10
B9: =B8+1 -> 2 | C9: controler la fixation du réducteur sur le convoyeur et corriger si necessaire. | D9: 30
B10: =+B9+1 -> 3 | C10: controler l'usure du pignon et le remplacé au besoin. Aucun glissement n'est acceptable. | D10: 30
B11: =B10+1 -> 4 | C11: controler l'alignement et la fixation du pignon de l'axe moteur et remedier au besoin. | D11: 30
B12: =+B11+1 -> 5 | C12: controler l'usure de la roue libre et la remplacée au besoin. Aucun glissement n'est acceptable. | D12: 30
B13: =B12+1 -> 6 | C13: controler l'alignement et la fixation de la roue libre et remedier au problème. | D13: 30
B14: =+B13+1 -> 7 | C14: controler l'usure de la clavette et la rainure et reparer au besoin | D14: 30
B15: =B14+1 -> 8 | C15: controler l'état des glissières et remplacer les au besoin | D15: 25
B16: =+B15+1 -> 9 | C16: controler l'arret d'huile et le remplacé au besoin. Aucune fuite d'huile n'est acceptable. | D16: 10
B17: =B16+1 -> 10 | C17: controler l'usure des roulements et paliers de l'axe moteur et remplacer si necessaire. | D17: 30
B18: =+B17+1 -> 11 | C18: controler l'usure du pignon et le remplacé au besoin. Aucun glissement n'est acceptable. | D18: 30
B19: =B18+1 -> 12 | C19: controler l'alignement et la fixation du pignon de l'axe moteur et remedier au besoin. | D19: 30
B20: =+B19+1 -> 13 | C20: controler l'usure de la clavette et la rainure et reparer au besoin | D20: 30
B21: =B20+1 -> 14 | C21: controler l'usure des roulements et paliers de l'axe moteur et remplacer si necessaire. | D21: 30
B22: =+B21+1 -> 15 | C22: controler l'usure de la roue libre et la remplacée au besoin. Aucun glissement n'est acceptable. | D22: 30
B23: =B22+1 -> 16 | C23: controler l'alignement et la fixation de la roue libre et remedier au problème. | D23: 30
B24: =+B23+1 -> 17 | C24: controler l'usure de la clavette et la rainure et reparer au besoin | D24: 30
B25: =B24+1 -> 18 | C25: controler l'arret d'huile et le remplacé au besoin. Aucune fuite d'huile n'est acceptable. | D25: 10
B26: =B25+1 -> 19 | C26: controler la fixation du réducteur sur le convoyeur et corriger si necessaire. | D26: 30
B27: =+B26+1 -> 20 | C27: controler l'usure des roulements et paliers de l'axe moteur et remplacer si necessaire. | D27: 30
B28: =B27+1 -> 21 | C28: controler l'usure des pignons et les remplacés au besoin. Aucun glissement n'est acceptable. | D28: 30
B29: =B28+1 -> 22 | C29: controler l'alignement et la fixation du pignon de l'axe moteur et remedier au besoin. | D29: 30
B30: =+B29+1 -> 23 | C30: controler l'usure de la clavette et la rainure et reparer au besoin | D30: 30
B31: =B30+1 -> 24 | C31: controler l'état des glissières et remplacer les au besoin | D31: 25
B32: =B31+1 -> 25 | C32: controler l'usure du tapis et remplacer les portions usées ou maillons cassés | D32: 120
B33: =+B32+1 -> 26 | C33: controler la tenson des tapis et ajuster au besoin | D33: 60
B34: =B33+1 -> 27
B35: =B34+1 -> 28
B36: =+B35+1 -> 29
B37: =B36+1 -> 30
B38: Commentaire | D38: Nom et Visa Intervenants | G38: Nom et Visa Responsables

Sheet CC C7
B3: CHECKLIST MECANIQUE | G3: Date
C4: CONVOYEURS CASIERS C7 | D4: =+'Line & frequency'!C1 -> CHAINE….. | G4: =+'Line & frequency'!C2 -> JOURNALIERE
E6: FAIT?
B7: N° | C7: DESCRIPTION DES TACHES | D7: Durée | E7: OUI | F7: NON | G7: REMARQUES (MATERIEL + PIECES)
B8: 1 | C8: controler l'arret d'huile et le remplacé au besoin. Aucune fuite d'huile n'est acceptable. | D8: 10
B9: =B8+1 -> 2 | C9: controler la fixation du réducteur sur le convoyeur et corriger si necessaire. | D9: 30
B10: =+B9+1 -> 3 | C10: controler l'usure du pignon et le remplacé au besoin. Aucun glissement n'est acceptable. | D10: 30
B11: =B10+1 -> 4 | C11: controler l'alignement et la fixation du pignon de l'axe moteur et remedier au besoin. | D11: 30
B12: =+B11+1 -> 5 | C12: controler l'usure de la roue libre et la remplacée au besoin. Aucun glissement n'est acceptable. | D12: 30
B13: =B12+1 -> 6 | C13: controler l'alignement et la fixation de la roue libre et remedier au problème. | D13: 30
B14: =+B13+1 -> 7 | C14: controler l'usure de la clavette et la rainure et reparer au besoin | D14: 30
B15: =B14+1 -> 8 | C15: controler l'état des glissières et remplacer les au besoin | D15: 25
B16: =+B15+1 -> 9 | C16: controler l'arret d'huile et le remplacé au besoin. Aucune fuite d'huile n'est acceptable. | D16: 10
B17: =B16+1 -> 10 | C17: controler l'usure des roulements et paliers de l'axe moteur et remplacer si necessaire. | D17: 30
B18: =+B17+1 -> 11 | C18: controler l'usure du pignon et le remplacé au besoin. Aucun glissement n'est acceptable. | D18: 30
B19: =B18+1 -> 12 | C19: controler l'alignement et la fixation du pignon de l'axe moteur et remedier au besoin. | D19: 30
B20: =+B19+1 -> 13 | C20: controler l'usure de la clavette et la rainure et reparer au besoin | D20: 30
B21: =B20+1 -> 14 | C21: controler l'usure des roulements et paliers de l'axe moteur et remplacer si necessaire. | D21: 30
B22: =+B21+1 -> 15 | C22: controler l'usure de la roue libre et la remplacée au besoin. Aucun glissement n'est acceptable. | D22: 30
B23: =B22+1 -> 16 | C23: controler l'alignement et la fixation de la roue libre et remedier au problème. | D23: 30
B24: =+B23+1 -> 17 | C24: controler l'usure de la clavette et la rainure et reparer au besoin | D24: 30
B25: =B24+1 -> 18 | C25: controler l'arret d'huile et le remplacé au besoin. Aucune fuite d'huile n'est acceptable. | D25: 10
B26: =B25+1 -> 19 | C26: controler la fixation du réducteur sur le convoyeur et corriger si necessaire. | D26: 30
B27: =+B26+1 -> 20 | C27: controler l'usure des roulements et paliers de l'axe moteur et remplacer si necessaire. | D27: 30
B28: =B27+1 -> 21 | C28: controler l'usure des pignons et les remplacés au besoin. Aucun glissement n'est acceptable. | D28: 30
B29: =B28+1 -> 22 | C29: controler l'alignement et la fixation du pignon de l'axe moteur et remedier au besoin. | D29: 30
B30: =+B29+1 -> 23 | C30: controler l'usure de la clavette et la rainure et reparer au besoin | D30: 30
B31: =B30+1 -> 24 | C31: controler l'état des glissières et remplacer les au besoin | D31: 25
B32: =B31+1 -> 25 | C32: controler l'usure du tapis et remplacer les portions usées ou maillons cassés | D32: 120
B33: =+B32+1 -> 26 | C33: controler la tenson des tapis et ajuster au besoin | D33: 60
B34: =B33+1 -> 27
B35: =B34+1 -> 28
B36: =+B35+1 -> 29
B37: =B36+1 -> 30
B38: Commentaire | D38: Nom et Visa Intervenants | G38: Nom et Visa Responsables

Sheet CC C8
B3: CHECKLIST MECANIQUE | G3: Date
C4: CONVOYEURS CASIERS C8 | D4: =+'Line & frequency'!C1 -> CHAINE….. | G4: =+'Line & frequency'!C2 -> JOURNALIERE
E6: FAIT?
B7: N° | C7: DESCRIPTION DES TACHES | D7: Durée | E7: OUI | F7: NON | G7: REMARQUES (MATERIEL + PIECES)
B8: 1 | C8: controler l'arret d'huile et le remplacé au besoin. Aucune fuite d'huile n'est acceptable. | D8: 10
B9: =B8+1 -> 2 | C9: controler la fixation du réducteur sur le convoyeur et corriger si necessaire. | D9: 30
B10: =+B9+1 -> 3 | C10: controler l'usure du pignon et le remplacé au besoin. Aucun glissement n'est acceptable. | D10: 30
B11: =B10+1 -> 4 | C11: controler l'alignement et la fixation du pignon de l'axe moteur et remedier au besoin. | D11: 30
B12: =+B11+1 -> 5 | C12: controler l'usure de la roue libre et la remplacée au besoin. Aucun glissement n'est acceptable. | D12: 30
B13: =B12+1 -> 6 | C13: controler l'alignement et la fixation de la roue libre et remedier au problème. | D13: 30
B14: =+B13+1 -> 7 | C14: controler l'usure de la clavette et la rainure et reparer au besoin | D14: 30
B15: =B14+1 -> 8 | C15: controler l'état des glissières et remplacer les au besoin | D15: 25
B16: =+B15+1 -> 9 | C16: controler l'arret d'huile et le remplacé au besoin. Aucune fuite d'huile n'est acceptable. | D16: 10
B17: =B16+1 -> 10 | C17: controler la fixation du réducteur sur le convoyeur et corriger si necessaire. | D17: 30
B18: =+B17+1 -> 11 | C18: controler l'usure des roulements et paliers de l'axe moteur et remplacer si necessaire. | D18: 30
B19: =B18+1 -> 12 | C19: controler l'usure des pignons et les remplacés au besoin. Aucun glissement n'est acceptable. | D19: 30
B20: =+B19+1 -> 13 | C20: controler l'alignement et la fixation du pignon de l'axe moteur et remedier au besoin. | D20: 30
B21: =B20+1 -> 14 | C21: controler l'usure de la clavette et la rainure et reparer au besoin | D21: 30
B22: =+B21+1 -> 15 | C22: controler l'état des glissières et remplacer les au besoin | D22: 25
B23: =B22+1 -> 16 | C23: controler l'usure du tapis et remplacer les portions usées ou maillons cassés | D23: 120
B24: =+B23+1 -> 17 | C24: controler la tenson des tapis et ajuster au besoin | D24: 60
B25: =B24+1 -> 18
B26: =B25+1 -> 19
B27: =+B26+1 -> 20
B28: =B27+1 -> 21
B29: =B28+1 -> 22
B30: =+B29+1 -> 23
B31: =B30+1 -> 24
B32: =B31+1 -> 25
B33: =+B32+1 -> 26
B34: =B33+1 -> 27
B35: =B34+1 -> 28
B36: =+B35+1 -> 29
B37: =B36+1 -> 30
B38: Commentaire | D38: Nom et Visa Intervenants | G38: Nom et Visa Responsables

Sheet Line & frequency
B1: Line | C1: CHAINE….. | D1: CHAINE 4
B2: Frequency | C2: JOURNALIERE
B3: Date | C3: 44985 | G3: =+'Line & frequency'!C3 -> 44985

Sheet Feuil2

Sheet Feuil1
B1: TACHES | C1: DUREE
B2: Contrôler usure des sellettes et les remplacer au besoin | C2: 10
B3: Contrôler les colliers à ergot de fixation des têtes de pression | C3: 10
B4: S'assurer de la présence des embouts de protection au bout des têtes de pression | C4: 5 | D4: =+C4*1.5 -> 7.5
B5: Contrôler galets coniques et cylindriques étoile de sortie et remplacer si défectueux | C5: 90
B6: Contrôler et renforcer fixation des glissières du guide central | C6: 15
B7: Contrôler et ajuster l'alignement de la tôle de transfert avec les sellettes à l'entrée et à la sortie | C7: 5 | I7: =970/60 -> 16.166667
B8: Contrôler boulons de fixation des tôles de transfert à l'entrée et à la sortie | C8: 5
B9: Contrôler usure vis de sélection et la remplacer si usée | C9: 5
B10: S'assurer de l'absence de jeu au niveau du manchon de la vis de sélection | C10: 5
B11: S'assurer du bon serrage de la vis de fixation du manchon de la vis de sélection | C11: 5
B12: Ajuster la position des pignons coniques du renvoi d'angle et serrer les vis de blocage en translation | C12: 10
B13: Inspecter courroie de transmission principale et nettoyer casses présentes sur le poulie et la couronne | C13: 10
B14: Vérifier tension de la courroie de transmission principale | C14: 5
B15: Contrôler état et tension courroies trapézoïdales de lissage des stagnoles à la sortie | C15: 5
B16: Inspecter et ajuster couteau avec brosses rondes | C16: 10
B17: Inspecter brosses rondes et ajuster leur position pour rattraper leur usure | C17: 15
B18: Se rassurer que le dispositif de lubrification à l'eau des brosses rondes fonctionne normalement | C18: 10
B19: Contrôler usure étoile d'entrée | C19: 5
... B65: Contrôler portières de sécurité et fenêtres d'inspection de la machine | C65: 5
