Workbook

Sheet Compresseur à air,
B3: CHECKLIST MECANIQUE
C4: Compresseur à air | D4: New PET line | G4: SEMESTRIELLE
E6: FAIT?
B7: N° | C7: DESCRIPTION DES TACHES | D7: Durée | E7: OUI | F7: NON | G7: REMARQUES (MATERIEL + PIECES)
B8: 1 | C8: Contrôler le système de refroidissement d'eau
B9: =B8+1 -> 2 | C9: Contrôler et/ou nettoyer le système de refroidissement du sécheur
B10: =+B9+1 -> 3 | C10: Controler le filtre d'huile et nettoyer si besoin
B11: =B10+1 -> 4 | C11: Controler l'état du filtre d'air d'alimentation sur le verre indicateur et nettoyer si besoin
B12: =+B11+1 -> 5 | C12: Controler le niveau d'huile
B13: =B12+1 -> 6 | C13: Opérez le commutateur TEST au purgeur automatique
B14: =B13+1 -> 7 | C14: Contrôler le bon fonctionnement de l'élimination du condensat
B15: =B14+1 -> 8 | C15: Nettoyer le Air dryer
B16: =B15+1 -> 9 | C16: Nettoyer les moteurs
B17: =B16+1 -> 10 | C17: Chercher le bruit anormal et eliminer
B18: =B17+1 -> 11 | C18: Tester la machine à la fin de la maintenance
B19: Commentaire | D19: Nom et Visa Intervenants | G19: Nom et Visa Responsables

Sheet Blomax
B3: CHECKLIST MECANIQUE | G3: Date:
C4: BLOMAX | D4: New PET line | G4: SEMESTRIELLE
E6: FAIT?
B7: N° | C7: DESCRIPTION DES TACHES | D7: Durée | E7: OUI | F7: NON | G7: REMARQUES (MATERIEL + PIECES)
B8: 1 | C8: Vérifier l'étanchéité de l'alimentation en air du Module de soufflage
B9: 2 | C9: Vérifier l'étanchéité du bloc de soupapes sur le poste de soufflage (bloc de commande)
B10: 3 | C10: Vérifier les flexibles spiralés
B11: 4 | C11: Contrôler la corroson sur les contacts et les connexions des Connecteurs
B12: 5 | C12: Controler la Soufflerie du Filtre d'aspiration
B13: 6 | C13: Controler les cellules des filtres d'aspiration
B14: 7 | C14: Contrôler le fonctionnement des ventilateurs des Armoire électrique
B15: 8 | C15: Remplacer les inserts de filtre stérile et de filtre à charbon actif de la Paroi pneumatique
B16: 9 | C16: Remplacer les radiateurs du Caisson chauffant
B17: 10 | C17: Remplacer les paliers lisses et des galets de came des Postes de transfert
B18: 11 | C18: Remplacer les joints et les joints en U de la Buse soufflante
B19: 12 | C19: Remplacer l'ensemble des joints des tiges d'étirage
... B21: 14 | C21: Remplacer systèmatiquement toutes les lampes chauffantes
B22: 15
B23: Commentaire | D23: Nom et Visa Intervenants | G23: Nom et Visa Responsables

Sheet Paramix
B3: CHECKLIST MECANIQUE | G3: Date:
C4: PARAMIX | D4: New PET line | G4: SEMESTRIELLE
E5: FAIT?
B6: N° | C6: DESCRIPTION DES TACHES | D6: Durée | E6: OUI | F6: NON | G6: REMARQUES (MATERIEL + PIECES)
B7: 1 | C7: Nettoyer le collecteur d'impuretés et contrôler les joints
B8: =B7+1 -> 2
B9: =+B8+1 -> 3
B10: Commentaire | D10: Nom et Visa Intervenants | G10: Nom et Visa Responsables

Sheet CIP 
B3: CHECKLIST MECANIQUE | G3: Date:
C4: CIP | D4: New PET line | G4: SEMESTRIELLE
E5: FAIT?
B6: N° | C6: DESCRIPTION DES TACHES | D6: Durée | E6: OUI | F6: NON | G6: REMARQUES (MATERIEL + PIECES)
B7: 1 | C7: Nettoyer le collecteur d'impuretés et contrôler les joints. Au besoin, remplacer le tamis (Collecteur d'impuretés dans la conduite de vapeur)
B8: =B7+1 -> 2
B9: =+B8+1 -> 3
B10: Commentaire | D10: Nom et Visa Intervenants | G10: Nom et Visa Responsables

Sheet Kisters 
B3: CHECKLIST MECANIQUE | G3: Date:
C4: KISTERS | D4: New PET line | G4: SEMESTRIELLE
E6: FAIT?
B7: N° | C7: DESCRIPTION DES TACHES | D7: Durée | E7: OUI | F7: NON | G7: REMARQUES (MATERIEL + PIECES)
B8: 1 | C8: Remplacer le Palier en cas de jeu de roulement important
B9: =+B8+1 -> 2 | C9: Remplacer le Palier en cas d'écoulement de grandes quantités de graisse
B10: =B9+1 -> 3 | C10: Remplacer le Palier en cas de bruits de roulement.
B11: =+B10+1 -> 4 | C11: Vérifier le fonctionnement du Palier
B12: =B11+1 -> 5 | C12: Vérifier tout changement visible survenu sur les pièces des capots.
B13: =+B12+1 -> 6 | C13: Contrôler le bon fonctionnement des pièces mobiles des capots
B14: =B13+1 -> 7
B15: 8
B16: Commentaire | D16: Nom et Visa Intervenants | G16: Nom et Visa Responsables

Sheet Handle applicator
B3: CHECKLIST MECANIQUE | G3: Date:
C4: HANDLE APPLICATOR | D4: New PET line | G4: SEMESTRIELLE
E6: FAIT?
B7: N° | C7: DESCRIPTION DES TACHES | D7: Durée | E7: OUI | F7: NON | G7: REMARQUES (MATERIEL + PIECES)
B8: 1 | C8: Remplacer le Palier en cas de jeu de roulement important
B9: =B8+1 -> 2 | C9: Remplacer le Palier en cas d'écoulement de grandes quantités de graisse
B10: =+B9+1 -> 3 | C10: Remplacer le Palier en cas de bruits de roulement.
B11: =B10+1 -> 4 | C11: Vérifier le fonctionnement du Palier
B12: =+B11+1 -> 5 | C12: Vérifier tout changement visible survenu sur les pièces des capots.
B13: 6 | C13: Contrôler le bon fonctionnement des pièces mobiles des capots
B14: =B13+1 -> 7 | C14: Vérifier tout changement visible survenu sur les pièces mobiles des portes de protection
B15: 8 | C15: Contrôler le bon fonctionnement des pièces mobiles des portes de protection
B16: 9 | C16: Introduire de la graisse de lubrification à l'aide d'une presse à graisse via les graisseurs sur les Guidage latéral et unité XY
B17: =+B16+1 -> 10 | C17: Après avoir graissé les guidage latéraux et unité XY déplacer le guidage linéaire une fois sur toute la longueur
B18: =B17+1 -> 11
B19: =+B18+1 -> 12
B20: Commentaire | D20: Nom et Visa Intervenants | G20: Nom et Visa Responsables

Sheet Cvyr Btles
B3: CHECKLIST MECANIQUE | G3: Date
C4: PALETTISEUR | D4: =+'Line & frequency'!C1 -> CHAINE 4 | G4: =+'Line & frequency'!C2 -> HEBDOMADAIRE
E6: FAIT?
B7: N° | C7: DESCRIPTION DES TACHES | D7: Durée | E7: OUI | F7: NON | G7: REMARQUES (MATERIEL + PIECES)
B8: 1
B9: =B8+1 -> 2
B10: =+B9+1 -> 3
B11: =B10+1 -> 4
B12: =+B11+1 -> 5
B13: =B12+1 -> 6
B14: =+B13+1 -> 7
B15: =B14+1 -> 8
B16: =+B15+1 -> 9
B17: =B16+1 -> 10
B18: =+B17+1 -> 11
B19: =B18+1 -> 12
B20: =+B19+1 -> 13
B21: =B20+1 -> 14
B22: =+B21+1 -> 15
B23: =B22+1 -> 16
B24: =+B23+1 -> 17
B25: =B24+1 -> 18
B26: =+B25+1 -> 19
B27: =B26+1 -> 20
B28: =+B27+1 -> 21
B29: =B28+1 -> 22
B30: =+B29+1 -> 23
B31: =B30+1 -> 24
B32: =+B31+1 -> 25
B33: =B32+1 -> 26
B34: =+B33+1 -> 27
B35: =B34+1 -> 28
B36: =+B35+1 -> 29
B37: =B36+1 -> 30
B38: =+B37+1 -> 31
B39: =B38+1 -> 32
B40: =+B39+1 -> 33
B41: =B40+1 -> 34
B42: =+B41+1 -> 35
B43: =B42+1 -> 36
...

Sheet CC C1
B3: CHECKLIST MECANIQUE | G3: Date
C4: CONVOYEURS CASIERS C1 | D4: =+'Line & frequency'!C1 -> CHAINE 4 | G4: =+'Line & frequency'!C2 -> HEBDOMADAIRE
E6: FAIT?
B7: N° | C7: DESCRIPTION DES TACHES | D7: Durée | E7: OUI | F7: NON | G7: REMARQUES (MATERIEL + PIECES)
B8: 1 | C8: controler l'arret d'huile et le remplacé au besoin. Aucune fuite d'huile n'est acceptable. | D8: 10
B9: =B8+1 -> 2 | C9: controler la fixation du réducteur sur le convoyeur et corriger si necessaire. | D9: 30
B10: =+B9+1 -> 3 | C10: controler l'usure du pignon et le remplacé au besoin. Aucun glissement n'est acceptable. | D10: 30
B11: =B10+1 -> 4 | C11: controler l'alignement et la fixation du pignon de l'axe moteur et remedier au besoin. | D11: 30
B12: =+B11+1 -> 5 | C12: controler l'usure de la roue libre et la remplacée au besoin. Aucun glissement n'est acceptable. | D12: 30
B13: =B12+1 -> 6 | C13: controler l'alignement et la fixation de la roue libre et remedier au problème. | D13: 30
B14: =+B13+1 -> 7 | C14: controler l'usure de la clavette et la rainure et reparer au besoin | D14: 30
B15: =B14+1 -> 8 | C15: controler l'état des glissières et remplacer les au besoin | D15: 25
B16: =+B15+1 -> 9 | C16: controler l'arret d'huile et le remplacé au besoin. Aucune fuite d'huile n'est acceptable. | D16: 10
B17: =B16+1 -> 10 | C17: controler l'usure des roulements et paliers de l'axe moteur et remplacer si necessaire. | D17: 30
B18: =+B17+1 -> 11 | C18: controler l'usure du pignon et le remplacé au besoin. Aucun glissement n'est acceptable. | D18: 30
B19: =B18+1 -> 12 | C19: controler l'alignement et la fixation du pignon de l'axe moteur et remedier au besoin. | D19: 30
B20: =+B19+1 -> 13 | C20: controler l'usure de la clavette et la rainure et reparer au besoin | D20: 30
B21: =B20+1 -> 14 | C21: controler l'usure des roulements et paliers de l'axe moteur et remplacer si necessaire. | D21: 30
B22: =+B21+1 -> 15 | C22: controler l'usure de la roue libre et la remplacée au besoin. Aucun glissement n'est acceptable. | D22: 30
B23: =B22+1 -> 16 | C23: controler l'alignement et la fixation de la roue libre et remedier au problème. | D23: 30
B24: =+B23+1 -> 17 | C24: controler l'usure de la clavette et la rainure et reparer au besoin | D24: 30
B25: =B24+1 -> 18 | C25: controler l'arret d'huile et le remplacé au besoin. Aucune fuite d'huile n'est acceptable. | D25: 10
B26: =+B25+1 -> 19 | C26: controler la fixation du réducteur sur le convoyeur et corriger si necessaire. | D26: 30
B27: =B26+1 -> 20 | C27: controler l'usure des roulements et paliers de l'axe moteur et remplacer si necessaire. | D27: 30
B28: =+B27+1 -> 21 | C28: controler l'usure du pignon et le remplacé au besoin. Aucun glissement n'est acceptable. | D28: 30
B29: =B28+1 -> 22 | C29: controler l'alignement et la fixation du pignon de l'axe moteur et remedier au besoin. | D29: 30
B30: =+B29+1 -> 23 | C30: controler l'usure de la clavette et la rainure et reparer au besoin | D30: 30
B31: =B30+1 -> 24 | C31: controler l'usure des roulements et paliers de l'axe moteur et remplacer si necessaire. | D31: 30
B32: =+B31+1 -> 25 | C32: controler l'usure de la clavette et la rainure et reparer au besoin | D32: 30
B33: =B32+1 -> 26 | C33: controler l'état des glissières et remplacer les au besoin | D33: 25
B34: =+B33+1 -> 27 | C34: controler l'arret d'huile et le remplacé au besoin. Aucune fuite d'huile n'est acceptable. | D34: 10
B35: =B34+1 -> 28 | C35: controler la fixation du réducteur sur le convoyeur et corriger si necessaire. | D35: 30
B36: =+B35+1 -> 29 | C36: controler l'usure des roulements et paliers de l'axe moteur et remplacer si necessaire. | D36: 30
B37: =B36+1 -> 30 | C37: controler l'usure des pignons et les remplacés au besoin. Aucun glissement n'est acceptable. | D37: 30
B38: =+B37+1 -> 31 | C38: controler l'alignement et la fixation du pignon de l'axe moteur et remedier au besoin. | D38: 30
B39: =B38+1 -> 32 | C39: controler l'usure de la clavette et la rainure et reparer au besoin | D39: 30
B40: =+B39+1 -> 33 | C40: controler l'état des glissières et remplacer les au besoin | D40: 25
B41: =B40+1 -> 34 | C41: controler l'usure du tapis et remplacer les portions usées ou maillons cassés | D41: 120
B42: =+B41+1 -> 35 | C42: controler la tenson des tapis et ajuster au besoin | D42: 60
B43: =B42+1 -> 36 | C43: controler l'arret d'huile et le remplacé au besoin. Aucune fuite d'huile n'est acceptable. | D43: 10
...

Sheet CC C2
B3: CHECKLIST MECANIQUE | G3: Date
C4: CONVOYEURS CASIERS C2 | D4: =+'Line & frequency'!C1 -> CHAINE 4 | G4: =+'Line & frequency'!C2 -> HEBDOMADAIRE
E6: FAIT?
B7: N° | C7: DESCRIPTION DES TACHES | D7: Durée | E7: OUI | F7: NON | G7: REMARQUES (MATERIEL + PIECES)
B8: 1 | C8: controler l'arret d'huile et le remplacé au besoin. Aucune fuite d'huile n'est acceptable. | D8: 10
B9: =B8+1 -> 2 | C9: controler la fixation du réducteur sur le convoyeur et corriger si necessaire. | D9: 30
B10: =+B9+1 -> 3 | C10: controler l'usure du pignon et le remplacé au besoin. Aucun glissement n'est acceptable. | D10: 30
B11: =B10+1 -> 4 | C11: controler l'alignement et la fixation du pignon de l'axe moteur et remedier au besoin. | D11: 30
B12: =+B11+1 -> 5 | C12: controler l'usure de la roue libre et la remplacée au besoin. Aucun glissement n'est acceptable. | D12: 30
B13: =B12+1 -> 6 | C13: controler l'alignement et la fixation de la roue libre et remedier au problème. | D13: 30
B14: =+B13+1 -> 7 | C14: controler l'usure de la clavette et la rainure et reparer au besoin | D14: 30
B15: =B14+1 -> 8 | C15: controler l'état des glissières et remplacer les au besoin | D15: 25
B16: =+B15+1 -> 9 | C16: controler l'arret d'huile et le remplacé au besoin. Aucune fuite d'huile n'est acceptable. | D16: 10
B17: =B16+1 -> 10 | C17: controler l'usure des roulements et paliers de l'axe moteur et remplacer si necessaire. | D17: 30
B18: =+B17+1 -> 11 | C18: controler l'usure du pignon et le remplacé au besoin. Aucun glissement n'est acceptable. | D18: 30
B19: =B18+1 -> 12 | C19: controler l'alignement et la fixation du pignon de l'axe moteur et remedier au besoin. | D19: 30
B20: =+B19+1 -> 13 | C20: controler l'usure de la clavette et la rainure et reparer au besoin | D20: 30
B21: =B20+1 -> 14 | C21: controler l'usure des roulements et paliers de l'axe moteur et remplacer si necessaire. | D21: 30
B22: =+B21+1 -> 15 | C22: controler l'usure de la roue libre et la remplacée au besoin. Aucun glissement n'est acceptable. | D22: 30
B23: =B22+1 -> 16 | C23: controler l'alignement et la fixation de la roue libre et remedier au problème. | D23: 30
B24: =+B23+1 -> 17 | C24: controler l'usure de la clavette et la rainure et reparer au besoin | D24: 30
B25: =B24+1 -> 18 | C25: controler l'arret d'huile et le remplacé au besoin. Aucune fuite d'huile n'est acceptable. | D25: 10
B26: =+B25+1 -> 19 | C26: controler la fixation du réducteur sur le convoyeur et corriger si necessaire. | D26: 30
B27: =B26+1 -> 20 | C27: controler l'usure des roulements et paliers de l'axe moteur et remplacer si necessaire. | D27: 30
B28: =+B27+1 -> 21 | C28: controler l'usure des pignons et les remplacés au besoin. Aucun glissement n'est acceptable. | D28: 30
B29: =B28+1 -> 22 | C29: controler l'alignement et la fixation du pignon de l'axe moteur et remedier au besoin. | D29: 30
B30: =+B29+1 -> 23 | C30: controler l'usure de la clavette et la rainure et reparer au besoin | D30: 30
B31: =B30+1 -> 24 | C31: controler l'état des glissières et remplacer les au besoin | D31: 25
B32: =+B31+1 -> 25 | C32: controler l'usure du tapis et remplacer les portions usées ou maillons cassés | D32: 120
B33: =B32+1 -> 26 | C33: controler la tenson des tapis et ajuster au besoin | D33: 60
B34: =+B33+1 -> 27
B35: =B34+1 -> 28
B36: =+B35+1 -> 29
B37: =B36+1 -> 30
B38: =+B37+1 -> 31
B39: =B38+1 -> 32
B40: =+B39+1 -> 33
B41: =B40+1 -> 34
B42: =+B41+1 -> 35
B43: =B42+1 -> 36
...

Sheet CC C3
B3: CHECKLIST MECANIQUE | G3: Date
C4: CONVOYEURS CASIERS C3 | D4: =+'Line & frequency'!C1 -> CHAINE 4 | G4: =+'Line & frequency'!C2 -> HEBDOMADAIRE
E6: FAIT?
B7: N° | C7: DESCRIPTION DES TACHES | D7: Durée | E7: OUI | F7: NON | G7: REMARQUES (MATERIEL + PIECES)
B8: 1 | C8: controler l'arret d'huile et le remplacé au besoin. Aucune fuite d'huile n'est acceptable. | D8: 10
B9: =B8+1 -> 2 | C9: controler la fixation du réducteur sur le convoyeur et corriger si necessaire. | D9: 30
B10: =+B9+1 -> 3 | C10: controler l'usure du pignon et le remplacé au besoin. Aucun glissement n'est acceptable. | D10: 30
B11: =B10+1 -> 4 | C11: controler l'alignement et la fixation du pignon de l'axe moteur et remedier au besoin. | D11: 30
B12: =+B11+1 -> 5 | C12: controler l'usure de la roue libre et la remplacée au besoin. Aucun glissement n'est acceptable. | D12: 30
B13: =B12+1 -> 6 | C13: controler l'alignement et la fixation de la roue libre et remedier au problème. | D13: 30
B14: =+B13+1 -> 7 | C14: controler l'usure de la clavette et la rainure et reparer au besoin | D14: 30
B15: =B14+1 -> 8 | C15: controler l'état des glissières et remplacer les au besoin | D15: 25
B16: =+B15+1 -> 9 | C16: controler l'arret d'huile et le remplacé au besoin. Aucune fuite d'huile n'est acceptable. | D16: 10
B17: =B16+1 -> 10 | C17: controler l'usure des roulements et paliers de l'axe moteur et remplacer si necessaire. | D17: 30
B18: =+B17+1 -> 11 | C18: controler l'usure du pignon et le remplacé au besoin. Aucun glissement n'est acceptable. | D18: 30
B19: =B18+1 -> 12 | C19: controler l'alignement et la fixation du pignon de l'axe moteur et remedier au besoin. | D19: 30
B20: =+B19+1 -> 13 | C20: controler l'usure de la clavette et la rainure et reparer au besoin | D20: 30
B21: =B20+1 -> 14 | C21: controler l'usure des roulements et paliers de l'axe moteur et remplacer si necessaire. | D21: 30
B22: =+B21+1 -> 15 | C22: controler l'usure de la roue libre et la remplacée au besoin. Aucun glissement n'est acceptable. | D22: 30
B23: =B22+1 -> 16 | C23: controler l'alignement et la fixation de la roue libre et remedier au problème. | D23: 30
B24: =+B23+1 -> 17 | C24: controler l'usure de la clavette et la rainure et reparer au besoin | D24: 30
B25: =B24+1 -> 18
B26: =+B25+1 -> 19
B27: =B26+1 -> 20
B28: =+B27+1 -> 21
B29: =B28+1 -> 22
B30: =+B29+1 -> 23
B31: =B30+1 -> 24
B32: =+B31+1 -> 25
B33: Commentaire | D33: Nom et Visa Intervenants | G33: Nom et Visa Responsables

Sheet CC C4
B3: CHECKLIST MECANIQUE | G3: Date
C4: CONVOYEURS CASIERS C4 | D4: =+'Line & frequency'!C1 -> CHAINE 4 | G4: =+'Line & frequency'!C2 -> HEBDOMADAIRE
E6: FAIT?
B7: N° | C7: DESCRIPTION DES TACHES | D7: Durée | E7: OUI | F7: NON | G7: REMARQUES (MATERIEL + PIECES)
B8: 1 | C8: controler l'arret d'huile et le remplacé au besoin. Aucune fuite d'huile n'est acceptable. | D8: 10
B9: =B8+1 -> 2 | C9: controler la fixation du réducteur sur le convoyeur et corriger si necessaire. | D9: 30
B10: =+B9+1 -> 3 | C10: controler l'usure du pignon et le remplacé au besoin. Aucun glissement n'est acceptable. | D10: 30
B11: =B10+1 -> 4 | C11: controler l'alignement et la fixation du pignon de l'axe moteur et remedier au besoin. | D11: 30
B12: =+B11+1 -> 5 | C12: controler l'usure de la roue libre et la remplacée au besoin. Aucun glissement n'est acceptable. | D12: 30
B13: =B12+1 -> 6 | C13: controler l'alignement et la fixation de la roue libre et remedier au problème. | D13: 30
B14: =+B13+1 -> 7 | C14: controler l'usure de la clavette et la rainure et reparer au besoin | D14: 30
B15: =B14+1 -> 8 | C15: controler l'état des glissières et remplacer les au besoin | D15: 25
B16: =+B15+1 -> 9 | C16: controler l'arret d'huile et le remplacé au besoin. Aucune fuite d'huile n'est acceptable. | D16: 10
B17: =B16+1 -> 10 | C17: controler l'usure des roulements et paliers de l'axe moteur et remplacer si necessaire. | D17: 30
B18: =+B17+1 -> 11 | C18: controler l'usure du pignon et le remplacé au besoin. Aucun glissement n'est acceptable. | D18: 30
B19: =B18+1 -> 12 | C19: controler l'alignement et la fixation du pignon de l'axe moteur et remedier au besoin. | D19: 30
B20: =+B19+1 -> 13 | C20: controler l'usure de la clavette et la rainure et reparer au besoin | D20: 30
B21: =B20+1 -> 14 | C21: controler l'usure des roulements et paliers de l'axe moteur et remplacer si necessaire. | D21: 30
B22: =+B21+1 -> 15 | C22: controler l'usure de la roue libre et la remplacée au besoin. Aucun glissement n'est acceptable. | D22: 30
B23: =B22+1 -> 16 | C23: controler l'alignement et la fixation de la roue libre et remedier au problème. | D23: 30
B24: =+B23+1 -> 17 | C24: controler l'usure de la clavette et la rainure et reparer au besoin | D24: 30
B25: =B24+1 -> 18 | C25: controler l'arret d'huile et le remplacé au besoin. Aucune fuite d'huile n'est acceptable. | D25: 10
B26: =B25+1 -> 19 | C26: controler la fixation du réducteur sur le convoyeur et corriger si necessaire. | D26: 30
B27: =+B26+1 -> 20 | C27: controler l'usure des roulements et paliers de l'axe moteur et remplacer si necessaire. | D27: 30
B28: =B27+1 -> 21 | C28: controler l'usure du pignon et le remplacé au besoin. Aucun glissement n'est acceptable. | D28: 30
B29: =B28+1 -> 22 | C29: controler l'alignement et la fixation du pignon de l'axe moteur et remedier au besoin. | D29: 30
B30: =+B29+1 -> 23 | C30: controler l'usure de la clavette et la rainure et reparer au besoin | D30: 30
B31: =B30+1 -> 24 | C31: controler l'usure des roulements et paliers de l'axe moteur et remplacer si necessaire. | D31: 30
B32: =B31+1 -> 25 | C32: controler l'usure de la clavette et la rainure et reparer au besoin | D32: 30
B33: =+B32+1 -> 26 | C33: controler l'état des glissières et remplacer les au besoin | D33: 25
B34: =B33+1 -> 27
B35: =B34+1 -> 28
B36: =+B35+1 -> 29
B37: =B36+1 -> 30
B38: Commentaire | D38: Nom et Visa Intervenants | G38: Nom et Visa Responsables

Sheet CC C5
B3: CHECKLIST MECANIQUE | G3: Date
C4: CONVOYEURS CASIERS C5 | D4: =+'Line & frequency'!C1 -> CHAINE 4 | G4: =+'Line & frequency'!C2 -> HEBDOMADAIRE
E6: FAIT?
B7: N° | C7: DESCRIPTION DES TACHES | D7: Durée | E7: OUI | F7: NON | G7: REMARQUES (MATERIEL + PIECES)
B8: 1 | C8: controler l'arret d'huile et le remplacé au besoin. Aucune fuite d'huile n'est acceptable. | D8: 10
B9: =B8+1 -> 2 | C9: controler la fixation du réducteur sur le convoyeur et corriger si necessaire. | D9: 30
B10: =+B9+1 -> 3 | C10: controler l'usure du pignon et le remplacé au besoin. Aucun glissement n'est acceptable. | D10: 30
B11: =B10+1 -> 4 | C11: controler l'alignement et la fixation du pignon de l'axe moteur et remedier au besoin. | D11: 30
B12: =+B11+1 -> 5 | C12: controler l'usure de la roue libre et la remplacée au besoin. Aucun glissement n'est acceptable. | D12: 30
B13: =B12+1 -> 6 | C13: controler l'alignement et la fixation de la roue libre et remedier au problème. | D13: 30
B14: =+B13+1 -> 7 | C14: controler l'usure de la clavette et la rainure et reparer au besoin | D14: 30
B15: =B14+1 -> 8 | C15: controler l'état des glissières et remplacer les au besoin | D15: 25
B16: =+B15+1 -> 9 | C16: controler l'arret d'huile et le remplacé au besoin. Aucune fuite d'huile n'est acceptable. | D16: 10
B17: =B16+1 -> 10 | C17: controler l'usure des roulements et paliers de l'axe moteur et remplacer si necessaire. | D17: 30
B18: =+B17+1 -> 11 | C18: controler l'usure du pignon et le remplacé au besoin. Aucun glissement n'est acceptable. | D18: 30
B19: =B18+1 -> 12 | C19: controler l'alignement et la fixation du pignon de l'axe moteur et remedier au besoin. | D19: 30
B20: =+B19+1 -> 13 | C20: controler l'usure de la clavette et la rainure et reparer au besoin | D20: 30
B21: =B20+1 -> 14 | C21: controler l'usure des roulements et paliers de l'axe moteur et remplacer si necessaire. | D21: 30
B22: =+B21+1 -> 15 | C22: controler l'usure de la roue libre et la remplacée au besoin. Aucun glissement n'est acceptable. | D22: 30
B23: =B22+1 -> 16 | C23: controler l'alignement et la fixation de la roue libre et remedier au problème. | D23: 30
B24: =+B23+1 -> 17 | C24: controler l'usure de la clavette et la rainure et reparer au besoin | D24: 30
B25: =B24+1 -> 18
B26: =B25+1 -> 19
B27: =+B26+1 -> 20
B28: =B27+1 -> 21
B29: =B28+1 -> 22
B30: =+B29+1 -> 23
B31: =B30+1 -> 24
B32: =B31+1 -> 25
B33: =+B32+1 -> 26
B34: =B33+1 -> 27
B35: =B34+1 -> 28
B36: =+B35+1 -> 29
B37: =B36+1 -> 30
B38: Commentaire | D38: Nom et Visa Intervenants | G38: Nom et Visa Responsables

Sheet CC C6
B3: CHECKLIST MECANIQUE | G3: Date
C4: CONVOYEURS CASIERS C6 | D4: =+'Line & frequency'!C1 -> CHAINE 4 | G4: =+'Line & frequency'!C2 -> HEBDOMADAIRE
E6: FAIT?
B7: N° | C7: DESCRIPTION DES TACHES | D7: Durée | E7: OUI | F7: NON | G7: REMARQUES (MATERIEL + PIECES)
B8: 1 | C8: controler l'arret d'huile et le remplacé au besoin. Aucune fuite d'huile n'est acceptable. | D8: 10
B9: =B8+1 -> 2 | C9: controler la fixation du réducteur sur le convoyeur et corriger si necessaire. | D9: 30
B10: =+B9+1 -> 3 | C10: controler l'usure du pignon et le remplacé au besoin. Aucun glissement n'est acceptable. | D10: 30
B11: =B10+1 -> 4 | C11: controler l'alignement et la fixation du pignon de l'axe moteur et remedier au besoin. | D11: 30
B12: =+B11+1 -> 5 | C12: controler l'usure de la roue libre et la remplacée au besoin. Aucun glissement n'est acceptable. | D12: 30
B13: =B12+1 -> 6 | C13: controler l'alignement et la fixation de la roue libre et remedier au problème. | D13: 30
B14: =+B13+1 -> 7 | C14: controler l'usure de la clavette et la rainure et reparer au besoin | D14: 30
B15: =B14+1 -> 8 | C15: controler l'état des glissières et remplacer les au besoin | D15: 25
B16: =+B15+1 -> 9 | C16: controler l'arret d'huile et le remplacé au besoin. Aucune fuite d'huile n'est acceptable. | D16: 10
B17: =B16+1 -> 10 | C17: controler l'usure des roulements et paliers de l'axe moteur et remplacer si necessaire. | D17: 30
B18: =+B17+1 -> 11 | C18: controler l'usure du pignon et le remplacé au besoin. Aucun glissement n'est acceptable. | D18: 30
B19: =B18+1 -> 12 | C19: controler l'alignement et la fixation du pignon de l'axe moteur et remedier au besoin. | D19: 30
B20: =+B19+1 -> 13 | C20: controler l'usure de la clavette et la rainure et reparer au besoin | D20: 30
B21: =B20+1 -> 14 | C21: controler l'usure des roulements et paliers de l'axe moteur et remplacer si necessaire. | D21: 30
B22: =+B21+1 -> 15 | C22: controler l'usure de la roue libre et la remplacée au besoin. Aucun glissement n'est acceptable. | D22: 30
B23: =B22+1 -> 16 | C23: controler l'alignement et la fixation de la roue libre et remedier au problème. | D23: 30
B24: =+B23+1 -> 17 | C24: controler l'usure de la clavette et la rainure et reparer au besoin | D24: 30
B25: =B24+1 -> 18 | C25: controler l'arret d'huile et le remplacé au besoin. Aucune fuite d'huile n'est acceptable. | D25: 10
B26: =B25+1 -> 19 | C26: controler la fixation du réducteur sur le convoyeur et corriger si necessaire. | D26: 30
B27: =+B26+1 -> 20 | C27: controler l'usure des roulements et paliers de l'axe moteur et remplacer si necessaire. | D27: 30
B28: =B27+1 -> 21 | C28: controler l'usure des pignons et les remplacés au besoin. Aucun glissement n'est acceptable. | D28: 30
B29: =B28+1 -> 22 | C29: controler l'alignement et la fixation du pignon de l'axe moteur et remedier au besoin. | D29: 30
B30: =+B29+1 -> 23 | C30: controler l'usure de la clavette et la rainure et reparer au besoin | D30: 30
B31: =B30+1 -> 24 | C31: controler l'état des glissières et remplacer les au besoin | D31: 25
B32: =B31+1 -> 25 | C32: controler l'usure du tapis et remplacer les portions usées ou maillons cassés | D32: 120
B33: =+B32+1 -> 26 | C33: controler la tenson des tapis et ajuster au besoin | D33: 60
B34: =B33+1 -> 27
B35: =B34+1 -> 28
B36: =+B35+1 -> 29
B37: =B36+1 -> 30
B38: Commentaire | D38: Nom et Visa Intervenants | G38: Nom et Visa Responsables

Sheet CC C7
B3: CHECKLIST MECANIQUE | G3: Date
C4: CONVOYEURS CASIERS C7 | D4: =+'Line & frequency'!C1 -> CHAINE 4 | G4: =+'Line & frequency'!C2 -> HEBDOMADAIRE
E6: FAIT?
B7: N° | C7: DESCRIPTION DES TACHES | D7: Durée | E7: OUI | F7: NON | G7: REMARQUES (MATERIEL + PIECES)
B8: 1 | C8: controler l'arret d'huile et le remplacé au besoin. Aucune fuite d'huile n'est acceptable. | D8: 10
B9: =B8+1 -> 2 | C9: controler la fixation du réducteur sur le convoyeur et corriger si necessaire. | D9: 30
B10: =+B9+1 -> 3 | C10: controler l'usure du pignon et le remplacé au besoin. Aucun glissement n'est acceptable. | D10: 30
B11: =B10+1 -> 4 | C11: controler l'alignement et la fixation du pignon de l'axe moteur et remedier au besoin. | D11: 30
B12: =+B11+1 -> 5 | C12: controler l'usure de la roue libre et la remplacée au besoin. Aucun glissement n'est acceptable. | D12: 30
B13: =B12+1 -> 6 | C13: controler l'alignement et la fixation de la roue libre et remedier au problème. | D13: 30
B14: =+B13+1 -> 7 | C14: controler l'usure de la clavette et la rainure et reparer au besoin | D14: 30
B15: =B14+1 -> 8 | C15: controler l'état des glissières et remplacer les au besoin | D15: 25
B16: =+B15+1 -> 9 | C16: controler l'arret d'huile et le remplacé au besoin. Aucune fuite d'huile n'est acceptable. | D16: 10
B17: =B16+1 -> 10 | C17: controler l'usure des roulements et paliers de l'axe moteur et remplacer si necessaire. | D17: 30
B18: =+B17+1 -> 11 | C18: controler l'usure du pignon et le remplacé au besoin. Aucun glissement n'est acceptable. | D18: 30
B19: =B18+1 -> 12 | C19: controler l'alignement et la fixation du pignon de l'axe moteur et remedier au besoin. | D19: 30
B20: =+B19+1 -> 13 | C20: controler l'usure de la clavette et la rainure et reparer au besoin | D20: 30
B21: =B20+1 -> 14 | C21: controler l'usure des roulements et paliers de l'axe moteur et remplacer si necessaire. | D21: 30
B22: =+B21+1 -> 15 | C22: controler l'usure de la roue libre et la remplacée au besoin. Aucun glissement n'est acceptable. | D22: 30
B23: =B22+1 -> 16 | C23: controler l'alignement et la fixation de la roue libre et remedier au problème. | D23: 30
B24: =+B23+1 -> 17 | C24: controler l'usure de la clavette et la rainure et reparer au besoin | D24: 30
B25: =B24+1 -> 18 | C25: controler l'arret d'huile et le remplacé au besoin. Aucune fuite d'huile n'est acceptable. | D25: 10
B26: =B25+1 -> 19 | C26: controler la fixation du réducteur sur le convoyeur et corriger si necessaire. | D26: 30
B27: =+B26+1 -> 20 | C27: controler l'usure des roulements et paliers de l'axe moteur et remplacer si necessaire. | D27: 30
B28: =B27+1 -> 21 | C28: controler l'usure des pignons et les remplacés au besoin. Aucun glissement n'est acceptable. | D28: 30
B29: =B28+1 -> 22 | C29: controler l'alignement et la fixation du pignon de l'axe moteur et remedier au besoin. | D29: 30
B30: =+B29+1 -> 23 | C30: controler l'usure de la clavette et la rainure et reparer au besoin | D30: 30
B31: =B30+1 -> 24 | C31: controler l'état des glissières et remplacer les au besoin | D31: 25
B32: =B31+1 -> 25 | C32: controler l'usure du tapis et remplacer les portions usées ou maillons cassés | D32: 120
B33: =+B32+1 -> 26 | C33: controler la tenson des tapis et ajuster au besoin | D33: 60
B34: =B33+1 -> 27
B35: =B34+1 -> 28
B36: =+B35+1 -> 29
B37: =B36+1 -> 30
B38: Commentaire | D38: Nom et Visa Intervenants | G38: Nom et Visa Responsables

Sheet CC C8
B3: CHECKLIST MECANIQUE | G3: Date
C4: CONVOYEURS CASIERS C8 | D4: =+'Line & frequency'!C1 -> CHAINE 4 | G4: =+'Line & frequency'!C2 -> HEBDOMADAIRE
E6: FAIT?
B7: N° | C7: DESCRIPTION DES TACHES | D7: Durée | E7: OUI | F7: NON | G7: REMARQUES (MATERIEL + PIECES)
B8: 1 | C8: controler l'arret d'huile et le remplacé au besoin. Aucune fuite d'huile n'est acceptable. | D8: 10
B9: =B8+1 -> 2 | C9: controler la fixation du réducteur sur le convoyeur et corriger si necessaire. | D9: 30
B10: =+B9+1 -> 3 | C10: controler l'usure du pignon et le remplacé au besoin. Aucun glissement n'est acceptable. | D10: 30
B11: =B10+1 -> 4 | C11: controler l'alignement et la fixation du pignon de l'axe moteur et remedier au besoin. | D11: 30
B12: =+B11+1 -> 5 | C12: controler l'usure de la roue libre et la remplacée au besoin. Aucun glissement n'est acceptable. | D12: 30
B13: =B12+1 -> 6 | C13: controler l'alignement et la fixation de la roue libre et remedier au problème. | D13: 30
B14: =+B13+1 -> 7 | C14: controler l'usure de la clavette et la rainure et reparer au besoin | D14: 30
B15: =B14+1 -> 8 | C15: controler l'état des glissières et remplacer les au besoin | D15: 25
B16: =+B15+1 -> 9 | C16: controler l'arret d'huile et le remplacé au besoin. Aucune fuite d'huile n'est acceptable. | D16: 10
B17: =B16+1 -> 10 | C17: controler la fixation du réducteur sur le convoyeur et corriger si necessaire. | D17: 30
B18: =+B17+1 -> 11 | C18: controler l'usure des roulements et paliers de l'axe moteur et remplacer si necessaire. | D18: 30
B19: =B18+1 -> 12 | C19: controler l'usure des pignons et les remplacés au besoin. Aucun glissement n'est acceptable. | D19: 30
B20: =+B19+1 -> 13 | C20: controler l'alignement et la fixation du pignon de l'axe moteur et remedier au besoin. | D20: 30
B21: =B20+1 -> 14 | C21: controler l'usure de la clavette et la rainure et reparer au besoin | D21: 30
B22: =+B21+1 -> 15 | C22: controler l'état des glissières et remplacer les au besoin | D22: 25
B23: =B22+1 -> 16 | C23: controler l'usure du tapis et remplacer les portions usées ou maillons cassés | D23: 120
B24: =+B23+1 -> 17 | C24: controler la tenson des tapis et ajuster au besoin | D24: 60
B25: =B24+1 -> 18
B26: =B25+1 -> 19
B27: =+B26+1 -> 20
B28: =B27+1 -> 21
B29: =B28+1 -> 22
B30: =+B29+1 -> 23
B31: =B30+1 -> 24
B32: =B31+1 -> 25
B33: =+B32+1 -> 26
B34: =B33+1 -> 27
B35: =B34+1 -> 28
B36: =+B35+1 -> 29
B37: =B36+1 -> 30
B38: Commentaire | D38: Nom et Visa Intervenants | G38: Nom et Visa Responsables

Sheet Line & frequency
B1: Line | C1: CHAINE 4
B2: Frequency | C2: HEBDOMADAIRE
B3: Date | C3: 44273 | G3: =+'Line & frequency'!C3 -> 44273
