Workbook

Sheet AF Compressor
B3: CHECKLIST ELECTRIQUE | G3: Date:
C4: AF Compressor | D4: New PET line | G4: MENSUELLE
E6: FAIT?
B7: N° | C7: DESCRIPTION DES TACHES | D7: Durée | E7: OUI | F7: NON | G7: REMARQUES (MATERIEL + PIECES)
B8: 1 | C8: Vérifier l'état d'encrassement des mats filtrants situés derrière les filtres de sortie et les ventilateurs et les remplacer si nécessaire | D8: 20min
B9: =B8+1 -> 2 | C9: Vérifier les raccords, les presse étoupes et des joints. Si besoin, resserrer les presse-étoupes. Si besoin, remettre les raccords et les joints en état. | D9: 20min
B10: =+B9+1 -> 3 | C10: controler l'etat des câbles | D10: 20min
B11: =+B10+1 -> 4 | C11: Vérifier l'étanchéité des raccords, des presse-étoupes et des joints | D11: 15min
B12: =+B11+1 -> 5 | C12: Controler le serrage de tous les contacts des armoires électriques (serrer si neccessaire) | D12: 20min
B13: =+B12+1 -> 6 | C13: mesurer les valeurs de l'intensité de courant des moteurs | D13: 10min
B14: =+B13+1 -> 7 | C14: mesurer la valeur ohmique des enroulements | D14: 20min
B15: =+B14+1 -> 8 | C15: controler le serrage des bornes des moteurs | D15: 20min
B16: =+B15+1 -> 9 | C16: controler le serrage des contacts des contacteurs, relais et disjoncteurs | D16: 20min
B17: =+B16+1 -> 10 | C17: Contrôle et/ou nettoyage du système de refroidissement du sécheur | D17: 20min
B18: =+B17+1 -> 11 | C18: Soufler les armoires électriques | D18: 20min
B19: =+B18+1 -> 12 | C19: Néttoyer les coffrets electriques et ranger l'intérieur | D19: 20min
B20: =+B19+1 -> 13 | C20: Controler la connection des cables réseau | D20: 10min
B21: =+B20+1 -> 14 | C21: Néttoyer le moteur principal (ouvrir le capot et nettoyer l'helice) | D21: 20min
... B25: =+B24+1 -> 18 | C25: Tester la fonctionnalité des arrets d'urgence | D25: 5min
B26: Commentaire | D26: Nom et Visa Intervenants | G26: Nom et Visa Responsables

Sheet Blomax
B3: CHECKLIST ELECTRIQUE | G3: Date:
C4: Blomax | D4: New PET line | G4: MENSUELLE
E6: FAIT?
B7: N° | C7: DESCRIPTION DES TACHES | D7: Durée | E7: OUI | F7: NON | G7: REMARQUES (MATERIEL + PIECES)
B8: 1 | C8: Vérifier l'état d'encrassement des mats filtrants situés derrière les filtres de sortie et les ventilateurs et les remplacer si nécessaire | D8: 20min
B9: 2 | C9: Vérifier les raccords, les presse étoupes et des joints. Si besoin, resserrer les presse-étoupes. Si besoin, remettre les raccords et les joints en état. | D9: 20min
B10: 4 | C10: Vérifier l'étanchéité des raccords, des presse-étoupes et des joints | D10: 20min
B11: 5 | C11: Controler le serrage de tous les contacts des armoires électriques (serrer si neccessaire) | D11: 25min
B12: 6 | C12: mesurer les valeurs de l'intensité de courant des moteurs | D12: 10min
B13: 7 | C13: mesurer la valeur ohmique des enroulements | D13: 20min
B14: 8 | C14: controler le serrage des bornes des moteurs | D14: 20min
B15: 9 | C15: controler le serrage des contacts des contacteurs, relais et disjoncteurs | D15: 20min
B16: 10 | C16: Néttoyer le moteur principal (ouvrir le capot et nettoyer l'helice) | D16: 20min
B17: 11 | C17: Néttoyer tous les moteurs du périphèrique (ouvrir les capot et nettoyer les helices) | D17: 20min
B18: 12 | C18: Néttoyer le moteur de la pompe d'eau de refroidissement du Chiller (ouvrir les capot et nettoyer les helices) | D18: 20min
B19: 13 | C19: Néttoyer le moteur d'entrainement des mandrins (ouvrir les capot et nettoyer les helices) | D19: 10min
... B21: 15 | C21: Tester la fonctionnalité des arrets d'urgence | D21: 5min
B22: Commentaire | D22: Nom et Visa Intervenants | G22: Nom et Visa Responsables

Sheet Filler
B3: CHECKLIST ELECTRIQUE | G3: Date:
C4: FILLER | D4: New PET line | G4: MENSUELLE
E6: FAIT?
B7: N° | C7: DESCRIPTION DES TACHES | D7: Durée | E7: OUI | F7: NON | G7: REMARQUES (MATERIEL + PIECES)
B8: 1 | C8: Vérifier l'absence d'endommagement sur les moteurs, | D8: 10min
B9: =B8+1 -> 2 | C9: Vérifier l'absence d'endommagement sur les raccords | D9: 10min
B10: =+B9+1 -> 3 | C10: Vérifier l'absence d'endommagement sur les distributeurs électriques. | D10: 10min
B11: =B10+1 -> 4 | C11: Contrôler les cartouches filtrantes de la ventilation et des appareils de refroidissement, et les nettoyer au besoin. | D11: 20min
B12: =+B11+1 -> 5 | C12: Néttoyer tous les moteurs du Gassner (ouvrir les capot et nettoyer les helices) | D12: 25min
B13: =B12+1 -> 6 | C13: Néttoyer le moteur de la pompe du Foam cleaning (ouvrir les capot et nettoyer les helices) | D13: 30min
B14: =+B13+1 -> 7 | C14: Néttoyer tous les hélice des ventillateurs de la salle | D14: 1h
B15: =B14+1 -> 8 | C15: Tester la fonctionnalité des arrets d'urgence | D15: 5min
B16: Commentaire | D16: Nom et Visa Intervenants | G16: Nom et Visa Responsables

Sheet Paramix
B1: CHECKLIST ELECTRIQUE | G1: Date:
C2: Paramix | D2: New PET line | G2: MENSUELLE
E3: FAIT?
B4: N° | C4: DESCRIPTION DES TACHES | D4: Durée | E4: OUI | F4: NON | G4: REMARQUES (MATERIEL + PIECES)
B5: 1 | C5: Vérifier le fonctionnement de l'interrupteur d'arrêt d'urgence. | D5: 5min
B6: =B5+1 -> 2 | C6: Vérifier l'absence d'endommagement sur les moteurs, | D6: 10min
B7: =+B6+1 -> 3 | C7: Vérifier l'absence d'endommagement sur les raccords | D7: 10min
B8: =B7+1 -> 4 | C8: Vérifier l'absence d'endommagement sur les distributeurs électriques. | D8: 10min
B9: =+B8+1 -> 5 | C9: Contrôler les cartouches filtrantes de la ventilation et des appareils de refroidissement, et les nettoyer au besoin. | D9: 20min
B10: =B9+1 -> 6 | C10: Néttoyer tous les moteurs des pompes (ouvrir les capots et nettoyer les hélices) | D10: 20min
B11: =+B10+1 -> 7 | C11: Néttoyer le moteur de la pompe de Madiba (ouvrir le capot et souffler) | D11: 20min
B12: =B11+1 -> 8 | C12: Néttoyer la pompe à vide (ouvrir le capot et souffler) | D12: 20min
B13: =+B12+1 -> 9
B14: Commentaire | D14: Nom et Visa Intervenants | G14: Nom et Visa Responsables

Sheet Labeller
B3: CHECKLIST ELECTRIQUE | G3: Date:
C4: LABELLER | D4: New PET line | G4: MENSUELLE
E6: FAIT?
B7: N° | C7: DESCRIPTION DES TACHES | D7: Durée | E7: OUI | F7: NON | G7: REMARQUES (MATERIEL + PIECES)
B8: 1 | C8: Vérifier les raccords, les presse étoupes et des joints. Si besoin, resserrer les presse-étoupes. Si besoin, remettre les raccords et les joints en état.
B9: 2 | C9: Vérifier l'absence d'endommagement sur les moteurs,
B10: 3 | C10: controler le serrage des contacts des contacteurs, relais et disjoncteurs
B11: 4 | C11: Vérifier l'étanchéité des raccords, des presse-étoupes et des joints
B12: 5 | C12: controler l'etat des câbles
B13: 6 | C13: Controler le serrage des connecteurs de cable reseau
B14: 7 | C14: Néttoyer les moteurs de translation (ouvrir le capot et nettoyer l'helice)
B15: 8 | C15: Néttoyer le moteur la pompe à vide (ouvrir le capot et nettoyer l'helice)
B16: 9 | C16: Tester la fonctionnalité des arrets d'urgence
B17: Commentaire | D17: Nom et Visa Intervenants | G17: Nom et Visa Responsables

Sheet Kisters
B3: CHECKLIST ELECTRIQUE | G3: Date:
C4: KISTERS | D4: New PET line | G4: MENSUELLE
E6: FAIT?
B7: N° | C7: DESCRIPTION DES TACHES | D7: Durée | E7: OUI | F7: NON | G7: REMARQUES (MATERIEL + PIECES)
B8: 1 | C8: Vérifier l'état d'encrassement sur les grilles de protection de tous les ventilateurs | G8: Présence de la rouille à l'intérieur
B9: =+B8+1 -> 2 | C9: Vérifier les raccords, les presse étoupes et des joints. Si besoin, resserrer les presse-étoupes. Si besoin, remettre les raccords et les joints en état.
B10: 3 | C10: controler l'etat des câbles
B11: 4 | C11: Vérifier l'étanchéité des raccords, des presse-étoupes et des joints
B12: 5 | C12: Controler le serrage de tous les contacts des armoires électriques (serrer si neccessaire)
B13: 6 | C13: Soufler l'armoire électrique
B14: 7 | C14: Nettoyer les éléments filtrants dans la ventilation de l'armoire électrique
B15: 8 | C15: Néttoyer tous les hélices des ventillateurs de refroidissement
B16: 9 | C16: Néttoyer le moteur du tapis du four (ouvrir le capot et nettoyer l'helice)
B17: 10 | C17: Néttoyer les rideaux à l'entrée et sortie du four
B18: 11 | C18: Néttoyer les moteurs de pompes (ouvrir le capot et nettoyer l'helice)
B19: 12 | C19: Tester la fonctionnalité des arrets d'urgence
B20: Commentaire | D20: Nom et Visa Intervenants | G20: Nom et Visa Responsables

Sheet Handle applicator
B3: CHECKLIST ELECTRIQUE | G3: Date:
C4: HANDLE APPLICATOR | D4: New PET line | G4: MENSUELLE
E6: FAIT?
B7: N° | C7: DESCRIPTION DES TACHES | D7: Durée | E7: OUI | F7: NON | G7: REMARQUES (MATERIEL + PIECES)
B8: 1 | C8: Vérifier l'état d'encrassement sur le ventilateur des climatiseurs
B9: =B8+1 -> 2 | C9: Vérifier les raccords, les presse étoupes et des joints. Si besoin, resserrer les presse-étoupes. Si besoin, remettre les raccords et les joints en état.
B10: 2 | C10: controler l'etat des câbles
B11: =B10+1 -> 3 | C11: Controler le serrage de tous les contacts des armoires électriques
B12: 3 | C12: Soufler l'armoire électrique
B13: =B12+1 -> 4 | C13: Néttoyer les coffrets electriques et ranger l'intérieur
B14: 4 | C14: Néttoyer le moteur du tapis interieur (ouvrir le capot et nettoyer l'helice)
B15: =B14+1 -> 5 | C15: Tester la fonctionnalité des arrets d'urgence
B16: 5
B17: =B16+1 -> 6
B18: Commentaire | D18: Nom et Visa Intervenants | G18: Nom et Visa Responsables

Sheet Conveyors
B3: CHECKLIST ELECTRIQUE | G3: Date:
C4: CONVEYORS | D4: New PET line | G4: MENSUELLE
E6: FAIT?
B7: N° | C7: DESCRIPTION DES TACHES | D7: Durée | E7: OUI | F7: NON | G7: REMARQUES (MATERIEL + PIECES)
B8: 1 | C8: Vérifier l'état d'encrassement des mats filtrants situés derrière les filtres de sortie et les ventilateurs et les remplacer si nécessaire
B9: =B8+1 -> 2 | C9: Vérifier les raccords, les presse étoupes et des joints. Si besoin, resserrer les presse-étoupes. Si besoin, remettre les raccords et les joints en état.
B10: =+B9+1 -> 3 | C10: controler l'etat des câbles
B11: =B10+1 -> 4 | C11: Vérifier l'étanchéité des raccords, des presse-étoupes et des joints
B12: =+B11+1 -> 5 | C12: Néttoyer les coffrets electriques et ranger l'intérieur
B13: =B12+1 -> 6 | C13: Souffler les ventilateurs des variateurs
B14: =+B13+1 -> 7 | C14: Tester la fonctionnalité des arrets d'urgence
B15: Commentaire | D15: Nom et Visa Intervenants | G15: Nom et Visa Responsables

Sheet Blower
B3: CHECKLIST ELECTRIQUE | G3: Date:
C4: Blower | D4: New PET line | G4: MENSUELLE
E6: FAIT?
B7: N° | C7: DESCRIPTION DES TACHES | D7: Durée | E7: OUI | F7: NON | G7: REMARQUES (MATERIEL + PIECES)
B8: 1 | C8: Controler le fonctionnement de toutes les portes de sécurité
B9: =B8+1 -> 2 | C9: Mesurer la valeur ohmique des enroulements des moteurs des pompes
B10: =+B9+1 -> 3 | C10: Controler le serrage des bornes des moteurs des pompes
B11: =B10+1 -> 4 | C11: Tester la fonctionnalité des arrets d'urgence
B12: =+B11+1 -> 5
B13: =B12+1 -> 6
B14: =+B13+1 -> 7
B15: Commentaire | D15: Nom et Visa Intervenants | G15: Nom et Visa Responsables

Sheet CIP
B1: CHECKLIST ELECTRIQUE | G1: Date:
C2: CIP | D2: New PET line | G2: MENSUELLE
E3: FAIT?
B4: N° | C4: DESCRIPTION DES TACHES | D4: Durée | E4: OUI | F4: NON | G4: REMARQUES (MATERIEL + PIECES)
B5: 1 | C5: Néttoyer le moteur de la pompes de circulation (ouvrir les capots et nettoyer l'hélices)
B6: =B5+1 -> 2 | C6: Néttoyer tous les moteurs des pompes de dosage (ouvrir les capots et nettoyer les hélices)
B7: =+B6+1 -> 3 | C7: Tester la fonctionnalité des arrets d'urgence
B8: =B7+1 -> 4
B9: =+B8+1 -> 5
B10: =B9+1 -> 6
B11: =B10+1 -> 7
B12: Commentaire | D12: Nom et Visa Intervenants | G12: Nom et Visa Responsables

Sheet Robopac
B1: CHECKLIST ELECTRIQUE | G1: Date:
C2: Robopac | D2: New PET line | G2: MENSUELLE
E3: FAIT?
B4: N° | C4: DESCRIPTION DES TACHES | D4: Durée | E4: OUI | F4: NON | G4: REMARQUES (MATERIEL + PIECES)
B5: 1 | C5: Néttoyer le moteur du chariot (ouvrir les capots et nettoyer l'hélices) | D5: 20min
B6: =B5+1 -> 2 | C6: Néttoyer le moteur du plateau (ouvrir les capots et nettoyer l'hélices) | D6: 20min
B7: =+B6+1 -> 3 | C7: Tester la fonctionnalité des arrets d'urgence | D7: 5min
B8: =B7+1 -> 4
B9: =+B8+1 -> 5
B10: =B9+1 -> 6
B11: =B10+1 -> 7
B12: Commentaire | D12: Nom et Visa Intervenants | G12: Nom et Visa Responsables

Sheet Cvyr Btles
B3: CHECKLIST MECANIQUE | G3: Date
C4: PALETTISEUR | D4: =+'Line & frequency'!C1 -> CHAINE 4 | G4: =+'Line & frequency'!C2 -> HEBDOMADAIRE
E6: FAIT?
B7: N° | C7: DESCRIPTION DES TACHES | D7: Durée | E7: OUI | F7: NON | G7: REMARQUES (MATERIEL + PIECES)
B8: 1
B9: =B8+1 -> 2
B10: =+B9+1 -> 3
B11: =B10+1 -> 4
B12: =+B11+1 -> 5
B13: =B12+1 -> 6
B14: =+B13+1 -> 7
B15: =B14+1 -> 8
B16: =+B15+1 -> 9
B17: =B16+1 -> 10
B18: =+B17+1 -> 11
B19: =B18+1 -> 12
B20: =+B19+1 -> 13
B21: =B20+1 -> 14
B22: =+B21+1 -> 15
B23: =B22+1 -> 16
B24: =+B23+1 -> 17
B25: =B24+1 -> 18
B26: =+B25+1 -> 19
B27: =B26+1 -> 20
B28: =+B27+1 -> 21
B29: =B28+1 -> 22
B30: =+B29+1 -> 23
B31: =B30+1 -> 24
B32: =+B31+1 -> 25
B33: =B32+1 -> 26
B34: =+B33+1 -> 27
B35: =B34+1 -> 28
B36: =+B35+1 -> 29
B37: =B36+1 -> 30
B38: =+B37+1 -> 31
B39: =B38+1 -> 32
B40: =+B39+1 -> 33
B41: =B40+1 -> 34
B42: =+B41+1 -> 35
B43: =B42+1 -> 36
...

Sheet CC C1
B3: CHECKLIST MECANIQUE | G3: Date
C4: CONVOYEURS CASIERS C1 | D4: =+'Line & frequency'!C1 -> CHAINE 4 | G4: =+'Line & frequency'!C2 -> HEBDOMADAIRE
E6: FAIT?
B7: N° | C7: DESCRIPTION DES TACHES | D7: Durée | E7: OUI | F7: NON | G7: REMARQUES (MATERIEL + PIECES)
B8: 1 | C8: controler l'arret d'huile et le remplacé au besoin. Aucune fuite d'huile n'est acceptable. | D8: 10
B9: =B8+1 -> 2 | C9: controler la fixation du réducteur sur le convoyeur et corriger si necessaire. | D9: 30
B10: =+B9+1 -> 3 | C10: controler l'usure du pignon et le remplacé au besoin. Aucun glissement n'est acceptable. | D10: 30
B11: =B10+1 -> 4 | C11: controler l'alignement et la fixation du pignon de l'axe moteur et remedier au besoin. | D11: 30
B12: =+B11+1 -> 5 | C12: controler l'usure de la roue libre et la remplacée au besoin. Aucun glissement n'est acceptable. | D12: 30
B13: =B12+1 -> 6 | C13: controler l'alignement et la fixation de la roue libre et remedier au problème. | D13: 30
B14: =+B13+1 -> 7 | C14: controler l'usure de la clavette et la rainure et reparer au besoin | D14: 30
B15: =B14+1 -> 8 | C15: controler l'état des glissières et remplacer les au besoin | D15: 25
B16: =+B15+1 -> 9 | C16: controler l'arret d'huile et le remplacé au besoin. Aucune fuite d'huile n'est acceptable. | D16: 10
B17: =B16+1 -> 10 | C17: controler l'usure des roulements et paliers de l'axe moteur et remplacer si necessaire. | D17: 30
B18: =+B17+1 -> 11 | C18: controler l'usure du pignon et le remplacé au besoin. Aucun glissement n'est acceptable. | D18: 30
B19: =B18+1 -> 12 | C19: controler l'alignement et la fixation du pignon de l'axe moteur et remedier au besoin. | D19: 30
B20: =+B19+1 -> 13 | C20: controler l'usure de la clavette et la rainure et reparer au besoin | D20: 30
B21: =B20+1 -> 14 | C21: controler l'usure des roulements et paliers de l'axe moteur et remplacer si necessaire. | D21: 30
B22: =+B21+1 -> 15 | C22: controler l'usure de la roue libre et la remplacée au besoin. Aucun glissement n'est acceptable. | D22: 30
B23: =B22+1 -> 16 | C23: controler l'alignement et la fixation de la roue libre et remedier au problème. | D23: 30
B24: =+B23+1 -> 17 | C24: controler l'usure de la clavette et la rainure et reparer au besoin | D24: 30
B25: =B24+1 -> 18 | C25: controler l'arret d'huile et le remplacé au besoin. Aucune fuite d'huile n'est acceptable. | D25: 10
B26: =+B25+1 -> 19 | C26: controler la fixation du réducteur sur le convoyeur et corriger si necessaire. | D26: 30
B27: =B26+1 -> 20 | C27: controler l'usure des roulements et paliers de l'axe moteur et remplacer si necessaire. | D27: 30
B28: =+B27+1 -> 21 | C28: controler l'usure du pignon et le remplacé au besoin. Aucun glissement n'est acceptable. | D28: 30
B29: =B28+1 -> 22 | C29: controler l'alignement et la fixation du pignon de l'axe moteur et remedier au besoin. | D29: 30
B30: =+B29+1 -> 23 | C30: controler l'usure de la clavette et la rainure et reparer au besoin | D30: 30
B31: =B30+1 -> 24 | C31: controler l'usure des roulements et paliers de l'axe moteur et remplacer si necessaire. | D31: 30
B32: =+B31+1 -> 25 | C32: controler l'usure de la clavette et la rainure et reparer au besoin | D32: 30
B33: =B32+1 -> 26 | C33: controler l'état des glissières et remplacer les au besoin | D33: 25
B34: =+B33+1 -> 27 | C34: controler l'arret d'huile et le remplacé au besoin. Aucune fuite d'huile n'est acceptable. | D34: 10
B35: =B34+1 -> 28 | C35: controler la fixation du réducteur sur le convoyeur et corriger si necessaire. | D35: 30
B36: =+B35+1 -> 29 | C36: controler l'usure des roulements et paliers de l'axe moteur et remplacer si necessaire. | D36: 30
B37: =B36+1 -> 30 | C37: controler l'usure des pignons et les remplacés au besoin. Aucun glissement n'est acceptable. | D37: 30
B38: =+B37+1 -> 31 | C38: controler l'alignement et la fixation du pignon de l'axe moteur et remedier au besoin. | D38: 30
B39: =B38+1 -> 32 | C39: controler l'usure de la clavette et la rainure et reparer au besoin | D39: 30
B40: =+B39+1 -> 33 | C40: controler l'état des glissières et remplacer les au besoin | D40: 25
B41: =B40+1 -> 34 | C41: controler l'usure du tapis et remplacer les portions usées ou maillons cassés | D41: 120
B42: =+B41+1 -> 35 | C42: controler la tenson des tapis et ajuster au besoin | D42: 60
B43: =B42+1 -> 36 | C43: controler l'arret d'huile et le remplacé au besoin. Aucune fuite d'huile n'est acceptable. | D43: 10
...

Sheet CC C2
B3: CHECKLIST MECANIQUE | G3: Date
C4: CONVOYEURS CASIERS C2 | D4: =+'Line & frequency'!C1 -> CHAINE 4 | G4: =+'Line & frequency'!C2 -> HEBDOMADAIRE
E6: FAIT?
B7: N° | C7: DESCRIPTION DES TACHES | D7: Durée | E7: OUI | F7: NON | G7: REMARQUES (MATERIEL + PIECES)
B8: 1 | C8: controler l'arret d'huile et le remplacé au besoin. Aucune fuite d'huile n'est acceptable. | D8: 10
B9: =B8+1 -> 2 | C9: controler la fixation du réducteur sur le convoyeur et corriger si necessaire. | D9: 30
B10: =+B9+1 -> 3 | C10: controler l'usure du pignon et le remplacé au besoin. Aucun glissement n'est acceptable. | D10: 30
B11: =B10+1 -> 4 | C11: controler l'alignement et la fixation du pignon de l'axe moteur et remedier au besoin. | D11: 30
B12: =+B11+1 -> 5 | C12: controler l'usure de la roue libre et la remplacée au besoin. Aucun glissement n'est acceptable. | D12: 30
B13: =B12+1 -> 6 | C13: controler l'alignement et la fixation de la roue libre et remedier au problème. | D13: 30
B14: =+B13+1 -> 7 | C14: controler l'usure de la clavette et la rainure et reparer au besoin | D14: 30
B15: =B14+1 -> 8 | C15: controler l'état des glissières et remplacer les au besoin | D15: 25
B16: =+B15+1 -> 9 | C16: controler l'arret d'huile et le remplacé au besoin. Aucune fuite d'huile n'est acceptable. | D16: 10
B17: =B16+1 -> 10 | C17: controler l'usure des roulements et paliers de l'axe moteur et remplacer si necessaire. | D17: 30
B18: =+B17+1 -> 11 | C18: controler l'usure du pignon et le remplacé au besoin. Aucun glissement n'est acceptable. | D18: 30
B19: =B18+1 -> 12 | C19: controler l'alignement et la fixation du pignon de l'axe moteur et remedier au besoin. | D19: 30
B20: =+B19+1 -> 13 | C20: controler l'usure de la clavette et la rainure et reparer au besoin | D20: 30
B21: =B20+1 -> 14 | C21: controler l'usure des roulements et paliers de l'axe moteur et remplacer si necessaire. | D21: 30
B22: =+B21+1 -> 15 | C22: controler l'usure de la roue libre et la remplacée au besoin. Aucun glissement n'est acceptable. | D22: 30
B23: =B22+1 -> 16 | C23: controler l'alignement et la fixation de la roue libre et remedier au problème. | D23: 30
B24: =+B23+1 -> 17 | C24: controler l'usure de la clavette et la rainure et reparer au besoin | D24: 30
B25: =B24+1 -> 18 | C25: controler l'arret d'huile et le remplacé au besoin. Aucune fuite d'huile n'est acceptable. | D25: 10
B26: =+B25+1 -> 19 | C26: controler la fixation du réducteur sur le convoyeur et corriger si necessaire. | D26: 30
B27: =B26+1 -> 20 | C27: controler l'usure des roulements et paliers de l'axe moteur et remplacer si necessaire. | D27: 30
B28: =+B27+1 -> 21 | C28: controler l'usure des pignons et les remplacés au besoin. Aucun glissement n'est acceptable. | D28: 30
B29: =B28+1 -> 22 | C29: controler l'alignement et la fixation du pignon de l'axe moteur et remedier au besoin. | D29: 30
B30: =+B29+1 -> 23 | C30: controler l'usure de la clavette et la rainure et reparer au besoin | D30: 30
B31: =B30+1 -> 24 | C31: controler l'état des glissières et remplacer les au besoin | D31: 25
B32: =+B31+1 -> 25 | C32: controler l'usure du tapis et remplacer les portions usées ou maillons cassés | D32: 120
B33: =B32+1 -> 26 | C33: controler la tenson des tapis et ajuster au besoin | D33: 60
B34: =+B33+1 -> 27
B35: =B34+1 -> 28
B36: =+B35+1 -> 29
B37: =B36+1 -> 30
B38: =+B37+1 -> 31
B39: =B38+1 -> 32
B40: =+B39+1 -> 33
B41: =B40+1 -> 34
B42: =+B41+1 -> 35
B43: =B42+1 -> 36
...

Sheet CC C3
B3: CHECKLIST MECANIQUE | G3: Date
C4: CONVOYEURS CASIERS C3 | D4: =+'Line & frequency'!C1 -> CHAINE 4 | G4: =+'Line & frequency'!C2 -> HEBDOMADAIRE
E6: FAIT?
B7: N° | C7: DESCRIPTION DES TACHES | D7: Durée | E7: OUI | F7: NON | G7: REMARQUES (MATERIEL + PIECES)
B8: 1 | C8: controler l'arret d'huile et le remplacé au besoin. Aucune fuite d'huile n'est acceptable. | D8: 10
B9: =B8+1 -> 2 | C9: controler la fixation du réducteur sur le convoyeur et corriger si necessaire. | D9: 30
B10: =+B9+1 -> 3 | C10: controler l'usure du pignon et le remplacé au besoin. Aucun glissement n'est acceptable. | D10: 30
B11: =B10+1 -> 4 | C11: controler l'alignement et la fixation du pignon de l'axe moteur et remedier au besoin. | D11: 30
B12: =+B11+1 -> 5 | C12: controler l'usure de la roue libre et la remplacée au besoin. Aucun glissement n'est acceptable. | D12: 30
B13: =B12+1 -> 6 | C13: controler l'alignement et la fixation de la roue libre et remedier au problème. | D13: 30
B14: =+B13+1 -> 7 | C14: controler l'usure de la clavette et la rainure et reparer au besoin | D14: 30
B15: =B14+1 -> 8 | C15: controler l'état des glissières et remplacer les au besoin | D15: 25
B16: =+B15+1 -> 9 | C16: controler l'arret d'huile et le remplacé au besoin. Aucune fuite d'huile n'est acceptable. | D16: 10
B17: =B16+1 -> 10 | C17: controler l'usure des roulements et paliers de l'axe moteur et remplacer si necessaire. | D17: 30
B18: =+B17+1 -> 11 | C18: controler l'usure du pignon et le remplacé au besoin. Aucun glissement n'est acceptable. | D18: 30
B19: =B18+1 -> 12 | C19: controler l'alignement et la fixation du pignon de l'axe moteur et remedier au besoin. | D19: 30
B20: =+B19+1 -> 13 | C20: controler l'usure de la clavette et la rainure et reparer au besoin | D20: 30
B21: =B20+1 -> 14 | C21: controler l'usure des roulements et paliers de l'axe moteur et remplacer si necessaire. | D21: 30
B22: =+B21+1 -> 15 | C22: controler l'usure de la roue libre et la remplacée au besoin. Aucun glissement n'est acceptable. | D22: 30
B23: =B22+1 -> 16 | C23: controler l'alignement et la fixation de la roue libre et remedier au problème. | D23: 30
B24: =+B23+1 -> 17 | C24: controler l'usure de la clavette et la rainure et reparer au besoin | D24: 30
B25: =B24+1 -> 18
B26: =+B25+1 -> 19
B27: =B26+1 -> 20
B28: =+B27+1 -> 21
B29: =B28+1 -> 22
B30: =+B29+1 -> 23
B31: =B30+1 -> 24
B32: =+B31+1 -> 25
B33: Commentaire | D33: Nom et Visa Intervenants | G33: Nom et Visa Responsables

Sheet CC C4
B3: CHECKLIST MECANIQUE | G3: Date
C4: CONVOYEURS CASIERS C4 | D4: =+'Line & frequency'!C1 -> CHAINE 4 | G4: =+'Line & frequency'!C2 -> HEBDOMADAIRE
E6: FAIT?
B7: N° | C7: DESCRIPTION DES TACHES | D7: Durée | E7: OUI | F7: NON | G7: REMARQUES (MATERIEL + PIECES)
B8: 1 | C8: controler l'arret d'huile et le remplacé au besoin. Aucune fuite d'huile n'est acceptable. | D8: 10
B9: =B8+1 -> 2 | C9: controler la fixation du réducteur sur le convoyeur et corriger si necessaire. | D9: 30
B10: =+B9+1 -> 3 | C10: controler l'usure du pignon et le remplacé au besoin. Aucun glissement n'est acceptable. | D10: 30
B11: =B10+1 -> 4 | C11: controler l'alignement et la fixation du pignon de l'axe moteur et remedier au besoin. | D11: 30
B12: =+B11+1 -> 5 | C12: controler l'usure de la roue libre et la remplacée au besoin. Aucun glissement n'est acceptable. | D12: 30
B13: =B12+1 -> 6 | C13: controler l'alignement et la fixation de la roue libre et remedier au problème. | D13: 30
B14: =+B13+1 -> 7 | C14: controler l'usure de la clavette et la rainure et reparer au besoin | D14: 30
B15: =B14+1 -> 8 | C15: controler l'état des glissières et remplacer les au besoin | D15: 25
B16: =+B15+1 -> 9 | C16: controler l'arret d'huile et le remplacé au besoin. Aucune fuite d'huile n'est acceptable. | D16: 10
B17: =B16+1 -> 10 | C17: controler l'usure des roulements et paliers de l'axe moteur et remplacer si necessaire. | D17: 30
B18: =+B17+1 -> 11 | C18: controler l'usure du pignon et le remplacé au besoin. Aucun glissement n'est acceptable. | D18: 30
B19: =B18+1 -> 12 | C19: controler l'alignement et la fixation du pignon de l'axe moteur et remedier au besoin. | D19: 30
B20: =+B19+1 -> 13 | C20: controler l'usure de la clavette et la rainure et reparer au besoin | D20: 30
B21: =B20+1 -> 14 | C21: controler l'usure des roulements et paliers de l'axe moteur et remplacer si necessaire. | D21: 30
B22: =+B21+1 -> 15 | C22: controler l'usure de la roue libre et la remplacée au besoin. Aucun glissement n'est acceptable. | D22: 30
B23: =B22+1 -> 16 | C23: controler l'alignement et la fixation de la roue libre et remedier au problème. | D23: 30
B24: =+B23+1 -> 17 | C24: controler l'usure de la clavette et la rainure et reparer au besoin | D24: 30
B25: =B24+1 -> 18 | C25: controler l'arret d'huile et le remplacé au besoin. Aucune fuite d'huile n'est acceptable. | D25: 10
B26: =B25+1 -> 19 | C26: controler la fixation du réducteur sur le convoyeur et corriger si necessaire. | D26: 30
B27: =+B26+1 -> 20 | C27: controler l'usure des roulements et paliers de l'axe moteur et remplacer si necessaire. | D27: 30
B28: =B27+1 -> 21 | C28: controler l'usure du pignon et le remplacé au besoin. Aucun glissement n'est acceptable. | D28: 30
B29: =B28+1 -> 22 | C29: controler l'alignement et la fixation du pignon de l'axe moteur et remedier au besoin. | D29: 30
B30: =+B29+1 -> 23 | C30: controler l'usure de la clavette et la rainure et reparer au besoin | D30: 30
B31: =B30+1 -> 24 | C31: controler l'usure des roulements et paliers de l'axe moteur et remplacer si necessaire. | D31: 30
B32: =B31+1 -> 25 | C32: controler l'usure de la clavette et la rainure et reparer au besoin | D32: 30
B33: =+B32+1 -> 26 | C33: controler l'état des glissières et remplacer les au besoin | D33: 25
B34: =B33+1 -> 27
B35: =B34+1 -> 28
B36: =+B35+1 -> 29
B37: =B36+1 -> 30
B38: Commentaire | D38: Nom et Visa Intervenants | G38: Nom et Visa Responsables

Sheet CC C5
B3: CHECKLIST MECANIQUE | G3: Date
C4: CONVOYEURS CASIERS C5 | D4: =+'Line & frequency'!C1 -> CHAINE 4 | G4: =+'Line & frequency'!C2 -> HEBDOMADAIRE
E6: FAIT?
B7: N° | C7: DESCRIPTION DES TACHES | D7: Durée | E7: OUI | F7: NON | G7: REMARQUES (MATERIEL + PIECES)
B8: 1 | C8: controler l'arret d'huile et le remplacé au besoin. Aucune fuite d'huile n'est acceptable. | D8: 10
B9: =B8+1 -> 2 | C9: controler la fixation du réducteur sur le convoyeur et corriger si necessaire. | D9: 30
B10: =+B9+1 -> 3 | C10: controler l'usure du pignon et le remplacé au besoin. Aucun glissement n'est acceptable. | D10: 30
B11: =B10+1 -> 4 | C11: controler l'alignement et la fixation du pignon de l'axe moteur et remedier au besoin. | D11: 30
B12: =+B11+1 -> 5 | C12: controler l'usure de la roue libre et la remplacée au besoin. Aucun glissement n'est acceptable. | D12: 30
B13: =B12+1 -> 6 | C13: controler l'alignement et la fixation de la roue libre et remedier au problème. | D13: 30
B14: =+B13+1 -> 7 | C14: controler l'usure de la clavette et la rainure et reparer au besoin | D14: 30
B15: =B14+1 -> 8 | C15: controler l'état des glissières et remplacer les au besoin | D15: 25
B16: =+B15+1 -> 9 | C16: controler l'arret d'huile et le remplacé au besoin. Aucune fuite d'huile n'est acceptable. | D16: 10
B17: =B16+1 -> 10 | C17: controler l'usure des roulements et paliers de l'axe moteur et remplacer si necessaire. | D17: 30
B18: =+B17+1 -> 11 | C18: controler l'usure du pignon et le remplacé au besoin. Aucun glissement n'est acceptable. | D18: 30
B19: =B18+1 -> 12 | C19: controler l'alignement et la fixation du pignon de l'axe moteur et remedier au besoin. | D19: 30
B20: =+B19+1 -> 13 | C20: controler l'usure de la clavette et la rainure et reparer au besoin | D20: 30
B21: =B20+1 -> 14 | C21: controler l'usure des roulements et paliers de l'axe moteur et remplacer si necessaire. | D21: 30
B22: =+B21+1 -> 15 | C22: controler l'usure de la roue libre et la remplacée au besoin. Aucun glissement n'est acceptable. | D22: 30
B23: =B22+1 -> 16 | C23: controler l'alignement et la fixation de la roue libre et remedier au problème. | D23: 30
B24: =+B23+1 -> 17 | C24: controler l'usure de la clavette et la rainure et reparer au besoin | D24: 30
B25: =B24+1 -> 18
B26: =B25+1 -> 19
B27: =+B26+1 -> 20
B28: =B27+1 -> 21
B29: =B28+1 -> 22
B30: =+B29+1 -> 23
B31: =B30+1 -> 24
B32: =B31+1 -> 25
B33: =+B32+1 -> 26
B34: =B33+1 -> 27
B35: =B34+1 -> 28
B36: =+B35+1 -> 29
B37: =B36+1 -> 30
B38: Commentaire | D38: Nom et Visa Intervenants | G38: Nom et Visa Responsables

Sheet CC C6
B3: CHECKLIST MECANIQUE | G3: Date
C4: CONVOYEURS CASIERS C6 | D4: =+'Line & frequency'!C1 -> CHAINE 4 | G4: =+'Line & frequency'!C2 -> HEBDOMADAIRE
E6: FAIT?
B7: N° | C7: DESCRIPTION DES TACHES | D7: Durée | E7: OUI | F7: NON | G7: REMARQUES (MATERIEL + PIECES)
B8: 1 | C8: controler l'arret d'huile et le remplacé au besoin. Aucune fuite d'huile n'est acceptable. | D8: 10
B9: =B8+1 -> 2 | C9: controler la fixation du réducteur sur le convoyeur et corriger si necessaire. | D9: 30
B10: =+B9+1 -> 3 | C10: controler l'usure du pignon et le remplacé au besoin. Aucun glissement n'est acceptable. | D10: 30
B11: =B10+1 -> 4 | C11: controler l'alignement et la fixation du pignon de l'axe moteur et remedier au besoin. | D11: 30
B12: =+B11+1 -> 5 | C12: controler l'usure de la roue libre et la remplacée au besoin. Aucun glissement n'est acceptable. | D12: 30
B13: =B12+1 -> 6 | C13: controler l'alignement et la fixation de la roue libre et remedier au problème. | D13: 30
B14: =+B13+1 -> 7 | C14: controler l'usure de la clavette et la rainure et reparer au besoin | D14: 30
B15: =B14+1 -> 8 | C15: controler l'état des glissières et remplacer les au besoin | D15: 25
B16: =+B15+1 -> 9 | C16: controler l'arret d'huile et le remplacé au besoin. Aucune fuite d'huile n'est acceptable. | D16: 10
B17: =B16+1 -> 10 | C17: controler l'usure des roulements et paliers de l'axe moteur et remplacer si necessaire. | D17: 30
B18: =+B17+1 -> 11 | C18: controler l'usure du pignon et le remplacé au besoin. Aucun glissement n'est acceptable. | D18: 30
B19: =B18+1 -> 12 | C19: controler l'alignement et la fixation du pignon de l'axe moteur et remedier au besoin. | D19: 30
B20: =+B19+1 -> 13 | C20: controler l'usure de la clavette et la rainure et reparer au besoin | D20: 30
B21: =B20+1 -> 14 | C21: controler l'usure des roulements et paliers de l'axe moteur et remplacer si necessaire. | D21: 30
B22: =+B21+1 -> 15 | C22: controler l'usure de la roue libre et la remplacée au besoin. Aucun glissement n'est acceptable. | D22: 30
B23: =B22+1 -> 16 | C23: controler l'alignement et la fixation de la roue libre et remedier au problème. | D23: 30
B24: =+B23+1 -> 17 | C24: controler l'usure de la clavette et la rainure et reparer au besoin | D24: 30
B25: =B24+1 -> 18 | C25: controler l'arret d'huile et le remplacé au besoin. Aucune fuite d'huile n'est acceptable. | D25: 10
B26: =B25+1 -> 19 | C26: controler la fixation du réducteur sur le convoyeur et corriger si necessaire. | D26: 30
B27: =+B26+1 -> 20 | C27: controler l'usure des roulements et paliers de l'axe moteur et remplacer si necessaire. | D27: 30
B28: =B27+1 -> 21 | C28: controler l'usure des pignons et les remplacés au besoin. Aucun glissement n'est acceptable. | D28: 30
B29: =B28+1 -> 22 | C29: controler l'alignement et la fixation du pignon de l'axe moteur et remedier au besoin. | D29: 30
B30: =+B29+1 -> 23 | C30: controler l'usure de la clavette et la rainure et reparer au besoin | D30: 30
B31: =B30+1 -> 24 | C31: controler l'état des glissières et remplacer les au besoin | D31: 25
B32: =B31+1 -> 25 | C32: controler l'usure du tapis et remplacer les portions usées ou maillons cassés | D32: 120
B33: =+B32+1 -> 26 | C33: controler la tenson des tapis et ajuster au besoin | D33: 60
B34: =B33+1 -> 27
B35: =B34+1 -> 28
B36: =+B35+1 -> 29
B37: =B36+1 -> 30
B38: Commentaire | D38: Nom et Visa Intervenants | G38: Nom et Visa Responsables

Sheet CC C7
B3: CHECKLIST MECANIQUE | G3: Date
C4: CONVOYEURS CASIERS C7 | D4: =+'Line & frequency'!C1 -> CHAINE 4 | G4: =+'Line & frequency'!C2 -> HEBDOMADAIRE
E6: FAIT?
B7: N° | C7: DESCRIPTION DES TACHES | D7: Durée | E7: OUI | F7: NON | G7: REMARQUES (MATERIEL + PIECES)
B8: 1 | C8: controler l'arret d'huile et le remplacé au besoin. Aucune fuite d'huile n'est acceptable. | D8: 10
B9: =B8+1 -> 2 | C9: controler la fixation du réducteur sur le convoyeur et corriger si necessaire. | D9: 30
B10: =+B9+1 -> 3 | C10: controler l'usure du pignon et le remplacé au besoin. Aucun glissement n'est acceptable. | D10: 30
B11: =B10+1 -> 4 | C11: controler l'alignement et la fixation du pignon de l'axe moteur et remedier au besoin. | D11: 30
B12: =+B11+1 -> 5 | C12: controler l'usure de la roue libre et la remplacée au besoin. Aucun glissement n'est acceptable. | D12: 30
B13: =B12+1 -> 6 | C13: controler l'alignement et la fixation de la roue libre et remedier au problème. | D13: 30
B14: =+B13+1 -> 7 | C14: controler l'usure de la clavette et la rainure et reparer au besoin | D14: 30
B15: =B14+1 -> 8 | C15: controler l'état des glissières et remplacer les au besoin | D15: 25
B16: =+B15+1 -> 9 | C16: controler l'arret d'huile et le remplacé au besoin. Aucune fuite d'huile n'est acceptable. | D16: 10
B17: =B16+1 -> 10 | C17: controler l'usure des roulements et paliers de l'axe moteur et remplacer si necessaire. | D17: 30
B18: =+B17+1 -> 11 | C18: controler l'usure du pignon et le remplacé au besoin. Aucun glissement n'est acceptable. | D18: 30
B19: =B18+1 -> 12 | C19: controler l'alignement et la fixation du pignon de l'axe moteur et remedier au besoin. | D19: 30
B20: =+B19+1 -> 13 | C20: controler l'usure de la clavette et la rainure et reparer au besoin | D20: 30
B21: =B20+1 -> 14 | C21: controler l'usure des roulements et paliers de l'axe moteur et remplacer si necessaire. | D21: 30
B22: =+B21+1 -> 15 | C22: controler l'usure de la roue libre et la remplacée au besoin. Aucun glissement n'est acceptable. | D22: 30
B23: =B22+1 -> 16 | C23: controler l'alignement et la fixation de la roue libre et remedier au problème. | D23: 30
B24: =+B23+1 -> 17 | C24: controler l'usure de la clavette et la rainure et reparer au besoin | D24: 30
B25: =B24+1 -> 18 | C25: controler l'arret d'huile et le remplacé au besoin. Aucune fuite d'huile n'est acceptable. | D25: 10
B26: =B25+1 -> 19 | C26: controler la fixation du réducteur sur le convoyeur et corriger si necessaire. | D26: 30
B27: =+B26+1 -> 20 | C27: controler l'usure des roulements et paliers de l'axe moteur et remplacer si necessaire. | D27: 30
B28: =B27+1 -> 21 | C28: controler l'usure des pignons et les remplacés au besoin. Aucun glissement n'est acceptable. | D28: 30
B29: =B28+1 -> 22 | C29: controler l'alignement et la fixation du pignon de l'axe moteur et remedier au besoin. | D29: 30
B30: =+B29+1 -> 23 | C30: controler l'usure de la clavette et la rainure et reparer au besoin | D30: 30
B31: =B30+1 -> 24 | C31: controler l'état des glissières et remplacer les au besoin | D31: 25
B32: =B31+1 -> 25 | C32: controler l'usure du tapis et remplacer les portions usées ou maillons cassés | D32: 120
B33: =+B32+1 -> 26 | C33: controler la tenson des tapis et ajuster au besoin | D33: 60
B34: =B33+1 -> 27
B35: =B34+1 -> 28
B36: =+B35+1 -> 29
B37: =B36+1 -> 30
B38: Commentaire | D38: Nom et Visa Intervenants | G38: Nom et Visa Responsables

Sheet CC C8
B3: CHECKLIST MECANIQUE | G3: Date
C4: CONVOYEURS CASIERS C8 | D4: =+'Line & frequency'!C1 -> CHAINE 4 | G4: =+'Line & frequency'!C2 -> HEBDOMADAIRE
E6: FAIT?
B7: N° | C7: DESCRIPTION DES TACHES | D7: Durée | E7: OUI | F7: NON | G7: REMARQUES (MATERIEL + PIECES)
B8: 1 | C8: controler l'arret d'huile et le remplacé au besoin. Aucune fuite d'huile n'est acceptable. | D8: 10
B9: =B8+1 -> 2 | C9: controler la fixation du réducteur sur le convoyeur et corriger si necessaire. | D9: 30
B10: =+B9+1 -> 3 | C10: controler l'usure du pignon et le remplacé au besoin. Aucun glissement n'est acceptable. | D10: 30
B11: =B10+1 -> 4 | C11: controler l'alignement et la fixation du pignon de l'axe moteur et remedier au besoin. | D11: 30
B12: =+B11+1 -> 5 | C12: controler l'usure de la roue libre et la remplacée au besoin. Aucun glissement n'est acceptable. | D12: 30
B13: =B12+1 -> 6 | C13: controler l'alignement et la fixation de la roue libre et remedier au problème. | D13: 30
B14: =+B13+1 -> 7 | C14: controler l'usure de la clavette et la rainure et reparer au besoin | D14: 30
B15: =B14+1 -> 8 | C15: controler l'état des glissières et remplacer les au besoin | D15: 25
B16: =+B15+1 -> 9 | C16: controler l'arret d'huile et le remplacé au besoin. Aucune fuite d'huile n'est acceptable. | D16: 10
B17: =B16+1 -> 10 | C17: controler la fixation du réducteur sur le convoyeur et corriger si necessaire. | D17: 30
B18: =+B17+1 -> 11 | C18: controler l'usure des roulements et paliers de l'axe moteur et remplacer si necessaire. | D18: 30
B19: =B18+1 -> 12 | C19: controler l'usure des pignons et les remplacés au besoin. Aucun glissement n'est acceptable. | D19: 30
B20: =+B19+1 -> 13 | C20: controler l'alignement et la fixation du pignon de l'axe moteur et remedier au besoin. | D20: 30
B21: =B20+1 -> 14 | C21: controler l'usure de la clavette et la rainure et reparer au besoin | D21: 30
B22: =+B21+1 -> 15 | C22: controler l'état des glissières et remplacer les au besoin | D22: 25
B23: =B22+1 -> 16 | C23: controler l'usure du tapis et remplacer les portions usées ou maillons cassés | D23: 120
B24: =+B23+1 -> 17 | C24: controler la tenson des tapis et ajuster au besoin | D24: 60
B25: =B24+1 -> 18
B26: =B25+1 -> 19
B27: =+B26+1 -> 20
B28: =B27+1 -> 21
B29: =B28+1 -> 22
B30: =+B29+1 -> 23
B31: =B30+1 -> 24
B32: =B31+1 -> 25
B33: =+B32+1 -> 26
B34: =B33+1 -> 27
B35: =B34+1 -> 28
B36: =+B35+1 -> 29
B37: =B36+1 -> 30
B38: Commentaire | D38: Nom et Visa Intervenants | G38: Nom et Visa Responsables

Sheet Line & frequency
B1: Line | C1: CHAINE 4
B2: Frequency | C2: HEBDOMADAIRE
B3: Date | C3: 44273 | G3: =+'Line & frequency'!C3 -> 44273
