Workbook

Sheet AF Compressor
B3: CHECKLIST ELECTRIQUE | F3: Date:
C4: AF Compressor | D4: LIGNE 6 | F4: =+'Line & frequency'!C2 -> HEBDOMADAIRE
D6: FAIT?
B7: N° | C7: DESCRIPTION DES TACHES | D7: OUI | E7: NON | F7: REMARQUES (MATERIEL + PIECES)
B8: 1 | C8: Contrôle du système de refroidissement d'eau
B9: 2 | C9: Soufler l'armoire électrique
B10: 3 | C10: Vérifier le fonctionnement de l'interrupteur d'arrêt d'urgence.
B11: 4 | C11: Controler le fonctionnement (système) du sécheur d'air
B12: 5 | C12: Controler les enroulements de la pompe à huile
B13: 6 | C13: Verifier l'état des joints de l'électrovanne de purge du troisième étage
D15: % arret avant mtce | E15: % arret aprés mtce
B16: Commentaire | F16: Nom et Visa Responsables

Sheet Blomax
B3: CHECKLIST ELECTRIQUE | F3: Date:
C4: BLOMAX | D4: LIGNE 6 | F4: =+'Line & frequency'!C2 -> HEBDOMADAIRE
D6: FAIT?
B7: N° | C7: DESCRIPTION DES TACHES | D7: OUI | E7: NON | F7: REMARQUES (MATERIEL + PIECES)
B8: 1 | C8: Soufler l'armoire électrique pour Dépoussiérer
B9: 2 | C9: controler le retour des signaux de tous les capteurs
B10: 3 | C10: Néttoyer les coffrets electriques et ranger l'intérieur
B11: 4 | C11: Contrôler visuellement l'etat des moteurs
B12: 5 | C12: controler l'etat des chemins de câble
B13: 6 | C13: controler l'etat des câbles
B14: 7 | C14: controler l'état de de fontionnement et la manœuvre des commutateurs et boutons poursoirs sur les pupitres de commande
B15: 8 | C15: Vérifier le serrage du IHM
B16: 9 | C16: Nettoyer et contrôler la barrière photoélectrique et le réflecteur du Module de chauffe -Four-linéaire
B17: 10 | C17: Nettoyer et Contrôler la fixation du pyromètre du Module de chauffe des preformes
B18: 11 | C18: Nettoyer et contrôler la barrière photoélectrique et le réflecteur du Module de chauffe
B19: 12 | C19: Nettoyer et contrôler la barrière photoélectrique et le réflecteur du Bâti de base
... B23: 16 | C23: Controler le l'état des batteries de l'automate et signaler toutes anomalies observées
D25: % arret avant mtce | E25: % arret aprés mtce
B27: Commentaire | F27: Nom et Visa Responsables

Sheet FILLER
B3: CHECKLIST ELECTRIQUE | F3: Date:
C4: FILLER | D4: LIGNE 6 | F4: =+'Line & frequency'!C2 -> HEBDOMADAIRE
D6: FAIT?
B7: N° | C7: DESCRIPTION DES TACHES | D7: OUI | E7: NON | F7: REMARQUES (MATERIEL + PIECES)
B8: 1 | C8: Vérifier l'état correct des capteurs et reflecteurs de l'ensemble de la machine
B9: =B8+1 -> 2 | C9: Activer l'un des interrupteurs d'arrêt d'urgence.
B10: =+B9+1 -> 3 | C10: ouvrir et fermer une porte dans chaque zone de la machine.
B11: =+B10+1 -> 4 | C11: Soufler l'armoire électrique du cap feeder
B12: =+B11+1 -> 5 | C12: Soufler l'armoire électrique
B13: =+B12+1 -> 6 | C13: Néttoyer les coffrets electriques et ranger l'intérieur
B14: =+B13+1 -> 7 | C14: controler l'etat des chemins de câble
B15: =+B14+1 -> 8 | C15: controler l'état de de fontionnement et la manœuvre des commutateurs et boutons poursoirs sur les pupitres de commande
B16: =+B15+1 -> 9 | C16: controler le retour des signaux des capteurs
B17: 10 | C17: controler l'etat et la des câbles et le serrage des cables réseau
B18: 11 | C18: Vérifier le serrage du IHM
B19: 12 | C19: Ouvrir les push-pull key (clé de porte) et souffler
D21: % arret avant mtce | E21: % arret aprés mtce
B23: Commentaire | F23: Nom et Visa Responsables

Sheet Paramix
B3: CHECKLIST ELECTRIQUE | F3: Date:
C4: PARAMIX | D4: LIGNE 6 | F4: HEBDMADAIRE
D5: FAIT?
B6: N° | C6: DESCRIPTION DES TACHES | D6: OUI | E6: NON | F6: REMARQUES (MATERIEL + PIECES)
B7: 1 | C7: Nettoyer les éléments filtrants dans la ventilation de l'armoire électrique
B8: 2 | C8: Vérifier le bon fonctionnement du climatiseur
B9: 3 | C9: Réaliser le test des lampes
B10: 4 | C10: Soufler l'armoire électrique
B11: 5 | C11: Néttoyer les coffrets electriques et ranger l'intérieur
B12: 6 | C12: controler l'etat des chemins de câble
B13: 7 | C13: controler le retour des signaux des capteurs
B14: 8 | C14: controler l'état de de fontionnement et la manœuvre des commutateurs et boutons poursoirs sur les pupitres de commande
D16: % arret avant mtce | E16: % arret aprés mtce
B18: Commentaire | F18: Nom et Visa Responsables

Sheet CIP
B3: CHECKLIST ELECTRIQUE | F3: Date:
C4: CIP | D4: LIGNE 6 | F4: =+'Line & frequency'!C2 -> HEBDOMADAIRE
D5: FAIT?
B6: N° | C6: DESCRIPTION DES TACHES | D6: OUI | E6: NON | F6: REMARQUES (MATERIEL + PIECES)
B7: 1 | C7: Soufler l'armoire électrique
B8: =B7+1 -> 2 | C8: Nettoyer les éléments filtrants dans la ventilation de l'armoire électrique
B9: =+B8+1 -> 3 | C9: Réaliser le test des lampes
B10: =B9+1 -> 4 | C10: Vérifier que le climatiseurs fonctionne bien
B11: =B10+1 -> 5 | C11: controler l'etat des chemins de câble
B12: =B11+1 -> 6 | C12: Néttoyer les coffrets electriques et ranger l'intérieur
D14: % arret avant mtce | E14: % arret aprés mtce
B16: Commentaire | F16: Nom et Visa Responsables

Sheet Labeller
B3: CHECKLIST ELECTRIQUE | F3: Date:
C4: LABELLER | D4: LIGNE 6 | F4: =+'Line & frequency'!C2 -> HEBDOMADAIRE
D6: FAIT?
B7: N° | C7: DESCRIPTION DES TACHES | D7: OUI | E7: NON | F7: REMARQUES (MATERIEL + PIECES)
B8: 1 | C8: Contrôler le fonctionnement des dispositifs d’arrêt d’urgence et des lampes
B9: 2 | C9: Vérifier que le climatiseurs fonctionne bien
B10: 3 | C10: controler l'etat des chemins de câble
B11: 4 | C11: controler le retour des signaux des capteurs
B12: 5 | C12: Nettoyer les cellules photos
B13: 6 | C13: Soufler l'armoire électrique
B14: 7 | C14: Néttoyer les coffrets electriques et ranger l'intérieur
B15: 8 | C15: Verifier le bon fonctionnement du couteau
B16: 9 | C16: Vérifier le serrage du IHM
B17: 10
D18: % arret avant mtce | E18: % arret aprés mtce
B20: Commentaire | F20: Nom et Visa Responsables

Sheet Kisters
B3: CHECKLIST ELECTRIQUE | F3: Date:
C4: KISTERS | D4: LIGNE 6 | F4: =+'Line & frequency'!C2 -> HEBDOMADAIRE
D6: FAIT?
B7: N° | C7: DESCRIPTION DES TACHES | D7: OUI | E7: NON | F7: REMARQUES (MATERIEL + PIECES)
B8: 1 | C8: Nettoyer les éléments filtrants dans la ventilation de l'armoire électrique
B9: =+B8+1 -> 2 | C9: Vérifier le bon fonctionnement du climatiseur
B10: 3 | C10: Réaliser le test des lampes
B11: 4 | C11: Néttoyer les coffrets electriques et ranger l'intérieur
B12: =+B11+1 -> 5 | C12: controler l'etat des chemins de câble
B13: 6 | C13: controler la fixation des capteurs et leur retour de signaux
B14: 7 | C14: controler l'état de de fontionnement et la manœuvre des commutateurs et boutons poursoirs sur les pupitres de commande
B15: =+B14+1 -> 8 | C15: Contrôler visuellement l'etat des moteurs
B16: 9 | C16: Controler l'alignement des capteurs et reflecteurs
B17: 10 | C17: Vérifier le serrage du IHM
B18: 11
D20: % arret avant mtce | E20: % arret aprés mtce
B22: Commentaire | F22: Nom et Visa Responsables

Sheet Handle applicator
B3: CHECKLIST ELECTRIQUE | F3: Date:
C4: HANDLE APPLICATOR | D4: LIGNE 6 | F4: =+'Line & frequency'!C2 -> HEBDOMADAIRE
D6: FAIT?
B7: N° | C7: DESCRIPTION DES TACHES | D7: OUI | E7: NON | F7: REMARQUES (MATERIEL + PIECES)
B8: 1 | C8: Vérifier le bon fonctionnement du climatiseur
B9: 2 | C9: Réaliser le test des lampes
B10: 3 | C10: controler l'etat des chemins de câble
B11: 4 | C11: controler la fixation des capteurs et leur retour de signaux
B12: 5 | C12: controler l'état de de fontionnement et la manœuvre des commutateurs et boutons poursoirs sur les pupitres de commande
B13: 6 | C13: Contrôler visuellement l'etat des moteurs
B14: 7 | C14: Controler l'alignement des capteurs et reflecteurs
B15: 8 | C15: Vérifier le serrage du IHM
B16: 9
B17: 10
D18: % arret avant mtce | E18: % arret aprés mtce
B20: Commentaire | F20: Nom et Visa Responsables

Sheet Convoyeurs
B3: CHECKLIST ELECTRIQUE | F3: Date:
C4: CONVOYEURS | D4: LIGNE 6 | F4: =+'Line & frequency'!C2 -> HEBDOMADAIRE
D6: FAIT?
B7: N° | C7: DESCRIPTION DES TACHES | D7: OUI | E7: NON | F7: REMARQUES (MATERIEL + PIECES)
B8: 1 | C8: Vérifier l'étanchéité de tous les boîtiers
B9: 2 | C9: Vérifier les flexibles et les raccords du système pneumatique
B10: 3 | C10: Nettoyer les capteurs et reflecteurs
B11: 4 | C11: Nettoyer les éléments filtrants dans la ventilation de l'armoire électrique
B12: 5 | C12: Vérifier le bon fonctionnement du climatiseur de l'armoire électrique
B13: 6 | C13: Réaliser le test des lampes
B14: 7 | C14: controler l'etat des chemins de câble
B15: 8 | C15: controler le retour des signaux des capteurs
B16: 9 | C16: controler l'état de de fontionnement et la manœuvre des commutateurs et boutons poursoirs sur les pupitres de commande
B17: 10 | C17: Contrôler visuellement l'etat des moteurs
B18: 11 | C18: Controler l'alignement des capteurs et reflecteurs
B19: 12 | C19: Nettoyer les moteurs
B20: 13
B21: 14
D22: % arret avant mtce | E22: % arret aprés mtce
B24: Commentaire | F24: Nom et Visa Responsables

Sheet Cvyr Btles
B3: CHECKLIST MECANIQUE | G3: Date
C4: PALETTISEUR | D4: =+'Line & frequency'!C1 -> CHAINE 4 | G4: =+'Line & frequency'!C2 -> HEBDOMADAIRE
E6: FAIT?
B7: N° | C7: DESCRIPTION DES TACHES | D7: Durée | E7: OUI | F7: NON | G7: REMARQUES (MATERIEL + PIECES)
B8: 1
B9: =B8+1 -> 2
B10: =+B9+1 -> 3
B11: =B10+1 -> 4
B12: =+B11+1 -> 5
B13: =B12+1 -> 6
B14: =+B13+1 -> 7
B15: =B14+1 -> 8
B16: =+B15+1 -> 9
B17: =B16+1 -> 10
B18: =+B17+1 -> 11
B19: =B18+1 -> 12
B20: =+B19+1 -> 13
B21: =B20+1 -> 14
B22: =+B21+1 -> 15
B23: =B22+1 -> 16
B24: =+B23+1 -> 17
B25: =B24+1 -> 18
B26: =+B25+1 -> 19
B27: =B26+1 -> 20
B28: =+B27+1 -> 21
B29: =B28+1 -> 22
B30: =+B29+1 -> 23
B31: =B30+1 -> 24
B32: =+B31+1 -> 25
B33: =B32+1 -> 26
B34: =+B33+1 -> 27
B35: =B34+1 -> 28
B36: =+B35+1 -> 29
B37: =B36+1 -> 30
B38: =+B37+1 -> 31
B39: =B38+1 -> 32
B40: =+B39+1 -> 33
B41: =B40+1 -> 34
B42: =+B41+1 -> 35
B43: =B42+1 -> 36
...

Sheet CC C1
B3: CHECKLIST MECANIQUE | G3: Date
C4: CONVOYEURS CASIERS C1 | D4: =+'Line & frequency'!C1 -> CHAINE 4 | G4: =+'Line & frequency'!C2 -> HEBDOMADAIRE
E6: FAIT?
B7: N° | C7: DESCRIPTION DES TACHES | D7: Durée | E7: OUI | F7: NON | G7: REMARQUES (MATERIEL + PIECES)
B8: 1 | C8: controler l'arret d'huile et le remplacé au besoin. Aucune fuite d'huile n'est acceptable. | D8: 10
B9: =B8+1 -> 2 | C9: controler la fixation du réducteur sur le convoyeur et corriger si necessaire. | D9: 30
B10: =+B9+1 -> 3 | C10: controler l'usure du pignon et le remplacé au besoin. Aucun glissement n'est acceptable. | D10: 30
B11: =B10+1 -> 4 | C11: controler l'alignement et la fixation du pignon de l'axe moteur et remedier au besoin. | D11: 30
B12: =+B11+1 -> 5 | C12: controler l'usure de la roue libre et la remplacée au besoin. Aucun glissement n'est acceptable. | D12: 30
B13: =B12+1 -> 6 | C13: controler l'alignement et la fixation de la roue libre et remedier au problème. | D13: 30
B14: =+B13+1 -> 7 | C14: controler l'usure de la clavette et la rainure et reparer au besoin | D14: 30
B15: =B14+1 -> 8 | C15: controler l'état des glissières et remplacer les au besoin | D15: 25
B16: =+B15+1 -> 9 | C16: controler l'arret d'huile et le remplacé au besoin. Aucune fuite d'huile n'est acceptable. | D16: 10
B17: =B16+1 -> 10 | C17: controler l'usure des roulements et paliers de l'axe moteur et remplacer si necessaire. | D17: 30
B18: =+B17+1 -> 11 | C18: controler l'usure du pignon et le remplacé au besoin. Aucun glissement n'est acceptable. | D18: 30
B19: =B18+1 -> 12 | C19: controler l'alignement et la fixation du pignon de l'axe moteur et remedier au besoin. | D19: 30
B20: =+B19+1 -> 13 | C20: controler l'usure de la clavette et la rainure et reparer au besoin | D20: 30
B21: =B20+1 -> 14 | C21: controler l'usure des roulements et paliers de l'axe moteur et remplacer si necessaire. | D21: 30
B22: =+B21+1 -> 15 | C22: controler l'usure de la roue libre et la remplacée au besoin. Aucun glissement n'est acceptable. | D22: 30
B23: =B22+1 -> 16 | C23: controler l'alignement et la fixation de la roue libre et remedier au problème. | D23: 30
B24: =+B23+1 -> 17 | C24: controler l'usure de la clavette et la rainure et reparer au besoin | D24: 30
B25: =B24+1 -> 18 | C25: controler l'arret d'huile et le remplacé au besoin. Aucune fuite d'huile n'est acceptable. | D25: 10
B26: =+B25+1 -> 19 | C26: controler la fixation du réducteur sur le convoyeur et corriger si necessaire. | D26: 30
B27: =B26+1 -> 20 | C27: controler l'usure des roulements et paliers de l'axe moteur et remplacer si necessaire. | D27: 30
B28: =+B27+1 -> 21 | C28: controler l'usure du pignon et le remplacé au besoin. Aucun glissement n'est acceptable. | D28: 30
B29: =B28+1 -> 22 | C29: controler l'alignement et la fixation du pignon de l'axe moteur et remedier au besoin. | D29: 30
B30: =+B29+1 -> 23 | C30: controler l'usure de la clavette et la rainure et reparer au besoin | D30: 30
B31: =B30+1 -> 24 | C31: controler l'usure des roulements et paliers de l'axe moteur et remplacer si necessaire. | D31: 30
B32: =+B31+1 -> 25 | C32: controler l'usure de la clavette et la rainure et reparer au besoin | D32: 30
B33: =B32+1 -> 26 | C33: controler l'état des glissières et remplacer les au besoin | D33: 25
B34: =+B33+1 -> 27 | C34: controler l'arret d'huile et le remplacé au besoin. Aucune fuite d'huile n'est acceptable. | D34: 10
B35: =B34+1 -> 28 | C35: controler la fixation du réducteur sur le convoyeur et corriger si necessaire. | D35: 30
B36: =+B35+1 -> 29 | C36: controler l'usure des roulements et paliers de l'axe moteur et remplacer si necessaire. | D36: 30
B37: =B36+1 -> 30 | C37: controler l'usure des pignons et les remplacés au besoin. Aucun glissement n'est acceptable. | D37: 30
B38: =+B37+1 -> 31 | C38: controler l'alignement et la fixation du pignon de l'axe moteur et remedier au besoin. | D38: 30
B39: =B38+1 -> 32 | C39: controler l'usure de la clavette et la rainure et reparer au besoin | D39: 30
B40: =+B39+1 -> 33 | C40: controler l'état des glissières et remplacer les au besoin | D40: 25
B41: =B40+1 -> 34 | C41: controler l'usure du tapis et remplacer les portions usées ou maillons cassés | D41: 120
B42: =+B41+1 -> 35 | C42: controler la tenson des tapis et ajuster au besoin | D42: 60
B43: =B42+1 -> 36 | C43: controler l'arret d'huile et le remplacé au besoin. Aucune fuite d'huile n'est acceptable. | D43: 10
...

Sheet CC C2
B3: CHECKLIST MECANIQUE | G3: Date
C4: CONVOYEURS CASIERS C2 | D4: =+'Line & frequency'!C1 -> CHAINE 4 | G4: =+'Line & frequency'!C2 -> HEBDOMADAIRE
E6: FAIT?
B7: N° | C7: DESCRIPTION DES TACHES | D7: Durée | E7: OUI | F7: NON | G7: REMARQUES (MATERIEL + PIECES)
B8: 1 | C8: controler l'arret d'huile et le remplacé au besoin. Aucune fuite d'huile n'est acceptable. | D8: 10
B9: =B8+1 -> 2 | C9: controler la fixation du réducteur sur le convoyeur et corriger si necessaire. | D9: 30
B10: =+B9+1 -> 3 | C10: controler l'usure du pignon et le remplacé au besoin. Aucun glissement n'est acceptable. | D10: 30
B11: =B10+1 -> 4 | C11: controler l'alignement et la fixation du pignon de l'axe moteur et remedier au besoin. | D11: 30
B12: =+B11+1 -> 5 | C12: controler l'usure de la roue libre et la remplacée au besoin. Aucun glissement n'est acceptable. | D12: 30
B13: =B12+1 -> 6 | C13: controler l'alignement et la fixation de la roue libre et remedier au problème. | D13: 30
B14: =+B13+1 -> 7 | C14: controler l'usure de la clavette et la rainure et reparer au besoin | D14: 30
B15: =B14+1 -> 8 | C15: controler l'état des glissières et remplacer les au besoin | D15: 25
B16: =+B15+1 -> 9 | C16: controler l'arret d'huile et le remplacé au besoin. Aucune fuite d'huile n'est acceptable. | D16: 10
B17: =B16+1 -> 10 | C17: controler l'usure des roulements et paliers de l'axe moteur et remplacer si necessaire. | D17: 30
B18: =+B17+1 -> 11 | C18: controler l'usure du pignon et le remplacé au besoin. Aucun glissement n'est acceptable. | D18: 30
B19: =B18+1 -> 12 | C19: controler l'alignement et la fixation du pignon de l'axe moteur et remedier au besoin. | D19: 30
B20: =+B19+1 -> 13 | C20: controler l'usure de la clavette et la rainure et reparer au besoin | D20: 30
B21: =B20+1 -> 14 | C21: controler l'usure des roulements et paliers de l'axe moteur et remplacer si necessaire. | D21: 30
B22: =+B21+1 -> 15 | C22: controler l'usure de la roue libre et la remplacée au besoin. Aucun glissement n'est acceptable. | D22: 30
B23: =B22+1 -> 16 | C23: controler l'alignement et la fixation de la roue libre et remedier au problème. | D23: 30
B24: =+B23+1 -> 17 | C24: controler l'usure de la clavette et la rainure et reparer au besoin | D24: 30
B25: =B24+1 -> 18 | C25: controler l'arret d'huile et le remplacé au besoin. Aucune fuite d'huile n'est acceptable. | D25: 10
B26: =+B25+1 -> 19 | C26: controler la fixation du réducteur sur le convoyeur et corriger si necessaire. | D26: 30
B27: =B26+1 -> 20 | C27: controler l'usure des roulements et paliers de l'axe moteur et remplacer si necessaire. | D27: 30
B28: =+B27+1 -> 21 | C28: controler l'usure des pignons et les remplacés au besoin. Aucun glissement n'est acceptable. | D28: 30
B29: =B28+1 -> 22 | C29: controler l'alignement et la fixation du pignon de l'axe moteur et remedier au besoin. | D29: 30
B30: =+B29+1 -> 23 | C30: controler l'usure de la clavette et la rainure et reparer au besoin | D30: 30
B31: =B30+1 -> 24 | C31: controler l'état des glissières et remplacer les au besoin | D31: 25
B32: =+B31+1 -> 25 | C32: controler l'usure du tapis et remplacer les portions usées ou maillons cassés | D32: 120
B33: =B32+1 -> 26 | C33: controler la tenson des tapis et ajuster au besoin | D33: 60
B34: =+B33+1 -> 27
B35: =B34+1 -> 28
B36: =+B35+1 -> 29
B37: =B36+1 -> 30
B38: =+B37+1 -> 31
B39: =B38+1 -> 32
B40: =+B39+1 -> 33
B41: =B40+1 -> 34
B42: =+B41+1 -> 35
B43: =B42+1 -> 36
...

Sheet CC C3
B3: CHECKLIST MECANIQUE | G3: Date
C4: CONVOYEURS CASIERS C3 | D4: =+'Line & frequency'!C1 -> CHAINE 4 | G4: =+'Line & frequency'!C2 -> HEBDOMADAIRE
E6: FAIT?
B7: N° | C7: DESCRIPTION DES TACHES | D7: Durée | E7: OUI | F7: NON | G7: REMARQUES (MATERIEL + PIECES)
B8: 1 | C8: controler l'arret d'huile et le remplacé au besoin. Aucune fuite d'huile n'est acceptable. | D8: 10
B9: =B8+1 -> 2 | C9: controler la fixation du réducteur sur le convoyeur et corriger si necessaire. | D9: 30
B10: =+B9+1 -> 3 | C10: controler l'usure du pignon et le remplacé au besoin. Aucun glissement n'est acceptable. | D10: 30
B11: =B10+1 -> 4 | C11: controler l'alignement et la fixation du pignon de l'axe moteur et remedier au besoin. | D11: 30
B12: =+B11+1 -> 5 | C12: controler l'usure de la roue libre et la remplacée au besoin. Aucun glissement n'est acceptable. | D12: 30
B13: =B12+1 -> 6 | C13: controler l'alignement et la fixation de la roue libre et remedier au problème. | D13: 30
B14: =+B13+1 -> 7 | C14: controler l'usure de la clavette et la rainure et reparer au besoin | D14: 30
B15: =B14+1 -> 8 | C15: controler l'état des glissières et remplacer les au besoin | D15: 25
B16: =+B15+1 -> 9 | C16: controler l'arret d'huile et le remplacé au besoin. Aucune fuite d'huile n'est acceptable. | D16: 10
B17: =B16+1 -> 10 | C17: controler l'usure des roulements et paliers de l'axe moteur et remplacer si necessaire. | D17: 30
B18: =+B17+1 -> 11 | C18: controler l'usure du pignon et le remplacé au besoin. Aucun glissement n'est acceptable. | D18: 30
B19: =B18+1 -> 12 | C19: controler l'alignement et la fixation du pignon de l'axe moteur et remedier au besoin. | D19: 30
B20: =+B19+1 -> 13 | C20: controler l'usure de la clavette et la rainure et reparer au besoin | D20: 30
B21: =B20+1 -> 14 | C21: controler l'usure des roulements et paliers de l'axe moteur et remplacer si necessaire. | D21: 30
B22: =+B21+1 -> 15 | C22: controler l'usure de la roue libre et la remplacée au besoin. Aucun glissement n'est acceptable. | D22: 30
B23: =B22+1 -> 16 | C23: controler l'alignement et la fixation de la roue libre et remedier au problème. | D23: 30
B24: =+B23+1 -> 17 | C24: controler l'usure de la clavette et la rainure et reparer au besoin | D24: 30
B25: =B24+1 -> 18
B26: =+B25+1 -> 19
B27: =B26+1 -> 20
B28: =+B27+1 -> 21
B29: =B28+1 -> 22
B30: =+B29+1 -> 23
B31: =B30+1 -> 24
B32: =+B31+1 -> 25
B33: Commentaire | D33: Nom et Visa Intervenants | G33: Nom et Visa Responsables

Sheet CC C4
B3: CHECKLIST MECANIQUE | G3: Date
C4: CONVOYEURS CASIERS C4 | D4: =+'Line & frequency'!C1 -> CHAINE 4 | G4: =+'Line & frequency'!C2 -> HEBDOMADAIRE
E6: FAIT?
B7: N° | C7: DESCRIPTION DES TACHES | D7: Durée | E7: OUI | F7: NON | G7: REMARQUES (MATERIEL + PIECES)
B8: 1 | C8: controler l'arret d'huile et le remplacé au besoin. Aucune fuite d'huile n'est acceptable. | D8: 10
B9: =B8+1 -> 2 | C9: controler la fixation du réducteur sur le convoyeur et corriger si necessaire. | D9: 30
B10: =+B9+1 -> 3 | C10: controler l'usure du pignon et le remplacé au besoin. Aucun glissement n'est acceptable. | D10: 30
B11: =B10+1 -> 4 | C11: controler l'alignement et la fixation du pignon de l'axe moteur et remedier au besoin. | D11: 30
B12: =+B11+1 -> 5 | C12: controler l'usure de la roue libre et la remplacée au besoin. Aucun glissement n'est acceptable. | D12: 30
B13: =B12+1 -> 6 | C13: controler l'alignement et la fixation de la roue libre et remedier au problème. | D13: 30
B14: =+B13+1 -> 7 | C14: controler l'usure de la clavette et la rainure et reparer au besoin | D14: 30
B15: =B14+1 -> 8 | C15: controler l'état des glissières et remplacer les au besoin | D15: 25
B16: =+B15+1 -> 9 | C16: controler l'arret d'huile et le remplacé au besoin. Aucune fuite d'huile n'est acceptable. | D16: 10
B17: =B16+1 -> 10 | C17: controler l'usure des roulements et paliers de l'axe moteur et remplacer si necessaire. | D17: 30
B18: =+B17+1 -> 11 | C18: controler l'usure du pignon et le remplacé au besoin. Aucun glissement n'est acceptable. | D18: 30
B19: =B18+1 -> 12 | C19: controler l'alignement et la fixation du pignon de l'axe moteur et remedier au besoin. | D19: 30
B20: =+B19+1 -> 13 | C20: controler l'usure de la clavette et la rainure et reparer au besoin | D20: 30
B21: =B20+1 -> 14 | C21: controler l'usure des roulements et paliers de l'axe moteur et remplacer si necessaire. | D21: 30
B22: =+B21+1 -> 15 | C22: controler l'usure de la roue libre et la remplacée au besoin. Aucun glissement n'est acceptable. | D22: 30
B23: =B22+1 -> 16 | C23: controler l'alignement et la fixation de la roue libre et remedier au problème. | D23: 30
B24: =+B23+1 -> 17 | C24: controler l'usure de la clavette et la rainure et reparer au besoin | D24: 30
B25: =B24+1 -> 18 | C25: controler l'arret d'huile et le remplacé au besoin. Aucune fuite d'huile n'est acceptable. | D25: 10
B26: =B25+1 -> 19 | C26: controler la fixation du réducteur sur le convoyeur et corriger si necessaire. | D26: 30
B27: =+B26+1 -> 20 | C27: controler l'usure des roulements et paliers de l'axe moteur et remplacer si necessaire. | D27: 30
B28: =B27+1 -> 21 | C28: controler l'usure du pignon et le remplacé au besoin. Aucun glissement n'est acceptable. | D28: 30
B29: =B28+1 -> 22 | C29: controler l'alignement et la fixation du pignon de l'axe moteur et remedier au besoin. | D29: 30
B30: =+B29+1 -> 23 | C30: controler l'usure de la clavette et la rainure et reparer au besoin | D30: 30
B31: =B30+1 -> 24 | C31: controler l'usure des roulements et paliers de l'axe moteur et remplacer si necessaire. | D31: 30
B32: =B31+1 -> 25 | C32: controler l'usure de la clavette et la rainure et reparer au besoin | D32: 30
B33: =+B32+1 -> 26 | C33: controler l'état des glissières et remplacer les au besoin | D33: 25
B34: =B33+1 -> 27
B35: =B34+1 -> 28
B36: =+B35+1 -> 29
B37: =B36+1 -> 30
B38: Commentaire | D38: Nom et Visa Intervenants | G38: Nom et Visa Responsables

Sheet CC C5
B3: CHECKLIST MECANIQUE | G3: Date
C4: CONVOYEURS CASIERS C5 | D4: =+'Line & frequency'!C1 -> CHAINE 4 | G4: =+'Line & frequency'!C2 -> HEBDOMADAIRE
E6: FAIT?
B7: N° | C7: DESCRIPTION DES TACHES | D7: Durée | E7: OUI | F7: NON | G7: REMARQUES (MATERIEL + PIECES)
B8: 1 | C8: controler l'arret d'huile et le remplacé au besoin. Aucune fuite d'huile n'est acceptable. | D8: 10
B9: =B8+1 -> 2 | C9: controler la fixation du réducteur sur le convoyeur et corriger si necessaire. | D9: 30
B10: =+B9+1 -> 3 | C10: controler l'usure du pignon et le remplacé au besoin. Aucun glissement n'est acceptable. | D10: 30
B11: =B10+1 -> 4 | C11: controler l'alignement et la fixation du pignon de l'axe moteur et remedier au besoin. | D11: 30
B12: =+B11+1 -> 5 | C12: controler l'usure de la roue libre et la remplacée au besoin. Aucun glissement n'est acceptable. | D12: 30
B13: =B12+1 -> 6 | C13: controler l'alignement et la fixation de la roue libre et remedier au problème. | D13: 30
B14: =+B13+1 -> 7 | C14: controler l'usure de la clavette et la rainure et reparer au besoin | D14: 30
B15: =B14+1 -> 8 | C15: controler l'état des glissières et remplacer les au besoin | D15: 25
B16: =+B15+1 -> 9 | C16: controler l'arret d'huile et le remplacé au besoin. Aucune fuite d'huile n'est acceptable. | D16: 10
B17: =B16+1 -> 10 | C17: controler l'usure des roulements et paliers de l'axe moteur et remplacer si necessaire. | D17: 30
B18: =+B17+1 -> 11 | C18: controler l'usure du pignon et le remplacé au besoin. Aucun glissement n'est acceptable. | D18: 30
B19: =B18+1 -> 12 | C19: controler l'alignement et la fixation du pignon de l'axe moteur et remedier au besoin. | D19: 30
B20: =+B19+1 -> 13 | C20: controler l'usure de la clavette et la rainure et reparer au besoin | D20: 30
B21: =B20+1 -> 14 | C21: controler l'usure des roulements et paliers de l'axe moteur et remplacer si necessaire. | D21: 30
B22: =+B21+1 -> 15 | C22: controler l'usure de la roue libre et la remplacée au besoin. Aucun glissement n'est acceptable. | D22: 30
B23: =B22+1 -> 16 | C23: controler l'alignement et la fixation de la roue libre et remedier au problème. | D23: 30
B24: =+B23+1 -> 17 | C24: controler l'usure de la clavette et la rainure et reparer au besoin | D24: 30
B25: =B24+1 -> 18
B26: =B25+1 -> 19
B27: =+B26+1 -> 20
B28: =B27+1 -> 21
B29: =B28+1 -> 22
B30: =+B29+1 -> 23
B31: =B30+1 -> 24
B32: =B31+1 -> 25
B33: =+B32+1 -> 26
B34: =B33+1 -> 27
B35: =B34+1 -> 28
B36: =+B35+1 -> 29
B37: =B36+1 -> 30
B38: Commentaire | D38: Nom et Visa Intervenants | G38: Nom et Visa Responsables

Sheet CC C6
B3: CHECKLIST MECANIQUE | G3: Date
C4: CONVOYEURS CASIERS C6 | D4: =+'Line & frequency'!C1 -> CHAINE 4 | G4: =+'Line & frequency'!C2 -> HEBDOMADAIRE
E6: FAIT?
B7: N° | C7: DESCRIPTION DES TACHES | D7: Durée | E7: OUI | F7: NON | G7: REMARQUES (MATERIEL + PIECES)
B8: 1 | C8: controler l'arret d'huile et le remplacé au besoin. Aucune fuite d'huile n'est acceptable. | D8: 10
B9: =B8+1 -> 2 | C9: controler la fixation du réducteur sur le convoyeur et corriger si necessaire. | D9: 30
B10: =+B9+1 -> 3 | C10: controler l'usure du pignon et le remplacé au besoin. Aucun glissement n'est acceptable. | D10: 30
B11: =B10+1 -> 4 | C11: controler l'alignement et la fixation du pignon de l'axe moteur et remedier au besoin. | D11: 30
B12: =+B11+1 -> 5 | C12: controler l'usure de la roue libre et la remplacée au besoin. Aucun glissement n'est acceptable. | D12: 30
B13: =B12+1 -> 6 | C13: controler l'alignement et la fixation de la roue libre et remedier au problème. | D13: 30
B14: =+B13+1 -> 7 | C14: controler l'usure de la clavette et la rainure et reparer au besoin | D14: 30
B15: =B14+1 -> 8 | C15: controler l'état des glissières et remplacer les au besoin | D15: 25
B16: =+B15+1 -> 9 | C16: controler l'arret d'huile et le remplacé au besoin. Aucune fuite d'huile n'est acceptable. | D16: 10
B17: =B16+1 -> 10 | C17: controler l'usure des roulements et paliers de l'axe moteur et remplacer si necessaire. | D17: 30
B18: =+B17+1 -> 11 | C18: controler l'usure du pignon et le remplacé au besoin. Aucun glissement n'est acceptable. | D18: 30
B19: =B18+1 -> 12 | C19: controler l'alignement et la fixation du pignon de l'axe moteur et remedier au besoin. | D19: 30
B20: =+B19+1 -> 13 | C20: controler l'usure de la clavette et la rainure et reparer au besoin | D20: 30
B21: =B20+1 -> 14 | C21: controler l'usure des roulements et paliers de l'axe moteur et remplacer si necessaire. | D21: 30
B22: =+B21+1 -> 15 | C22: controler l'usure de la roue libre et la remplacée au besoin. Aucun glissement n'est acceptable. | D22: 30
B23: =B22+1 -> 16 | C23: controler l'alignement et la fixation de la roue libre et remedier au problème. | D23: 30
B24: =+B23+1 -> 17 | C24: controler l'usure de la clavette et la rainure et reparer au besoin | D24: 30
B25: =B24+1 -> 18 | C25: controler l'arret d'huile et le remplacé au besoin. Aucune fuite d'huile n'est acceptable. | D25: 10
B26: =B25+1 -> 19 | C26: controler la fixation du réducteur sur le convoyeur et corriger si necessaire. | D26: 30
B27: =+B26+1 -> 20 | C27: controler l'usure des roulements et paliers de l'axe moteur et remplacer si necessaire. | D27: 30
B28: =B27+1 -> 21 | C28: controler l'usure des pignons et les remplacés au besoin. Aucun glissement n'est acceptable. | D28: 30
B29: =B28+1 -> 22 | C29: controler l'alignement et la fixation du pignon de l'axe moteur et remedier au besoin. | D29: 30
B30: =+B29+1 -> 23 | C30: controler l'usure de la clavette et la rainure et reparer au besoin | D30: 30
B31: =B30+1 -> 24 | C31: controler l'état des glissières et remplacer les au besoin | D31: 25
B32: =B31+1 -> 25 | C32: controler l'usure du tapis et remplacer les portions usées ou maillons cassés | D32: 120
B33: =+B32+1 -> 26 | C33: controler la tenson des tapis et ajuster au besoin | D33: 60
B34: =B33+1 -> 27
B35: =B34+1 -> 28
B36: =+B35+1 -> 29
B37: =B36+1 -> 30
B38: Commentaire | D38: Nom et Visa Intervenants | G38: Nom et Visa Responsables

Sheet CC C7
B3: CHECKLIST MECANIQUE | G3: Date
C4: CONVOYEURS CASIERS C7 | D4: =+'Line & frequency'!C1 -> CHAINE 4 | G4: =+'Line & frequency'!C2 -> HEBDOMADAIRE
E6: FAIT?
B7: N° | C7: DESCRIPTION DES TACHES | D7: Durée | E7: OUI | F7: NON | G7: REMARQUES (MATERIEL + PIECES)
B8: 1 | C8: controler l'arret d'huile et le remplacé au besoin. Aucune fuite d'huile n'est acceptable. | D8: 10
B9: =B8+1 -> 2 | C9: controler la fixation du réducteur sur le convoyeur et corriger si necessaire. | D9: 30
B10: =+B9+1 -> 3 | C10: controler l'usure du pignon et le remplacé au besoin. Aucun glissement n'est acceptable. | D10: 30
B11: =B10+1 -> 4 | C11: controler l'alignement et la fixation du pignon de l'axe moteur et remedier au besoin. | D11: 30
B12: =+B11+1 -> 5 | C12: controler l'usure de la roue libre et la remplacée au besoin. Aucun glissement n'est acceptable. | D12: 30
B13: =B12+1 -> 6 | C13: controler l'alignement et la fixation de la roue libre et remedier au problème. | D13: 30
B14: =+B13+1 -> 7 | C14: controler l'usure de la clavette et la rainure et reparer au besoin | D14: 30
B15: =B14+1 -> 8 | C15: controler l'état des glissières et remplacer les au besoin | D15: 25
B16: =+B15+1 -> 9 | C16: controler l'arret d'huile et le remplacé au besoin. Aucune fuite d'huile n'est acceptable. | D16: 10
B17: =B16+1 -> 10 | C17: controler l'usure des roulements et paliers de l'axe moteur et remplacer si necessaire. | D17: 30
B18: =+B17+1 -> 11 | C18: controler l'usure du pignon et le remplacé au besoin. Aucun glissement n'est acceptable. | D18: 30
B19: =B18+1 -> 12 | C19: controler l'alignement et la fixation du pignon de l'axe moteur et remedier au besoin. | D19: 30
B20: =+B19+1 -> 13 | C20: controler l'usure de la clavette et la rainure et reparer au besoin | D20: 30
B21: =B20+1 -> 14 | C21: controler l'usure des roulements et paliers de l'axe moteur et remplacer si necessaire. | D21: 30
B22: =+B21+1 -> 15 | C22: controler l'usure de la roue libre et la remplacée au besoin. Aucun glissement n'est acceptable. | D22: 30
B23: =B22+1 -> 16 | C23: controler l'alignement et la fixation de la roue libre et remedier au problème. | D23: 30
B24: =+B23+1 -> 17 | C24: controler l'usure de la clavette et la rainure et reparer au besoin | D24: 30
B25: =B24+1 -> 18 | C25: controler l'arret d'huile et le remplacé au besoin. Aucune fuite d'huile n'est acceptable. | D25: 10
B26: =B25+1 -> 19 | C26: controler la fixation du réducteur sur le convoyeur et corriger si necessaire. | D26: 30
B27: =+B26+1 -> 20 | C27: controler l'usure des roulements et paliers de l'axe moteur et remplacer si necessaire. | D27: 30
B28: =B27+1 -> 21 | C28: controler l'usure des pignons et les remplacés au besoin. Aucun glissement n'est acceptable. | D28: 30
B29: =B28+1 -> 22 | C29: controler l'alignement et la fixation du pignon de l'axe moteur et remedier au besoin. | D29: 30
B30: =+B29+1 -> 23 | C30: controler l'usure de la clavette et la rainure et reparer au besoin | D30: 30
B31: =B30+1 -> 24 | C31: controler l'état des glissières et remplacer les au besoin | D31: 25
B32: =B31+1 -> 25 | C32: controler l'usure du tapis et remplacer les portions usées ou maillons cassés | D32: 120
B33: =+B32+1 -> 26 | C33: controler la tenson des tapis et ajuster au besoin | D33: 60
B34: =B33+1 -> 27
B35: =B34+1 -> 28
B36: =+B35+1 -> 29
B37: =B36+1 -> 30
B38: Commentaire | D38: Nom et Visa Intervenants | G38: Nom et Visa Responsables

Sheet CC C8
B3: CHECKLIST MECANIQUE | G3: Date
C4: CONVOYEURS CASIERS C8 | D4: =+'Line & frequency'!C1 -> CHAINE 4 | G4: =+'Line & frequency'!C2 -> HEBDOMADAIRE
E6: FAIT?
B7: N° | C7: DESCRIPTION DES TACHES | D7: Durée | E7: OUI | F7: NON | G7: REMARQUES (MATERIEL + PIECES)
B8: 1 | C8: controler l'arret d'huile et le remplacé au besoin. Aucune fuite d'huile n'est acceptable. | D8: 10
B9: =B8+1 -> 2 | C9: controler la fixation du réducteur sur le convoyeur et corriger si necessaire. | D9: 30
B10: =+B9+1 -> 3 | C10: controler l'usure du pignon et le remplacé au besoin. Aucun glissement n'est acceptable. | D10: 30
B11: =B10+1 -> 4 | C11: controler l'alignement et la fixation du pignon de l'axe moteur et remedier au besoin. | D11: 30
B12: =+B11+1 -> 5 | C12: controler l'usure de la roue libre et la remplacée au besoin. Aucun glissement n'est acceptable. | D12: 30
B13: =B12+1 -> 6 | C13: controler l'alignement et la fixation de la roue libre et remedier au problème. | D13: 30
B14: =+B13+1 -> 7 | C14: controler l'usure de la clavette et la rainure et reparer au besoin | D14: 30
B15: =B14+1 -> 8 | C15: controler l'état des glissières et remplacer les au besoin | D15: 25
B16: =+B15+1 -> 9 | C16: controler l'arret d'huile et le remplacé au besoin. Aucune fuite d'huile n'est acceptable. | D16: 10
B17: =B16+1 -> 10 | C17: controler la fixation du réducteur sur le convoyeur et corriger si necessaire. | D17: 30
B18: =+B17+1 -> 11 | C18: controler l'usure des roulements et paliers de l'axe moteur et remplacer si necessaire. | D18: 30
B19: =B18+1 -> 12 | C19: controler l'usure des pignons et les remplacés au besoin. Aucun glissement n'est acceptable. | D19: 30
B20: =+B19+1 -> 13 | C20: controler l'alignement et la fixation du pignon de l'axe moteur et remedier au besoin. | D20: 30
B21: =B20+1 -> 14 | C21: controler l'usure de la clavette et la rainure et reparer au besoin | D21: 30
B22: =+B21+1 -> 15 | C22: controler l'état des glissières et remplacer les au besoin | D22: 25
B23: =B22+1 -> 16 | C23: controler l'usure du tapis et remplacer les portions usées ou maillons cassés | D23: 120
B24: =+B23+1 -> 17 | C24: controler la tenson des tapis et ajuster au besoin | D24: 60
B25: =B24+1 -> 18
B26: =B25+1 -> 19
B27: =+B26+1 -> 20
B28: =B27+1 -> 21
B29: =B28+1 -> 22
B30: =+B29+1 -> 23
B31: =B30+1 -> 24
B32: =B31+1 -> 25
B33: =+B32+1 -> 26
B34: =B33+1 -> 27
B35: =B34+1 -> 28
B36: =+B35+1 -> 29
B37: =B36+1 -> 30
B38: Commentaire | D38: Nom et Visa Intervenants | G38: Nom et Visa Responsables

Sheet Line & frequency
B1: Line | C1: CHAINE 4
B2: Frequency | C2: HEBDOMADAIRE
B3: Date | C3: 44273 | G3: =+'Line & frequency'!C3 -> 44273

Sheet Cooling towers
B3: CHECKLIST ELECTRIQUE | F3: Date:
C4: Cooling towers | D4: LIGNE 6 | F4: =+'Line & frequency'!C2 -> HEBDOMADAIRE
D5: FAIT?
B6: N° | C6: DESCRIPTION DES TACHES | D6: OUI | E6: NON | F6: REMARQUES (MATERIEL + PIECES)
B7: 1 | C7: Contrôler visuellement l'etat des moteurs
B8: =B7+1 -> 2 | C8: controler l'etat des chemins de câble
B9: =+B8+1 -> 3 | C9: controler l'etat des câbles
B10: 4 | C10: Controler la continuité des sectionneurs
B11: 5 | C11: Controler les enroulements des moteurs
D14: % arret avant mtce | E14: % arret aprés mtce
B16: Commentaire | F16: Nom et Visa Responsables

Sheet FBI
B3: CHECKLIST ELECTRIQUE | F3: Date:
C4: FBI | D4: LIGNE 6 | F4: =+'Line & frequency'!C2 -> HEBDOMADAIRE
D5: FAIT?
B6: N° | C6: DESCRIPTION DES TACHES | D6: OUI | E6: NON | F6: REMARQUES (MATERIEL + PIECES)
B7: 1 | C7: controler l'état des buses d'eau du brumisateur
B8: =B7+1 -> 2 | C8: controler l'etat des trigger
B9: =+B8+1 -> 3 | C9: controler la pression d'air sur le manometre des ejecteurs
B10: =B9+1 -> 4 | C10: verifier le guidage des bouteille à l'entrée et à la sortie
B11: =B10+1 -> 5 | C11: controler l'etat des vitres antireflex des paroies
B12: =+B11+1 -> 6 | C12: nettoyer la surface exterieure de la machine
B13: =B12+1 -> 7 | C13: vérifier l'etat du vérins d'éjection
B14: =B13+1 -> 8 | C14: Controler les fixation la connection des capteurs
B15: =+B14+1 -> 9 | C15: Souffler l'armoire électrique
D17: % arret avant mtce | E17: % arret aprés mtce
B19: Commentaire | F19: Nom et Visa Responsables

Sheet Video Jet
B3: CHECKLIST ELECTRIQUE | F3: Date:
C4: DATEUSE | D4: LIGNE 6 | F4: =+'Line & frequency'!C2 -> HEBDOMADAIRE
D5: FAIT?
B6: N° | C6: DESCRIPTION DES TACHES | D6: OUI | E6: NON | F6: REMARQUES (MATERIEL + PIECES)
B7: 1 | C7: Nettoyer la machine
B8: 2 | C8: Controler tous les capteurs
B9: 3 | C9: Vérifier l'état des filtres et nettoyer
B10: 4 | C10: Contrôler les fuites sur le tuyau d'aspiration
D12: % arret avant mtce | E12: % arret aprés mtce
B14: Commentaire | F14: Nom et Visa Responsables
