Workbook

Sheet AF Ccompressor
B3: CHECKLIST MECANIQUE | G3: Date:
C4: AF COMPRESSOR | D4: New PET line | G4: =+'Line & frequency'!C2 -> HEBDOMADAIRE
E6: FAIT?
B7: N° | C7: DESCRIPTION DES TACHES | D7: Durée | E7: OUI | F7: NON | G7: REMARQUES (MATERIEL + PIECES)
B8: 1 | C8: Contrôler le système de refroidissement d'eau
B9: 2 | C9: Contrôler et/ou nettoyer le système de refroidissement du sécheur
B10: 3 | C10: Controler le filtre d'huile et nettoyer si besoin
B11: 4 | C11: Controler l'état du filtre d'air d'alimentation sur le verre indicateur et nettoyer si besoin
B12: 5 | C12: Purger le filtre d'air à la sortie du sécheur
B13: 6 | C13: Opérez le commutateur TEST au purgeur automatique
B14: 7 | C14: Contrôler le bon fonctionnement de l'élimination du condensat
B15: 8 | C15: Nettoyer le Air dryer
B16: 9 | C16: Controler l'état des courroies
B17: 10 | C17: Nettoyer les moteurs
B18: 11 | C18: Tester la machine à la fin de la maintenance
B19: 12
B20: 13
B21: 14
B22: Commentaire | D22: Nom et Visa Intervenants | G22: Nom et Visa Responsables
K36: +

Sheet Blomax
B3: CHECKLIST MECANIQUE | G3: Date:
C4: BLOMAX | D4: New PET line | G4: =+'Line & frequency'!C2 -> HEBDOMADAIRE
E6: FAIT?
B7: N° | C7: DESCRIPTION DES TACHES | D7: Durée | E7: OUI | F7: NON | G7: REMARQUES (MATERIEL + PIECES)
B8: 1 | C8: Controler l'état de la roue d'expulsion des preformes
B9: 2 | C9: Nettoyer les orifices de ventilation
B10: 3 | C10: Contrôler la céramique réflectrice du Module de chauffe - Four linéaire
B11: 4 | C11: Nettoyer la cuve de récupération du Module de chauffe
B12: 5 | C12: Nettoyer les surfaces de guidage du Module de transfert
B13: 6 | C13: Nettoyer les surfaces de guidage de Détection de fonds des bouteilles
B14: 7 | C14: Contrôler la fluidité du rotor du Module de soufflage
B15: 8 | C15: Controler l'état la Roue de soufflage
B16: 9 | C16: Controler le Dispositif d'étirage
B17: 10 | C17: Controler l'état des Chariots d'étirage et nettoyer
B18: 11 | C18: Verifier la presence de graisse sur le rotor du Module de soufflage
B19: 12 | C19: Nettoyer Roue de soufflage
... B35: 28 | C35: Controler le serrage des pinces de maintien des mandrins
B36: 29 | C36: Controler les chemises (bagues) des bielles de la roue de tete | K36: +
B37: 30 | C37: Verifier l'état des chemises des bielles de la roue de tete
B38: 31 | C38: Controler les tiges de mandrins
B39: 32 | C39: contrôler les axes de support de préhension
B40: 33 | C40: Controler l'état des Blindeurs et les nettoyer
B41: 34 | C41: Nettoyer la paroi d'air
B42: 35 | C42: Controler le serrage des raccords enfichables du circuit de refroidissement des portes moules
B43: 36 | C43: Contrôler la fuite d'eau sur le distributeur rotatif et les flexibles
B44: 37 | C44: Contrôler visuellement l'état des roulements et des flexibles (signaler toute anomalie)
B45: 38 | C45: Tester la machine à la fin de la maintenance
B46: Commentaire | D46: Nom et Visa Intervenants | G46: Nom et Visa Responsables
B47: Roulements des extracteurs du chiller remplacés le 21/01/2025

Sheet Soutireuse  
B3: CHECKLIST MECANIQUE | G3: Date:
C4: SOUTIREUSE | D4: New PET line | G4: =+'Line & frequency'!C2 -> HEBDOMADAIRE
E6: FAIT?
B7: N° | C7: DESCRIPTION DES TACHES | D7: Durée | E7: OUI | F7: NON | G7: REMARQUES (MATERIEL + PIECES)
B8: 1 | C8: Nettoyer la salle blanche
B9: =B8+1 -> 2 | C9: Vérifier l'encrassement du préfiltre sur le couvercle
B10: =+B9+1 -> 3 | C10: Vérifier l'encrassement et la sécheresse du filtre principal (filtre HEPA)
B11: =+B10+1 -> 4 | C11: Vérifier la différence de pression du filtre à air sur le couvercle
B12: =+B11+1 -> 5 | C12: Vérifier la propreté de l'air dans la salle.
B13: =+B12+1 -> 6 | C13: Contrôler les fuites sur les groupes de soupapes.
B14: =+B13+1 -> 7 | C14: Contrôler les orifices de décharge sur le passage rotatif
B15: =+B14+1 -> 8 | C15: Contrôler l'état et la lisibilité des panneaux.
B16: =+B15+1 -> 9 | C16: Contrôler l'étanchéité des réducteurs.
B17: =+B16+1 -> 10 | C17: Nettoyer le couvercle de la salle blanche de l'intérieur.
B18: =+B17+1 -> 11 | C18: Souffler les pré-filtres
B19: 12 | C19: Controler l'état des filtre d'eau et d'air du product maniford et nettoyer si sale
B20: =+B19+1 -> 13 | C20: controler les pinces des étoiles et remplacer si neccessaire
B21: =+B20+1 -> 14 | C21: Controler les injecteurs d'eau et d'air et déboucher si neccessaire
B22: =+B21+1 -> 15 | C22: Controler les circlipses des robinets et redresser si neccessaire
B23: =+B22+1 -> 16 | C23: Controler les serrages des robinets
B24: =+B23+1 -> 17 | C24: controler manuellement le circuit de graissage
B25: =+B24+1 -> 18 | C25: Controler l'état des tuyaux de compression et decompression
B26: 19 | C26: Controler l'état des supports de bouteilles sur l'étoile centrale
B27: 20 | C27: Controler l'état du Slip ring et envoyer une photo dans le groupe de Line 6 maintenance
B28: =+B27+1 -> 21 | C28: Verifier que les points de refrence des tetes de scellage sont alignés à 18 pour les BG (si non, les aligner)
B29: 22 | C29: Tester manuellement l'ouverture et la fermeture des vannes
B30: 23 | C30: Ouvrir le capot de la roue centrale pour controler l'état du pignon et nettoyer l'excès de graisse
B31: 24 | C31: Tester la machine à la fin de la maintenance
B32: Commentaire | D32: Nom et Visa Intervenants | G32: Nom et Visa Responsables
K36: +

Sheet Gassnerr
B3: CHECKLIST MECANIQUE | G3: Date:
C4: GASSNER (BOUCHEUSE) | D4: New PET line | G4: =+'Line & frequency'!C2 -> HEBDOMADAIRE
E6: FAIT?
B7: N° | C7: DESCRIPTION DES TACHES | D7: Durée | E7: OUI | F7: NON | G7: REMARQUES (MATERIEL + PIECES)
B8: 1 | C8: Nettoyer le récipient d'alimentation en bouchons
B9: 2 | C9: Nettoyer le canal à bouchons.
B10: 3 | C10: Controler l'état des filtres d'air sur l'indicateur de salissure
B11: 4 | C11: Controler l'espacement du canal de bouchons
B12: 5 | C12: Controler l'état des joints des tetes de scellage
B13: 6 | C13: Controler l'état de transmission du système de distribution des bouchons
B14: 7 | C14: Verifier le serrage des galets
B15: 8 | C15: Verifier le couple sur les tetes de fermeture (la vis de marquage doit doit etre alignée avec le chiffre 14)
B16: 9 | C16: Controler l'état de tous les cone de serrage
B17: 10 | C17: Tester la machine à la fin de la maintenance
B18: Commentaire | D18: Nom et Visa Intervenants | G18: Nom et Visa Responsables
K36: +

Sheet Paramix
B3: CHECKLIST MECANIQUE | G3: Date:
C4: PARAMIX | D4: New PET line | G4: HEBDMADAIRE
E5: FAIT?
B6: N° | C6: DESCRIPTION DES TACHES | D6: Durée | E6: OUI | F6: NON | G6: REMARQUES (MATERIEL + PIECES)
B7: 1 | C7: Vérifier si le liquide s'échappe des raccords laitiers.
B8: =B7+1 -> 2 | C8: Nettoyer puis essuyer les surfaces et les sols.
B9: =+B8+1 -> 3 | C9: Vérifier la pression de l'entraînement des soupapes à disques et de régulation.
B10: =B9+1 -> 4 | C10: Vérifier le niveau de liquide dans le séparateur d'eau.
B11: =+B10+1 -> 5 | C11: Vérifier si les conduites pneumatiques sont endommagées
B12: =B11+1 -> 6 | C12: Vérifier que le manomètre installé fournit des valeurs de pression plausibles à des pressions connues
B13: =B12+1 -> 7 | C13: Vérifier si le silencieux est bouché.
B14: =+B13+1 -> 8 | C14: Vérifier si le tube de protection du silencieux est manquant ou relâché.
B15: =+B14+1 -> 9 | C15: Verifier les l'état des joints des vannes pneumatiques
B16: =+B15+1 -> 10 | C16: Nettoyer les moteurs
B17: =+B16+1 -> 11 | C17: Verifier si le liquide s'échappe sur les pompes (garnitures)
B18: =+B17+1 -> 12 | C18: Controler l'état du filtre du CO2 et nettoyer si sale
B19: =+B18+1 -> 13 | C19: Controler, tester l'ouverture et fermeture de toutes les vannes pneumatiques
B20: =+B19+1 -> 14 | C20: Nettoyer le radiateur de la pompe à vide
B21: =+B20+1 -> 15 | C21: Tester la machine à la fin de la maintenance
B22: Commentaire | D22: Nom et Visa Intervenants | G22: Nom et Visa Responsables
K36: +

Sheet CIP
B3: CHECKLIST MECANIQUE | G3: Date:
C4: CIP | D4: New PET line | G4: =+'Line & frequency'!C2 -> HEBDOMADAIRE
E5: FAIT?
B6: N° | C6: DESCRIPTION DES TACHES | D6: Durée | E6: OUI | F6: NON | G6: REMARQUES (MATERIEL + PIECES)
B7: 1 | C7: Vérifier si du liquide s'échappe des raccords laitiers.
B8: =B7+1 -> 2 | C8: Nettoyer puis essuyer les surfaces et les sols.
B9: =+B8+1 -> 3 | C9: Vérifier la pression de l'entraînement des soupapes à disques et de régulation.
B10: =B9+1 -> 4 | C10: Vérifier le niveau de liquide dans le séparateur d'eau.
B11: =B10+1 -> 5 | C11: Vérifier si les conduites pneumatiques sont endommagées.
B12: =B11+1 -> 6 | C12: Vérifier que le manomètre installé affiche des valeurs plausibles.
B13: =B12+1 -> 7 | C13: Verifier l'état des vannes pneumatiques
B14: =B13+1 -> 8 | C14: Nettoyer les moteurs
B15: =B14+1 -> 9 | C15: Verifier si le liquide s'échappe des pompes
B16: =B15+1 -> 10 | C16: Tester la machine à la fin de la maintenance
B17: =B16+1 -> 11
B18: =B17+1 -> 12
B19: Commentaire | D19: Nom et Visa Intervenants | G19: Nom et Visa Responsables
K36: +

Sheet Etiqueteuse
B3: CHECKLIST MECANIQUE | G3: Date:
C4: ETIQUETEUSE | D4: New PET line | G4: =+'Line & frequency'!C2 -> HEBDOMADAIRE
E6: FAIT?
B7: N° | C7: DESCRIPTION DES TACHES | D7: Durée | E7: OUI | F7: NON | G7: REMARQUES (MATERIEL + PIECES)
B8: 1 | C8: Vérifier et serrer toute les stations | D8: 15min
B9: 2 | C9: Controler les raccords et robinetteries de raccordement d'air | D9: 10min
B10: 3 | C10: Controler les flexibles d'air du tambour à vide et signaler toute anomalie | D10: 5min
B11: 4 | C11: Controler les flexibles d'air du rouleau de transfert et signaler toute anomalie | D11: 5min
B12: 5 | C12: Controler le flexible d'air de refoulement et signaler toute anomalie | D12: 5min
B13: 6 | C13: Nettoyer le banc à essai | D13: 10min
B14: 7 | C14: Mesurer l'usure et l'endommagement des bagues de centrage et des garnitures. (inf à 3mm) | D14: 20min
B15: 8 | C15: Vérifier le fonctionnement des composants de l'utilisation des étiquettes, | D15: 30min
B16: 9 | C16: Vérifier l'état du dispositif de brossage des étiquettes. | D16: 5min
B17: 10 | C17: Vérifier l'usure de la chaîne de transport et les barres de glissement | D17: 15min
B18: 11 | C18: Contrôler l'usure de la courroie d'entraînement | D18: 20min
B19: 12 | C19: Controler l'état des tetes de piston | D19: 15min
... B33: 26 | C33: Tester la machine à la fin de la maintenance | D33: 10min
B34: 27
B35: Commentaire | D35: Nom et Visa Intervenants | G35: Nom et Visa Responsables
K36: +

Sheet Kisters
B3: CHECKLIST MECANIQUE | G3: Date:
C4: KISTERS | D4: New PET line | G4: =+'Line & frequency'!C2 -> HEBDOMADAIRE
E6: FAIT?
B7: N° | C7: DESCRIPTION DES TACHES | D7: Durée | E7: OUI | F7: NON | G7: REMARQUES (MATERIEL + PIECES)
B8: 1 | C8: Contrôler le déroulement en ligne droite du Tapis de transport de film
B9: 2 | C9: Vérifier le fonctionnement de la Soufflerie à vide de la station de coupe de film,
B10: 3 | C10: Éliminer les encrassements et Vérifier l'absence de dommages visibles sur la machine
B11: 4 | C11: Contrôler le déroulement en ligne droite du tapis d'alimentation
B12: 5 | C12: Vérifier que les capots restent bien dans les positions finales supérieure et inférieure.
B13: 6 | C13: Vérifier la peinture à la recherche de détériorations.
B14: 7 | C14: Vérifier les liaisons par vis des pièces sollicitées et mobiles sur les Raccords vissés
B15: 8 | C15: Contrôler l'étanchéité des conduites pneumatiques
B16: 9 | C16: Vérifier l'absence de dommages visibles sur la Courroie d'entraînement
B17: 10 | C17: Éliminer les encrassements sur les Chaînes d'entraînement
B18: 11 | C18: Éliminer les salissures à l'aide d'un pinceau à poils durs sur les Tendeurs de chaîne (Contrôler la position et Vérifier le fonctionnemen
B19: 12 | C19: Vérifier si les chaînes et les roues à chaîne sont alignées (entrainement)
... B35: 28 | C35: Vérifier que la tension des Chaînes de groupage est correcte
B36: 29 | C36: Éliminer les encrassements sur les Supports de produits et Vérifier la presence de dommages visibles | K36: +
B37: 30 | C37: Éliminer les encrassements sur le Couteau de film et Retirer les résidus de film (Ne pas uti‐ liser d'outils durs !) et Vérifier l'absence de dommages visibles
B38: 31 | C38: Éliminer les encrassements sur Rouleaux en caoutchouc de la station de coupe de film Vérifier l'absence de dommages visibles et Vérifier l'absence d'abrasion et d'aspérités
B39: 32 | C39: Controler les Barres antistatiques
B40: 33 | C40: Éliminer les encrassements sur les Mandrins de prise de bobine de film et Vérifier l'absence de dommages visibles
B41: 34 | C41: Contrôler la chaîne à maillons ou à barres du Tunnel de rétraction et Éliminer les encrassements
B42: 35 | C42: Éliminer les encrassements sur les Rideaux du tunnel de rétraction
B43: 36 | C43: nettoyer les ventilenteurs de refroidissement à la sortie de machine
B44: 37 | C44: Controler l'état des barres de Fardelage
B45: 38 | C45: Controler le niveau d'huile dans le bac
B46: 39 | C46: Nettoyer les debris de film à la sortie du tunnel
B47: 40 | C47: Controler l'état de toutes les courroies
B48: 41 | C48: Nettoyer les débrits de film à la sortie du four
B49: 42 | C49: Tester la machine à la fin de maintenance
B51: Commentaire | D51: Nom et Visa Intervenants | G51: Nom et Visa Responsables
B52: Nb: tapis entrée four remplacé le 28/03/2024

Sheet Handle applicator
B3: CHECKLIST MECANIQUE | G3: Date:
C4: HANDLE APPLICATOR | D4: New PET line | G4: =+'Line & frequency'!C2 -> HEBDOMADAIRE
E6: FAIT?
B7: N° | C7: DESCRIPTION DES TACHES | D7: Durée | E7: OUI | F7: NON | G7: REMARQUES (MATERIEL + PIECES)
B8: 1 | C8: Éliminer les encrassements sur Interrupteur de sécurité et Vérifier le fonctionnement
B9: 2 | C9: Contrôler le déroulement en ligne droite du Tapis d'alimentation et tapis de convoyeur
B10: 3 | C10: Contrôler le bon fonctionnement des portes de protection
B11: 4 | C11: Vérifier la peinture à la recherche de détériorations
B12: 5 | C12: Vérifier les liaisons par vis des pièces sollicitées et mobiles (Raccords vissés)
B13: 6 | C13: Contrôler l'étanchéité des conduites pneumatiques
B14: 7 | C14: Nettoyer les Capteurs avec un chiffon doux et humide
B15: 8 | C15: Éliminer les encrassements sur les Guidages et transferts
B16: 9 | C16: Contrôler l'étanchéité des vérins et des soupapes
B17: 10 | C17: Vérifier le fonctionnement des Vérins pneumatiques et soupapes
B18: 11 | C18: Éliminer les encrassements sur les Tapis d'alimentation et tapis de convoyeur
B19: 12 | C19: Nettoyer les galets d'entraînement, les poulies de renvoi et les transferts à rouleaux des Tapis d'alimentation et tapis de convoyeur
... B29: 15 | C29: Tester la machine à la fin de la maintenance
B30: 16
B31: Commentaire | D31: Nom et Visa Intervenants | G31: Nom et Visa Responsables
K36: +

Sheet Convoyeurs
B3: CHECKLIST MECANIQUE | G3: Date:
C4: CONVOYEURS | D4: New PET line | G4: =+'Line & frequency'!C2 -> HEBDOMADAIRE
E6: FAIT?
B7: N° | C7: DESCRIPTION DES TACHES | D7: Durée | E7: OUI | F7: NON | G7: REMARQUES (MATERIEL + PIECES)
B8: 1 | C8: Nettoyer les rampes latérales
B9: 2 | C9: Nettoyer les rampes automatiques
B10: 3 | C10: Nettoyer les rampes de renvoi
B11: 4 | C11: Contrôler l'étanchéité des conduites de lubrification
B12: 5 | C12: Éliminer les encrassements sur les Conduites de lubrification
B13: 6 | C13: Controler la tension des chaines des convoyeurs et reduire si neccessaire
B14: 7 | C14: Controler la tension des chaines motrices au niveau des combiners et reduire si neccessaire
B15: 8 | C15: Tester les convoyeurs à la fin de la maintenance
B16: 9
B17: 10
B18: Commentaire | D18: Nom et Visa Intervenants | G18: Nom et Visa Responsables
K36: +

Sheet Cvyr Btles
B3: CHECKLIST MECANIQUE | G3: Date
C4: PALETTISEUR | D4: =+'Line & frequency'!C1 -> CHAINE 4 | G4: =+'Line & frequency'!C2 -> HEBDOMADAIRE
E6: FAIT?
B7: N° | C7: DESCRIPTION DES TACHES | D7: Durée | E7: OUI | F7: NON | G7: REMARQUES (MATERIEL + PIECES)
B8: 1
B9: =B8+1 -> 2
B10: =+B9+1 -> 3
B11: =B10+1 -> 4
B12: =+B11+1 -> 5
B13: =B12+1 -> 6
B14: =+B13+1 -> 7
B15: =B14+1 -> 8
B16: =+B15+1 -> 9
B17: =B16+1 -> 10
B18: =+B17+1 -> 11
B19: =B18+1 -> 12
B20: =+B19+1 -> 13
B21: =B20+1 -> 14
B22: =+B21+1 -> 15
B23: =B22+1 -> 16
B24: =+B23+1 -> 17
B25: =B24+1 -> 18
B26: =+B25+1 -> 19
B27: =B26+1 -> 20
B28: =+B27+1 -> 21
B29: =B28+1 -> 22
B30: =+B29+1 -> 23
B31: =B30+1 -> 24
B32: =+B31+1 -> 25
B33: =B32+1 -> 26
B34: =+B33+1 -> 27
B35: =B34+1 -> 28
B36: =+B35+1 -> 29
B37: =B36+1 -> 30
B38: =+B37+1 -> 31
B39: =B38+1 -> 32
B40: =+B39+1 -> 33
B41: =B40+1 -> 34
B42: =+B41+1 -> 35
B43: =B42+1 -> 36
...

Sheet CC C1
B3: CHECKLIST MECANIQUE | G3: Date
C4: CONVOYEURS CASIERS C1 | D4: =+'Line & frequency'!C1 -> CHAINE 4 | G4: =+'Line & frequency'!C2 -> HEBDOMADAIRE
E6: FAIT?
B7: N° | C7: DESCRIPTION DES TACHES | D7: Durée | E7: OUI | F7: NON | G7: REMARQUES (MATERIEL + PIECES)
B8: 1 | C8: controler l'arret d'huile et le remplacé au besoin. Aucune fuite d'huile n'est acceptable. | D8: 10
B9: =B8+1 -> 2 | C9: controler la fixation du réducteur sur le convoyeur et corriger si necessaire. | D9: 30
B10: =+B9+1 -> 3 | C10: controler l'usure du pignon et le remplacé au besoin. Aucun glissement n'est acceptable. | D10: 30
B11: =B10+1 -> 4 | C11: controler l'alignement et la fixation du pignon de l'axe moteur et remedier au besoin. | D11: 30
B12: =+B11+1 -> 5 | C12: controler l'usure de la roue libre et la remplacée au besoin. Aucun glissement n'est acceptable. | D12: 30
B13: =B12+1 -> 6 | C13: controler l'alignement et la fixation de la roue libre et remedier au problème. | D13: 30
B14: =+B13+1 -> 7 | C14: controler l'usure de la clavette et la rainure et reparer au besoin | D14: 30
B15: =B14+1 -> 8 | C15: controler l'état des glissières et remplacer les au besoin | D15: 25
B16: =+B15+1 -> 9 | C16: controler l'arret d'huile et le remplacé au besoin. Aucune fuite d'huile n'est acceptable. | D16: 10
B17: =B16+1 -> 10 | C17: controler l'usure des roulements et paliers de l'axe moteur et remplacer si necessaire. | D17: 30
B18: =+B17+1 -> 11 | C18: controler l'usure du pignon et le remplacé au besoin. Aucun glissement n'est acceptable. | D18: 30
B19: =B18+1 -> 12 | C19: controler l'alignement et la fixation du pignon de l'axe moteur et remedier au besoin. | D19: 30
B20: =+B19+1 -> 13 | C20: controler l'usure de la clavette et la rainure et reparer au besoin | D20: 30
B21: =B20+1 -> 14 | C21: controler l'usure des roulements et paliers de l'axe moteur et remplacer si necessaire. | D21: 30
B22: =+B21+1 -> 15 | C22: controler l'usure de la roue libre et la remplacée au besoin. Aucun glissement n'est acceptable. | D22: 30
B23: =B22+1 -> 16 | C23: controler l'alignement et la fixation de la roue libre et remedier au problème. | D23: 30
B24: =+B23+1 -> 17 | C24: controler l'usure de la clavette et la rainure et reparer au besoin | D24: 30
B25: =B24+1 -> 18 | C25: controler l'arret d'huile et le remplacé au besoin. Aucune fuite d'huile n'est acceptable. | D25: 10
B26: =+B25+1 -> 19 | C26: controler la fixation du réducteur sur le convoyeur et corriger si necessaire. | D26: 30
B27: =B26+1 -> 20 | C27: controler l'usure des roulements et paliers de l'axe moteur et remplacer si necessaire. | D27: 30
B28: =+B27+1 -> 21 | C28: controler l'usure du pignon et le remplacé au besoin. Aucun glissement n'est acceptable. | D28: 30
B29: =B28+1 -> 22 | C29: controler l'alignement et la fixation du pignon de l'axe moteur et remedier au besoin. | D29: 30
B30: =+B29+1 -> 23 | C30: controler l'usure de la clavette et la rainure et reparer au besoin | D30: 30
B31: =B30+1 -> 24 | C31: controler l'usure des roulements et paliers de l'axe moteur et remplacer si necessaire. | D31: 30
B32: =+B31+1 -> 25 | C32: controler l'usure de la clavette et la rainure et reparer au besoin | D32: 30
B33: =B32+1 -> 26 | C33: controler l'état des glissières et remplacer les au besoin | D33: 25
B34: =+B33+1 -> 27 | C34: controler l'arret d'huile et le remplacé au besoin. Aucune fuite d'huile n'est acceptable. | D34: 10
B35: =B34+1 -> 28 | C35: controler la fixation du réducteur sur le convoyeur et corriger si necessaire. | D35: 30
B36: =+B35+1 -> 29 | C36: controler l'usure des roulements et paliers de l'axe moteur et remplacer si necessaire. | D36: 30
B37: =B36+1 -> 30 | C37: controler l'usure des pignons et les remplacés au besoin. Aucun glissement n'est acceptable. | D37: 30
B38: =+B37+1 -> 31 | C38: controler l'alignement et la fixation du pignon de l'axe moteur et remedier au besoin. | D38: 30
B39: =B38+1 -> 32 | C39: controler l'usure de la clavette et la rainure et reparer au besoin | D39: 30
B40: =+B39+1 -> 33 | C40: controler l'état des glissières et remplacer les au besoin | D40: 25
B41: =B40+1 -> 34 | C41: controler l'usure du tapis et remplacer les portions usées ou maillons cassés | D41: 120
B42: =+B41+1 -> 35 | C42: controler la tenson des tapis et ajuster au besoin | D42: 60
B43: =B42+1 -> 36 | C43: controler l'arret d'huile et le remplacé au besoin. Aucune fuite d'huile n'est acceptable. | D43: 10
...

Sheet CC C2
B3: CHECKLIST MECANIQUE | G3: Date
C4: CONVOYEURS CASIERS C2 | D4: =+'Line & frequency'!C1 -> CHAINE 4 | G4: =+'Line & frequency'!C2 -> HEBDOMADAIRE
E6: FAIT?
B7: N° | C7: DESCRIPTION DES TACHES | D7: Durée | E7: OUI | F7: NON | G7: REMARQUES (MATERIEL + PIECES)
B8: 1 | C8: controler l'arret d'huile et le remplacé au besoin. Aucune fuite d'huile n'est acceptable. | D8: 10
B9: =B8+1 -> 2 | C9: controler la fixation du réducteur sur le convoyeur et corriger si necessaire. | D9: 30
B10: =+B9+1 -> 3 | C10: controler l'usure du pignon et le remplacé au besoin. Aucun glissement n'est acceptable. | D10: 30
B11: =B10+1 -> 4 | C11: controler l'alignement et la fixation du pignon de l'axe moteur et remedier au besoin. | D11: 30
B12: =+B11+1 -> 5 | C12: controler l'usure de la roue libre et la remplacée au besoin. Aucun glissement n'est acceptable. | D12: 30
B13: =B12+1 -> 6 | C13: controler l'alignement et la fixation de la roue libre et remedier au problème. | D13: 30
B14: =+B13+1 -> 7 | C14: controler l'usure de la clavette et la rainure et reparer au besoin | D14: 30
B15: =B14+1 -> 8 | C15: controler l'état des glissières et remplacer les au besoin | D15: 25
B16: =+B15+1 -> 9 | C16: controler l'arret d'huile et le remplacé au besoin. Aucune fuite d'huile n'est acceptable. | D16: 10
B17: =B16+1 -> 10 | C17: controler l'usure des roulements et paliers de l'axe moteur et remplacer si necessaire. | D17: 30
B18: =+B17+1 -> 11 | C18: controler l'usure du pignon et le remplacé au besoin. Aucun glissement n'est acceptable. | D18: 30
B19: =B18+1 -> 12 | C19: controler l'alignement et la fixation du pignon de l'axe moteur et remedier au besoin. | D19: 30
B20: =+B19+1 -> 13 | C20: controler l'usure de la clavette et la rainure et reparer au besoin | D20: 30
B21: =B20+1 -> 14 | C21: controler l'usure des roulements et paliers de l'axe moteur et remplacer si necessaire. | D21: 30
B22: =+B21+1 -> 15 | C22: controler l'usure de la roue libre et la remplacée au besoin. Aucun glissement n'est acceptable. | D22: 30
B23: =B22+1 -> 16 | C23: controler l'alignement et la fixation de la roue libre et remedier au problème. | D23: 30
B24: =+B23+1 -> 17 | C24: controler l'usure de la clavette et la rainure et reparer au besoin | D24: 30
B25: =B24+1 -> 18 | C25: controler l'arret d'huile et le remplacé au besoin. Aucune fuite d'huile n'est acceptable. | D25: 10
B26: =+B25+1 -> 19 | C26: controler la fixation du réducteur sur le convoyeur et corriger si necessaire. | D26: 30
B27: =B26+1 -> 20 | C27: controler l'usure des roulements et paliers de l'axe moteur et remplacer si necessaire. | D27: 30
B28: =+B27+1 -> 21 | C28: controler l'usure des pignons et les remplacés au besoin. Aucun glissement n'est acceptable. | D28: 30
B29: =B28+1 -> 22 | C29: controler l'alignement et la fixation du pignon de l'axe moteur et remedier au besoin. | D29: 30
B30: =+B29+1 -> 23 | C30: controler l'usure de la clavette et la rainure et reparer au besoin | D30: 30
B31: =B30+1 -> 24 | C31: controler l'état des glissières et remplacer les au besoin | D31: 25
B32: =+B31+1 -> 25 | C32: controler l'usure du tapis et remplacer les portions usées ou maillons cassés | D32: 120
B33: =B32+1 -> 26 | C33: controler la tenson des tapis et ajuster au besoin | D33: 60
B34: =+B33+1 -> 27
B35: =B34+1 -> 28
B36: =+B35+1 -> 29
B37: =B36+1 -> 30
B38: =+B37+1 -> 31
B39: =B38+1 -> 32
B40: =+B39+1 -> 33
B41: =B40+1 -> 34
B42: =+B41+1 -> 35
B43: =B42+1 -> 36
...

Sheet CC C3
B3: CHECKLIST MECANIQUE | G3: Date
C4: CONVOYEURS CASIERS C3 | D4: =+'Line & frequency'!C1 -> CHAINE 4 | G4: =+'Line & frequency'!C2 -> HEBDOMADAIRE
E6: FAIT?
B7: N° | C7: DESCRIPTION DES TACHES | D7: Durée | E7: OUI | F7: NON | G7: REMARQUES (MATERIEL + PIECES)
B8: 1 | C8: controler l'arret d'huile et le remplacé au besoin. Aucune fuite d'huile n'est acceptable. | D8: 10
B9: =B8+1 -> 2 | C9: controler la fixation du réducteur sur le convoyeur et corriger si necessaire. | D9: 30
B10: =+B9+1 -> 3 | C10: controler l'usure du pignon et le remplacé au besoin. Aucun glissement n'est acceptable. | D10: 30
B11: =B10+1 -> 4 | C11: controler l'alignement et la fixation du pignon de l'axe moteur et remedier au besoin. | D11: 30
B12: =+B11+1 -> 5 | C12: controler l'usure de la roue libre et la remplacée au besoin. Aucun glissement n'est acceptable. | D12: 30
B13: =B12+1 -> 6 | C13: controler l'alignement et la fixation de la roue libre et remedier au problème. | D13: 30
B14: =+B13+1 -> 7 | C14: controler l'usure de la clavette et la rainure et reparer au besoin | D14: 30
B15: =B14+1 -> 8 | C15: controler l'état des glissières et remplacer les au besoin | D15: 25
B16: =+B15+1 -> 9 | C16: controler l'arret d'huile et le remplacé au besoin. Aucune fuite d'huile n'est acceptable. | D16: 10
B17: =B16+1 -> 10 | C17: controler l'usure des roulements et paliers de l'axe moteur et remplacer si necessaire. | D17: 30
B18: =+B17+1 -> 11 | C18: controler l'usure du pignon et le remplacé au besoin. Aucun glissement n'est acceptable. | D18: 30
B19: =B18+1 -> 12 | C19: controler l'alignement et la fixation du pignon de l'axe moteur et remedier au besoin. | D19: 30
B20: =+B19+1 -> 13 | C20: controler l'usure de la clavette et la rainure et reparer au besoin | D20: 30
B21: =B20+1 -> 14 | C21: controler l'usure des roulements et paliers de l'axe moteur et remplacer si necessaire. | D21: 30
B22: =+B21+1 -> 15 | C22: controler l'usure de la roue libre et la remplacée au besoin. Aucun glissement n'est acceptable. | D22: 30
B23: =B22+1 -> 16 | C23: controler l'alignement et la fixation de la roue libre et remedier au problème. | D23: 30
B24: =+B23+1 -> 17 | C24: controler l'usure de la clavette et la rainure et reparer au besoin | D24: 30
B25: =B24+1 -> 18
B26: =+B25+1 -> 19
B27: =B26+1 -> 20
B28: =+B27+1 -> 21
B29: =B28+1 -> 22
B30: =+B29+1 -> 23
B31: =B30+1 -> 24
B32: =+B31+1 -> 25
B33: Commentaire | D33: Nom et Visa Intervenants | G33: Nom et Visa Responsables

Sheet CC C4
B3: CHECKLIST MECANIQUE | G3: Date
C4: CONVOYEURS CASIERS C4 | D4: =+'Line & frequency'!C1 -> CHAINE 4 | G4: =+'Line & frequency'!C2 -> HEBDOMADAIRE
E6: FAIT?
B7: N° | C7: DESCRIPTION DES TACHES | D7: Durée | E7: OUI | F7: NON | G7: REMARQUES (MATERIEL + PIECES)
B8: 1 | C8: controler l'arret d'huile et le remplacé au besoin. Aucune fuite d'huile n'est acceptable. | D8: 10
B9: =B8+1 -> 2 | C9: controler la fixation du réducteur sur le convoyeur et corriger si necessaire. | D9: 30
B10: =+B9+1 -> 3 | C10: controler l'usure du pignon et le remplacé au besoin. Aucun glissement n'est acceptable. | D10: 30
B11: =B10+1 -> 4 | C11: controler l'alignement et la fixation du pignon de l'axe moteur et remedier au besoin. | D11: 30
B12: =+B11+1 -> 5 | C12: controler l'usure de la roue libre et la remplacée au besoin. Aucun glissement n'est acceptable. | D12: 30
B13: =B12+1 -> 6 | C13: controler l'alignement et la fixation de la roue libre et remedier au problème. | D13: 30
B14: =+B13+1 -> 7 | C14: controler l'usure de la clavette et la rainure et reparer au besoin | D14: 30
B15: =B14+1 -> 8 | C15: controler l'état des glissières et remplacer les au besoin | D15: 25
B16: =+B15+1 -> 9 | C16: controler l'arret d'huile et le remplacé au besoin. Aucune fuite d'huile n'est acceptable. | D16: 10
B17: =B16+1 -> 10 | C17: controler l'usure des roulements et paliers de l'axe moteur et remplacer si necessaire. | D17: 30
B18: =+B17+1 -> 11 | C18: controler l'usure du pignon et le remplacé au besoin. Aucun glissement n'est acceptable. | D18: 30
B19: =B18+1 -> 12 | C19: controler l'alignement et la fixation du pignon de l'axe moteur et remedier au besoin. | D19: 30
B20: =+B19+1 -> 13 | C20: controler l'usure de la clavette et la rainure et reparer au besoin | D20: 30
B21: =B20+1 -> 14 | C21: controler l'usure des roulements et paliers de l'axe moteur et remplacer si necessaire. | D21: 30
B22: =+B21+1 -> 15 | C22: controler l'usure de la roue libre et la remplacée au besoin. Aucun glissement n'est acceptable. | D22: 30
B23: =B22+1 -> 16 | C23: controler l'alignement et la fixation de la roue libre et remedier au problème. | D23: 30
B24: =+B23+1 -> 17 | C24: controler l'usure de la clavette et la rainure et reparer au besoin | D24: 30
B25: =B24+1 -> 18 | C25: controler l'arret d'huile et le remplacé au besoin. Aucune fuite d'huile n'est acceptable. | D25: 10
B26: =B25+1 -> 19 | C26: controler la fixation du réducteur sur le convoyeur et corriger si necessaire. | D26: 30
B27: =+B26+1 -> 20 | C27: controler l'usure des roulements et paliers de l'axe moteur et remplacer si necessaire. | D27: 30
B28: =B27+1 -> 21 | C28: controler l'usure du pignon et le remplacé au besoin. Aucun glissement n'est acceptable. | D28: 30
B29: =B28+1 -> 22 | C29: controler l'alignement et la fixation du pignon de l'axe moteur et remedier au besoin. | D29: 30
B30: =+B29+1 -> 23 | C30: controler l'usure de la clavette et la rainure et reparer au besoin | D30: 30
B31: =B30+1 -> 24 | C31: controler l'usure des roulements et paliers de l'axe moteur et remplacer si necessaire. | D31: 30
B32: =B31+1 -> 25 | C32: controler l'usure de la clavette et la rainure et reparer au besoin | D32: 30
B33: =+B32+1 -> 26 | C33: controler l'état des glissières et remplacer les au besoin | D33: 25
B34: =B33+1 -> 27
B35: =B34+1 -> 28
B36: =+B35+1 -> 29
B37: =B36+1 -> 30
B38: Commentaire | D38: Nom et Visa Intervenants | G38: Nom et Visa Responsables

Sheet CC C5
B3: CHECKLIST MECANIQUE | G3: Date
C4: CONVOYEURS CASIERS C5 | D4: =+'Line & frequency'!C1 -> CHAINE 4 | G4: =+'Line & frequency'!C2 -> HEBDOMADAIRE
E6: FAIT?
B7: N° | C7: DESCRIPTION DES TACHES | D7: Durée | E7: OUI | F7: NON | G7: REMARQUES (MATERIEL + PIECES)
B8: 1 | C8: controler l'arret d'huile et le remplacé au besoin. Aucune fuite d'huile n'est acceptable. | D8: 10
B9: =B8+1 -> 2 | C9: controler la fixation du réducteur sur le convoyeur et corriger si necessaire. | D9: 30
B10: =+B9+1 -> 3 | C10: controler l'usure du pignon et le remplacé au besoin. Aucun glissement n'est acceptable. | D10: 30
B11: =B10+1 -> 4 | C11: controler l'alignement et la fixation du pignon de l'axe moteur et remedier au besoin. | D11: 30
B12: =+B11+1 -> 5 | C12: controler l'usure de la roue libre et la remplacée au besoin. Aucun glissement n'est acceptable. | D12: 30
B13: =B12+1 -> 6 | C13: controler l'alignement et la fixation de la roue libre et remedier au problème. | D13: 30
B14: =+B13+1 -> 7 | C14: controler l'usure de la clavette et la rainure et reparer au besoin | D14: 30
B15: =B14+1 -> 8 | C15: controler l'état des glissières et remplacer les au besoin | D15: 25
B16: =+B15+1 -> 9 | C16: controler l'arret d'huile et le remplacé au besoin. Aucune fuite d'huile n'est acceptable. | D16: 10
B17: =B16+1 -> 10 | C17: controler l'usure des roulements et paliers de l'axe moteur et remplacer si necessaire. | D17: 30
B18: =+B17+1 -> 11 | C18: controler l'usure du pignon et le remplacé au besoin. Aucun glissement n'est acceptable. | D18: 30
B19: =B18+1 -> 12 | C19: controler l'alignement et la fixation du pignon de l'axe moteur et remedier au besoin. | D19: 30
B20: =+B19+1 -> 13 | C20: controler l'usure de la clavette et la rainure et reparer au besoin | D20: 30
B21: =B20+1 -> 14 | C21: controler l'usure des roulements et paliers de l'axe moteur et remplacer si necessaire. | D21: 30
B22: =+B21+1 -> 15 | C22: controler l'usure de la roue libre et la remplacée au besoin. Aucun glissement n'est acceptable. | D22: 30
B23: =B22+1 -> 16 | C23: controler l'alignement et la fixation de la roue libre et remedier au problème. | D23: 30
B24: =+B23+1 -> 17 | C24: controler l'usure de la clavette et la rainure et reparer au besoin | D24: 30
B25: =B24+1 -> 18
B26: =B25+1 -> 19
B27: =+B26+1 -> 20
B28: =B27+1 -> 21
B29: =B28+1 -> 22
B30: =+B29+1 -> 23
B31: =B30+1 -> 24
B32: =B31+1 -> 25
B33: =+B32+1 -> 26
B34: =B33+1 -> 27
B35: =B34+1 -> 28
B36: =+B35+1 -> 29
B37: =B36+1 -> 30
B38: Commentaire | D38: Nom et Visa Intervenants | G38: Nom et Visa Responsables

Sheet CC C6
B3: CHECKLIST MECANIQUE | G3: Date
C4: CONVOYEURS CASIERS C6 | D4: =+'Line & frequency'!C1 -> CHAINE 4 | G4: =+'Line & frequency'!C2 -> HEBDOMADAIRE
E6: FAIT?
B7: N° | C7: DESCRIPTION DES TACHES | D7: Durée | E7: OUI | F7: NON | G7: REMARQUES (MATERIEL + PIECES)
B8: 1 | C8: controler l'arret d'huile et le remplacé au besoin. Aucune fuite d'huile n'est acceptable. | D8: 10
B9: =B8+1 -> 2 | C9: controler la fixation du réducteur sur le convoyeur et corriger si necessaire. | D9: 30
B10: =+B9+1 -> 3 | C10: controler l'usure du pignon et le remplacé au besoin. Aucun glissement n'est acceptable. | D10: 30
B11: =B10+1 -> 4 | C11: controler l'alignement et la fixation du pignon de l'axe moteur et remedier au besoin. | D11: 30
B12: =+B11+1 -> 5 | C12: controler l'usure de la roue libre et la remplacée au besoin. Aucun glissement n'est acceptable. | D12: 30
B13: =B12+1 -> 6 | C13: controler l'alignement et la fixation de la roue libre et remedier au problème. | D13: 30
B14: =+B13+1 -> 7 | C14: controler l'usure de la clavette et la rainure et reparer au besoin | D14: 30
B15: =B14+1 -> 8 | C15: controler l'état des glissières et remplacer les au besoin | D15: 25
B16: =+B15+1 -> 9 | C16: controler l'arret d'huile et le remplacé au besoin. Aucune fuite d'huile n'est acceptable. | D16: 10
B17: =B16+1 -> 10 | C17: controler l'usure des roulements et paliers de l'axe moteur et remplacer si necessaire. | D17: 30
B18: =+B17+1 -> 11 | C18: controler l'usure du pignon et le remplacé au besoin. Aucun glissement n'est acceptable. | D18: 30
B19: =B18+1 -> 12 | C19: controler l'alignement et la fixation du pignon de l'axe moteur et remedier au besoin. | D19: 30
B20: =+B19+1 -> 13 | C20: controler l'usure de la clavette et la rainure et reparer au besoin | D20: 30
B21: =B20+1 -> 14 | C21: controler l'usure des roulements et paliers de l'axe moteur et remplacer si necessaire. | D21: 30
B22: =+B21+1 -> 15 | C22: controler l'usure de la roue libre et la remplacée au besoin. Aucun glissement n'est acceptable. | D22: 30
B23: =B22+1 -> 16 | C23: controler l'alignement et la fixation de la roue libre et remedier au problème. | D23: 30
B24: =+B23+1 -> 17 | C24: controler l'usure de la clavette et la rainure et reparer au besoin | D24: 30
B25: =B24+1 -> 18 | C25: controler l'arret d'huile et le remplacé au besoin. Aucune fuite d'huile n'est acceptable. | D25: 10
B26: =B25+1 -> 19 | C26: controler la fixation du réducteur sur le convoyeur et corriger si necessaire. | D26: 30
B27: =+B26+1 -> 20 | C27: controler l'usure des roulements et paliers de l'axe moteur et remplacer si necessaire. | D27: 30
B28: =B27+1 -> 21 | C28: controler l'usure des pignons et les remplacés au besoin. Aucun glissement n'est acceptable. | D28: 30
B29: =B28+1 -> 22 | C29: controler l'alignement et la fixation du pignon de l'axe moteur et remedier au besoin. | D29: 30
B30: =+B29+1 -> 23 | C30: controler l'usure de la clavette et la rainure et reparer au besoin | D30: 30
B31: =B30+1 -> 24 | C31: controler l'état des glissières et remplacer les au besoin | D31: 25
B32: =B31+1 -> 25 | C32: controler l'usure du tapis et remplacer les portions usées ou maillons cassés | D32: 120
B33: =+B32+1 -> 26 | C33: controler la tenson des tapis et ajuster au besoin | D33: 60
B34: =B33+1 -> 27
B35: =B34+1 -> 28
B36: =+B35+1 -> 29
B37: =B36+1 -> 30
B38: Commentaire | D38: Nom et Visa Intervenants | G38: Nom et Visa Responsables

Sheet CC C7
B3: CHECKLIST MECANIQUE | G3: Date
C4: CONVOYEURS CASIERS C7 | D4: =+'Line & frequency'!C1 -> CHAINE 4 | G4: =+'Line & frequency'!C2 -> HEBDOMADAIRE
E6: FAIT?
B7: N° | C7: DESCRIPTION DES TACHES | D7: Durée | E7: OUI | F7: NON | G7: REMARQUES (MATERIEL + PIECES)
B8: 1 | C8: controler l'arret d'huile et le remplacé au besoin. Aucune fuite d'huile n'est acceptable. | D8: 10
B9: =B8+1 -> 2 | C9: controler la fixation du réducteur sur le convoyeur et corriger si necessaire. | D9: 30
B10: =+B9+1 -> 3 | C10: controler l'usure du pignon et le remplacé au besoin. Aucun glissement n'est acceptable. | D10: 30
B11: =B10+1 -> 4 | C11: controler l'alignement et la fixation du pignon de l'axe moteur et remedier au besoin. | D11: 30
B12: =+B11+1 -> 5 | C12: controler l'usure de la roue libre et la remplacée au besoin. Aucun glissement n'est acceptable. | D12: 30
B13: =B12+1 -> 6 | C13: controler l'alignement et la fixation de la roue libre et remedier au problème. | D13: 30
B14: =+B13+1 -> 7 | C14: controler l'usure de la clavette et la rainure et reparer au besoin | D14: 30
B15: =B14+1 -> 8 | C15: controler l'état des glissières et remplacer les au besoin | D15: 25
B16: =+B15+1 -> 9 | C16: controler l'arret d'huile et le remplacé au besoin. Aucune fuite d'huile n'est acceptable. | D16: 10
B17: =B16+1 -> 10 | C17: controler l'usure des roulements et paliers de l'axe moteur et remplacer si necessaire. | D17: 30
B18: =+B17+1 -> 11 | C18: controler l'usure du pignon et le remplacé au besoin. Aucun glissement n'est acceptable. | D18: 30
B19: =B18+1 -> 12 | C19: controler l'alignement et la fixation du pignon de l'axe moteur et remedier au besoin. | D19: 30
B20: =+B19+1 -> 13 | C20: controler l'usure de la clavette et la rainure et reparer au besoin | D20: 30
B21: =B20+1 -> 14 | C21: controler l'usure des roulements et paliers de l'axe moteur et remplacer si necessaire. | D21: 30
B22: =+B21+1 -> 15 | C22: controler l'usure de la roue libre et la remplacée au besoin. Aucun glissement n'est acceptable. | D22: 30
B23: =B22+1 -> 16 | C23: controler l'alignement et la fixation de la roue libre et remedier au problème. | D23: 30
B24: =+B23+1 -> 17 | C24: controler l'usure de la clavette et la rainure et reparer au besoin | D24: 30
B25: =B24+1 -> 18 | C25: controler l'arret d'huile et le remplacé au besoin. Aucune fuite d'huile n'est acceptable. | D25: 10
B26: =B25+1 -> 19 | C26: controler la fixation du réducteur sur le convoyeur et corriger si necessaire. | D26: 30
B27: =+B26+1 -> 20 | C27: controler l'usure des roulements et paliers de l'axe moteur et remplacer si necessaire. | D27: 30
B28: =B27+1 -> 21 | C28: controler l'usure des pignons et les remplacés au besoin. Aucun glissement n'est acceptable. | D28: 30
B29: =B28+1 -> 22 | C29: controler l'alignement et la fixation du pignon de l'axe moteur et remedier au besoin. | D29: 30
B30: =+B29+1 -> 23 | C30: controler l'usure de la clavette et la rainure et reparer au besoin | D30: 30
B31: =B30+1 -> 24 | C31: controler l'état des glissières et remplacer les au besoin | D31: 25
B32: =B31+1 -> 25 | C32: controler l'usure du tapis et remplacer les portions usées ou maillons cassés | D32: 120
B33: =+B32+1 -> 26 | C33: controler la tenson des tapis et ajuster au besoin | D33: 60
B34: =B33+1 -> 27
B35: =B34+1 -> 28
B36: =+B35+1 -> 29
B37: =B36+1 -> 30
B38: Commentaire | D38: Nom et Visa Intervenants | G38: Nom et Visa Responsables

Sheet CC C8
B3: CHECKLIST MECANIQUE | G3: Date
C4: CONVOYEURS CASIERS C8 | D4: =+'Line & frequency'!C1 -> CHAINE 4 | G4: =+'Line & frequency'!C2 -> HEBDOMADAIRE
E6: FAIT?
B7: N° | C7: DESCRIPTION DES TACHES | D7: Durée | E7: OUI | F7: NON | G7: REMARQUES (MATERIEL + PIECES)
B8: 1 | C8: controler l'arret d'huile et le remplacé au besoin. Aucune fuite d'huile n'est acceptable. | D8: 10
B9: =B8+1 -> 2 | C9: controler la fixation du réducteur sur le convoyeur et corriger si necessaire. | D9: 30
B10: =+B9+1 -> 3 | C10: controler l'usure du pignon et le remplacé au besoin. Aucun glissement n'est acceptable. | D10: 30
B11: =B10+1 -> 4 | C11: controler l'alignement et la fixation du pignon de l'axe moteur et remedier au besoin. | D11: 30
B12: =+B11+1 -> 5 | C12: controler l'usure de la roue libre et la remplacée au besoin. Aucun glissement n'est acceptable. | D12: 30
B13: =B12+1 -> 6 | C13: controler l'alignement et la fixation de la roue libre et remedier au problème. | D13: 30
B14: =+B13+1 -> 7 | C14: controler l'usure de la clavette et la rainure et reparer au besoin | D14: 30
B15: =B14+1 -> 8 | C15: controler l'état des glissières et remplacer les au besoin | D15: 25
B16: =+B15+1 -> 9 | C16: controler l'arret d'huile et le remplacé au besoin. Aucune fuite d'huile n'est acceptable. | D16: 10
B17: =B16+1 -> 10 | C17: controler la fixation du réducteur sur le convoyeur et corriger si necessaire. | D17: 30
B18: =+B17+1 -> 11 | C18: controler l'usure des roulements et paliers de l'axe moteur et remplacer si necessaire. | D18: 30
B19: =B18+1 -> 12 | C19: controler l'usure des pignons et les remplacés au besoin. Aucun glissement n'est acceptable. | D19: 30
B20: =+B19+1 -> 13 | C20: controler l'alignement et la fixation du pignon de l'axe moteur et remedier au besoin. | D20: 30
B21: =B20+1 -> 14 | C21: controler l'usure de la clavette et la rainure et reparer au besoin | D21: 30
B22: =+B21+1 -> 15 | C22: controler l'état des glissières et remplacer les au besoin | D22: 25
B23: =B22+1 -> 16 | C23: controler l'usure du tapis et remplacer les portions usées ou maillons cassés | D23: 120
B24: =+B23+1 -> 17 | C24: controler la tenson des tapis et ajuster au besoin | D24: 60
B25: =B24+1 -> 18
B26: =B25+1 -> 19
B27: =+B26+1 -> 20
B28: =B27+1 -> 21
B29: =B28+1 -> 22
B30: =+B29+1 -> 23
B31: =B30+1 -> 24
B32: =B31+1 -> 25
B33: =+B32+1 -> 26
B34: =B33+1 -> 27
B35: =B34+1 -> 28
B36: =+B35+1 -> 29
B37: =B36+1 -> 30
B38: Commentaire | D38: Nom et Visa Intervenants | G38: Nom et Visa Responsables

Sheet Line & frequency
B1: Line | C1: CHAINE 4
B2: Frequency | C2: HEBDOMADAIRE
B3: Date | C3: 44273 | G3: =+'Line & frequency'!C3 -> 44273

Sheet Cooling towers
B3: CHECKLIST MECANIQUE | G3: Date:
C4: Cooling towers | D4: New PET line | G4: =+'Line & frequency'!C2 -> HEBDOMADAIRE
E5: FAIT?
B6: N° | C6: DESCRIPTION DES TACHES | D6: Durée | E6: OUI | F6: NON | G6: REMARQUES (MATERIEL + PIECES)
B7: 1 | C7: nettoyer les grilles de protection des moteurs
B8: 2 | C8: nettoyer la carrosserie
B9: 3 | C9: Vérifier l'état de la peinture | G9: Présence de la rouille
B10: 4 | C10: Tester la machine à la fin de la maintenance
B11: 5
B12: 6
B13: 7
B14: Commentaire | D14: Nom et Visa Intervenants | G14: Nom et Visa Responsables
K36: +

Sheet Blower
B3: CHECKLIST MECANIQUE | G3: Date:
C4: Blower | D4: New PET line | G4: =+'Line & frequency'!C2 -> HEBDOMADAIRE
E5: FAIT?
B6: N° | C6: DESCRIPTION DES TACHES | D6: Durée | E6: OUI | F6: NON | G6: REMARQUES (MATERIEL + PIECES)
B7: 1 | C7: Controler le guidage des bouteilles à l'interieur et ajuster si necessaire | D7: 5min
B8: =B7+1 -> 2 | C8: Controler la position des buses sur les bouteilles et ajuster si necessaire | D8: 10min
B9: =B8+1 -> 3 | C9: Controler la fixation des supports des buses et serrer si necessaire | D9: 5min
B10: =B9+1 -> 4 | C10: Controler le fonctionnement des souffleurs et remedier si necessaire | D10: 5min
B11: =B10+1 -> 5 | C11: Deboucher toutes les buses bouchées | D11: 30min
B12: =B11+1 -> 6 | C12: Nettoyer les filtres sur les conduites d'aspiration des souffleurs | D12: 30min
B13: =B12+1 -> 7
B14: =B13+1 -> 8
B15: Commentaire | D15: Nom et Visa Intervenants | G15: Nom et Visa Responsables
K36: +
