Workbook

Sheet Blomax
B3: CHECKLIST GRAISSAGE | G3: Date:
C4: BLOMAX | D4: New PET line | G4: =+'Line & frequency'!C2 -> HEBDOMADAIRE
C6: Nb: Utiliser la graisse alimentaire blanche | E6: FAIT?
B7: N° | C7: DESCRIPTION DES TACHES | D7: Durée | E7: OUI | F7: NON | G7: REMARQUES (MATERIEL + PIECES)
B8: 1 | C8: Contrôler conteneur de graisse et faire l'appoint si neccessaire
B9: 2 | C9: Graisser l'anneau de serrage du Module de soufflage
B10: 3 | C10: Graisser tous les huit (8) Postes de soufflage
B11: 4 | C11: Graisser tous les guides linéaires
B12: 5 | C12: Contrôler la pellicule de graisse sur le rotor du moteur linéaire du Module de soufflage
B13: 6 | C13: Contrôler la pellicule de graisse sur le rotor du moteur linéaire du Poste de soufflage
B14: 7 | C14: Contrôler la pellicule de graisse sur le rotor du moteur linéaire du Dispositif d'étirage
B15: 8 | C15: Graisser tous les paliers (11) du peripherique du blomax
B16: 9 | C16: Verifier la quantité de graisse alimentaire blanche disponible au magasin
B17: 10 | C17: Nottoyer les anciennes graisses sur les portes moules et les moules, et graisser avec une nouvelle graisse
B18: 11 | C18: Nottoyer les anciennes graisses sur les tiges d'étirage et graisser avec une nouvelle huile (huile 68 de preference)
B19: 12 | C19: Contrôler l'engrenage (graisse) du Module de soufflage (Entraînement - Pignon lubrifiant)
B20: 13 | C20: Contrôler la voie de cames du Module de soufflage -Poste de soufflage - Élévation du fond
B21: Commentaire | D21: Nom et Visa Intervenants | G21: Nom et Visa Responsables

Sheet Filler
B3: CHECKLIST GRAISSAGE | G3: Date:
C4: FILLER | D4: New PET line | G4: =+'Line & frequency'!C2 -> HEBDOMADAIRE
C6: Nb: Utiliser la graisse alimentaire blanche | E6: FAIT?
B7: N° | C7: DESCRIPTION DES TACHES | D7: Durée | E7: OUI | F7: NON | G7: REMARQUES (MATERIEL + PIECES)
B8: 1 | C8: Contrôler conteneur de graisse et faire l'appoint si neccessaire
B9: =B8+1 -> 2 | C9: Graisser les Paliers des étoiles de guidage des bouteilles
B10: 3 | C10: Graisser les Palier de la partie supérieure de la boucheuse
B11: 4 | C11: Graisser les Palier du convoyeur d'évacuation
B12: 3 | C12: Graisser les Palier du convoyeur d'évacuation
B13: =B12+1 -> 4 | C13: Graisser les Palier du convoyeur d'évacuation
B14: 4 | C14: Graisser les Palier du convoyeur d'évacuation
B15: =B14+1 -> 5 | C15: Graisser les Palier du convoyeur d'évacuation
B16: 5 | C16: Graisser les Palier du convoyeur d'évacuation
B17: =B16+1 -> 6 | C17: Graisser les Palier du convoyeur d'évacuation
B18: 6 | C18: Graisser les Palier du convoyeur d'évacuation
B19: =B18+1 -> 7 | C19: Graisser les Palier du convoyeur d'évacuation
B20: 7 | C20: Graisser les Palier du convoyeur d'évacuation
B21: 5 | C21: Controler le circuit de lubrification automatique (demonter les tuyaux segment par segment et demarrer la pompe manuellement pour s'assurer que la graisse passe bien)
B22: 6 | C22: Relever la pression sur le manometre lors du fonctionnement manuel de la pompe à graisse
B23: 7 | C23: Se rassuerer que le branchement électrique est correctement effectué
B24: 8 | C24: Se rassuerer de l'absence de bruits inhabituels, de vibrations, d'accumulations d'humidité, d'odeurs
B25: 9 | C25: Se rassuerer de l'absenc de fuite de lubrifiant au niveau des raccordements
B26: 10 | C26: Se rassuerer que le lubrifiant est débité sans bulles d'air
B27: 11 | C27: Se rassuerer que les zones de frottement à lubrifier sont alimentés avec la quantité de lubrifiant neccessaire
B28: =B27+1 -> 12
B29: Commentaire | D29: Nom et Visa Intervenants | G29: Nom et Visa Responsables

Sheet Cvyr Btles
B3: CHECKLIST MECANIQUE | G3: Date
C4: PALETTISEUR | D4: =+'Line & frequency'!C1 -> CHAINE 4 | G4: =+'Line & frequency'!C2 -> HEBDOMADAIRE
E6: FAIT?
B7: N° | C7: DESCRIPTION DES TACHES | D7: Durée | E7: OUI | F7: NON | G7: REMARQUES (MATERIEL + PIECES)
B8: 1
B9: =B8+1 -> 2
B10: =+B9+1 -> 3
B11: =B10+1 -> 4
B12: =+B11+1 -> 5
B13: =B12+1 -> 6
B14: =+B13+1 -> 7
B15: =B14+1 -> 8
B16: =+B15+1 -> 9
B17: =B16+1 -> 10
B18: =+B17+1 -> 11
B19: =B18+1 -> 12
B20: =+B19+1 -> 13
B21: =B20+1 -> 14
B22: =+B21+1 -> 15
B23: =B22+1 -> 16
B24: =+B23+1 -> 17
B25: =B24+1 -> 18
B26: =+B25+1 -> 19
B27: =B26+1 -> 20
B28: =+B27+1 -> 21
B29: =B28+1 -> 22
B30: =+B29+1 -> 23
B31: =B30+1 -> 24
B32: =+B31+1 -> 25
B33: =B32+1 -> 26
B34: =+B33+1 -> 27
B35: =B34+1 -> 28
B36: =+B35+1 -> 29
B37: =B36+1 -> 30
B38: =+B37+1 -> 31
B39: =B38+1 -> 32
B40: =+B39+1 -> 33
B41: =B40+1 -> 34
B42: =+B41+1 -> 35
B43: =B42+1 -> 36
...

Sheet CC C1
B3: CHECKLIST MECANIQUE | G3: Date
C4: CONVOYEURS CASIERS C1 | D4: =+'Line & frequency'!C1 -> CHAINE 4 | G4: =+'Line & frequency'!C2 -> HEBDOMADAIRE
E6: FAIT?
B7: N° | C7: DESCRIPTION DES TACHES | D7: Durée | E7: OUI | F7: NON | G7: REMARQUES (MATERIEL + PIECES)
B8: 1 | C8: controler l'arret d'huile et le remplacé au besoin. Aucune fuite d'huile n'est acceptable. | D8: 10
B9: =B8+1 -> 2 | C9: controler la fixation du réducteur sur le convoyeur et corriger si necessaire. | D9: 30
B10: =+B9+1 -> 3 | C10: controler l'usure du pignon et le remplacé au besoin. Aucun glissement n'est acceptable. | D10: 30
B11: =B10+1 -> 4 | C11: controler l'alignement et la fixation du pignon de l'axe moteur et remedier au besoin. | D11: 30
B12: =+B11+1 -> 5 | C12: controler l'usure de la roue libre et la remplacée au besoin. Aucun glissement n'est acceptable. | D12: 30
B13: =B12+1 -> 6 | C13: controler l'alignement et la fixation de la roue libre et remedier au problème. | D13: 30
B14: =+B13+1 -> 7 | C14: controler l'usure de la clavette et la rainure et reparer au besoin | D14: 30
B15: =B14+1 -> 8 | C15: controler l'état des glissières et remplacer les au besoin | D15: 25
B16: =+B15+1 -> 9 | C16: controler l'arret d'huile et le remplacé au besoin. Aucune fuite d'huile n'est acceptable. | D16: 10
B17: =B16+1 -> 10 | C17: controler l'usure des roulements et paliers de l'axe moteur et remplacer si necessaire. | D17: 30
B18: =+B17+1 -> 11 | C18: controler l'usure du pignon et le remplacé au besoin. Aucun glissement n'est acceptable. | D18: 30
B19: =B18+1 -> 12 | C19: controler l'alignement et la fixation du pignon de l'axe moteur et remedier au besoin. | D19: 30
B20: =+B19+1 -> 13 | C20: controler l'usure de la clavette et la rainure et reparer au besoin | D20: 30
B21: =B20+1 -> 14 | C21: controler l'usure des roulements et paliers de l'axe moteur et remplacer si necessaire. | D21: 30
B22: =+B21+1 -> 15 | C22: controler l'usure de la roue libre et la remplacée au besoin. Aucun glissement n'est acceptable. | D22: 30
B23: =B22+1 -> 16 | C23: controler l'alignement et la fixation de la roue libre et remedier au problème. | D23: 30
B24: =+B23+1 -> 17 | C24: controler l'usure de la clavette et la rainure et reparer au besoin | D24: 30
B25: =B24+1 -> 18 | C25: controler l'arret d'huile et le remplacé au besoin. Aucune fuite d'huile n'est acceptable. | D25: 10
B26: =+B25+1 -> 19 | C26: controler la fixation du réducteur sur le convoyeur et corriger si necessaire. | D26: 30
B27: =B26+1 -> 20 | C27: controler l'usure des roulements et paliers de l'axe moteur et remplacer si necessaire. | D27: 30
B28: =+B27+1 -> 21 | C28: controler l'usure du pignon et le remplacé au besoin. Aucun glissement n'est acceptable. | D28: 30
B29: =B28+1 -> 22 | C29: controler l'alignement et la fixation du pignon de l'axe moteur et remedier au besoin. | D29: 30
B30: =+B29+1 -> 23 | C30: controler l'usure de la clavette et la rainure et reparer au besoin | D30: 30
B31: =B30+1 -> 24 | C31: controler l'usure des roulements et paliers de l'axe moteur et remplacer si necessaire. | D31: 30
B32: =+B31+1 -> 25 | C32: controler l'usure de la clavette et la rainure et reparer au besoin | D32: 30
B33: =B32+1 -> 26 | C33: controler l'état des glissières et remplacer les au besoin | D33: 25
B34: =+B33+1 -> 27 | C34: controler l'arret d'huile et le remplacé au besoin. Aucune fuite d'huile n'est acceptable. | D34: 10
B35: =B34+1 -> 28 | C35: controler la fixation du réducteur sur le convoyeur et corriger si necessaire. | D35: 30
B36: =+B35+1 -> 29 | C36: controler l'usure des roulements et paliers de l'axe moteur et remplacer si necessaire. | D36: 30
B37: =B36+1 -> 30 | C37: controler l'usure des pignons et les remplacés au besoin. Aucun glissement n'est acceptable. | D37: 30
B38: =+B37+1 -> 31 | C38: controler l'alignement et la fixation du pignon de l'axe moteur et remedier au besoin. | D38: 30
B39: =B38+1 -> 32 | C39: controler l'usure de la clavette et la rainure et reparer au besoin | D39: 30
B40: =+B39+1 -> 33 | C40: controler l'état des glissières et remplacer les au besoin | D40: 25
B41: =B40+1 -> 34 | C41: controler l'usure du tapis et remplacer les portions usées ou maillons cassés | D41: 120
B42: =+B41+1 -> 35 | C42: controler la tenson des tapis et ajuster au besoin | D42: 60
B43: =B42+1 -> 36 | C43: controler l'arret d'huile et le remplacé au besoin. Aucune fuite d'huile n'est acceptable. | D43: 10
...

Sheet CC C2
B3: CHECKLIST MECANIQUE | G3: Date
C4: CONVOYEURS CASIERS C2 | D4: =+'Line & frequency'!C1 -> CHAINE 4 | G4: =+'Line & frequency'!C2 -> HEBDOMADAIRE
E6: FAIT?
B7: N° | C7: DESCRIPTION DES TACHES | D7: Durée | E7: OUI | F7: NON | G7: REMARQUES (MATERIEL + PIECES)
B8: 1 | C8: controler l'arret d'huile et le remplacé au besoin. Aucune fuite d'huile n'est acceptable. | D8: 10
B9: =B8+1 -> 2 | C9: controler la fixation du réducteur sur le convoyeur et corriger si necessaire. | D9: 30
B10: =+B9+1 -> 3 | C10: controler l'usure du pignon et le remplacé au besoin. Aucun glissement n'est acceptable. | D10: 30
B11: =B10+1 -> 4 | C11: controler l'alignement et la fixation du pignon de l'axe moteur et remedier au besoin. | D11: 30
B12: =+B11+1 -> 5 | C12: controler l'usure de la roue libre et la remplacée au besoin. Aucun glissement n'est acceptable. | D12: 30
B13: =B12+1 -> 6 | C13: controler l'alignement et la fixation de la roue libre et remedier au problème. | D13: 30
B14: =+B13+1 -> 7 | C14: controler l'usure de la clavette et la rainure et reparer au besoin | D14: 30
B15: =B14+1 -> 8 | C15: controler l'état des glissières et remplacer les au besoin | D15: 25
B16: =+B15+1 -> 9 | C16: controler l'arret d'huile et le remplacé au besoin. Aucune fuite d'huile n'est acceptable. | D16: 10
B17: =B16+1 -> 10 | C17: controler l'usure des roulements et paliers de l'axe moteur et remplacer si necessaire. | D17: 30
B18: =+B17+1 -> 11 | C18: controler l'usure du pignon et le remplacé au besoin. Aucun glissement n'est acceptable. | D18: 30
B19: =B18+1 -> 12 | C19: controler l'alignement et la fixation du pignon de l'axe moteur et remedier au besoin. | D19: 30
B20: =+B19+1 -> 13 | C20: controler l'usure de la clavette et la rainure et reparer au besoin | D20: 30
B21: =B20+1 -> 14 | C21: controler l'usure des roulements et paliers de l'axe moteur et remplacer si necessaire. | D21: 30
B22: =+B21+1 -> 15 | C22: controler l'usure de la roue libre et la remplacée au besoin. Aucun glissement n'est acceptable. | D22: 30
B23: =B22+1 -> 16 | C23: controler l'alignement et la fixation de la roue libre et remedier au problème. | D23: 30
B24: =+B23+1 -> 17 | C24: controler l'usure de la clavette et la rainure et reparer au besoin | D24: 30
B25: =B24+1 -> 18 | C25: controler l'arret d'huile et le remplacé au besoin. Aucune fuite d'huile n'est acceptable. | D25: 10
B26: =+B25+1 -> 19 | C26: controler la fixation du réducteur sur le convoyeur et corriger si necessaire. | D26: 30
B27: =B26+1 -> 20 | C27: controler l'usure des roulements et paliers de l'axe moteur et remplacer si necessaire. | D27: 30
B28: =+B27+1 -> 21 | C28: controler l'usure des pignons et les remplacés au besoin. Aucun glissement n'est acceptable. | D28: 30
B29: =B28+1 -> 22 | C29: controler l'alignement et la fixation du pignon de l'axe moteur et remedier au besoin. | D29: 30
B30: =+B29+1 -> 23 | C30: controler l'usure de la clavette et la rainure et reparer au besoin | D30: 30
B31: =B30+1 -> 24 | C31: controler l'état des glissières et remplacer les au besoin | D31: 25
B32: =+B31+1 -> 25 | C32: controler l'usure du tapis et remplacer les portions usées ou maillons cassés | D32: 120
B33: =B32+1 -> 26 | C33: controler la tenson des tapis et ajuster au besoin | D33: 60
B34: =+B33+1 -> 27
B35: =B34+1 -> 28
B36: =+B35+1 -> 29
B37: =B36+1 -> 30
B38: =+B37+1 -> 31
B39: =B38+1 -> 32
B40: =+B39+1 -> 33
B41: =B40+1 -> 34
B42: =+B41+1 -> 35
B43: =B42+1 -> 36
...

Sheet CC C3
B3: CHECKLIST MECANIQUE | G3: Date
C4: CONVOYEURS CASIERS C3 | D4: =+'Line & frequency'!C1 -> CHAINE 4 | G4: =+'Line & frequency'!C2 -> HEBDOMADAIRE
E6: FAIT?
B7: N° | C7: DESCRIPTION DES TACHES | D7: Durée | E7: OUI | F7: NON | G7: REMARQUES (MATERIEL + PIECES)
B8: 1 | C8: controler l'arret d'huile et le remplacé au besoin. Aucune fuite d'huile n'est acceptable. | D8: 10
B9: =B8+1 -> 2 | C9: controler la fixation du réducteur sur le convoyeur et corriger si necessaire. | D9: 30
B10: =+B9+1 -> 3 | C10: controler l'usure du pignon et le remplacé au besoin. Aucun glissement n'est acceptable. | D10: 30
B11: =B10+1 -> 4 | C11: controler l'alignement et la fixation du pignon de l'axe moteur et remedier au besoin. | D11: 30
B12: =+B11+1 -> 5 | C12: controler l'usure de la roue libre et la remplacée au besoin. Aucun glissement n'est acceptable. | D12: 30
B13: =B12+1 -> 6 | C13: controler l'alignement et la fixation de la roue libre et remedier au problème. | D13: 30
B14: =+B13+1 -> 7 | C14: controler l'usure de la clavette et la rainure et reparer au besoin | D14: 30
B15: =B14+1 -> 8 | C15: controler l'état des glissières et remplacer les au besoin | D15: 25
B16: =+B15+1 -> 9 | C16: controler l'arret d'huile et le remplacé au besoin. Aucune fuite d'huile n'est acceptable. | D16: 10
B17: =B16+1 -> 10 | C17: controler l'usure des roulements et paliers de l'axe moteur et remplacer si necessaire. | D17: 30
B18: =+B17+1 -> 11 | C18: controler l'usure du pignon et le remplacé au besoin. Aucun glissement n'est acceptable. | D18: 30
B19: =B18+1 -> 12 | C19: controler l'alignement et la fixation du pignon de l'axe moteur et remedier au besoin. | D19: 30
B20: =+B19+1 -> 13 | C20: controler l'usure de la clavette et la rainure et reparer au besoin | D20: 30
B21: =B20+1 -> 14 | C21: controler l'usure des roulements et paliers de l'axe moteur et remplacer si necessaire. | D21: 30
B22: =+B21+1 -> 15 | C22: controler l'usure de la roue libre et la remplacée au besoin. Aucun glissement n'est acceptable. | D22: 30
B23: =B22+1 -> 16 | C23: controler l'alignement et la fixation de la roue libre et remedier au problème. | D23: 30
B24: =+B23+1 -> 17 | C24: controler l'usure de la clavette et la rainure et reparer au besoin | D24: 30
B25: =B24+1 -> 18
B26: =+B25+1 -> 19
B27: =B26+1 -> 20
B28: =+B27+1 -> 21
B29: =B28+1 -> 22
B30: =+B29+1 -> 23
B31: =B30+1 -> 24
B32: =+B31+1 -> 25
B33: Commentaire | D33: Nom et Visa Intervenants | G33: Nom et Visa Responsables

Sheet CC C4
B3: CHECKLIST MECANIQUE | G3: Date
C4: CONVOYEURS CASIERS C4 | D4: =+'Line & frequency'!C1 -> CHAINE 4 | G4: =+'Line & frequency'!C2 -> HEBDOMADAIRE
E6: FAIT?
B7: N° | C7: DESCRIPTION DES TACHES | D7: Durée | E7: OUI | F7: NON | G7: REMARQUES (MATERIEL + PIECES)
B8: 1 | C8: controler l'arret d'huile et le remplacé au besoin. Aucune fuite d'huile n'est acceptable. | D8: 10
B9: =B8+1 -> 2 | C9: controler la fixation du réducteur sur le convoyeur et corriger si necessaire. | D9: 30
B10: =+B9+1 -> 3 | C10: controler l'usure du pignon et le remplacé au besoin. Aucun glissement n'est acceptable. | D10: 30
B11: =B10+1 -> 4 | C11: controler l'alignement et la fixation du pignon de l'axe moteur et remedier au besoin. | D11: 30
B12: =+B11+1 -> 5 | C12: controler l'usure de la roue libre et la remplacée au besoin. Aucun glissement n'est acceptable. | D12: 30
B13: =B12+1 -> 6 | C13: controler l'alignement et la fixation de la roue libre et remedier au problème. | D13: 30
B14: =+B13+1 -> 7 | C14: controler l'usure de la clavette et la rainure et reparer au besoin | D14: 30
B15: =B14+1 -> 8 | C15: controler l'état des glissières et remplacer les au besoin | D15: 25
B16: =+B15+1 -> 9 | C16: controler l'arret d'huile et le remplacé au besoin. Aucune fuite d'huile n'est acceptable. | D16: 10
B17: =B16+1 -> 10 | C17: controler l'usure des roulements et paliers de l'axe moteur et remplacer si necessaire. | D17: 30
B18: =+B17+1 -> 11 | C18: controler l'usure du pignon et le remplacé au besoin. Aucun glissement n'est acceptable. | D18: 30
B19: =B18+1 -> 12 | C19: controler l'alignement et la fixation du pignon de l'axe moteur et remedier au besoin. | D19: 30
B20: =+B19+1 -> 13 | C20: controler l'usure de la clavette et la rainure et reparer au besoin | D20: 30
B21: =B20+1 -> 14 | C21: controler l'usure des roulements et paliers de l'axe moteur et remplacer si necessaire. | D21: 30
B22: =+B21+1 -> 15 | C22: controler l'usure de la roue libre et la remplacée au besoin. Aucun glissement n'est acceptable. | D22: 30
B23: =B22+1 -> 16 | C23: controler l'alignement et la fixation de la roue libre et remedier au problème. | D23: 30
B24: =+B23+1 -> 17 | C24: controler l'usure de la clavette et la rainure et reparer au besoin | D24: 30
B25: =B24+1 -> 18 | C25: controler l'arret d'huile et le remplacé au besoin. Aucune fuite d'huile n'est acceptable. | D25: 10
B26: =B25+1 -> 19 | C26: controler la fixation du réducteur sur le convoyeur et corriger si necessaire. | D26: 30
B27: =+B26+1 -> 20 | C27: controler l'usure des roulements et paliers de l'axe moteur et remplacer si necessaire. | D27: 30
B28: =B27+1 -> 21 | C28: controler l'usure du pignon et le remplacé au besoin. Aucun glissement n'est acceptable. | D28: 30
B29: =B28+1 -> 22 | C29: controler l'alignement et la fixation du pignon de l'axe moteur et remedier au besoin. | D29: 30
B30: =+B29+1 -> 23 | C30: controler l'usure de la clavette et la rainure et reparer au besoin | D30: 30
B31: =B30+1 -> 24 | C31: controler l'usure des roulements et paliers de l'axe moteur et remplacer si necessaire. | D31: 30
B32: =B31+1 -> 25 | C32: controler l'usure de la clavette et la rainure et reparer au besoin | D32: 30
B33: =+B32+1 -> 26 | C33: controler l'état des glissières et remplacer les au besoin | D33: 25
B34: =B33+1 -> 27
B35: =B34+1 -> 28
B36: =+B35+1 -> 29
B37: =B36+1 -> 30
B38: Commentaire | D38: Nom et Visa Intervenants | G38: Nom et Visa Responsables

Sheet CC C5
B3: CHECKLIST MECANIQUE | G3: Date
C4: CONVOYEURS CASIERS C5 | D4: =+'Line & frequency'!C1 -> CHAINE 4 | G4: =+'Line & frequency'!C2 -> HEBDOMADAIRE
E6: FAIT?
B7: N° | C7: DESCRIPTION DES TACHES | D7: Durée | E7: OUI | F7: NON | G7: REMARQUES (MATERIEL + PIECES)
B8: 1 | C8: controler l'arret d'huile et le remplacé au besoin. Aucune fuite d'huile n'est acceptable. | D8: 10
B9: =B8+1 -> 2 | C9: controler la fixation du réducteur sur le convoyeur et corriger si necessaire. | D9: 30
B10: =+B9+1 -> 3 | C10: controler l'usure du pignon et le remplacé au besoin. Aucun glissement n'est acceptable. | D10: 30
B11: =B10+1 -> 4 | C11: controler l'alignement et la fixation du pignon de l'axe moteur et remedier au besoin. | D11: 30
B12: =+B11+1 -> 5 | C12: controler l'usure de la roue libre et la remplacée au besoin. Aucun glissement n'est acceptable. | D12: 30
B13: =B12+1 -> 6 | C13: controler l'alignement et la fixation de la roue libre et remedier au problème. | D13: 30
B14: =+B13+1 -> 7 | C14: controler l'usure de la clavette et la rainure et reparer au besoin | D14: 30
B15: =B14+1 -> 8 | C15: controler l'état des glissières et remplacer les au besoin | D15: 25
B16: =+B15+1 -> 9 | C16: controler l'arret d'huile et le remplacé au besoin. Aucune fuite d'huile n'est acceptable. | D16: 10
B17: =B16+1 -> 10 | C17: controler l'usure des roulements et paliers de l'axe moteur et remplacer si necessaire. | D17: 30
B18: =+B17+1 -> 11 | C18: controler l'usure du pignon et le remplacé au besoin. Aucun glissement n'est acceptable. | D18: 30
B19: =B18+1 -> 12 | C19: controler l'alignement et la fixation du pignon de l'axe moteur et remedier au besoin. | D19: 30
B20: =+B19+1 -> 13 | C20: controler l'usure de la clavette et la rainure et reparer au besoin | D20: 30
B21: =B20+1 -> 14 | C21: controler l'usure des roulements et paliers de l'axe moteur et remplacer si necessaire. | D21: 30
B22: =+B21+1 -> 15 | C22: controler l'usure de la roue libre et la remplacée au besoin. Aucun glissement n'est acceptable. | D22: 30
B23: =B22+1 -> 16 | C23: controler l'alignement et la fixation de la roue libre et remedier au problème. | D23: 30
B24: =+B23+1 -> 17 | C24: controler l'usure de la clavette et la rainure et reparer au besoin | D24: 30
B25: =B24+1 -> 18
B26: =B25+1 -> 19
B27: =+B26+1 -> 20
B28: =B27+1 -> 21
B29: =B28+1 -> 22
B30: =+B29+1 -> 23
B31: =B30+1 -> 24
B32: =B31+1 -> 25
B33: =+B32+1 -> 26
B34: =B33+1 -> 27
B35: =B34+1 -> 28
B36: =+B35+1 -> 29
B37: =B36+1 -> 30
B38: Commentaire | D38: Nom et Visa Intervenants | G38: Nom et Visa Responsables

Sheet CC C6
B3: CHECKLIST MECANIQUE | G3: Date
C4: CONVOYEURS CASIERS C6 | D4: =+'Line & frequency'!C1 -> CHAINE 4 | G4: =+'Line & frequency'!C2 -> HEBDOMADAIRE
E6: FAIT?
B7: N° | C7: DESCRIPTION DES TACHES | D7: Durée | E7: OUI | F7: NON | G7: REMARQUES (MATERIEL + PIECES)
B8: 1 | C8: controler l'arret d'huile et le remplacé au besoin. Aucune fuite d'huile n'est acceptable. | D8: 10
B9: =B8+1 -> 2 | C9: controler la fixation du réducteur sur le convoyeur et corriger si necessaire. | D9: 30
B10: =+B9+1 -> 3 | C10: controler l'usure du pignon et le remplacé au besoin. Aucun glissement n'est acceptable. | D10: 30
B11: =B10+1 -> 4 | C11: controler l'alignement et la fixation du pignon de l'axe moteur et remedier au besoin. | D11: 30
B12: =+B11+1 -> 5 | C12: controler l'usure de la roue libre et la remplacée au besoin. Aucun glissement n'est acceptable. | D12: 30
B13: =B12+1 -> 6 | C13: controler l'alignement et la fixation de la roue libre et remedier au problème. | D13: 30
B14: =+B13+1 -> 7 | C14: controler l'usure de la clavette et la rainure et reparer au besoin | D14: 30
B15: =B14+1 -> 8 | C15: controler l'état des glissières et remplacer les au besoin | D15: 25
B16: =+B15+1 -> 9 | C16: controler l'arret d'huile et le remplacé au besoin. Aucune fuite d'huile n'est acceptable. | D16: 10
B17: =B16+1 -> 10 | C17: controler l'usure des roulements et paliers de l'axe moteur et remplacer si necessaire. | D17: 30
B18: =+B17+1 -> 11 | C18: controler l'usure du pignon et le remplacé au besoin. Aucun glissement n'est acceptable. | D18: 30
B19: =B18+1 -> 12 | C19: controler l'alignement et la fixation du pignon de l'axe moteur et remedier au besoin. | D19: 30
B20: =+B19+1 -> 13 | C20: controler l'usure de la clavette et la rainure et reparer au besoin | D20: 30
B21: =B20+1 -> 14 | C21: controler l'usure des roulements et paliers de l'axe moteur et remplacer si necessaire. | D21: 30
B22: =+B21+1 -> 15 | C22: controler l'usure de la roue libre et la remplacée au besoin. Aucun glissement n'est acceptable. | D22: 30
B23: =B22+1 -> 16 | C23: controler l'alignement et la fixation de la roue libre et remedier au problème. | D23: 30
B24: =+B23+1 -> 17 | C24: controler l'usure de la clavette et la rainure et reparer au besoin | D24: 30
B25: =B24+1 -> 18 | C25: controler l'arret d'huile et le remplacé au besoin. Aucune fuite d'huile n'est acceptable. | D25: 10
B26: =B25+1 -> 19 | C26: controler la fixation du réducteur sur le convoyeur et corriger si necessaire. | D26: 30
B27: =+B26+1 -> 20 | C27: controler l'usure des roulements et paliers de l'axe moteur et remplacer si necessaire. | D27: 30
B28: =B27+1 -> 21 | C28: controler l'usure des pignons et les remplacés au besoin. Aucun glissement n'est acceptable. | D28: 30
B29: =B28+1 -> 22 | C29: controler l'alignement et la fixation du pignon de l'axe moteur et remedier au besoin. | D29: 30
B30: =+B29+1 -> 23 | C30: controler l'usure de la clavette et la rainure et reparer au besoin | D30: 30
B31: =B30+1 -> 24 | C31: controler l'état des glissières et remplacer les au besoin | D31: 25
B32: =B31+1 -> 25 | C32: controler l'usure du tapis et remplacer les portions usées ou maillons cassés | D32: 120
B33: =+B32+1 -> 26 | C33: controler la tenson des tapis et ajuster au besoin | D33: 60
B34: =B33+1 -> 27
B35: =B34+1 -> 28
B36: =+B35+1 -> 29
B37: =B36+1 -> 30
B38: Commentaire | D38: Nom et Visa Intervenants | G38: Nom et Visa Responsables

Sheet CC C7
B3: CHECKLIST MECANIQUE | G3: Date
C4: CONVOYEURS CASIERS C7 | D4: =+'Line & frequency'!C1 -> CHAINE 4 | G4: =+'Line & frequency'!C2 -> HEBDOMADAIRE
E6: FAIT?
B7: N° | C7: DESCRIPTION DES TACHES | D7: Durée | E7: OUI | F7: NON | G7: REMARQUES (MATERIEL + PIECES)
B8: 1 | C8: controler l'arret d'huile et le remplacé au besoin. Aucune fuite d'huile n'est acceptable. | D8: 10
B9: =B8+1 -> 2 | C9: controler la fixation du réducteur sur le convoyeur et corriger si necessaire. | D9: 30
B10: =+B9+1 -> 3 | C10: controler l'usure du pignon et le remplacé au besoin. Aucun glissement n'est acceptable. | D10: 30
B11: =B10+1 -> 4 | C11: controler l'alignement et la fixation du pignon de l'axe moteur et remedier au besoin. | D11: 30
B12: =+B11+1 -> 5 | C12: controler l'usure de la roue libre et la remplacée au besoin. Aucun glissement n'est acceptable. | D12: 30
B13: =B12+1 -> 6 | C13: controler l'alignement et la fixation de la roue libre et remedier au problème. | D13: 30
B14: =+B13+1 -> 7 | C14: controler l'usure de la clavette et la rainure et reparer au besoin | D14: 30
B15: =B14+1 -> 8 | C15: controler l'état des glissières et remplacer les au besoin | D15: 25
B16: =+B15+1 -> 9 | C16: controler l'arret d'huile et le remplacé au besoin. Aucune fuite d'huile n'est acceptable. | D16: 10
B17: =B16+1 -> 10 | C17: controler l'usure des roulements et paliers de l'axe moteur et remplacer si necessaire. | D17: 30
B18: =+B17+1 -> 11 | C18: controler l'usure du pignon et le remplacé au besoin. Aucun glissement n'est acceptable. | D18: 30
B19: =B18+1 -> 12 | C19: controler l'alignement et la fixation du pignon de l'axe moteur et remedier au besoin. | D19: 30
B20: =+B19+1 -> 13 | C20: controler l'usure de la clavette et la rainure et reparer au besoin | D20: 30
B21: =B20+1 -> 14 | C21: controler l'usure des roulements et paliers de l'axe moteur et remplacer si necessaire. | D21: 30
B22: =+B21+1 -> 15 | C22: controler l'usure de la roue libre et la remplacée au besoin. Aucun glissement n'est acceptable. | D22: 30
B23: =B22+1 -> 16 | C23: controler l'alignement et la fixation de la roue libre et remedier au problème. | D23: 30
B24: =+B23+1 -> 17 | C24: controler l'usure de la clavette et la rainure et reparer au besoin | D24: 30
B25: =B24+1 -> 18 | C25: controler l'arret d'huile et le remplacé au besoin. Aucune fuite d'huile n'est acceptable. | D25: 10
B26: =B25+1 -> 19 | C26: controler la fixation du réducteur sur le convoyeur et corriger si necessaire. | D26: 30
B27: =+B26+1 -> 20 | C27: controler l'usure des roulements et paliers de l'axe moteur et remplacer si necessaire. | D27: 30
B28: =B27+1 -> 21 | C28: controler l'usure des pignons et les remplacés au besoin. Aucun glissement n'est acceptable. | D28: 30
B29: =B28+1 -> 22 | C29: controler l'alignement et la fixation du pignon de l'axe moteur et remedier au besoin. | D29: 30
B30: =+B29+1 -> 23 | C30: controler l'usure de la clavette et la rainure et reparer au besoin | D30: 30
B31: =B30+1 -> 24 | C31: controler l'état des glissières et remplacer les au besoin | D31: 25
B32: =B31+1 -> 25 | C32: controler l'usure du tapis et remplacer les portions usées ou maillons cassés | D32: 120
B33: =+B32+1 -> 26 | C33: controler la tenson des tapis et ajuster au besoin | D33: 60
B34: =B33+1 -> 27
B35: =B34+1 -> 28
B36: =+B35+1 -> 29
B37: =B36+1 -> 30
B38: Commentaire | D38: Nom et Visa Intervenants | G38: Nom et Visa Responsables

Sheet CC C8
B3: CHECKLIST MECANIQUE | G3: Date
C4: CONVOYEURS CASIERS C8 | D4: =+'Line & frequency'!C1 -> CHAINE 4 | G4: =+'Line & frequency'!C2 -> HEBDOMADAIRE
E6: FAIT?
B7: N° | C7: DESCRIPTION DES TACHES | D7: Durée | E7: OUI | F7: NON | G7: REMARQUES (MATERIEL + PIECES)
B8: 1 | C8: controler l'arret d'huile et le remplacé au besoin. Aucune fuite d'huile n'est acceptable. | D8: 10
B9: =B8+1 -> 2 | C9: controler la fixation du réducteur sur le convoyeur et corriger si necessaire. | D9: 30
B10: =+B9+1 -> 3 | C10: controler l'usure du pignon et le remplacé au besoin. Aucun glissement n'est acceptable. | D10: 30
B11: =B10+1 -> 4 | C11: controler l'alignement et la fixation du pignon de l'axe moteur et remedier au besoin. | D11: 30
B12: =+B11+1 -> 5 | C12: controler l'usure de la roue libre et la remplacée au besoin. Aucun glissement n'est acceptable. | D12: 30
B13: =B12+1 -> 6 | C13: controler l'alignement et la fixation de la roue libre et remedier au problème. | D13: 30
B14: =+B13+1 -> 7 | C14: controler l'usure de la clavette et la rainure et reparer au besoin | D14: 30
B15: =B14+1 -> 8 | C15: controler l'état des glissières et remplacer les au besoin | D15: 25
B16: =+B15+1 -> 9 | C16: controler l'arret d'huile et le remplacé au besoin. Aucune fuite d'huile n'est acceptable. | D16: 10
B17: =B16+1 -> 10 | C17: controler la fixation du réducteur sur le convoyeur et corriger si necessaire. | D17: 30
B18: =+B17+1 -> 11 | C18: controler l'usure des roulements et paliers de l'axe moteur et remplacer si necessaire. | D18: 30
B19: =B18+1 -> 12 | C19: controler l'usure des pignons et les remplacés au besoin. Aucun glissement n'est acceptable. | D19: 30
B20: =+B19+1 -> 13 | C20: controler l'alignement et la fixation du pignon de l'axe moteur et remedier au besoin. | D20: 30
B21: =B20+1 -> 14 | C21: controler l'usure de la clavette et la rainure et reparer au besoin | D21: 30
B22: =+B21+1 -> 15 | C22: controler l'état des glissières et remplacer les au besoin | D22: 25
B23: =B22+1 -> 16 | C23: controler l'usure du tapis et remplacer les portions usées ou maillons cassés | D23: 120
B24: =+B23+1 -> 17 | C24: controler la tenson des tapis et ajuster au besoin | D24: 60
B25: =B24+1 -> 18
B26: =B25+1 -> 19
B27: =+B26+1 -> 20
B28: =B27+1 -> 21
B29: =B28+1 -> 22
B30: =+B29+1 -> 23
B31: =B30+1 -> 24
B32: =B31+1 -> 25
B33: =+B32+1 -> 26
B34: =B33+1 -> 27
B35: =B34+1 -> 28
B36: =+B35+1 -> 29
B37: =B36+1 -> 30
B38: Commentaire | D38: Nom et Visa Intervenants | G38: Nom et Visa Responsables

Sheet Line & frequency
B1: Line | C1: CHAINE 4
B2: Frequency | C2: HEBDOMADAIRE
B3: Date | C3: 44273 | G3: =+'Line & frequency'!C3 -> 44273

Sheet Convoyeurs
B3: CHECKLIST GRAISSAGE | G3: Date:
C4: CONVEYORS | D4: New PET line | G4: =+'Line & frequency'!C2 -> HEBDOMADAIRE
E6: FAIT?
B7: N° | C7: DESCRIPTION DES TACHES | D7: Durée | E7: OUI | F7: NON | G7: REMARQUES (MATERIEL + PIECES)
B8: 1 | C8: Graisser tous les paliers à brides des convoyeurs sortie shrink packer
B9: =B8+1 -> 2 | C9: Graisser tous les paliers à brides des convoyeurs sortie handle applicator
B10: 3 | C10: Graisser tous les paliers à brides des convoyeurs sortie soutireuse
B11: 4 | C11: Graisser tous les paliers à brides des convoyeurs entrée étiquetteuse
B12: =+B11+1 -> 5 | C12: Graisser les Engrenage à maillons de chaîne entrée étiquetteuse
B13: =B12+1 -> 6 | C13: Ouvrir la vanne de soupape de la conduite de lubrification pendant 4h de temps et fermer après
B14: Commentaire | D14: Nom et Visa Intervenants | G14: Nom et Visa Responsables

Sheet Labeller
B3: CHECKLIST GRAISSAGE | G3: Date:
C4: LABELLER | D4: New PET line | G4: =+'Line & frequency'!C2 -> HEBDOMADAIRE
E6: FAIT?
B7: N° | C7: DESCRIPTION DES TACHES | D7: Durée | E7: OUI | F7: NON | G7: REMARQUES (MATERIEL + PIECES)
B8: 1 | C8: Graisser toutes les pieces en mouvement dans le capot
B9: =B8+1 -> 2 | C9: Graisser l'étoile du convoyeur d'entrée
B10: 3 | C10: Controler l'état des ressorts des galets d'entrainement
B11: 4 | C11: Controler l'usure des galets de tete de piston
B12: =+B11+1 -> 5
B13: =B12+1 -> 6
B14: Commentaire | D14: Nom et Visa Intervenants | G14: Nom et Visa Responsables

Sheet Kisters
B3: CHECKLIST GRAISSAGE | G3: Date:
C4: KISTERS | D4: New PET line | G4: =+'Line & frequency'!C2 -> HEBDOMADAIRE
E6: FAIT?
B7: N° | C7: DESCRIPTION DES TACHES | D7: Durée | E7: OUI | F7: NON | G7: REMARQUES (MATERIEL + PIECES)
B8: 1 | C8: Graisser tous le paliers
B9: 2 | C9: Lubrifier les chaines à maillons
B10: 3 | C10: Vérifier la quantité du high pressure greasse disponible
B11: 4 | C11: Vérifier le niveau d'huile dans le reservoir et faire si neccessaire
B12: 5 | C12: Controler le circuit de lubrification automatique (demonter les tuyaux segment par segment et demarrer la pompe manuellement pour s'assurer que l'huile passe bien)
B13: 6 | C13: Se rassuerer que les zones de frottement à lubrifier sont alimentés avec la quantité de lubrifiant neccessaire
B14: 7 | C14: Se rassuerer que le branchement électrique est correctement effectué
B15: 8 | C15: Se rassuerer que le raccordement mécanique est correctement effectué
B16: 9 | C16: Se rassuerer de l'absenc de fuite de lubrifiant au niveau des raccordements
B17: Commentaire | D17: Nom et Visa Intervenants | G17: Nom et Visa Responsables

Sheet Handle applicator
B3: CHECKLIST GRAISSAGE | G3: Date:
C4: HANDLE APPLICATOR | D4: New PET line | G4: =+'Line & frequency'!C2 -> HEBDOMADAIRE
E6: FAIT?
B7: N° | C7: DESCRIPTION DES TACHES | D7: Durée | E7: OUI | F7: NON | G7: REMARQUES (MATERIEL + PIECES)
B8: 1 | C8: Graisser tous le paliers
B9: =B8+1 -> 2
B10: 3
B11: Commentaire | D11: Nom et Visa Intervenants | G11: Nom et Visa Responsables

Sheet Robopac
B3: CHECKLIST GRAISSAGE | G3: Date:
C4: ROBOPAC | D4: New PET line | G4: =+'Line & frequency'!C2 -> HEBDOMADAIRE
E6: FAIT?
B7: N° | C7: DESCRIPTION DES TACHES | D7: Durée | E7: OUI | F7: NON | G7: REMARQUES (MATERIEL + PIECES)
B8: 1 | C8: Graisser les chaines motrices des chariots
B9: =B8+1 -> 2 | C9: Graisser les chaines motrices des plateaux
B10: 3
B11: Commentaire | D11: Nom et Visa Intervenants | G11: Nom et Visa Responsables
