Workbook

Sheet UTILITIES PM
AK1: 0
E2: PROCESSUS GERER LES INFRASTRUCTURES ET EQUIPEMENTS DE PRODUCTION | AM2: PS3-ID02
E3: PLAN ANNUEL DE MAINTENANCE | AM3: Version : 01
E4: Département/Service: technique / utiltiy | T4: Unité de conditionnement: | AF4: Equipement: critiques
E5: Quart: | H5: Journalier: | M5: Hebdomadaire: | T5: Mensuel: | Y5: Trimestriel: | AE5: Semestriel: | AK5: Annuel: | AO5: Bimensuel:
E6: Date mise à jour: 22/01/2022
E7: JANVIER | I7: FÉVRIER | M7: MARS | Q7: AVRIL | U7: MAI | Y7: JUIN | AC7: JUILLET | AG7: AOÛT | AK7: SEPTEMBRE | AO7: OCTOBRE | AS7: NOVEMBRE | AW7: DECEMBRE
B8: Equipement | C8: Actions | D8: Période | E8: S1 | F8: S2 | G8: S3 | H8: S4 | I8: S5 | J8: S6 | K8: S7 | L8: S8 | M8: S9 | N8: S10 | O8: S11 | P8: S12 | Q8: S13 | R8: S14 | S8: S15 | T8: S16 | U8: S17 | V8: S18 | W8: S19 | X8: S20 | Y8: S21 | Z8: S22 | AA8: S23 | AB8: S24 | AC8: S25 | AD8: S26 | AE8: S27 | AF8: S28 | AG8: S29 | AH8: S30 | AI8: S31 | AJ8: S32 | AK8: S33 | AL8: S34 | AM8: S35 | AN8: S36 | AO8: S37 | AP8: S38 | AQ8: S39 | AR8: S40 | AS8: S41 | AT8: S42 | AU8: S43 | AV8: S44 | AW8: S45 | AX8: S46 | AY8: S47 | AZ8: S48 | BA8: personnel | BB8: L | BC8: M | BD8: M | BE8: J | BF8: V | BG8: S | BH8: D | BI8: Resultat | BJ8: Observation
B9: Boiler 15T BOSCH | C9: Si vous fonctionnez au gazoil, veuillez nettoyez les filtres | D9: TRIM
B10: Boiler 15T BOSCH | C10: Si vous fonctionnez au gazoil verifier toutes les connections electriques, nettoyer le gicleur de gazoil | D10: TRIM
B11: Boiler 15T BOSCH | C11: Nettoyer Verifier la photocellule | D11: TRIM
B12: Boiler 15T BOSCH | C12: Vérifier le fonctionnement de la vanne de regulation d'eau | D12: TRIM
B13: Boiler 15T BOSCH | C13: Verifier les conduites de distribution de vapeur (header) | D13: TRIM
B14: Boiler 15T BOSCH | C14: Rincage de la soupape de sécurité par essai | D14: TRIM
B15: Boiler 15T BOSCH | C15: verifier les tubes de fumées,et effectuer un ramonage si necessaire | D15: TRIM
B16: Boiler 15T BOSCH | C16: Nettoyer et Vérifier le capteur de niveau,de conductivité | D16: TRIM
B17: Boiler 15T BOSCH | C17: Verifié la vanne de vidange automatique | D17: TRIM
B18: Boiler 10T BOSCH | C18: Si vous fonctionnez au gazoil, veuillez nettoyez les filtres | D18: TRIM
B19: Boiler 10T BOSCH | C19: Si vous fonctionnez au gazoil verifier toutes les connections electriques, nettoyer le gicleur de gazoil | D19: TRIM
B20: Boiler 10T BOSCH | C20: Nettoyer Verifier la photocellule | D20: TRIM
... B55: Acf dryer | C55: Verifier les filtres de poussieres et remplacer si nécessaire | D55: TRIM
C56: Remplace les filtres de poussieres | D56: TRIM
B57: Cooling unit | C57: Verifier le bon fonctionnement des differents capteurs de pression | D57: TRIM
B58: CO2 reticulation | C58: Vérifier les éventuelles fuites | D58: TRIM
B59: Boiler 15T BOSCH | C59: Si vous fonctionnez au gazoil faites des tests de fumées | D59: SEME
B60: Boiler 10T BOSCH | C60: Si vous fonctionnez au gazoil faites des tests de fumées | D60: SEME
B61: SABROE 4 refrigeration plant | C61: Changer l'huile | D61: SEME
B62: SABROE 4 refrigeration plant | C62: Changer les filtres | D62: SEME
B63: SABROE 4 refrigeration plant | C63: Analyse de l'huile | D63: SEME
B64: SABROE 4 refrigeration plant | C64: Verifier l'alignement du moteur (SABROE 4,5,6,7,8) | D64: SEME
B65: SABROE 4 refrigeration plant | C65: Vérifier les connections électriques | D65: SEME
B66: SABROE 4 refrigeration plant | C66: Vérifier et analyser le niveau de vibration | D66: SEME
B67: SABROE 5 refrigeration plant | C67: Changer l'huile | D67: SEME
B68: SABROE 5 refrigeration plant | C68: Changer les filtres | D68: SEME
... B138: Condenseur BAC 4 | C138: verifier les tensions des moteurs des ventilateurs | D138: MENS
B139: Condenseur BAC 4 | C139: verifier les arbres des ventilatteurs | D139: MENS | AZ139: 1
B140: Condenseur BAC 4 | C140: graisser les roulements des ventilateurs | D140: MENS | AZ140: 1
B141: Condenseur BAC 5 | C141: Changer l'eau et nettoyer l'intérieur du condenseur | D141: MENS
B142: Condenseur BAC 5 | C142: Verifier les pulvérisateurs | D142: MENS
B143: Condenseur BAC 5 | C143: verifier les tensions des courroies | D143: MENS
...

Sheet PM 2025
AN1: 0
E2: PROCESSUS GERER LES INFRASTRUCTURES ET EQUIPEMENTS DE PRODUCTION | AP2: PS3-ID02
E3: PLAN ANNUEL DE MAINTENANCE | AP3: Version : 01
E4: Département/Service: technique / utiltiy | U4: Unité de conditionnement: | AI4: Equipement: critiques
E5: Quart: | H5: Journalier: | N5: Hebdomadaire: | U5: Mensuel: | AA5: Trimestriel: | AG5: Semestriel: | AN5: Annuel: | AR5: Bimensuel:
E6: Date mise à jour: 24 /6/ 2025
E7: JANVIER | J7: FÉVRIER | N7: MARS | R7: AVRIL | V7: MAI | AA7: JUIN | AE7: JUILLET | AJ7: AOÛT | AN7: SEPTEMBRE | AR7: OCTOBRE | AW7: NOVEMBRE | BA7: DECEMBRE | BE7: Spare parts
B8: Equipement | C8: Actions | D8: Période | E8: S1 | F8: S2 | G8: S3 | H8: S4 | I8: S5 | J8: S6 | K8: S7 | L8: S8 | M8: S9 | N8: S10 | O8: S11 | P8: S12 | Q8: S13 | R8: S14 | S8: S15 | T8: S16 | U8: S17 | V8: S18 | W8: S19 | X8: S20 | Y8: S21 | Z8: S22 | AA8: S23 | AB8: S24 | AC8: S25 | AD8: S26 | AE8: S27 | AF8: S28 | AG8: S29 | AH8: S30 | AI8: S31 | AJ8: S32 | AK8: S33 | AL8: S34 | AM8: S35 | AN8: S36 | AO8: S37 | AP8: S38 | AQ8: S39 | AR8: S40 | AS8: S41 | AT8: S42 | AU8: S43 | AV8: S44 | AW8: S45 | AX8: S46 | AY8: S47 | AZ8: S48 | BA8: S49 | BB8: S50 | BC8: S51 | BD8: S52 | BE8: Names | BF8: QUANTITY | BG8: Observation
C9: Nettoyer le bruleur | D9: HEBDO | E9: DT02510 fotsing
C10: Nettoyer les les filtres fuels | D10: HEBDO
C11: Nettoyer le corps de la chaudière | D11: HEBDO
C12: Verifier le fonctionnement des pompes alimentaires d'eau | D12: HEBDO
C13: Vérifier le bon fonctionnement des servo moteurs. | D13: MENS | BE13: Servo moteurs | BF13: 4 | BG13: Servo motor for gas control, for oil flow control, for primary air damper and for secondary air control damper
C14: Nettoyer le bruleur | D14: MENS
C15: Nettoyer filtre à gaz | D15: MENS | BE15: Filtre gaz | BF15: 1
C16: Si vous fonctionnez au gazoil, veuillez nettoyez les filtres | D16: TRIM
C17: Si vous fonctionnez au gazoil verifier toutes les connections electriques, nettoyer le gicleur de gazoil | D17: TRIM
C18: Nettoyer Verifier la photocellule | D18: TRIM | BE18: Photocellule | BF18: 1
C19: Vérifier le fonctionnement de la vanne de regulation d'eau | D19: TRIM | BE19: Vanne de regulation | BF19: 1
C20: Verifier les conduites de distribution de vapeur (header) | D20: TRIM
C21: Rincage de la soupape de sécurité par essai | D21: TRIM
C22: Nettoyer et Vérifier le capteur de niveau,de conductivité | D22: TRIM
C23: Verifié la vanne de vidange automatique | D23: TRIM | BE23: Vanne de vidange | BF23: 1
C24: Effectuer le ramonage des tubes de fumées | D24: SEME
C25: Effectuer le test de pression | D25: SEME
C26: Si vous fonctionnez au gazoil faites des tests de fumées | D26: SEME
C27: Effectuer les tests de pression programmée de la chaudiere | D27: ANNU
C28: Ouvrir et nettoyer le couvercle | D28: ANNU
C29: Contrôle et reparation du mur réfractaire | D29: ANNU
C30: Changement des joints de portes du mur réfractaire | D30: ANNU | BE30: Rouleau de joint | BF30: 1
C31: Verifier et enlever les joints de mailles | D31: ANNU | BE31: Joint mailles | BF31: 4
C32: Changer les joints des trous d'hommes/ d'eau | D32: ANNU | BE32: Joint trou d'homme | BF32: 3
C33: Nettoyer les crépines des pompes d'alimentations | D33: ANNU | BE33: Crepines des pompes | BF33: 2
C34: Ramonage et Test de pression de la chaudiere | D34: ANNU | BE34: Soupapes de securites | BF34: 2
C35: Remplace le roulement du moteur du bruleur | D35: ANNU | BE35: Roulement bruleur | BF35: 4
C36: Verifier et nettoyer les pales du ventillateur a air | D36: ANNU
C37: Nettoyer Verifier la coupelle rotative du bruleur | D37: ANNU
C38: Effectuer les tests de pression et de contrainte annuel de la chaudiere | D38: ANNU
B39: Boiler 10T BOSCH | C39: Nettoyer le bruleur | D39: HEBDO
C40: Nettoyer les les filtres fuels | D40: HEBDO
...

Sheet CHECK LIST
H4: semaine | L4: à
H6: technicien
E8: CHECK LIST MAINTENANCE DE RONDE
D12: AIR COMPRESSED PLANT
D13: CHECK | F13: Unit | G13: temps planifié | H13: Frequence | I13: Lun | J13: Mar | K13: Mer | L13: Jeu | M13: Ven | N13: Sam | O13: Dim
D14: VÉRIFIER LA LECTURE SUR LES ÉCRANS | F14: N°1 & 2 | G14: 2min | H14: jour
D15: VÉRIFIEZ QUE LE CONDENSAT EST ÉVACUÉ PENDANT CHARGEMENT. | F15: N°1 & 2 | G15: 5min | H15: jour
D16: VÉRIFIEZ QU'IL N'YAI AUCUN BRUIT ANORMALE DU COMPRESSEUR | F16: N°1 & 2 | G16: 5min | H16: jour
D17: VÉRIFIEZ QUE L'INDICATEUR D'HUMIDITÉ DU SÉCHOIR INTÉGRÉ EST BLEU | F17: N°1 & 2 | G17: 2min | H17: jour
D18: VÉRIFIEZ L'ABSCENCE DES FUITES SUR LE CIRCUIT JUSQU'AU DISTRIBUTEUR | F18: N°1 & 2 | G18: 2min | H18: jour
D19: ENLEVER LA POUSSIÈRE DU RADIATEUR DU COMPRESSEUR ET NETTOYER LE FILTRE | F19: N°1 & 2 | G19: 1h | H19: hebdo
D20: TESTER LE RELAIS THERMIQUE DU MOTEUR | F20: N°1 & 2 | G20: 30min | H20: hebdo
D21: VÉRIFIER LE NIVEAU D'HUILE | F21: N°1 & 2 | G21: 30min | H21: hebdo
D22: STEAM PLANT
D23: CHECK | F23: Unité | G23: temps planifié | H23: Frequence | I23: lundi | J23: mardi | K23: mercredi | L23: jeudi | M23: vendredi | N23: samedi | O23: dimanche
D24: VÉRIFIER SI LE DÉBITMÈTRE DE GAZ DE FONCTIONNEMENT | F24: B10T & 15T | G24: 5min | H24: hebdo
D25: VÉRIFIER LA PRESSION DE GAZ PRINCIPALE ( VALEUR DANS LA CASE) | F25: B10T & 15T | G25: 5min | H25: hebdo
D26: VÉRIFIER LE FONCTIONNEMENT DE L'ÉLECTRODE D'ALLUMAGE | F26: B10T & 15T | G26: 15min | H26: hebdo
D27: VÉRIFIEZ LE NIVEAU DANS LES RÉSERVOIR DE DOSAGE DE SEES (POUDRE ET HUILE) ET REMPLISSEZ-LE SI NECESSAIRE | F27: B10T & 15T | G27: 15min | H27: jour
D28: VÉRIFIEZ LA VALEUR DANS LA BACHE ALIMENTAIRE | F28: B10T & 15T | G28: 5min | H28: jour
D29: VÉRIFIER LE PROCESSUS DE CHANGEMENT DE BATEAU (ADOUCISSEUR D'EAU) | F29: B10T & 15T | G29: 5min | H29: jour
D30: VÉRIFIER LE NIVEAU DU RÉSERVOIR DE SAUMURE ET LE SUPÉRIEUR (4 SACS AXAL) | F30: B10T & 15T | G30: 5min | H30: jour
D31: VÉRIFIEZ L'ABSCENCE DES FUITES SUR LE CIRCUIT VAPEUR JUSQU'AU DISTRIBUTEUR | F31: B10T & 15T | G31: 30min | H31: jour
D32: VÉRIFIEZ LE FONCTIONNEMENT DES MOTEURS DES POMPES ALIMENTAIRE EN EAU,ET PURGER LES POMPES | F32: B10T & 15T | G32: 30min | H32: jour
D33: VANNE DE VIDANGE OUVERTE | F33: B10T & 15T | G33: 30min | H33: jour
D34: VENTILATION DU CONDENSAT | F34: B10T & 15T | G34: 30min | H34: jour
D35: PRENEZ UN ÉCHANTILLON D'EAU ET SOUMETTRE AU LABORATOIRE POUR L'ANALYSE | F35: B10T & 15T | G35: 30min | H35: jour
... D37: NETTOYER LE BRÛLEUR | F37: B10T & 15T | G37: 30min | H37: hebdo
D38: COOLING PLANT
D39: CHECK | F39: Unité | G39: temps planifié | H39: Frequence | I39: lundi | J39: mardi | K39: mercredi | L39: jeudi | M39: vendredi | N39: samedi | O39: dimanche
D40: INSPECTER L'APPAREIL (VÉRIFIER LE BRUIT ET LES VIBRATIONS) | F40: S4 & 5 | G40: 20min | H40: jour
D41: VÉRIFIEZ LE NIVEAU D'HUILE DANS LE SÉPARATEUR (DOIT AU MOINS VOIR L'HUILE DANS LA VITRE) | F41: S4 & 5 | G41: 10min | H41: jour
D42: VÉRIFIEZ LA CHARGE DE RÉFRIGÉRANT (NH3 DOIT TOUJOURS ÊTRE AU-DESSUS DE LA MARQUE INFÉRIEURE) | F42: S4 & 5 | G42: 10min | H42: jour
D43: INSPECTER SI IL Y'A DES FUITES, GAZ, HUILE, EAU | F43: S4 & 5 | G43: 20min | H43: jour
D44: VÉRIFIER LE JOINT MÉCANIQUE (SI LA FUITE DÉPASSE 7 GOUTTES PAR MINUTE, REMPLACER LE JOINT.) | F44: S4 & 5 | G44: 20min | H44: jour
D45: VÉRIFIER LES FUITES SUR LES POMPES À GLYCOL | F45: S4 & 5 | G45: 20min | H45: jour
D46: VÉRIFIEZ LE SYSTÈME DE CONTRÔLE POUR LES ALARMES / ARRÊT (LES 5 DERNIERS AU MOINS) | F46: S4 & 5 | G46: 10min | H46: jour
D47: VÉRIFIER LE GLYCOL À PHE SABROE FLOWRATE ET NETTOYER LE FILTRE GLYCOL SI NÉCESSAIRE | F47: S4 & 5 | G47: 20min | H47: jour
D48: VÉRIFIEZ LE NIVEAU DE GLYCOL (LA SOMME DU RÉSERVOIR CHAUD ET FROID NE DOIT PAS ÊTRE INFÉRIEURE À 86%) | F48: S4 & 5 | G48: 20min | H48: jour
D49: CO2 PLANT
...

Sheet Suivi Plan Maint 25
B3: ANNEE 2025
B4: Mois | C4: JANVIER | H4: FÉVRIER | L4: MARS | P4: AVRIL | T4: MAI | Y4: JUIN | AC4: JUILLET | AH4: AOÛT | AL4: SEPTEMBRE | AP4: OCTOBRE | AU4: NOVEMBRE | AY4: DECEMBRE
B5: Semaine | C5: S1 | D5: S2 | E5: S3 | F5: S4 | G5: S5 | H5: S6 | I5: S7 | J5: S8 | K5: S9 | L5: S10 | M5: S11 | N5: S12 | O5: S13 | P5: S14 | Q5: S15 | R5: S16 | S5: S17 | T5: S18 | U5: S19 | V5: S20 | W5: S21 | X5: S22 | Y5: S23 | Z5: S24 | AA5: S25 | AB5: S26 | AC5: S27 | AD5: S28 | AE5: S29 | AF5: S30 | AG5: S31 | AH5: S32 | AI5: S33 | AJ5: S34 | AK5: S35 | AL5: S36 | AM5: S37 | AN5: S38 | AO5: S39 | AP5: S40 | AQ5: S41 | AR5: S42 | AS5: S43 | AT5: S44 | AU5: S45 | AV5: S46 | AW5: S47 | AX5: S48 | AY5: S49 | AZ5: S50 | BA5: S51 | BB5: S52
A6: Tâches UTILITY | B6: Planifiées Semaine | C6: =COUNTIF('PM 2025'!E9:E270,"0")+COUNTIF('PM 2025'!E9:E270,"1") -> 0 | D6: =COUNTIF('PM 2025'!F9:F270,"0")+COUNTIF('PM 2025'!F9:F270,"1") -> 0 | E6: =COUNTIF('PM 2025'!G9:G270,"0")+COUNTIF('PM 2025'!G9:G270,"1") -> 0 | F6: =COUNTIF('PM 2025'!H9:H270,"0")+COUNTIF('PM 2025'!H9:H270,"1") -> 0 | G6: =COUNTIF('PM 2025'!I9:I270,"0")+COUNTIF('PM 2025'!I9:I270,"1") -> 0 | H6: =COUNTIF('PM 2025'!J9:J270,"0")+COUNTIF('PM 2025'!J9:J270,"1") -> 0 | I6: =COUNTIF('PM 2025'!K9:K270,"0")+COUNTIF('PM 2025'!K9:K270,"1") -> 0 | J6: =COUNTIF('PM 2025'!L9:L270,"0")+COUNTIF('PM 2025'!L9:L270,"1") -> 0 | K6: 12 | L6: =COUNTIF('PM 2025'!N9:N270,"0")+COUNTIF('PM 2025'!N9:N270,"1") -> 0 | M6: =COUNTIF('PM 2025'!O9:O270,"0")+COUNTIF('PM 2025'!O9:O270,"1") -> 0 | N6: 12 | O6: 9 | P6: =COUNTIF('PM 2025'!R9:R270,"0")+COUNTIF('PM 2025'!R9:R270,"1") -> 10 | Q6: =COUNTIF('PM 2025'!S9:S270,"0")+COUNTIF('PM 2025'!S9:S270,"1") -> 0 | R6: 9 | S6: 7 | T6: 9 | U6: 9 | V6: 5 | W6: 10 | X6: 11 | Y6: 11 | Z6: 16 | AA6: 16 | AB6: =COUNTIF('PM 2025'!AD9:AD270,"0")+COUNTIF('PM 2025'!AD9:AD270,"1") -> 0 | AC6: =COUNTIF('PM 2025'!AE9:AE270,"0")+COUNTIF('PM 2025'!AE9:AE270,"1") -> 0 | AD6: =COUNTIF('PM 2025'!AF9:AF270,"0")+COUNTIF('PM 2025'!AF9:AF270,"1") -> 0 | AE6: =COUNTIF('PM 2025'!AG9:AG270,"0")+COUNTIF('PM 2025'!AG9:AG270,"1") -> 0 | AF6: =COUNTIF('PM 2025'!AH9:AH270,"0")+COUNTIF('PM 2025'!AH9:AH270,"1") -> 0 | AG6: =COUNTIF('PM 2025'!AI9:AI270,"0")+COUNTIF('PM 2025'!AI9:AI270,"1") -> 0 | AH6: =COUNTIF('PM 2025'!AJ9:AJ270,"0")+COUNTIF('PM 2025'!AJ9:AJ270,"1") -> 0 | AI6: =COUNTIF('PM 2025'!AK9:AK270,"0")+COUNTIF('PM 2025'!AK9:AK270,"1") -> 0 | ... AO6: =COUNTIF('PM 2025'!AQ9:AQ270,"0")+COUNTIF('PM 2025'!AQ9:AQ270,"1") -> 0
B7: Réalisées Semaine | C7: =COUNTIF('PM 2025'!E9:E270,"1") -> 0 | D7: =COUNTIF('PM 2025'!F9:F270,"1") -> 0 | E7: =COUNTIF('PM 2025'!G9:G270,"1") -> 0 | F7: =COUNTIF('PM 2025'!H9:H270,"1") -> 0 | G7: =COUNTIF('PM 2025'!I9:I270,"1") -> 0 | H7: =COUNTIF('PM 2025'!J9:J270,"1") -> 0 | I7: =COUNTIF('PM 2025'!K9:K270,"1") -> 0 | J7: =COUNTIF('PM 2025'!L9:L270,"1") -> 0 | K7: 11 | L7: =COUNTIF('PM 2025'!N9:N270,"1") -> 0 | M7: =COUNTIF('PM 2025'!O9:O270,"1") -> 0 | N7: 12 | O7: 9 | P7: =COUNTIF('PM 2025'!R9:R270,"1") -> 8 | Q7: =COUNTIF('PM 2025'!S9:S270,"1") -> 0 | R7: 9 | S7: 6 | T7: 9 | U7: 9 | V7: 5 | W7: 10 | X7: 11 | Y7: 11 | Z7: 16 | AA7: 16 | AB7: =COUNTIF('PM 2025'!AD9:AD270,"1") -> 0 | AC7: =COUNTIF('PM 2025'!AE9:AE270,"1") -> 0 | AD7: =COUNTIF('PM 2025'!AF9:AF270,"1") -> 0 | AE7: =COUNTIF('PM 2025'!AG9:AG270,"1") -> 0 | AF7: =COUNTIF('PM 2025'!AH9:AH270,"1") -> 0 | AG7: =COUNTIF('PM 2025'!AI9:AI270,"1") -> 0 | AH7: =COUNTIF('PM 2025'!AJ9:AJ270,"1") -> 0 | AI7: =COUNTIF('PM 2025'!AK9:AK270,"1") -> 0 | ... AO7: =COUNTIF('PM 2025'!AQ9:AQ270,"1") -> 0
B8: % Exécution Semaine | C8: =C7/C6 -> #DIV/0! | D8: =D7/D6 -> #DIV/0! | E8: =E7/E6 -> #DIV/0! | F8: =F7/F6 -> #DIV/0! | G8: =G7/G6 -> #DIV/0! | H8: =H7/H6 -> #DIV/0! | I8: =I7/I6 -> #DIV/0! | J8: =J7/J6 -> #DIV/0! | ... BB8: =BB7/BB6 -> #DIV/0!
B9: Planifiées Mois | C9: =SUM(C6:G6) -> 0 | H9: =SUM(H6:K6) -> 12 | L9: =SUM(L6:O6) -> 21 | P9: =SUM(P6:S6) -> 26 | T9: =SUM(T6:X6) -> 44 | Y9: =SUM(Y6:AB6) -> 43 | AC9: =SUM(AC6:AG6) -> 0 | AH9: =SUM(AH6:AK6) -> 0 | AL9: =SUM(AL6:AO6) -> 0 | AP9: =SUM(AP6:AT6) -> 0 | AU9: =SUM(AU6:AX6) -> 0 | AY9: =SUM(AY6:BB6) -> 0
B10: Réalisées Mois | C10: =SUM(C7:G7) -> 0 | H10: =SUM(H7:K7) -> 11 | L10: =SUM(L7:O7) -> 21 | P10: =SUM(P7:S7) -> 23 | T10: =SUM(T7:X7) -> 44 | Y10: =SUM(Y7:AB7) -> 43 | AC10: =SUM(AC7:AG7) -> 0 | AH10: =SUM(AH7:AK7) -> 0 | AL10: =SUM(AL7:AO7) -> 0 | AP10: =SUM(AP7:AT7) -> 0 | AU10: =SUM(AU7:AX7) -> 0 | AY10: =SUM(AY7:BB7) -> 0
B11: % Exécution Mois | C11: =+C10/C9 -> #DIV/0! | H11: =+H10/H9 -> 0.91666667 | L11: =+L10/L9 -> 1 | P11: =+P10/P9 -> 0.88461538 | T11: =+T10/T9 -> 1 | Y11: =+Y10/Y9 -> 1 | AC11: =+AC10/AC9 -> #DIV/0! | AH11: =+AH10/AH9 -> #DIV/0! | AL11: =+AL10/AL9 -> #DIV/0! | AP11: =+AP10/AP9 -> #DIV/0! | AU11: =+AU10/AU9 -> #DIV/0! | AY11: =+AY10/AY9 -> #DIV/0!
B12: Cancelled PMs | C12: =COUNTIF('PM 2025'!E19:H270,"c")/1000 -> 0 | D12: =COUNTIF('PM 2025'!F19:F276,"0")+COUNTIF('PM 2025'!F19:F276,"1") -> 0 | E12: =COUNTIF('PM 2025'!G19:G276,"0")+COUNTIF('PM 2025'!G19:G276,"1") -> 0 | G12: =COUNTIF('PM 2025'!H19:H276,"0")+COUNTIF('PM 2025'!H19:H276,"1") -> 0 | H12: =COUNTIF('PM 2025'!J19:M270,"c")/1000 -> 0 | I12: =COUNTIF('PM 2025'!K19:K276,"0")+COUNTIF('PM 2025'!K19:K276,"1") -> 0 | J12: =COUNTIF('PM 2025'!L19:L276,"0")+COUNTIF('PM 2025'!L19:L276,"1") -> 0 | K12: =COUNTIF('PM 2025'!#REF!,"0")+COUNTIF('PM 2025'!#REF!,"1") -> #REF! | L12: =COUNTIF('PM 2025'!N19:Q270,"c")/1000 -> 0 | M12: =COUNTIF('PM 2025'!O19:O276,"0")+COUNTIF('PM 2025'!O19:O276,"1") -> 0 | N12: =COUNTIF('PM 2025'!P19:P276,"0")+COUNTIF('PM 2025'!P19:P276,"1") -> 0 | O12: =COUNTIF('PM 2025'!Q19:Q276,"0")+COUNTIF('PM 2025'!Q19:Q276,"1") -> 0 | P12: =COUNTIF('PM 2025'!R19:U270,"c")/1000 -> 0.002 | Q12: =COUNTIF('PM 2025'!S19:S276,"0")+COUNTIF('PM 2025'!S19:S276,"1") -> 0 | R12: =COUNTIF('PM 2025'!T19:T276,"0")+COUNTIF('PM 2025'!T19:T276,"1") -> 0 | S12: =COUNTIF('PM 2025'!U19:U276,"0")+COUNTIF('PM 2025'!U19:U276,"1") -> 0 | T12: =COUNTIF('PM 2025'!V19:Z270,"c")/1000 -> 0 | U12: =COUNTIF('PM 2025'!W19:W276,"0")+COUNTIF('PM 2025'!W19:W276,"1") -> 0 | V12: =COUNTIF('PM 2025'!X19:X276,"0")+COUNTIF('PM 2025'!X19:X276,"1") -> 0 | X12: =COUNTIF('PM 2025'!Z19:Z276,"0")+COUNTIF('PM 2025'!Z19:Z276,"1") -> 0 | Y12: =COUNTIF('PM 2025'!AA19:AD270,"c")/1000 -> 0 | Z12: =COUNTIF('PM 2025'!AB19:AB276,"0")+COUNTIF('PM 2025'!AB19:AB276,"1") -> 4 | AA12: =COUNTIF('PM 2025'!AC19:AC276,"0")+COUNTIF('PM 2025'!AC19:AC276,"1") -> 0 | AB12: =COUNTIF('PM 2025'!AD19:AD276,"0")+COUNTIF('PM 2025'!AD19:AD276,"1") -> 0 | AC12: =COUNTIF('PM 2025'!AE19:AI270,"c")/1000 -> 0 | AD12: =COUNTIF('PM 2025'!AF19:AF276,"0")+COUNTIF('PM 2025'!AF19:AF276,"1") -> 0 | AE12: =COUNTIF('PM 2025'!AG19:AG276,"0")+COUNTIF('PM 2025'!AG19:AG276,"1") -> 0 | AG12: =COUNTIF('PM 2025'!AI19:AI276,"0")+COUNTIF('PM 2025'!AI19:AI276,"1") -> 0 | AH12: =COUNTIF('PM 2025'!AJ19:AM270,"c")/1000 -> 0 | AI12: =COUNTIF('PM 2025'!AK19:AK276,"0")+COUNTIF('PM 2025'!AK19:AK276,"1") -> 0 | AJ12: =COUNTIF('PM 2025'!AL19:AL276,"0")+COUNTIF('PM 2025'!AL19:AL276,"1") -> 0 | AK12: =COUNTIF('PM 2025'!#REF!,"0")+COUNTIF('PM 2025'!#REF!,"1") -> #REF! | AL12: =COUNTIF('PM 2025'!AN19:AQ270,"c")/1000 -> 0 | AM12: =COUNTIF('PM 2025'!AO19:AO276,"0")+COUNTIF('PM 2025'!AO19:AO276,"1") -> 0 | AN12: =COUNTIF('PM 2025'!AP19:AP276,"0")+COUNTIF('PM 2025'!AP19:AP276,"1") -> 0 | AO12: =COUNTIF('PM 2025'!AQ19:AQ276,"0")+COUNTIF('PM 2025'!AQ19:AQ276,"1") -> 0 | AP12: =COUNTIF('PM 2025'!AR19:AV270,"c")/1000 -> 0 | AQ12: =COUNTIF('PM 2025'!AS19:AS276,"0")+COUNTIF('PM 2025'!AS19:AS276,"1") -> 0 | AR12: =COUNTIF('PM 2025'!AT19:AT276,"0")+COUNTIF('PM 2025'!AT19:AT276,"1") -> 0 | AT12: =COUNTIF('PM 2025'!AV19:AV276,"0")+COUNTIF('PM 2025'!AV19:AV276,"1") -> 12 | AU12: =COUNTIF('PM 2025'!AW19:AZ270,"c")/1000 -> 0 | AV12: =COUNTIF('PM 2025'!AX19:AX276,"0")+COUNTIF('PM 2025'!AX19:AX276,"1") -> 7 | AW12: =COUNTIF('PM 2025'!AY19:AY276,"0")+COUNTIF('PM 2025'!AY19:AY276,"1") -> 0 | AX12: =COUNTIF('PM 2025'!AZ19:AZ276,"0")+COUNTIF('PM 2025'!AZ19:AZ276,"1") -> 0 | AY12: =COUNTIF('PM 2025'!BA19:BD270,"c")/1000 -> 0 | AZ12: =COUNTIF('PM 2025'!BB19:BB276,"0")+COUNTIF('PM 2025'!BB19:BB276,"1") -> 4 | BA12: =COUNTIF('PM 2025'!BC19:BC276,"0")+COUNTIF('PM 2025'!BC19:BC276,"1") -> 0 | BB12: =COUNTIF('PM 2025'!BD19:BD276,"0")+COUNTIF('PM 2025'!BD19:BD276,"1") -> 0
B13: steam
B14: Mois | C14: JANVIER | H14: FÉVRIER | L14: MARS | P14: AVRIL | T14: MAI | Y14: JUIN | AC14: JUILLET | AH14: AOÛT | AL14: SEPTEMBRE | AP14: OCTOBRE | AU14: NOVEMBRE | AY14: DECEMBRE
B15: Semaine | C15: S1 | D15: S2 | E15: S3 | F15: S4 | G15: S5 | H15: S6 | I15: S7 | J15: S8 | K15: S9 | L15: S10 | M15: S11 | N15: S12 | O15: S13 | P15: S14 | Q15: S15 | R15: S16 | S15: S17 | T15: S18 | U15: S19 | V15: S20 | W15: S21 | X15: S22 | Y15: S23 | Z15: S24 | AA15: S25 | AB15: S26 | AC15: S27 | AD15: S28 | AE15: S29 | AF15: S30 | AG15: S31 | AH15: S32 | AI15: S33 | AJ15: S34 | AK15: S35 | AL15: S36 | AM15: S37 | AN15: S38 | AO15: S39 | AP15: S40 | AQ15: S41 | AR15: S42 | AS15: S43 | AT15: S44 | AU15: S45 | AV15: S46 | AW15: S47 | AX15: S48 | AY15: S49 | AZ15: S50 | BA15: S51 | BB15: S52 | BD15: plant | BE15: Taches | BF15: week1 | BG15: week2 | BH15: week3 | BI15: week4 | BJ15: week5 | BK15: week6 | BL15: week7 | BM15: week8 | BN15: week9 | BO15: week10 | BP15: week11 | BQ15: week12 | BR15: week13 | BS15: week14 | BT15: week15 | BU15: week16 | BV15: week17 | BW15: week18 | BX15: week19 | BY15: week20 | BZ15: week21 | CA15: week22 | CB15: week23 | CC15: week24 | CD15: week25 | CE15: week26 | CF15: week27 | CG15: week28 | CH15: week29 | CI15: week30 | CJ15: week31 | CK15: week32 | CL15: week33 | CM15: week34 | CN15: week35 | CO15: week36 | CP15: week37 | CQ15: week38 | CR15: week39 | CS15: week40 | CT15: week41 | CU15: week42 | CV15: week43 | CW15: week44 | CX15: week45 | CY15: week46 | CZ15: week47 | DA15: week48
A16: Boiler | B16: Planifiées Semaine | C16: =COUNTIF('PM 2025'!E9:E78,"0")+COUNTIF('PM 2025'!E9:E78,"1") -> 0 | D16: =COUNTIF('PM 2025'!F9:F78,"0")+COUNTIF('PM 2025'!F9:F78,"1") -> 0 | E16: =COUNTIF('PM 2025'!G9:G78,"0")+COUNTIF('PM 2025'!G9:G78,"1") -> 0 | G16: =COUNTIF('PM 2025'!H9:H78,"0")+COUNTIF('PM 2025'!H9:H78,"1") -> 0 | BD16: Boiler | BE16: Planifiées Semaine | BF16: =C16 -> 0 | BG16: =D16 -> 0 | BH16: =E16 -> 0 | BI16: =G16 -> 0 | BJ16: =H16 -> 0 | BK16: =I16 -> 0 | BL16: =J16 -> 0 | BM16: =K16 -> 0 | BN16: =L16 -> 0 | BO16: =M16 -> 0 | BP16: =N16 -> 0 | ... BX16: =V16 -> 0 | BY16: =X16 -> 0 | BZ16: =Y16 -> 0 | CA16: =Z16 -> 0 | CB16: =AA16 -> 0 | CC16: =AB16 -> 0 | CD16: =AC16 -> 0 | CE16: =AD16 -> 0 | CF16: =AE16 -> 0 | CG16: =AG16 -> 0 | CH16: =AH16 -> 0 | CI16: =AI16 -> 0 | CJ16: =AJ16 -> 0 | CK16: =AK16 -> 0 | CL16: =AL16 -> 0 | CM16: =AM16 -> 0 | CN16: =AN16 -> 0 | ... CR16: =AR16 -> 0 | CS16: =AT16 -> 0 | CT16: =AU16 -> 0 | CU16: =AV16 -> 0 | CV16: =AW16 -> 0 | CW16: =AX16 -> 0 | CX16: =AY16 -> 0 | CY16: =AZ16 -> 0 | CZ16: =BA16 -> 0 | DA16: =BB16 -> 0
B17: Réalisées Semaine | C17: =COUNTIF('PM 2025'!E9:E78,"1") -> 0 | D17: =COUNTIF('PM 2025'!F9:F78,"1") -> 0 | E17: =COUNTIF('PM 2025'!G9:G78,"1") -> 0 | G17: =COUNTIF('PM 2025'!H9:H78,"1") -> 0 | BD17: Boiler | BE17: Réalisées Semaine | BF17: =C17 -> 0 | BG17: =D17 -> 0 | BH17: =E17 -> 0 | BI17: =G17 -> 0 | BJ17: =H17 -> 0 | BK17: =I17 -> 0 | BL17: =J17 -> 0 | BM17: =K17 -> 0 | BN17: =L17 -> 0 | BO17: =M17 -> 0 | BP17: =N17 -> 0 | ... BX17: =V17 -> 0 | BY17: =X17 -> 0 | BZ17: =Y17 -> 0 | CA17: =Z17 -> 0 | CB17: =AA17 -> 0 | CC17: =AB17 -> 0 | CD17: =AC17 -> 0 | CE17: =AD17 -> 0 | CF17: =AE17 -> 0 | CG17: =AG17 -> 0 | CH17: =AH17 -> 0 | CI17: =AI17 -> 0 | CJ17: =AJ17 -> 0 | CK17: =AK17 -> 0 | CL17: =AL17 -> 0 | CM17: =AM17 -> 0 | CN17: =AN17 -> 0 | ... CR17: =AR17 -> 0 | CS17: =AT17 -> 0 | CT17: =AU17 -> 0 | CU17: =AV17 -> 0 | CV17: =AW17 -> 0 | CW17: =AX17 -> 0 | CX17: =AY17 -> 0 | CY17: =AZ17 -> 0 | CZ17: =BA17 -> 0 | DA17: =BB17 -> 0
B18: % Exécution Semaine | C18: =C17/C16 -> #DIV/0! | D18: =D17/D16 -> #DIV/0! | E18: =E17/E16 -> #DIV/0! | G18: =G17/G16 -> #DIV/0! | H18: =H17/H16 -> #DIV/0! | I18: =I17/I16 -> #DIV/0! | J18: =J17/J16 -> #DIV/0! | K18: =K17/K16 -> #DIV/0! | L18: =L17/L16 -> #DIV/0! | M18: =M17/M16 -> #DIV/0! | N18: =N17/N16 -> #DIV/0! | ... V18: =V17/V16 -> #DIV/0! | X18: =X17/X16 -> #DIV/0! | Y18: =Y17/Y16 -> #DIV/0! | Z18: =Z17/Z16 -> #DIV/0! | AA18: =AA17/AA16 -> #DIV/0! | AB18: =AB17/AB16 -> #DIV/0! | AC18: =AC17/AC16 -> #DIV/0! | AD18: =AD17/AD16 -> #DIV/0! | AE18: =AE17/AE16 -> #DIV/0! | AG18: =AG17/AG16 -> #DIV/0! | AH18: =AH17/AH16 -> #DIV/0! | AI18: =AI17/AI16 -> #DIV/0! | AJ18: =AJ17/AJ16 -> #DIV/0! | AK18: =AK17/AK16 -> #DIV/0! | AL18: =AL17/AL16 -> #DIV/0! | AM18: =AM17/AM16 -> #DIV/0! | AN18: =AN17/AN16 -> #DIV/0! | ... AR18: =AR17/AR16 -> #DIV/0! | AT18: =AT17/AT16 -> #DIV/0! | AU18: =AU17/AU16 -> #DIV/0! | AV18: =AV17/AV16 -> #DIV/0! | AW18: =AW17/AW16 -> #DIV/0! | AX18: =AX17/AX16 -> #DIV/0! | AY18: =AY17/AY16 -> #DIV/0! | AZ18: =AZ17/AZ16 -> #DIV/0! | BA18: =BA17/BA16 -> #DIV/0! | BB18: =BB17/BB16 -> #DIV/0! | BD18: Cooling | BE18: Planifiées Semaine | BF18: =C25 -> 0 | BG18: =D25 -> 0 | BH18: =E25 -> 0 | BI18: =G25 -> 0 | BJ18: =H25 -> 0 | BK18: =I25 -> 0 | BL18: =J25 -> 0 | BM18: =K25 -> 0 | BN18: =L25 -> 0 | BO18: =M25 -> 0 | BP18: =N25 -> 0 | ... BX18: =V25 -> 0 | BY18: =X25 -> 0 | BZ18: =Y25 -> 0 | CA18: =Z25 -> 0 | CB18: =AA25 -> 0 | CC18: =AB25 -> 0 | CD18: =AC25 -> 0 | CE18: =AD25 -> 0 | CF18: =AE25 -> 0 | CG18: =AG25 -> 0 | CH18: =AH25 -> 0 | CI18: =AI25 -> 0 | CJ18: =AJ25 -> 0 | CK18: =AK25 -> 0 | CL18: =AL25 -> 0 | CM18: =AM25 -> 0 | CN18: =AN25 -> 0 | ... CR18: =AR25 -> 0 | CS18: =AT25 -> 0 | CT18: =AU25 -> 0 | CU18: =AV25 -> 0 | CV18: =AW25 -> 0 | CW18: =AX25 -> 0 | CX18: =AY25 -> 0 | CY18: =AZ25 -> 0 | CZ18: =BA25 -> 0 | DA18: =BB25 -> 0
B19: Planifiées Mois | C19: =SUM(C16:G16) -> 0 | H19: =SUM(H16:K16) -> 0 | L19: =SUM(L16:O16) -> 0 | P19: =SUM(P16:S16) -> 0 | T19: =SUM(T16:X16) -> 0 | Y19: =SUM(Y16:AB16) -> 0 | AC19: =SUM(AC16:AG16) -> 0 | AH19: =SUM(AH16:AK16) -> 0 | AL19: =SUM(AL16:AO16) -> 0 | AP19: =SUM(AP16:AT16) -> 0 | AU19: =SUM(AU16:AX16) -> 0 | AY19: =SUM(AY16:BB16) -> 0 | BD19: Cooling | BE19: Réalisées Semaine | BF19: =C26 -> 0 | BG19: =D26 -> 0 | BH19: =E26 -> 0 | BI19: =G26 -> 0 | BJ19: =H26 -> 0 | BK19: =I26 -> 0 | BL19: =J26 -> 0 | BM19: =K26 -> 0 | BN19: =L26 -> 0 | BO19: =M26 -> 0 | BP19: =N26 -> 0 | ... BX19: =V26 -> 0 | BY19: =X26 -> 0 | BZ19: =Y26 -> 0 | CA19: =Z26 -> 0 | CB19: =AA26 -> 0 | CC19: =AB26 -> 0 | CD19: =AC26 -> 0 | CE19: =AD26 -> 0 | CF19: =AE26 -> 0 | CG19: =AG26 -> 0 | CH19: =AH26 -> 0 | CI19: =AI26 -> 0 | CJ19: =AJ26 -> 0 | CK19: =AK26 -> 0 | CL19: =AL26 -> 0 | CM19: =AM26 -> 0 | CN19: =AN26 -> 0 | ... CR19: =AR26 -> 0 | CS19: =AT26 -> 0 | CT19: =AU26 -> 0 | CU19: =AV26 -> 0 | CV19: =AW26 -> 0 | CW19: =AX26 -> 0 | CX19: =AY26 -> 0 | CY19: =AZ26 -> 0 | CZ19: =BA26 -> 0 | DA19: =BB26 -> 0
B20: Réalisées Mois | C20: =SUM(C17:G17) -> 0 | H20: =SUM(H17:K17) -> 0 | L20: =SUM(L17:O17) -> 0 | P20: =SUM(P17:S17) -> 0 | T20: =SUM(T17:X17) -> 0 | Y20: =SUM(Y17:AB17) -> 0 | AC20: =SUM(AC17:AG17) -> 0 | AH20: =SUM(AH17:AK17) -> 0 | AL20: =SUM(AL17:AO17) -> 0 | AP20: =SUM(AP17:AT17) -> 0 | AU20: =SUM(AU17:AX17) -> 0 | AY20: =SUM(AY17:BB17) -> 0 | BD20: Water | BE20: Planifiées Semaine | BF20: =C35 -> 0 | BG20: =D35 -> 0 | BH20: =E35 -> 0 | BI20: =G35 -> 0 | BJ20: =H35 -> 0 | BK20: =I35 -> 0 | BL20: =J35 -> 0 | BM20: =K35 -> 0 | BN20: =L35 -> 0 | BO20: =M35 -> 0 | BP20: =N35 -> 0 | ... BX20: =V35 -> 0 | BY20: =X35 -> 0 | BZ20: =Y35 -> 0 | CA20: =Z35 -> 0 | CB20: =AA35 -> 0 | CC20: =AB35 -> 0 | CD20: =AC35 -> 0 | CE20: =AD35 -> 0 | CF20: =AE35 -> 0 | CG20: =AG35 -> 0 | CH20: =AH35 -> 0 | CI20: =AI35 -> 0 | CJ20: =AJ35 -> 0 | CK20: =AK35 -> 0 | CL20: =AL35 -> 0 | CM20: =AM35 -> 0 | CN20: =AN35 -> 0 | ... CR20: =AR35 -> 0 | CS20: =AT35 -> 0 | CT20: =AU35 -> 0 | CU20: =AV35 -> 0 | CV20: =AW35 -> 0 | CW20: =AX35 -> 0 | CX20: =AY35 -> 0 | CY20: =AZ35 -> 0 | CZ20: =BA35 -> 0 | DA20: =BB35 -> 0
B21: % Exécution Mois | C21: =+C20/C19 -> #DIV/0! | H21: =+H20/H19 -> #DIV/0! | L21: =+L20/L19 -> #DIV/0! | P21: =+P20/P19 -> #DIV/0! | T21: =+T20/T19 -> #DIV/0! | Y21: =+Y20/Y19 -> #DIV/0! | AC21: =+AC20/AC19 -> #DIV/0! | AH21: =+AH20/AH19 -> #DIV/0! | AL21: =+AL20/AL19 -> #DIV/0! | AP21: =+AP20/AP19 -> #DIV/0! | AU21: =+AU20/AU19 -> #DIV/0! | AY21: =+AY20/AY19 -> #DIV/0! | BD21: Water | BE21: Réalisées Semaine | BF21: =C36 -> 0 | BG21: =D36 -> 0 | BH21: =E36 -> 0 | BI21: =G36 -> 0 | BJ21: =H36 -> 0 | BK21: =I36 -> 0 | BL21: =J36 -> 0 | BM21: =K36 -> 0 | BN21: =L36 -> 0 | BO21: =M36 -> 0 | BP21: =N36 -> 0 | ... BX21: =V36 -> 0 | BY21: =X36 -> 0 | BZ21: =Y36 -> 0 | CA21: =Z36 -> 0 | CB21: =AA36 -> 0 | CC21: =AB36 -> 0 | CD21: =AC36 -> 0 | CE21: =AD36 -> 0 | CF21: =AE36 -> 0 | CG21: =AG36 -> 0 | CH21: =AH36 -> 0 | CI21: =AI36 -> 0 | CJ21: =AJ36 -> 0 | CK21: =AK36 -> 0 | CL21: =AL36 -> 0 | CM21: =AM36 -> 0 | CN21: =AN36 -> 0 | ... CR21: =AR36 -> 0 | CS21: =AT36 -> 0 | CT21: =AU36 -> 0 | CU21: =AV36 -> 0 | CV21: =AW36 -> 0 | CW21: =AX36 -> 0 | CX21: =AY36 -> 0 | CY21: =AZ36 -> 0 | CZ21: =BA36 -> 0 | DA21: =BB36 -> 0
B22: air | BD22: CO2 recovery | BE22: Planifiées Semaine | BF22: =C44 -> 0 | BG22: =D44 -> 0 | BH22: =E44 -> 0 | BI22: =G44 -> 0 | BJ22: =H44 -> 0 | BK22: =I44 -> 0 | BL22: =J44 -> 0 | BM22: =K44 -> 0 | BN22: =L44 -> 0 | BO22: =M44 -> 0 | BP22: =N44 -> 0 | ... BX22: =V44 -> 0 | BY22: =X44 -> 0 | BZ22: =Y44 -> 0 | CA22: =Z44 -> 0 | CB22: =AA44 -> 0 | CC22: =AB44 -> 0 | CD22: =AC44 -> 0 | CE22: =AD44 -> 0 | CF22: =AE44 -> 0 | CG22: =AG44 -> 0 | CH22: =AH44 -> 0 | CI22: =AI44 -> 0 | CJ22: =AJ44 -> 0 | CK22: =AK44 -> 0 | CL22: =AL44 -> 0 | CM22: =AM44 -> 0 | CN22: =AN44 -> 0 | ... CR22: =AR44 -> 0 | CS22: =AT44 -> 0 | CT22: =AU44 -> 0 | CU22: =AV44 -> 0 | CV22: =AW44 -> 0 | CW22: =AX44 -> 0 | CX22: =AY44 -> 0 | CY22: =AZ44 -> 0 | CZ22: =BA44 -> 0 | DA22: =BB44 -> 0
B23: Mois | C23: JANVIER | H23: FÉVRIER | L23: MARS | P23: AVRIL | T23: MAI | Y23: JUIN | AC23: JUILLET | AH23: AOÛT | AL23: SEPTEMBRE | AP23: OCTOBRE | AU23: NOVEMBRE | AY23: DECEMBRE | BD23: CO2 recovery | BE23: Réalisées Semaine | BF23: =C45 -> 0 | BG23: =D45 -> 0 | BH23: =E45 -> 0 | BI23: =G45 -> 0 | BJ23: =H45 -> 0 | BK23: =I45 -> 0 | BL23: =J45 -> 0 | BM23: =K45 -> 0 | BN23: =L45 -> 0 | BO23: =M45 -> 0 | BP23: =N45 -> 0 | ... BX23: =V45 -> 0 | BY23: =X45 -> 0 | BZ23: =Y45 -> 0 | CA23: =Z45 -> 0 | CB23: =AA45 -> 0 | CC23: =AB45 -> 0 | CD23: =AC45 -> 0 | CE23: =AD45 -> 0 | CF23: =AE45 -> 0 | CG23: =AG45 -> 0 | CH23: =AH45 -> 0 | CI23: =AI45 -> 0 | CJ23: =AJ45 -> 0 | CK23: =AK45 -> 0 | CL23: =AL45 -> 0 | CM23: =AM45 -> 0 | CN23: =AN45 -> 0 | ... CR23: =AR45 -> 0 | CS23: =AT45 -> 0 | CT23: =AU45 -> 0 | CU23: =AV45 -> 0 | CV23: =AW45 -> 0 | CW23: =AX45 -> 0 | CX23: =AY45 -> 0 | CY23: =AZ45 -> 0 | CZ23: =BA45 -> 0 | DA23: =BB45 -> 0
B24: Semaine | C24: S1 | D24: S2 | E24: S3 | F24: S4 | G24: S5 | H24: S6 | I24: S7 | J24: S8 | K24: S9 | L24: S10 | M24: S11 | N24: S12 | O24: S13 | P24: S14 | Q24: S15 | R24: S16 | S24: S17 | T24: S18 | U24: S19 | V24: S20 | W24: S21 | X24: S22 | Y24: S23 | Z24: S24 | AA24: S25 | AB24: S26 | AC24: S27 | AD24: S28 | AE24: S29 | AF24: S30 | AG24: S31 | AH24: S32 | AI24: S33 | AJ24: S34 | AK24: S35 | AL24: S36 | AM24: S37 | AN24: S38 | AO24: S39 | AP24: S40 | AQ24: S41 | AR24: S42 | AS24: S43 | AT24: S44 | AU24: S45 | AV24: S46 | AW24: S47 | AX24: S48 | AY24: S49 | AZ24: S50 | BA24: S51 | BB24: S52 | BD24: Air | BE24: Planifiées Semaine | BF24: =C54 -> 0 | BG24: =D54 -> 0 | BH24: =E54 -> 0 | BI24: =G54 -> 0 | BJ24: =H54 -> 0 | BK24: =I54 -> 0 | BL24: =J54 -> 0 | BM24: =K54 -> 0 | BN24: =L54 -> 0 | BO24: =M54 -> 0 | BP24: =N54 -> 0 | ... BX24: =V54 -> 0 | BY24: =X54 -> 0 | BZ24: =Y54 -> 0 | CA24: =Z54 -> 0 | CB24: =AA54 -> 0 | CC24: =AB54 -> 0 | CD24: =AC54 -> 0 | CE24: =AD54 -> 0 | CF24: =AE54 -> 0 | CG24: =AG54 -> 0 | CH24: =AH54 -> 0 | CI24: =AI54 -> 0 | CJ24: =AJ54 -> 0 | CK24: =AK54 -> 0 | CL24: =AL54 -> 0 | CM24: =AM54 -> 0 | CN24: =AN54 -> 0 | ... CR24: =AR54 -> 0 | CS24: =AT54 -> 0 | CT24: =AU54 -> 0 | CU24: =AV54 -> 0 | CV24: =AW54 -> 0 | CW24: =AX54 -> 0 | CX24: =AY54 -> 0 | CY24: =AZ54 -> 0 | CZ24: =BA54 -> 0 | DA24: =BB54 -> 0
A25: Cooling | B25: Planifiées Semaine | C25: =COUNTIF('PM 2025'!E78:E191,"0")+COUNTIF('PM 2025'!E78:E191,"1") -> 0 | D25: =COUNTIF('PM 2025'!F78:F191,"0")+COUNTIF('PM 2025'!F78:F191,"1") -> 0 | E25: =COUNTIF('PM 2025'!G78:G191,"0")+COUNTIF('PM 2025'!G78:G191,"1") -> 0 | G25: =COUNTIF('PM 2025'!H78:H191,"0")+COUNTIF('PM 2025'!H78:H191,"1") -> 0 | BD25: Air | BE25: Réalisées Semaine | BF25: =C55 -> 0 | BG25: =D55 -> 0 | BH25: =E55 -> 0 | BI25: =G55 -> 0 | BJ25: =H55 -> 0 | BK25: =I55 -> 0 | BL25: =J55 -> 0 | BM25: =K55 -> 0 | BN25: =L55 -> 0 | BO25: =M55 -> 0 | BP25: =N55 -> 0 | ... BX25: =V55 -> 0 | BY25: =X55 -> 0 | BZ25: =Y55 -> 0 | CA25: =Z55 -> 0 | CB25: =AA55 -> 0 | CC25: =AB55 -> 0 | CD25: =AC55 -> 0 | CE25: =AD55 -> 0 | CF25: =AE55 -> 0 | CG25: =AG55 -> 0 | CH25: =AH55 -> 0 | CI25: =AI55 -> 0 | CJ25: =AJ55 -> 0 | CK25: =AK55 -> 0 | CL25: =AL55 -> 0 | CM25: =AM55 -> 0 | CN25: =AN55 -> 0 | ... CR25: =AR55 -> 0 | CS25: =AT55 -> 0 | CT25: =AU55 -> 0 | CU25: =AV55 -> 0 | CV25: =AW55 -> 0 | CW25: =AX55 -> 0 | CX25: =AY55 -> 0 | CY25: =AZ55 -> 0 | CZ25: =BA55 -> 0 | DA25: =BB55 -> 0
B26: Réalisées Semaine | C26: =COUNTIF('PM 2025'!E78:E191,"1") -> 0 | D26: =COUNTIF('PM 2025'!F78:F191,"1") -> 0 | E26: =COUNTIF('PM 2025'!G78:G191,"1") -> 0 | G26: =COUNTIF('PM 2025'!H78:H191,"1") -> 0 | BF26: plant | BG26: (All)
B27: % Exécution Semaine | C27: =C26/C25 -> #DIV/0! | D27: =D26/D25 -> #DIV/0! | E27: =E26/E25 -> #DIV/0! | G27: =G26/G25 -> #DIV/0! | H27: =H26/H25 -> #DIV/0! | I27: =I26/I25 -> #DIV/0! | J27: =J26/J25 -> #DIV/0! | K27: =K26/K25 -> #DIV/0! | L27: =L26/L25 -> #DIV/0! | M27: =M26/M25 -> #DIV/0! | N27: =N26/N25 -> #DIV/0! | ... V27: =V26/V25 -> #DIV/0! | X27: =X26/X25 -> #DIV/0! | Y27: =Y26/Y25 -> #DIV/0! | Z27: =Z26/Z25 -> #DIV/0! | AA27: =AA26/AA25 -> #DIV/0! | AB27: =AB26/AB25 -> #DIV/0! | AC27: =AC26/AC25 -> #DIV/0! | AD27: =AD26/AD25 -> #DIV/0! | AE27: =AE26/AE25 -> #DIV/0! | AG27: =AG26/AG25 -> #DIV/0! | AH27: =AH26/AH25 -> #DIV/0! | AI27: =AI26/AI25 -> #DIV/0! | AJ27: =AJ26/AJ25 -> #DIV/0! | AK27: =AK26/AK25 -> #DIV/0! | AL27: =AL26/AL25 -> #DIV/0! | AM27: =AM26/AM25 -> #DIV/0! | AN27: =AN26/AN25 -> #DIV/0! | ... AR27: =AR26/AR25 -> #DIV/0! | AT27: =AT26/AT25 -> #DIV/0! | AU27: =AU26/AU25 -> #DIV/0! | AV27: =AV26/AV25 -> #DIV/0! | AW27: =AW26/AW25 -> #DIV/0! | AX27: =AX26/AX25 -> #DIV/0! | AY27: =AY26/AY25 -> #DIV/0! | AZ27: =AZ26/AZ25 -> #DIV/0! | BA27: =BA26/BA25 -> #DIV/0! | BB27: =BB26/BB25 -> #DIV/0!
B28: Planifiées Mois | C28: =SUM(C25:G25) -> 0 | H28: =SUM(H25:K25) -> 0 | L28: =SUM(L25:O25) -> 0 | P28: =SUM(P25:S25) -> 0 | T28: =SUM(T25:X25) -> 0 | Y28: =SUM(Y25:AB25) -> 0 | AC28: =SUM(AC25:AG25) -> 0 | AH28: =SUM(AH25:AK25) -> 0 | AL28: =SUM(AL25:AO25) -> 0 | AP28: =SUM(AP25:AT25) -> 0 | AU28: =SUM(AU25:AX25) -> 0 | AY28: =SUM(AY25:BB25) -> 0 | BF28: Row Labels | BG28: Sum of week42
B29: Réalisées Mois | C29: =SUM(C26:G26) -> 0 | H29: =SUM(H26:K26) -> 0 | L29: =SUM(L26:O26) -> 0 | P29: =SUM(P26:S26) -> 0 | T29: =SUM(T26:X26) -> 0 | Y29: =SUM(Y26:AB26) -> 0 | AC29: =SUM(AC26:AG26) -> 0 | AH29: =SUM(AH26:AK26) -> 0 | AL29: =SUM(AL26:AO26) -> 0 | AP29: =SUM(AP26:AT26) -> 0 | AU29: =SUM(AU26:AX26) -> 0 | AY29: =SUM(AY26:BB26) -> 0 | BF29: Planifiées Semaine | BG29: 47
B30: % Exécution Mois | C30: =+C29/C28 -> #DIV/0! | H30: =+H29/H28 -> #DIV/0! | L30: =+L29/L28 -> #DIV/0! | P30: =+P29/P28 -> #DIV/0! | T30: =+T29/T28 -> #DIV/0! | Y30: =+Y29/Y28 -> #DIV/0! | AC30: =+AC29/AC28 -> #DIV/0! | AH30: =+AH29/AH28 -> #DIV/0! | AL30: =+AL29/AL28 -> #DIV/0! | AP30: =+AP29/AP28 -> #DIV/0! | AU30: =+AU29/AU28 -> #DIV/0! | AY30: =+AY29/AY28 -> #DIV/0! | BF30: Réalisées Semaine | BG30: 46
BF31: Grand Total | BG31: 93
B32: co2
B33: Mois | C33: JANVIER | H33: FÉVRIER | L33: MARS | P33: AVRIL | T33: MAI | Y33: JUIN | AC33: JUILLET | AH33: AOÛT | AL33: SEPTEMBRE | AP33: OCTOBRE | AU33: NOVEMBRE | AY33: DECEMBRE
B34: Semaine | C34: S1 | D34: S2 | E34: S3 | F34: S4 | G34: S5 | H34: S6 | I34: S7 | J34: S8 | K34: S9 | L34: S10 | M34: S11 | N34: S12 | O34: S13 | P34: S14 | Q34: S15 | R34: S16 | S34: S17 | T34: S18 | U34: S19 | V34: S20 | W34: S21 | X34: S22 | Y34: S23 | Z34: S24 | AA34: S25 | AB34: S26 | AC34: S27 | AD34: S28 | AE34: S29 | AF34: S30 | AG34: S31 | AH34: S32 | AI34: S33 | AJ34: S34 | AK34: S35 | AL34: S36 | AM34: S37 | AN34: S38 | AO34: S39 | AP34: S40 | AQ34: S41 | AR34: S42 | AS34: S43 | AT34: S44 | AU34: S45 | AV34: S46 | AW34: S47 | AX34: S48 | AY34: S49 | AZ34: S50 | BA34: S51 | BB34: S52
A35: Water | B35: Planifiées Semaine | C35: =COUNTIF('PM 2025'!E192:E193,"0")+COUNTIF('PM 2025'!E192:E193,"1") -> 0 | D35: =COUNTIF('PM 2025'!F192:F193,"0")+COUNTIF('PM 2025'!F192:F193,"1") -> 0 | E35: =COUNTIF('PM 2025'!G192:G193,"0")+COUNTIF('PM 2025'!G192:G193,"1") -> 0 | G35: =COUNTIF('PM 2025'!H192:H193,"0")+COUNTIF('PM 2025'!H192:H193,"1") -> 0
B36: Réalisées Semaine | C36: =COUNTIF('PM 2025'!E192:E193,"1") -> 0 | D36: =COUNTIF('PM 2025'!F192:F193,"1") -> 0 | E36: =COUNTIF('PM 2025'!G192:G193,"1") -> 0 | G36: =COUNTIF('PM 2025'!H192:H193,"1") -> 0
B37: % Exécution Semaine | C37: =C36/C35 -> #DIV/0! | D37: =D36/D35 -> #DIV/0! | E37: =E36/E35 -> #DIV/0! | G37: =G36/G35 -> #DIV/0! | H37: =H36/H35 -> #DIV/0! | I37: =I36/I35 -> #DIV/0! | J37: =J36/J35 -> #DIV/0! | K37: =K36/K35 -> #DIV/0! | L37: =L36/L35 -> #DIV/0! | M37: =M36/M35 -> #DIV/0! | N37: =N36/N35 -> #DIV/0! | ... V37: =V36/V35 -> #DIV/0! | X37: =X36/X35 -> #DIV/0! | Y37: =Y36/Y35 -> #DIV/0! | Z37: =Z36/Z35 -> #DIV/0! | AA37: =AA36/AA35 -> #DIV/0! | AB37: =AB36/AB35 -> #DIV/0! | AC37: =AC36/AC35 -> #DIV/0! | AD37: =AD36/AD35 -> #DIV/0! | AE37: =AE36/AE35 -> #DIV/0! | AG37: =AG36/AG35 -> #DIV/0! | AH37: =AH36/AH35 -> #DIV/0! | AI37: =AI36/AI35 -> #DIV/0! | AJ37: =AJ36/AJ35 -> #DIV/0! | AK37: =AK36/AK35 -> #DIV/0! | AL37: =AL36/AL35 -> #DIV/0! | AM37: =AM36/AM35 -> #DIV/0! | AN37: =AN36/AN35 -> #DIV/0! | ... AR37: =AR36/AR35 -> #DIV/0! | AT37: =AT36/AT35 -> #DIV/0! | AU37: =AU36/AU35 -> #DIV/0! | AV37: =AV36/AV35 -> #DIV/0! | AW37: =AW36/AW35 -> #DIV/0! | AX37: =AX36/AX35 -> #DIV/0! | AY37: =AY36/AY35 -> #DIV/0! | AZ37: =AZ36/AZ35 -> #DIV/0! | BA37: =BA36/BA35 -> #DIV/0! | BB37: =BB36/BB35 -> #DIV/0!
B38: Planifiées Mois | C38: =SUM(C35:G35) -> 0 | H38: =SUM(H35:K35) -> 0 | L38: =SUM(L35:O35) -> 0 | P38: =SUM(P35:S35) -> 0 | T38: =SUM(T35:X35) -> 0 | Y38: =SUM(Y35:AB35) -> 0 | AC38: =SUM(AC35:AG35) -> 0 | AH38: =SUM(AH35:AK35) -> 0 | AL38: =SUM(AL35:AO35) -> 0 | AP38: =SUM(AP35:AT35) -> 0 | AU38: =SUM(AU35:AX35) -> 0 | AY38: =SUM(AY35:BB35) -> 0
B39: Réalisées Mois | C39: =SUM(C36:G36) -> 0 | H39: =SUM(H36:K36) -> 0 | L39: =SUM(L36:O36) -> 0 | P39: =SUM(P36:S36) -> 0 | T39: =SUM(T36:X36) -> 0 | Y39: =SUM(Y36:AB36) -> 0 | AC39: =SUM(AC36:AG36) -> 0 | AH39: =SUM(AH36:AK36) -> 0 | AL39: =SUM(AL36:AO36) -> 0 | AP39: =SUM(AP36:AT36) -> 0 | AU39: =SUM(AU36:AX36) -> 0 | AY39: =SUM(AY36:BB36) -> 0
B40: % Exécution Mois | C40: =+C39/C38 -> #DIV/0! | H40: =+H39/H38 -> #DIV/0! | L40: =+L39/L38 -> #DIV/0! | P40: =+P39/P38 -> #DIV/0! | T40: =+T39/T38 -> #DIV/0! | Y40: =+Y39/Y38 -> #DIV/0! | AC40: =+AC39/AC38 -> #DIV/0! | AH40: =+AH39/AH38 -> #DIV/0! | AL40: =+AL39/AL38 -> #DIV/0! | AP40: =+AP39/AP38 -> #DIV/0! | AU40: =+AU39/AU38 -> #DIV/0! | AY40: =+AY39/AY38 -> #DIV/0!
B41: water
B42: Mois | C42: JANVIER | H42: FÉVRIER | L42: MARS | P42: AVRIL | T42: MAI | Y42: JUIN | AC42: JUILLET | AH42: AOÛT | AL42: SEPTEMBRE | AP42: OCTOBRE | AU42: NOVEMBRE | AY42: DECEMBRE
...

Sheet Plan de maintenance ST
B2: Equipements | C2: Running Hours | D2: Maintenance(Sous traitant) | E2: Prescription maintenance du constructeur | F2: Janvier | G2: Fevrier | H2: Mars | I2: Avril | J2: Mai | K2: Juin | L2: Juillet | M2: Aout | N2: Septembre | O2: Octobre | P2: Novembre | Q2: Decembre
A3: AIR | B3: Comp 1(ZT 90) | C3: 32232 | D3: CAMCI | E3: 16000
B4: Comp 2(ZT 75) | C4: 65797 | D4: CAMCI | E4: Over all
B5: Comp 3(ZT 75) | C5: 21745 | D5: CAMCI | E5: Over all
A6: BOILER | B6: 15T Burner | C6: 39377 | D6: BOSCH | E6: Chaque 12 mois
B7: 10T Burner | C7: 36926 | D7: BOSCH
A8: COOLING | B8: SABROE 4 | C8: 10564 | D8: JOHNSON CONTROLS | E8: 10000
B9: SABROE 5 | C9: 10585 | D9: JOHNSON CONTROLS
B10: SABROE 6 | C10: 14269 | D10: JOHNSON CONTROLS
B11: SABROE 7 | C11: 18673 | D11: JOHNSON CONTROLS
B12: SABROE 8 | C12: 8288 | D12: JOHNSON CONTROLS
A13: CO2 | B13: Comp1 | C13: 6706 | D13: PENTAIR | E13: 8000
B14: Comp2 | C14: 9601 | D14: PENTAIR | E14: 8000
B15: Cooling Compressor | C15: 34157 | D15: PENTAIR | E15: 8001
E17: Remarques
E18: Maintenance annuelle chaudière faite du 12/02/2025 au 23/02/2025

Sheet Plan de maintenance ST (2)
C2: Equipements | D2: Running Hours | E2: Maintenance(Sous traitant) | F2: Service Done | G2: Remark
B3: AIR | C3: Comp 1(ZT 90) | D3: 32232 | E3: CAMCI | F3: / | G3: /
C4: Comp 2(ZT 75) | D4: 65797 | E4: CAMCI | F4: / | G4: /
C5: Comp 3(ZT 75) | D5: 21745 | E5: CAMCI | F5: / | G5: /
B6: BOILER | C6: 15T Burner | D6: 39377 | E6: BOSCH | F6: Overhaul to 11.02.2025 to 24.02.2025 | G6: 1. We recommend urgent replacement of 15T Boiler shaft assembly. 2. We recommend proper dosage of quality chemical 3. Malfunctioning air pressure switch. 4. Faulty safety relieve valve opened at 10.5bar instead of 13.1bar
C7: 10T Burner | D7: 36926 | E7: BOSCH
B8: COOLING | C8: SABROE 4 | D8: 10564 | E8: JOHNSON CONTROLS | F8: Overhaul SABROE SCREW COMPRESSORS_x000B_18th – 27th March, 2025
C9: SABROE 5 | D9: 10585 | E9: JOHNSON CONTROLS
C10: SABROE 6 | D10: 14269 | E10: JOHNSON CONTROLS
C11: SABROE 7 | D11: 18673 | E11: JOHNSON CONTROLS
C12: SABROE 8 | D12: 8288 | E12: JOHNSON CONTROLS
B13: CO2 | C13: Comp1 | D13: 6706 | E13: PENTAIR | F13: / | G13: /
C14: Comp2 | D14: 9601 | E14: PENTAIR | F14: / | G14: /
C15: Cooling Compressor | D15: 34157 | E15: PENTAIR | F15: / | G15: /
F17: Remarques
F18: Maintenance annuelle chaudière faite du 12/02/2025 au 23/02/2025

Sheet week  MP
N4: Department Energy
A6: Week Maintenance Preventive Program utilities recap
A7: Zone | C7: Travaux | D7: Périodicité | E7: Temps | G7: Check List | O7: Rapport
A8: equipements | C8: activités | E8: temps planifié | F8: personnel | G8: L | H8: M | I8: M | J8: J | K8: V | L8: S | M8: D | N8: Resultat | O8: Ordre SAP | P8: Observation | Q8: Temps réalisé | R8: Commentaires
B9: 2 | C9: verifier les tensions des moteurs des ventilateurs | D9: MENS
B10: 2 | C10: verifier les arbres des ventilatteurs | D10: MENS
B11: 2 | C11: graisser les roulements des ventilateurs | D11: MENS
A12: Condenseur BAC 8 | B12: 1 | C12: Verifier l'abscence de fuites sur les pompes à eau et sur l'installation ammoniacque | D12: HEBDO
B13: 2 | C13: vidange de déconcentration du Bac | D13: HEBDO
B14: 2 | C14: Changer l'eau et nettoyer l'intérieur du condenseur | D14: MENS
B15: 2 | C15: Verifier les pulvérisateurs | D15: MENS
B16: 2 | C16: verifier les tensions des courroies | D16: MENS
B17: 2 | C17: verifier les tensions des moteurs des ventilateurs | D17: MENS
B18: 2 | C18: verifier les arbres des ventilatteurs | D18: MENS
B19: 2 | C19: graisser les roulements des ventilateurs | D19: MENS
A20: Pompes glycol Warmer | B20: 4 | C20: Verifier l'alignement du moteur (Glycol pump) | D20: SEME
B21: 2 | C21: Nettoyer les crépines à liquide (glycol) | D21: MENS
B22: 4 | C22: Verifier l'accouplement (Glycol pump) (SABROE 4,5,6,7,8) | D22: SEME
A23: Pompes glycol Primary | B23: 4 | C23: Verifier l'alignement du moteur (Glycol pump) | D23: SEME
B24: 2 | C24: Nettoyer les crépines à liquide (glycol) | D24: MENS
B25: 4 | C25: Verifier l'accouplement (Glycol pump) (SABROE 4,5,6,7,8) | D25: SEME
A26: Echangeurs 4 | B26: 1 | C26: Verifier les distances entres plaques des echangeurs | D26: TRIM
B27: 2 | C27: Purger l'echangeur | D27: MENS
B28: 3 | C28: Verifier le fonctionnement des débitmetres et des sondes de températures | D28: MENS
A29: Boiler 15T BOSCH | B29: 2 | C29: Nettoyer la coupelle rotative du bruleur | D29: HEBDO | F29: Mecanicien
B30: 2 | C30: Si vous fonctionnez au gazoil, veuillez nettoyez les filtres | D30: TRIM | F30: Mecanicien
B31: 1 | C31: Si vous fonctionnez au gazoil verifier toutes les connections electriques, nettoyer le gicleur de gazoil | D31: TRIM | F31: Mecanicien
B32: 2 | C32: Nettoyer Verifier la photocellule | D32: TRIM | F32: Mecanicien
B33: 2 | C33: Vérifier le fonctionnement de la vanne de regulation d'eau | D33: TRIM | F33: Mecanicien
A34: Boiler 10T BOSCH | B34: 2 | C34: Nettoyer la coupelle rotative du bruleur | D34: HEBDO | F34: Mecanicien
B35: 2 | C35: Si vous fonctionnez au gazoil, veuillez nettoyez les filtres | D35: TRIM | F35: Mecanicien
B36: 1 | C36: Si vous fonctionnez au gazoil verifier toutes les connections electriques, nettoyer le gicleur de gazoil | D36: TRIM | F36: Mecanicien
B37: 2 | C37: Nettoyer Verifier la photocellule | D37: TRIM | F37: Mecanicien
B38: 2 | C38: Vérifier le fonctionnement de la vanne de regulation d'eau | D38: TRIM | F38: Mecanicien
A39: Boiler 10T LOOS | B39: 2 | C39: Nettoyer la coupelle rotative du bruleur | D39: HEBDO | F39: Mecanicien
B40: 2 | C40: Si vous fonctionnez au gazoil, veuillez nettoyez les filtres | D40: TRIM | F40: Mecanicien
B41: 1 | C41: Si vous fonctionnez au gazoil verifier toutes les connections electriques, nettoyer le gicleur de gazoil | D41: TRIM | F41: Mecanicien
B42: 2 | C42: Nettoyer Verifier la photocellule | D42: TRIM | F42: Mecanicien
B43: 2 | C43: Vérifier le fonctionnement de la vanne de regulation d'eau | D43: TRIM | F43: Mecanicien
A44: Headers | B44: 3 | C44: Nettoyer tous les filtres et Rincage de la soupape de sécurité par essai ( Line4/Line5/Line6/Syroperie/Brassage) | D44: TRIM | F44: Mecanicien
...
